Workbook

Sheet Indice General
B1: Subsecretaría de Previsión Social Dirección de Estudios Previsionales
B9: Informe trimestral del Pilar No Contributivo
B10: Trimestre JAS 2023
B12: I. Pago de Beneficios del Pilar No Contributivo
B13: 1. Total de beneficios pagados del Pilar No Contributivo
B14: 2. Pagos Pensión Garantizada Universal (PGU)
B15: 3. Pagos Pensión Básica Solidaria (PBS)
B16: 4. Pagos Aporte Previsional Solidario (APS)
B17: II. Estado de solicitudes
B18: 1. Solicitudes del Pilar No Contributivo a nivel nacional
B19: 2. Solicitudes a nivel regional y comunal
B20: 3. Solicitudes concedidas del Pilar No Contributivo a nivel nacional
... B29: 3. Subsidio a la Cotización de Trabajadores Jóvenes

Sheet I. Beneficios pagados
B1: Subsecretaría de Previsión Social Dirección de Estudios Previsionales
B9: I. Pago de Beneficios del Pilar No Contributivo
B10: Trimestre JAS 2023
B12: 1. Total de beneficios pagados del Pilar No Contributivo
B13: i. Resumen trimestral de beneficios pagados, por tipo de beneficio y sexo
B14: ii. Serie resumen de pagos de beneficios acumulados, por tipo de beneficio
B15: 2. Pagos Pensión Garantizada Universal (PGU)
B16: i. Resumen trimestral de beneficios pagados, por tipo de beneficio y sexo
B17: ii. Serie resumen de pagos de beneficios acumulado, por tipo de beneficio y sexo
B18: 3. Pagos Pensión Básica Solidaria (PBS)
B19: i. Resumen trimestral de beneficios pagados, por tipo de beneficio y sexo
B20: ii. Serie resumen de pagos de beneficios acumulado, por tipo de beneficio y sexo
... B23: ii. Serie resumen de pagos de beneficios acumulado, por tipo de beneficio y sexo

Sheet dinamica pgu
A1: PERIODO | B1: (Varios elementos)
A3: Etiquetas de fila
A4: oct
A5: Suma de PGU_NC_Mujer_n | B5: 322141
A6: Suma de PGU_NC_hombre_N | B6: 109963
A7: Suma de PGU_C_Mujer_N | B7: 686334
A8: Suma de PGU_C_hombre_N | B8: 563950
A9: nov
A10: Suma de PGU_NC_Mujer_n | B10: 327443
A11: Suma de PGU_NC_hombre_N | B11: 121585
A12: Suma de PGU_C_Mujer_N | B12: 704099
A13: Suma de PGU_C_hombre_N | B13: 584193
A14: dic
A15: Suma de PGU_NC_Mujer_n | B15: 329180
A16: Suma de PGU_NC_hombre_N | B16: 125728
A17: Suma de PGU_C_Mujer_N | B17: 717919
A18: Suma de PGU_C_hombre_N | B18: 594890
A22: PERIODO | B22: (Varios elementos)
A24: Etiquetas de fila
A25: oct
A26: Suma de PGU_NC_Mujer_Nom | B26: 62098940
A27: Suma de PGU_NC_hombre_Nom | B27: 21312758
A28: Suma de PGU_C_Mujer_Nom | B28: 1.3198656e+08
A29: Suma de PGU_C_hombre_Nom | B29: 1.0801488e+08
A30: nov
A31: Suma de PGU_NC_Mujer_Nom | B31: 63080933
A32: Suma de PGU_NC_hombre_Nom | B32: 23564397
A33: Suma de PGU_C_Mujer_Nom | B33: 1.3523624e+08
A34: Suma de PGU_C_hombre_Nom | B34: 1.115372e+08
A35: dic
A36: Suma de PGU_NC_Mujer_Nom | B36: 63417032
A37: Suma de PGU_NC_hombre_Nom | B37: 24368203
A38: Suma de PGU_C_Mujer_Nom | B38: 1.3763622e+08
A39: Suma de PGU_C_hombre_Nom | B39: 1.1328694e+08
A43: PERIODO | B43: (Varios elementos)
A45: Etiquetas de fila
A46: oct
A47: Suma de PGU_NC_Mujer_REAL | B47: 61325232
A48: Suma de PGU_NC_hombre_REAL | B48: 21047217
A49: Suma de PGU_C_Mujer_REAL | B49: 1.303421e+08
...

Sheet N PBS
A3: Etiquetas de fila | B3: Promedio de PBS VEJEZ MUJER | C3: Promedio de PBS VEJEZ HOMBRE | D3: Promedio de PBS INVALIDEZ MUJER | E3: Promedio de PBS INVALIDEZ HOMBRE | F3: Promedio de PBS TOTAL MUJER | G3: Promedio de PBS TOTAL HOMBRE
A4: 2008 | B4: 218799.83 | C4: 107682.67 | D4: 108916.5 | E4: 84536 | F4: 327716.33 | G4: 192218.67
A5: 2009 | B5: 262267.25 | C5: 117026.58 | D5: 116205.08 | E5: 86817.667 | F5: 378472.33 | G5: 203844.25
A6: 2010 | B6: 284569.67 | C6: 119969.58 | D6: 125529.75 | E6: 89731.417 | F6: 410099.42 | G6: 209701
A7: 2011 | B7: 286982.92 | C7: 118668.92 | D7: 125674.58 | E7: 89317.917 | F7: 412657.5 | G7: 207986.83
A8: 2012 | B8: 288232.25 | C8: 116683.83 | D8: 120025.92 | E8: 85446.25 | F8: 408258.17 | G8: 202130.08
A9: 2013 | B9: 288720.25 | C9: 114312 | D9: 112605.08 | E9: 79812.917 | F9: 401325.33 | G9: 194124.92
A10: 2014 | B10: 288530.42 | C10: 111136.17 | D10: 107377.17 | E10: 75527.833 | F10: 395907.58 | G10: 186664
A11: 2015 | B11: 289070.58 | C11: 110162 | D11: 105105.42 | E11: 74655.333 | F11: 394176 | G11: 184817.33
A12: 2016 | B12: 290373 | C12: 108843.42 | D12: 105459.83 | E12: 75532.583 | F12: 395832.83 | G12: 184376
A13: 2017 | B13: 291754 | C13: 107694.83 | D13: 105581.83 | E13: 76434.167 | F13: 397335.83 | G13: 184129
A14: 2018 | B14: 295171.83 | C14: 107077.42 | D14: 105559.42 | E14: 77417 | F14: 400731.25 | G14: 184494.42
A15: 2019 | B15: 299821.5 | C15: 106705.25 | D15: 104899.17 | E15: 77850.417 | F15: 404720.67 | G15: 184555.67
... A42: dic | B42: 0 | C42: 0 | D42: 103979 | E42: 81605 | F42: 103979 | G42: 81605

Sheet MONTOS PBS
I1: PERIODO | J1: (Varios elementos)
A3: Etiquetas de fila | B3: Promedio de PBSV_MUJER | C3: Promedio de PBSV_HOMBRE | D3: Promedio de PBSI_MUJER | E3: Promedio de PBSI_HOMBRE | F3: Promedio de PBS_MUJER | G3: Promedio de PBS_HOMBRE | I3: Etiquetas de fila | J3: Suma de PBSV_MUJER | K3: Suma de PBSV_HOMBRE | L3: Suma de PBSV_TOTAL | M3: Suma de PBSI_MUJER | N3: Suma de PBSI_HOMBRE | O3: Suma de PBSI_TOTAL | P3: Suma de PBS_MUJER | Q3: Suma de PBS_HOMBRE | R3: Suma de PBS_TOTAL | T3: Etiquetas de fila | U3: Suma de PBSV_MUJER | V3: Suma de PBSV_HOMBRE | W3: Suma de PBSV_TOTAL | X3: Suma de PBSI_MUJER | Y3: Suma de PBSI_HOMBRE | Z3: Suma de PBSI_TOTAL | AA3: Suma de PBS_MUJER | AB3: Suma de PBS_HOMBRE | AC3: Suma de PBS_TOTAL | AE3: Etiquetas de fila | AF3: Suma de PBSV_MUJER | AG3: Suma de PBSV_HOMBRE | AH3: Suma de PBSV_TOTAL | AI3: Suma de PBSI_MUJER | AJ3: Suma de PBSI_HOMBRE | AK3: Suma de PBSI_TOTAL | AL3: Suma de PBS_MUJER | AM3: Suma de PBS_HOMBRE | AN3: Suma de PBS_TOTAL
A4: 2008 | B4: 8.2469269e+09 | C4: 3.9732077e+09 | D4: 3.9696562e+09 | E4: 3.0646136e+09 | F4: 1.2216583e+10 | G4: 7.0378213e+09 | I4: 2022 | J4: 0 | K4: 0 | L4: 0 | M4: 6.0133313e+10 | N4: 4.7149436e+10 | O4: 1.0728275e+11 | P4: 6.0133313e+10 | Q4: 4.7149436e+10 | R4: 1.0728275e+11 | T4: oct | U4: 0 | V4: 0 | W4: 0 | X4: 1.9903687e+10 | Y4: 1.5583475e+10 | Z4: 3.5487162e+10 | AA4: 1.9903687e+10 | AB4: 1.5583475e+10 | AC4: 3.5487162e+10 | AE4: oct | AF4: =+U4/1000 -> 0 | AG4: =+V4/1000 -> 0 | AH4: =+W4/1000 -> 0 | AI4: =+X4/1000 -> 19903687 | AJ4: =+Y4/1000 -> 15583475 | AK4: =+Z4/1000 -> 35487162 | AL4: =+AA4/1000 -> 19903687 | AM4: =+AB4/1000 -> 15583475 | AN4: =+AC4/1000 -> 35487162
A5: 2009 | B5: 1.0831943e+10 | C5: 4.7784934e+09 | D5: 5.149103e+09 | E5: 3.655593e+09 | F5: 1.5981046e+10 | G5: 8.4340864e+09 | I5: oct | J5: 0 | K5: 0 | L5: 0 | M5: 1.9903687e+10 | N5: 1.5583475e+10 | O5: 3.5487162e+10 | P5: 1.9903687e+10 | Q5: 1.5583475e+10 | R5: 3.5487162e+10 | T5: nov | U5: 0 | V5: 0 | W5: 0 | X5: 2.0075789e+10 | Y5: 1.5749774e+10 | Z5: 3.5825563e+10 | AA5: 2.0075789e+10 | AB5: 1.5749774e+10 | AC5: 3.5825563e+10 | AE5: nov | AF5: =+U5/1000 -> 0 | AG5: =+V5/1000 -> 0 | AH5: =+W5/1000 -> 0 | AI5: =+X5/1000 -> 20075789 | AJ5: =+Y5/1000 -> 15749774 | AK5: =+Z5/1000 -> 35825563 | AL5: =+AA5/1000 -> 20075789 | AM5: =+AB5/1000 -> 15749774 | AN5: =+AC5/1000 -> 35825563
A6: 2010 | B6: 1.3095568e+10 | C6: 5.5029662e+09 | D6: 5.9733298e+09 | E6: 4.1819318e+09 | F6: 1.9068897e+10 | G6: 9.684898e+09 | I6: nov | J6: 0 | K6: 0 | L6: 0 | M6: 2.0075789e+10 | N6: 1.5749774e+10 | O6: 3.5825563e+10 | P6: 2.0075789e+10 | Q6: 1.5749774e+10 | R6: 3.5825563e+10 | T6: dic | U6: 0 | V6: 0 | W6: 0 | X6: 20153837159 | Y6: 15816186175 | Z6: 35970023334 | AA6: 20153837159 | AB6: 15816186175 | AC6: 35970023334 | AE6: dic | AF6: =+U6/1000 -> 0 | AG6: =+V6/1000 -> 0 | AH6: =+W6/1000 -> 0 | AI6: =+X6/1000 -> 20153837 | AJ6: =+Y6/1000 -> 15816186 | AK6: =+Z6/1000 -> 35970023 | AL6: =+AA6/1000 -> 20153837 | AM6: =+AB6/1000 -> 15816186 | AN6: =+AC6/1000 -> 35970023
A7: 2011 | B7: 1.3994994e+10 | C7: 5.7801079e+09 | D7: 6.2216009e+09 | E7: 4.3734947e+09 | F7: 2.0216595e+10 | G7: 1.0153603e+10 | I7: dic | J7: 0 | K7: 0 | L7: 0 | M7: 20153837159 | N7: 15816186175 | O7: 35970023334 | P7: 20153837159 | Q7: 15816186175 | R7: 35970023334
A8: 2012 | B8: 1.4900592e+10 | C8: 6.0276417e+09 | D8: 6.3053347e+09 | E8: 4.4481809e+09 | F8: 2.1205927e+10 | G8: 1.0475823e+10
A9: 2013 | B9: 1.5464511e+10 | C9: 6.1276381e+09 | D9: 6.1333006e+09 | E9: 4.2916174e+09 | F9: 2.1597811e+10 | G9: 1.0419256e+10
A10: 2014 | B10: 1.6719242e+10 | C10: 6.4430339e+09 | D10: 6.3328754e+09 | E10: 4.3768174e+09 | F10: 2.3052118e+10 | G10: 1.0819851e+10
A11: 2015 | B11: 1.8210703e+10 | C11: 6.9460832e+09 | D11: 6.7614414e+09 | E11: 4.7714308e+09 | F11: 2.4972144e+10 | G11: 1.1717514e+10
A12: 2016 | B12: 1.9783297e+10 | C12: 7.4256197e+09 | D12: 7.3620108e+09 | E12: 5.231601e+09 | F12: 2.7145307e+10 | G12: 1.2657221e+10 | I12: PERIODO | J12: (Varios elementos) | AE12: nominales
A13: 2017 | B13: 2.3013212e+10 | C13: 8.5012643e+09 | D13: 8.4836307e+09 | E13: 6.1043568e+09 | F13: 3.1496842e+10 | G13: 1.4605621e+10 | AF13: vejez | AI13: invalidez | AL13: total
A14: 2018 | B14: 2.4370428e+10 | C14: 8.8423454e+09 | D14: 8.863105e+09 | E14: 6.4518852e+09 | F14: 3.3233533e+10 | G14: 1.5294231e+10 | I14: Etiquetas de fila | J14: Suma de MUJER | K14: Suma de HOMBRE | L14: Suma de TOTAL | M14: Suma de MUJER2 | N14: Suma de HOMBRE2 | O14: Suma de TOTAL2 | P14: Suma de MUJER3 | Q14: Suma de HOMBRE3 | R14: Suma de TOTAL3 | T14: Etiquetas de fila | U14: Suma de MUJER | V14: Suma de HOMBRE | W14: Suma de TOTAL | X14: Suma de MUJER2 | Y14: Suma de HOMBRE2 | Z14: Suma de TOTAL2 | AA14: Suma de MUJER3 | AB14: Suma de HOMBRE3 | AC14: Suma de TOTAL3 | AE14: Etiquetas de fila | AF14: Promedio de MUJER | AG14: Promedio de HOMBRE | AH14: Promedio de TOTAL | AI14: Promedio de MUJER2 | AJ14: Promedio de HOMBRE2 | AK14: Promedio de TOTAL2 | AL14: Promedio de MUJER3 | AM14: Promedio de HOMBRE3 | AN14: Promedio de TOTAL3
A15: 2019 | B15: 2.6689511e+10 | C15: 9.492244e+09 | D15: 9.429656e+09 | E15: 6.9564548e+09 | F15: 3.6119167e+10 | G15: 1.6448699e+10 | I15: 2022 | J15: 0 | K15: 0 | L15: 0 | M15: 60441368879 | N15: 47390715970 | O15: 107832084849 | P15: 60441368879 | Q15: 47390715970 | R15: 107832084849 | T15: oct | U15: 0 | V15: 0 | W15: 0 | X15: 20154801071 | Y15: 15780083599 | Z15: 35934884670 | AA15: 20154801071 | AB15: 15780083599 | AC15: 35934884670 | AE15: oct | AF15: =+U15/1000 -> 0 | AG15: =+V15/1000 -> 0 | AH15: =+W15/1000 -> 0 | AI15: =+X15/1000 -> 20154801 | AJ15: =+Y15/1000 -> 15780084 | AK15: =+Z15/1000 -> 35934885 | AL15: =+AA15/1000 -> 20154801 | AM15: =+AB15/1000 -> 15780084 | AN15: =+AC15/1000 -> 35934885
A16: 2020 | B16: 3.659289e+10 | C16: 1.2913294e+10 | D16: 1.1894674e+10 | E16: 8.9114229e+09 | F16: 4.8487564e+10 | G16: 2.1824717e+10 | I16: oct | J16: 0 | K16: 0 | L16: 0 | M16: 20154801071 | N16: 15780083599 | O16: 35934884670 | P16: 20154801071 | Q16: 15780083599 | R16: 35934884670 | T16: nov | U16: 0 | V16: 0 | W16: 0 | X16: 20132730649 | Y16: 15794446196 | Z16: 35927176845 | AA16: 20132730649 | AB16: 15794446196 | AC16: 35927176845 | AE16: nov | AF16: =+U16/1000 -> 0 | AG16: =+V16/1000 -> 0 | AH16: =+W16/1000 -> 0 | AI16: =+X16/1000 -> 20132731 | AJ16: =+Y16/1000 -> 15794446 | AK16: =+Z16/1000 -> 35927177 | AL16: =+AA16/1000 -> 20132731 | AM16: =+AB16/1000 -> 15794446 | AN16: =+AC16/1000 -> 35927177
A17: 2021 | B17: 4.3453866e+10 | C17: 1.494933e+10 | D17: 1.4114095e+10 | E17: 1.0837333e+10 | F17: 5.7567962e+10 | G17: 2.5786663e+10 | I17: nov | J17: 0 | K17: 0 | L17: 0 | M17: 20132730649 | N17: 15794446196 | O17: 35927176845 | P17: 20132730649 | Q17: 15794446196 | R17: 35927176845 | T17: dic | U17: 0 | V17: 0 | W17: 0 | X17: 20153837159 | Y17: 15816186175 | Z17: 35970023334 | AA17: 20153837159 | AB17: 15816186175 | AC17: 35970023334 | AE17: dic | AF17: =+U17/1000 -> 0 | AG17: =+V17/1000 -> 0 | AH17: =+W17/1000 -> 0 | AI17: =+X17/1000 -> 20153837 | AJ17: =+Y17/1000 -> 15816186 | AK17: =+Z17/1000 -> 35970023 | AL17: =+AA17/1000 -> 20153837 | AM17: =+AB17/1000 -> 15816186 | AN17: =+AC17/1000 -> 35970023
A18: ene | B18: 4.1412765e+10 | C18: 1.4344175e+10 | D18: 1.357545e+10 | E18: 1.0301137e+10 | F18: 5.4988215e+10 | G18: 2.4645311e+10 | I18: dic | J18: 0 | K18: 0 | L18: 0 | M18: 20153837159 | N18: 15816186175 | O18: 35970023334 | P18: 20153837159 | Q18: 15816186175 | R18: 35970023334 | T18: Total general | U18: 0 | V18: 0 | W18: 0 | X18: 2.0147123e+10 | Y18: 1.5796905e+10 | Z18: 35944028283 | AA18: 2.0147123e+10 | AB18: 1.5796905e+10 | AC18: 35944028283
A19: feb | B19: 4.1492133e+10 | C19: 1.4338672e+10 | D19: 1.35569e+10 | E19: 1.0317361e+10 | F19: 5.5049033e+10 | G19: 2.4656033e+10
A20: mar | B20: 4.1689378e+10 | C20: 1.4389108e+10 | D20: 1.3587482e+10 | E20: 1.0363694e+10 | F20: 5.527686e+10 | G20: 2.4752801e+10
A21: abr | B21: 4.1893694e+10 | C21: 1.4448119e+10 | D21: 1.3658161e+10 | E21: 1.0436146e+10 | F21: 5.5551855e+10 | G21: 2.4884265e+10
A22: may | B22: 4.2028716e+10 | C22: 1.4474202e+10 | D22: 1.3650261e+10 | E22: 1.0455982e+10 | F22: 5.5678977e+10 | G22: 2.4930184e+10
A23: jun | B23: 4.2051494e+10 | C23: 1.4454401e+10 | D23: 1.3673345e+10 | E23: 1.0488652e+10 | F23: 5.5724839e+10 | G23: 2.4943053e+10
A24: jul | B24: 4.3968065e+10 | C24: 1.5094747e+10 | D24: 1.4296201e+10 | E24: 1.0984398e+10 | F24: 5.8264265e+10 | G24: 2.6079145e+10
A25: ago | B25: 4.4239653e+10 | C25: 1.5183281e+10 | D25: 1.4359654e+10 | E25: 1.1056169e+10 | F25: 5.8599307e+10 | G25: 2.6239451e+10
A26: sept | B26: 4.4825753e+10 | C26: 1.5361682e+10 | D26: 1.4520122e+10 | E26: 1.1196684e+10 | F26: 5.9345875e+10 | G26: 2.6558366e+10
A27: oct | B27: 4.5558469e+10 | C27: 1.5619781e+10 | D27: 1.4731002e+10 | E27: 1.1378659e+10 | F27: 6.0289471e+10 | G27: 2.6998439e+10
A28: nov | B28: 4.5907806e+10 | C28: 1.5757842e+10 | D28: 1.4819941e+10 | E28: 1.1477734e+10 | F28: 6.0727747e+10 | G28: 2.7235576e+10
A29: dic | B29: 4.6378472e+10 | C29: 1.5925944e+10 | D29: 1.4940627e+10 | E29: 1.159138e+10 | F29: 6.1319099e+10 | G29: 2.7517324e+10
A30: 2022 | B30: 4.0614957e+09 | C30: 1.3943048e+09 | D30: 1.8608107e+10 | E30: 1.4541109e+10 | F30: 2.2669603e+10 | G30: 1.5935414e+10
... A43: Total general | B43: 1.9676256e+10 | C43: 7.3869635e+09 | D43: 8.5253168e+09 | E43: 6.2527955e+09 | F43: 2.8201573e+10 | G43: 1.3639759e+10
A52: Etiquetas de fila | B52: Promedio de PBSV_MUJER | C52: Promedio de PBSV_HOMBRE | D52: Promedio de PBSI_MUJER | E52: Promedio de PBSI_HOMBRE | F52: Promedio de PBS_MUJER | G52: Promedio de PBS_HOMBRE | I52: Etiquetas de fila | J52: Promedio de PBSV_MUJER | K52: Promedio de PBSV_HOMBRE | L52: Promedio de PBSI_MUJER | M52: Promedio de PBSI_HOMBRE | N52: Promedio de PBS_MUJER | O52: Promedio de PBS_HOMBRE
A53: 2008 | B53: 8.2469269e+09 | C53: 3.9732077e+09 | D53: 3.9696562e+09 | E53: 3.0646136e+09 | F53: 1.2216583e+10 | G53: 7.0378213e+09 | I53: 2008 | J53: 8246926.9 | K53: 3973207.7 | L53: 3969656.2 | M53: 3064613.6 | N53: 12216583 | O53: 7037821.3
A54: 2009 | B54: 1.0831943e+10 | C54: 4.7784934e+09 | D54: 5.149103e+09 | E54: 3.655593e+09 | F54: 1.5981046e+10 | G54: 8.4340864e+09 | I54: 2009 | J54: 10831943 | K54: 4778493.4 | L54: 5149103 | M54: 3655593 | N54: 15981046 | O54: 8434086.4
A55: 2010 | B55: 1.3095568e+10 | C55: 5.5029662e+09 | D55: 5.9733298e+09 | E55: 4.1819318e+09 | F55: 1.9068897e+10 | G55: 9.684898e+09 | I55: 2010 | J55: 13095568 | K55: 5502966.2 | L55: 5973329.8 | M55: 4181931.8 | N55: 19068897 | O55: 9684898
A56: 2011 | B56: 1.3994994e+10 | C56: 5.7801079e+09 | D56: 6.2216009e+09 | E56: 4.3734947e+09 | F56: 2.0216595e+10 | G56: 1.0153603e+10 | I56: 2011 | J56: 13994994 | K56: 5780107.9 | L56: 6221600.9 | M56: 4373494.7 | N56: 20216595 | O56: 10153603
A57: 2012 | B57: 1.4900592e+10 | C57: 6.0276417e+09 | D57: 6.3053347e+09 | E57: 4.4481809e+09 | F57: 2.1205927e+10 | G57: 1.0475823e+10 | I57: 2012 | J57: 14900592 | K57: 6027641.7 | L57: 6305334.7 | M57: 4448180.9 | N57: 21205927 | O57: 10475823
A58: 2013 | B58: 1.5464511e+10 | C58: 6.1276381e+09 | D58: 6.1333006e+09 | E58: 4.2916174e+09 | F58: 2.1597811e+10 | G58: 1.0419256e+10 | I58: 2013 | J58: 15464511 | K58: 6127638.1 | L58: 6133300.6 | M58: 4291617.4 | N58: 21597811 | O58: 10419256
A59: 2014 | B59: 1.6719242e+10 | C59: 6.4430339e+09 | D59: 6.3328754e+09 | E59: 4.3768174e+09 | F59: 2.3052118e+10 | G59: 1.0819851e+10 | I59: 2014 | J59: 16719242 | K59: 6443033.9 | L59: 6332875.4 | M59: 4376817.4 | N59: 23052118 | O59: 10819851
A60: 2015 | B60: 1.8210703e+10 | C60: 6.9460832e+09 | D60: 6.7614414e+09 | E60: 4.7714308e+09 | F60: 2.4972144e+10 | G60: 1.1717514e+10 | I60: 2015 | J60: 18210703 | K60: 6946083.2 | L60: 6761441.4 | M60: 4771430.8 | N60: 24972144 | O60: 11717514
A61: 2016 | B61: 1.9783297e+10 | C61: 7.4256197e+09 | D61: 7.3620108e+09 | E61: 5.231601e+09 | F61: 2.7145307e+10 | G61: 1.2657221e+10 | I61: 2016 | J61: 19783297 | K61: 7425619.7 | L61: 7362010.8 | M61: 5231601 | N61: 27145307 | O61: 12657221
...

Sheet 1.1
B2: TOTAL BENEFICIOS PAGADOS DEL PILAR NO CONTRIBUTIVO
B4: Resumen trimestral de beneficios pagados, por tipo de beneficio y sexo
B5: (julio 2023 a septiembre 2023)
D7: Mujeres | G7: Hombres | J7: Total
B8: Periodo | C8: Tipo de beneficio | D8: N° | E8: Monto nominal M$ * | F8: Monto real M$ ** | G8: N° | H8: Monto nominal M$ * | I8: Monto real M$ ** | J8: N° | K8: Monto nominal M$ * | L8: Monto real M$ **
B9: 45108 | C9: PGU No Contributiva | D9: 340958 | E9: 69854324 | F9: 70402476 | G9: 136319 | H9: 28019332 | I9: 28239201 | J9: 477277 | K9: 97873656 | L9: 98641677
C10: PGU Contributiva | D10: 785041 | E10: 1.5946034e+08 | F10: 1.6071163e+08 | G10: 656925 | H10: 1.3225078e+08 | I10: 1.3328857e+08 | J10: 1441966 | K10: 2.9171112e+08 | L10: 2.940002e+08
C11: PBS Invalidez | D11: 106121 | E11: 21866468 | F11: 22038056 | G11: 83495 | H11: 17204837 | I11: 17339844 | J11: 189616 | K11: 39071305 | L11: 39377900
C12: APS Vejez | D12: 107603 | E12: 25329300 | F12: 25528060 | G12: 61709 | H12: 14707933 | I12: 14823347 | J12: 169312 | K12: 40037232 | L12: 40351407
C13: APS Invalidez | D13: 47071 | E13: 8333096.5 | F13: 8398486.8 | G13: 49165 | H13: 8270074.9 | I13: 8334970.7 | J13: 96236 | K13: 16603171 | L13: 16733458
C14: Total Beneficios | D14: 1386794 | E14: 2.8484352e+08 | F14: 2.8707871e+08 | G14: 987613 | H14: 2.0045296e+08 | I14: 2.0202593e+08 | J14: 2374407 | K14: 4.8529648e+08 | L14: 4.8910464e+08
B15: 45139 | C15: PGU No Contributiva | D15: 342010 | E15: 70033844 | F15: 70504824 | G15: 136198 | H15: 27976921 | I15: 28165067 | J15: 478208 | K15: 98010765 | L15: 98669891
C16: PGU Contributiva | D16: 789396 | E16: 1.603224e+08 | F16: 1.6140057e+08 | G16: 661702 | H16: 1.3318598e+08 | I16: 1.3408166e+08 | J16: 1451098 | K16: 2.9350838e+08 | L16: 2.9548223e+08
C17: PBS Invalidez | D17: 106570 | E17: 21958710 | F17: 22106383 | G17: 83812 | H17: 17270379 | I17: 17386522 | J17: 190382 | K17: 39229088 | L17: 39492905
C18: APS Vejez | D18: 107495 | E18: 25328349 | F18: 25498683 | G18: 61425 | H18: 14670727 | I18: 14769388 | J18: 168920 | K18: 39999076 | L18: 40268071
C19: APS Invalidez | D19: 47164 | E19: 8347020.6 | F19: 8403154.5 | G19: 49448 | H19: 8312011.6 | I19: 8367910.1 | J19: 96612 | K19: 16659032 | L19: 16771065
C20: Total Beneficios | D20: 1392635 | E20: 2.8599032e+08 | F20: 2.8791362e+08 | G20: 992585 | H20: 2.0141602e+08 | I20: 2.0277055e+08 | J20: 2385220 | K20: 4.8740634e+08 | L20: 4.9068416e+08
B21: 45170 | C21: PGU No Contributiva | D21: 343880 | E21: 70389111 | F21: 70389111 | G21: 138475 | H21: 28428702 | I21: 28428702 | J21: 482355 | K21: 98817812 | L21: 98817812
C22: PGU Contributiva | D22: 795862 | E22: 1.6160243e+08 | F22: 1.6160243e+08 | G22: 666557 | H22: 1.3410851e+08 | I22: 1.3410851e+08 | J22: 1462419 | K22: 2.9571094e+08 | L22: 2.9571094e+08
C23: PBS Invalidez | D23: 106868 | E23: 22021397 | F23: 22021397 | G23: 84043 | H23: 17319291 | I23: 17319291 | J23: 190911 | K23: 39340689 | L23: 39340689
C24: APS Vejez | D24: 107346 | E24: 25293121 | F24: 25293121 | G24: 61168 | H24: 14619374 | I24: 14619374 | J24: 168514 | K24: 39912496 | L24: 39912496
C25: APS Invalidez | D25: 47248 | E25: 8349348.3 | F25: 8349348.3 | G25: 49763 | H25: 8344374.8 | I25: 8344374.8 | J25: 97011 | K25: 16693723 | L25: 16693723
C26: Total Beneficios | D26: 1401204 | E26: 2.876554e+08 | F26: 2.876554e+08 | G26: 1000006 | H26: 2.0282025e+08 | I26: 2.0282025e+08 | J26: 2401210 | K26: 4.9047566e+08 | L26: 4.9047566e+08
B27: Fuente: Elaboración propia con datos de la Superintendencia de Pensiones
B28: Nota 1: La Pensión Garantizada Universal (PGU) es un nuevo beneficio generado a partir de la ley 21.419 del 29-01-2022. El concepto de PGU No Contributiva o Contributiva está relacionado con la calidad de la persona que está recibiendo el beneficio, si es No Contributiva quiere decir que no estaba afiliado a un sistema previsional (D.L. 3.500 o antiguo Sistema de Reparto) ni recibe pensión de sobrevivencia, si es Contributiva quiere decir que sí estaba afiliado a un sistema previsional o que recibe una pensión de sobrevivencia. De manera automática, en febrero 2022, los PBS de Vejez pasaron a ser PGU No Contributiva y los APS Vejez Subsidio Definido, los Beneficio artículo 9° bis y los APS Vejez con una Pensión Final Garantizada inferior o igual al monto de la PGU pasaron a ser PGU Contributiva (Fuente: Superintendencia de Pensiones). Nota 2: Para los APS de Vejez, en aquellos casos en que este beneficio superaba el monto de la PGU se mantuvo el beneficio.
B29: * Montos nominales de cada periodo de pago. ** Montos deflactados a septiembre 2023
B31: Serie resumen de pagos de beneficios acumulados, por tipo de beneficio
B32: (julio 2008 a septiembre 2023)
C34: PGU No Contributiva | H34: PGU Contributiva | M34: PBS Vejez | R34: PBS Invalidez | W34: APS Vejez | AB34: APS Invalidez | AG34: Nbis | AL34: Total Beneficios
C35: N° Beneficios | E35: Monto real M$* | G35: Monto nominal M$** | H35: N° Beneficios | J35: Monto real M$* | L35: Monto nominal M$** | M35: N° Beneficios | O35: Monto real M$* | Q35: Monto nominal M$** | R35: N° Beneficios | T35: Monto real M$* | V35: Monto nominal M$** | W35: N° Beneficios | Y35: Monto real M$* | AA35: Monto nominal M$** | AB35: N° Beneficios | AD35: Monto real M$* | AF35: Monto nominal M$** | AG35: N° Beneficios | AI35: Monto real M$* | AK35: Monto nominal M$** | AL35: N° Beneficios | AN35: Monto real M$* | AP35: Monto nominal M$**
B36: Periodo | C36: N° | D36: %*** | E36: N° | F36: %*** | G36: N° | H36: N° | I36: %*** | J36: N° | K36: %*** | L36: N° | M36: N° | N36: %*** | O36: N° | P36: %*** | Q36: N° | R36: N° | S36: %*** | T36: N° | U36: %*** | V36: N° | W36: N° | X36: %*** | Y36: N° | Z36: %*** | AA36: N° | AB36: N° | AC36: %*** | AD36: N° | AE36: %*** | AF36: N° | AG36: N° | AH36: %*** | AI36: N° | AJ36: %*** | AK36: N° | AL36: N° | AM36: %*** | AN36: N° | AO36: %*** | AP36: N°
B37: 39630 | M37: 290570 | N37: 0.60124441 | O37: 30589054 | P37: 0.60124441 | Q37: 17434200 | R37: 192711 | S37: 0.39875559 | T37: 20287184 | U37: 0.39875559 | V37: 11562660 | AL37: 483281 | AM37: 1 | AN37: 50876238 | AO37: 1 | AP37: 28996860
B38: 39661 | M38: 292137 | N38: 0.60055999 | O38: 30469938 | P38: 0.60055999 | Q38: 17528220 | R38: 194304 | S38: 0.39944001 | T38: 20265940 | U38: 0.39944001 | V38: 11658240 | AL38: 486441 | AM38: 1 | AN38: 50735878 | AO38: 1 | AP38: 29186460
B39: 39692 | M39: 329546 | N39: 0.63002998 | O39: 34002856 | P39: 0.62997894 | Q39: 19768431 | R39: 193518 | S39: 0.36997002 | T39: 19971736 | U39: 0.37002106 | V39: 11611080 | AL39: 523064 | AM39: 1 | AN39: 53974591 | AO39: 1 | AP39: 31379511
B40: 39722 | M40: 340883 | N40: 0.63388369 | O40: 37752733 | P40: 0.64317182 | Q40: 22142510 | R40: 193041 | S40: 0.3589664 | T40: 19839322 | U40: 0.33799124 | V40: 11636042 | W40: 3399 | X40: 0.0063205577 | Y40: 984203.49 | Z40: 0.016767314 | AA40: 577249.22 | AB40: 446 | AC40: 0.00082935238 | AD40: 121482.6 | AE40: 0.0020696299 | AF40: 71251.256 | AL40: 537769 | AM40: 1 | AN40: 58697742 | AO40: 1 | AP40: 34427053
B41: 39753 | M41: 347314 | N41: 0.63749096 | O41: 37631185 | P41: 0.64785948 | Q41: 22044175 | R41: 192690 | S41: 0.35368034 | T41: 19910045 | U41: 0.34277187 | V41: 11663213 | W41: 4226 | X41: 0.0077567757 | Y41: 475630.31 | Z41: 0.0081884642 | AA41: 278622.06 | AB41: 584 | AC41: 0.0010719255 | AD41: 68551.346 | AE41: 0.0011801818 | AF41: 40157.064 | AL41: 544814 | AM41: 1 | AN41: 58085412 | AO41: 1 | AP41: 34026168
B42: 39783 | M42: 358445 | N42: 0.64228132 | O42: 40538460 | P42: 0.64842422 | Q42: 23467261 | R42: 194451 | S42: 0.34842792 | T42: 21379468 | U42: 0.34197068 | V42: 12376335 | W42: 4485 | X42: 0.0080364678 | Y42: 529037.25 | Z42: 0.0084621016 | AA42: 306253.75 | AB42: 700 | AC42: 0.0012542982 | AD42: 71458.738 | AE42: 0.0011430029 | AF42: 41366.664 | AL42: 558081 | AM42: 1 | AN42: 62518424 | AO42: 1 | AP42: 36191216
B43: Promedio 2008 | M43: 326482.5 | N43: 0.6224069 | O43: 35164038 | P43: 0.62580848 | R43: 193452.5 | S43: 0.36879824 | T43: 20275616 | U43: 0.36084174 | W43: 4036.6667 | X43: 0.0076955095 | Y43: 662957.02 | Z43: 0.011798535 | AB43: 576.66667 | AC43: 0.0010993585 | AD43: 87164.227 | AE43: 0.0015512471 | AL43: 524548.33 | AM43: 1 | AN43: 56189775 | AO43: 1
B44: 39814 | M44: 364131 | N44: 0.64167332 | O44: 39565944 | P44: 0.63183868 | Q44: 22729604 | R44: 196192 | S44: 0.34573044 | T44: 21899993 | U44: 0.34972659 | V44: 12580975 | W44: 6199 | X44: 0.010923906 | Y44: 1012124.9 | Z44: 0.016162881 | AA44: 581439.38 | AB44: 949 | AC44: 0.0016723322 | AD44: 142263.34 | AE44: 0.0022718397 | AF44: 81726.581 | AL44: 567471 | AM44: 1 | AN44: 62620326 | AO44: 1 | AP44: 35973745
B45: 39845 | M45: 366991 | N45: 0.64091253 | O45: 39601949 | P45: 0.63378798 | Q45: 22667397 | R45: 197256 | S45: 0.34448758 | T45: 21930414 | U45: 0.35097345 | V45: 12552549 | W45: 7180 | X45: 0.012539141 | Y45: 793357.51 | Z45: 0.012696861 | AA45: 454102.65 | AB45: 1180 | AC45: 0.0020607502 | AD45: 158817.13 | AE45: 0.0025417029 | AF45: 90903.886 | AL45: 572607 | AM45: 1 | AN45: 62484537 | AO45: 1 | AP45: 35764953
...

Sheet 1.2
B2: PAGOS PENSIÓN GARANTIZADA UNIVERSAL (PGU)
B5: Resumen trimestral de beneficios pagados, por tipo de beneficio y sexo
B6: (julio 2023 a septiembre 2023)
D8: PGU No Contributiva | G8: PGU Contributiva | J8: PGU Total
B9: Periodo | C9: Sexo Beneficiarios | D9: N° | E9: Monto nominal M$ * | F9: Monto real M$ ** | G9: N° | H9: Monto nominal M$ * | I9: Monto real M$ ** | J9: N° | K9: Monto nominal M$ * | L9: Monto real M$ **
B10: 45108 | C10: Mujeres | D10: 340958 | E10: 69854324 | F10: 70402476 | G10: 785041 | H10: 1.5946034e+08 | I10: 1.6071163e+08 | J10: 1125999 | K10: 2.2931466e+08 | L10: 2.3111411e+08
C11: Hombres | D11: 136319 | E11: 28019332 | F11: 28239201 | G11: 656925 | H11: 1.3225078e+08 | I11: 1.3328857e+08 | J11: 793244 | K11: 1.6027012e+08 | L11: 1.6152777e+08
C12: Total | D12: 477277 | E12: 97873656 | F12: 98641677 | G12: 1441966 | H12: 2.9171112e+08 | I12: 2.940002e+08 | J12: 1919243 | K12: 3.8958478e+08 | L12: 3.9264187e+08
B13: 45139 | C13: Mujeres | D13: 342010 | E13: 70033844 | F13: 70504824 | G13: 789396 | H13: 1.603224e+08 | I13: 1.6140057e+08 | J13: 1131406 | K13: 2.3035624e+08 | L13: 2.319054e+08
C14: Hombres | D14: 136198 | E14: 27976921 | F14: 28165067 | G14: 661702 | H14: 1.3318598e+08 | I14: 1.3408166e+08 | J14: 797900 | K14: 1.611629e+08 | L14: 1.6224673e+08
C15: Total | D15: 478208 | E15: 98010765 | F15: 98669891 | G15: 1451098 | H15: 2.9350838e+08 | I15: 2.9548223e+08 | J15: 1929306 | K15: 3.9151914e+08 | L15: 3.9415212e+08
B16: 45170 | C16: Mujeres | D16: 343880 | E16: 70389111 | F16: 70389111 | G16: 795862 | H16: 1.6160243e+08 | I16: 1.6160243e+08 | J16: 1139742 | K16: 2.3199154e+08 | L16: 2.3199154e+08
C17: Hombres | D17: 138475 | E17: 28428702 | F17: 28428702 | G17: 666557 | H17: 1.3410851e+08 | I17: 1.3410851e+08 | J17: 805032 | K17: 1.6253721e+08 | L17: 1.6253721e+08
C18: Total | D18: 482355 | E18: 98817812 | F18: 98817812 | G18: 1462419 | H18: 2.9571094e+08 | I18: 2.9571094e+08 | J18: 1944774 | K18: 3.9452875e+08 | L18: 3.9452875e+08
B19: Fuente: Elaboración propia con datos de la Superintendencia de Pensiones
B20: Nota 1: La Pensión Garantizada Universal (PGU) es un nuevo beneficio generado a partir de la ley 21.419 del 29-01-2022. El concepto de PGU No Contributiva o Contributiva está relacionado con la calidad de la persona que está recibiendo el beneficio, si es No Contributiva quiere decir que no estaba afiliado a un sistema previsional (D.L. 3.500 o antiguo Sistema de Reparto) ni recibe pensión de sobrevivencia, si es Contributiva quiere decir que si estaba afiliado a un sistema previsional o que recibe una pensión de sobrevivencia. De manera automática, en febrero 2022, los PBS de Vejez pasaron a ser PGU No Contributiva y los APS Vejez Subsidio Definido, los Beneficio artículo 9° bis y los APS Vejez con una Pensión Final Garantizada inferior o igual al monto de la PGU pasaron a ser PGU Contributiva (Fuente: Superintendencia de Pensiones). Nota 2: Para los APS de Vejez, en aquellos casos en que este beneficio superaba el monto de la PGU se mantuvo el beneficio.
B21: * Montos nominales de cada periodo de pago. ** Montos deflactados a septiembre 2023
B23: Serie resumen de pagos de beneficios acumulado, por tipo de beneficio y sexo
B24: (febrero 2022 a septiembre 2023)
C26: PGU No Contributiva | L26: PGU Contributiva | U26: PGU Total
C27: Mujeres | F27: Hombres | I27: Total | L27: Mujeres | O27: Hombres | R27: Total | U27: Mujeres | X27: Hombres | AA27: Total
B28: Periodo | C28: N° Beneficios | D28: Monto real M$ * | E28: Monto nominal M$ ** | F28: N° Beneficios | G28: Monto real M$ * | H28: Monto nominal M$ ** | I28: N° Beneficios | J28: Monto real M$ * | K28: Monto nominal M$ ** | L28: N° Beneficios | M28: Monto real M$ * | N28: Monto nominal M$ ** | O28: N° Beneficios | P28: Monto real M$ * | Q28: Monto nominal M$ ** | R28: N° Beneficios | S28: Monto real M$ * | T28: Monto nominal M$ ** | U28: N° Beneficios | V28: Monto real M$ * | W28: Monto nominal M$ ** | X28: N° Beneficios | Y28: Monto real M$ * | Z28: Monto nominal M$ ** | AA28: N° Beneficios | AB28: Monto real M$ * | AC28: Monto nominal M$ **
B29: 44593 | C29: 309683 | D29: 65647186 | E29: 57205361 | F29: 106066 | G29: 22512266 | H29: 19617327 | I29: 415749 | J29: 88159452 | K29: 76822687 | L29: 517361 | M29: 97633252 | N29: 85078214 | O29: 340110 | P29: 66908099 | Q29: 58304128 | R29: 857471 | S29: 1.6454135e+08 | T29: 1.4338234e+08 | U29: 827044 | V29: 1.6328044e+08 | W29: 1.4228357e+08 | X29: 446176 | Y29: 89420365 | Z29: 77921454 | AA29: 1273220 | AB29: 2.527008e+08 | AC29: 2.2020503e+08
B30: 44621 | C30: 312946 | D30: 65024928 | E30: 57713942 | F30: 107255 | G30: 22349687 | H30: 19836831 | I30: 420201 | J30: 87374615 | K30: 77550774 | L30: 536699 | M30: 1.1162744e+08 | N30: 99076767 | O30: 361057 | P30: 75172782 | Q30: 66720837 | R30: 897756 | S30: 1.8680022e+08 | T30: 1.657976e+08 | U30: 849645 | V30: 1.7665237e+08 | W30: 1.5679071e+08 | X30: 468312 | Y30: 97522469 | Z30: 86557668 | AA30: 1317957 | AB30: 2.7417484e+08 | AC30: 2.4334838e+08
B31: 44652 | C31: 314601 | D31: 64398460 | E31: 57957137 | F31: 107763 | G31: 22144900 | H31: 19929902 | I31: 422364 | J31: 86543360 | K31: 77887039 | L31: 552501 | M31: 1.1325326e+08 | N31: 1.0192533e+08 | O31: 374925 | P31: 77008669 | Q31: 69306036 | R31: 927426 | S31: 1.9026192e+08 | T31: 1.7123137e+08 | U31: 867102 | V31: 1.7765172e+08 | W31: 1.5988247e+08 | X31: 482688 | Y31: 99153569 | Z31: 89235939 | AA31: 1349790 | AB31: 2.7680528e+08 | AC31: 2.4911841e+08
B32: 44682 | C32: 316872 | D32: 64040185 | E32: 58325654 | F32: 108938 | G32: 22119131 | H32: 20145363 | I32: 425810 | J32: 86159315 | K32: 78471017 | L32: 605836 | M32: 1.2266475e+08 | N32: 1.1171894e+08 | O32: 477591 | P32: 96946925 | Q32: 88296010 | R32: 1083427 | S32: 2.1961167e+08 | T32: 2.0001495e+08 | U32: 922708 | V32: 1.8670493e+08 | W32: 1.700446e+08 | X32: 586529 | Y32: 1.1906606e+08 | Z32: 1.0844137e+08 | AA32: 1509237 | AB32: 3.0577099e+08 | AC32: 2.7848597e+08
B33: 44713 | C33: 317138 | D33: 63479807 | E33: 58354483 | F33: 109221 | G33: 21970942 | H33: 20197021 | I33: 426359 | J33: 85450749 | K33: 78551504 | L33: 615086 | M33: 1.2333625e+08 | N33: 1.1337815e+08 | O33: 487043 | P33: 97952144 | Q33: 90043543 | R33: 1102129 | S33: 2.212884e+08 | T33: 2.034217e+08 | U33: 932224 | V33: 1.8681606e+08 | W33: 1.7173264e+08 | X33: 596264 | Y33: 1.1992309e+08 | Z33: 1.1024056e+08 | AA33: 1528488 | AB33: 3.0673914e+08 | AC33: 2.819732e+08
B34: 44743 | C34: 317824 | D34: 65778530 | E34: 61298892 | F34: 109691 | G34: 22815305 | H34: 21261541 | I34: 427515 | J34: 88593835 | K34: 82560433 | L34: 621791 | M34: 1.2893053e+08 | N34: 1.2015012e+08 | O34: 498271 | P34: 1.0362305e+08 | Q34: 96566129 | R34: 1120062 | S34: 2.3255357e+08 | T34: 2.1671625e+08 | U34: 939615 | V34: 1.9470906e+08 | W34: 1.8144901e+08 | X34: 607962 | Y34: 1.2643835e+08 | Z34: 1.1782767e+08 | AA34: 1547577 | AB34: 3.2114741e+08 | AC34: 2.9927668e+08
B35: 44774 | C35: 322017 | D35: 65834798 | E35: 62094245 | F35: 110018 | G35: 22608662 | H35: 21324100 | I35: 432035 | J35: 88443461 | K35: 83418344 | L35: 660104 | M35: 1.3482405e+08 | N35: 1.2716371e+08 | O35: 538150 | P35: 1.0982522e+08 | Q35: 1.0358525e+08 | R35: 1198254 | S35: 2.4464927e+08 | T35: 2.3074897e+08 | U35: 982121 | V35: 2.0065885e+08 | W35: 1.8925796e+08 | X35: 648168 | Y35: 1.3243388e+08 | Z35: 1.2490935e+08 | AA35: 1630289 | AB35: 3.3309273e+08 | AC35: 3.1416731e+08
B36: 44805 | C36: 321661 | D36: 65185702 | E36: 62013553 | F36: 109838 | G36: 22377286 | H36: 21288335 | I36: 431499 | J36: 87562989 | K36: 83301888 | L36: 679141 | M36: 1.3737837e+08 | N36: 1.3069309e+08 | O36: 553055 | P36: 1.1154213e+08 | Q36: 1.0611412e+08 | R36: 1232196 | S36: 2.489205e+08 | T36: 2.3680722e+08 | U36: 1000802 | V36: 2.0256407e+08 | W36: 1.9270664e+08 | X36: 662893 | Y36: 1.3391942e+08 | Z36: 1.2740246e+08 | AA36: 1663695 | AB36: 3.3648349e+08 | AC36: 3.201091e+08
B37: 44835 | C37: 322141 | D37: 64939678 | E37: 62098940 | F37: 109963 | G37: 22287718 | H37: 21312758 | I37: 432104 | J37: 87227396 | K37: 83411698 | L37: 686334 | M37: 1.3802433e+08 | N37: 1.3198656e+08 | O37: 563950 | P37: 1.1295606e+08 | Q37: 1.0801488e+08 | R37: 1250284 | S37: 2.509804e+08 | T37: 2.4000144e+08 | U37: 1008475 | V37: 2.0296401e+08 | W37: 1.940855e+08 | X37: 673913 | Y37: 1.3524378e+08 | Z37: 1.2932764e+08 | AA37: 1682388 | AB37: 3.3820779e+08 | AC37: 3.2341314e+08
B38: 44866 | C38: 327443 | D38: 65329470 | E38: 63080933 | F38: 121585 | G38: 24404357 | H38: 23564397 | I38: 449028 | J38: 89733827 | K38: 86645330 | L38: 704099 | M38: 1.4005677e+08 | N38: 1.3523624e+08 | O38: 584193 | P38: 1.1551298e+08 | Q38: 1.115372e+08 | R38: 1288292 | S38: 2.5556975e+08 | T38: 2.4677344e+08 | U38: 1031542 | V38: 2.0538624e+08 | W38: 1.9831717e+08 | X38: 705778 | Y38: 1.3991733e+08 | Z38: 1.351016e+08 | AA38: 1737320 | AB38: 3.4530357e+08 | AC38: 3.3341877e+08
B39: 44896 | C39: 329180 | D39: 65491792 | E39: 63417032 | F39: 125728 | G39: 25165436 | H39: 24368203 | I39: 454908 | J39: 90657229 | K39: 87785234 | L39: 717919 | M39: 1.4213914e+08 | N39: 1.3763622e+08 | O39: 594890 | P39: 1.1699325e+08 | Q39: 1.1328694e+08 | R39: 1312809 | S39: 2.5913239e+08 | T39: 2.5092316e+08 | U39: 1047099 | V39: 2.0763094e+08 | W39: 2.0105325e+08 | X39: 720618 | Y39: 1.4215869e+08 | Z39: 1.3765514e+08 | AA39: 1767717 | AB39: 3.4978962e+08 | AC39: 3.3870839e+08
B40: Promedio 2022 | C40: 319227.82 | D40: 65013685 | F40: 111460.55 | G40: 22795972 | I40: 430688.36 | J40: 87809657 | L40: 626988.27 | M40: 1.2635165e+08 | O40: 488475.91 | P40: 98585573 | R40: 1115464.2 | S40: 2.2493722e+08 | U40: 946216.09 | V40: 1.9136533e+08 | X40: 599936.45 | Y40: 1.2138154e+08 | AA40: 1546152.5 | AB40: 3.1274688e+08
B41: 44927 | C41: 331003 | D41: 65497351 | E41: 63933034 | F41: 126303 | G41: 25048511 | H41: 24450261 | I41: 457306 | J41: 90545862 | K41: 88383295 | L41: 729835 | M41: 1.4328577e+08 | N41: 1.3986358e+08 | O41: 605454 | P41: 1.1792936e+08 | Q41: 1.1511277e+08 | R41: 1335289 | S41: 2.6121513e+08 | T41: 2.5497635e+08 | U41: 1060838 | V41: 2.0878312e+08 | W41: 2.0379661e+08 | X41: 731757 | Y41: 1.4297787e+08 | Z41: 1.3956303e+08 | AA41: 1792595 | AB41: 3.5176099e+08 | AC41: 3.4335965e+08
B42: 44958 | C42: 331827 | D42: 69855797 | E42: 68143594 | F42: 127315 | G42: 26819695 | H42: 26162330 | I42: 459142 | J42: 96675492 | K42: 94305924 | L42: 737271 | M42: 1.5424008e+08 | N42: 1.5045957e+08 | O42: 613433 | P42: 1.273714e+08 | Q42: 1.2424945e+08 | R42: 1350704 | S42: 2.8161147e+08 | T42: 2.7470903e+08 | U42: 1069098 | V42: 2.2409588e+08 | W42: 2.1860317e+08 | X42: 740748 | Y42: 1.5419109e+08 | Z42: 1.5041178e+08 | AA42: 1809846 | AB42: 3.7828697e+08 | AC42: 3.6901495e+08
B43: 44986 | C43: 332837 | D43: 69291957 | E43: 68328243 | F43: 128270 | G43: 26739871 | H43: 26367973 | I43: 461107 | J43: 96031828 | K43: 94696216 | L43: 745051 | M43: 1.5414314e+08 | N43: 1.5199931e+08 | O43: 620582 | P43: 1.2742588e+08 | Q43: 1.2565363e+08 | R43: 1365633 | S43: 2.8156901e+08 | T43: 2.7765294e+08 | U43: 1077888 | V43: 2.2343509e+08 | W43: 2.2032755e+08 | X43: 748852 | Y43: 1.5416575e+08 | Z43: 1.5202161e+08 | AA43: 1826740 | AB43: 3.7760084e+08 | AC43: 3.7234916e+08
B44: 45017 | C44: 337867 | D44: 70108140 | E44: 69346479 | F44: 132828 | G44: 27627198 | H44: 27327054 | I44: 470695 | J44: 97735338 | K44: 96673533 | L44: 767130 | M44: 1.577024e+08 | N44: 1.5598911e+08 | O44: 640210 | P44: 1.304476e+08 | Q44: 1.290304e+08 | R44: 1407340 | S44: 2.8815e+08 | T44: 2.8501951e+08 | U44: 1104997 | V44: 2.2781054e+08 | W44: 2.2533559e+08 | X44: 773038 | Y44: 1.580748e+08 | Z44: 1.5635746e+08 | AA44: 1878035 | AB44: 3.8588534e+08 | AC44: 3.8169305e+08
B45: 45047 | C45: 339302 | D45: 70297429 | E45: 69611830 | F45: 136126 | G45: 28275502 | H45: 27999735 | I45: 475428 | J45: 98572931 | K45: 97611565 | L45: 774874 | M45: 1.5904955e+08 | N45: 1.5749836e+08 | O45: 645979 | P45: 1.3141353e+08 | Q45: 1.3013187e+08 | R45: 1420853 | S45: 2.9046307e+08 | T45: 2.8763023e+08 | U45: 1114176 | V45: 2.2934698e+08 | W45: 2.2711019e+08 | X45: 782105 | Y45: 1.5968903e+08 | Z45: 1.5813161e+08 | AA45: 1896281 | AB45: 3.89036e+08 | AC45: 3.852418e+08
B46: 45078 | C46: 339850 | D46: 70481247 | E46: 69687358 | F46: 135689 | G46: 28227024 | H46: 27909080 | I46: 475539 | J46: 98708271 | K46: 97596438 | L46: 779821 | M46: 1.6023645e+08 | N46: 1.5843157e+08 | O46: 651738 | P46: 1.3270027e+08 | Q46: 1.3120556e+08 | R46: 1431559 | S46: 2.9293672e+08 | T46: 2.8963713e+08 | U46: 1119671 | V46: 2.307177e+08 | W46: 2.2811893e+08 | X46: 787427 | Y46: 1.6092729e+08 | Z46: 1.5911464e+08 | AA46: 1907098 | AB46: 3.9164499e+08 | AC46: 3.8723357e+08
...

Sheet 1.3
B2: PAGOS PENSIÓN BÁSICA SOLIDARIA (PBS)
B4: Resumen trimestral de beneficios pagados, por tipo de beneficio y sexo
B5: (julio 2023 a septiembre 2023)
D7: PBS Invalidez
B8: Periodo | C8: Sexo Beneficiarios | D8: N° | E8: Monto nominal M$ * | F8: Monto real M$ **
B9: 45108 | C9: Mujeres | D9: 106121 | E9: 21866468 | F9: 22038056
C10: Hombres | D10: 83495 | E10: 17204837 | F10: 17339844
C11: Total | D11: 189616 | E11: 39071305 | F11: 39377900
B12: 45139 | C12: Mujeres | D12: 106570 | E12: 21958710 | F12: 22106383
C13: Hombres | D13: 83812 | E13: 17270379 | F13: 17386522
C14: Total | D14: 190382 | E14: 39229088 | F14: 39492905
B15: 45170 | C15: Mujeres | D15: 106868 | E15: 22021397 | F15: 22021397
C16: Hombres | D16: 84043 | E16: 17319291 | F16: 17319291
C17: Total | D17: 190911 | E17: 39340689 | F17: 39340689
B18: Fuente: Elaboración propia con datos de la Superintendencia de Pensiones
B19: Nota 1: La Pensión Garantizada Universal (PGU) es un nuevo beneficio generado a partir de la ley 21.419 del 29-01-2022. El concepto de PGU No Contributiva o Contributiva está relacionado con la calidad de la persona que está recibiendo el beneficio, si es No Contributiva quiere decir que no estaba afiliado a un sistema previsional (D.L. 3.500 o antiguo Sistema de Reparto) ni recibe pensión de sobrevivencia, si es Contributiva quiere decir que si estaba afiliado a un sistema previsional o que recibe una pensión de sobrevivencia. De manera automática, en febrero 2022, los PBS de Vejez pasaron a ser PGU No Contributiva y los APS Vejez Subsidio Definido, los Beneficio artículo 9° bis y los APS Vejez con una Pensión Final Garantizada inferior o igual al monto de la PGU pasaron a ser PGU Contributiva (Fuente: Superintendencia de Pensiones). Nota 2: Para los APS de Vejez, en aquellos casos en que este beneficio superaba el monto de la PGU se mantuvo el beneficio.
B20: * Montos nominales de cada periodo de pago. ** Montos deflactados a septiembre 2023
B22: Serie resumen de pagos de beneficios acumulado, por tipo de beneficio y sexo
B23: (julio 2008 a septiembre 2023)
C25: PBS Vejez | L25: PBS Invalidez | U25: PBS Total
C26: Mujeres | F26: Hombres | I26: Total | L26: Mujeres | O26: Hombres | R26: Total | U26: Mujeres | X26: Hombres | AA26: Total
B27: Periodo | C27: N° Beneficiarios | D27: Monto real M$ * | E27: Monto nominal M$** | F27: N° Beneficiarios | G27: Monto real M$ * | H27: Monto nominal M$** | I27: N° Beneficiarios | J27: Monto real M$ * | K27: Monto nominal M$** | L27: N° Beneficiarios | M27: Monto real M$ * | N27: Monto nominal M$** | O27: N° Beneficiarios | P27: Monto real M$ * | Q27: Monto nominal M$** | R27: N° Beneficiarios | S27: Monto real M$ * | T27: Monto nominal M$** | U27: N° Beneficiarios | V27: Monto real M$ * | W27: Monto nominal M$** | X27: N° Beneficiarios | Y27: Monto real M$ * | Z27: Monto nominal M$** | AA27: N° Beneficiarios | AB27: Monto real M$ * | AC27: Monto nominal M$**
B28: 39630 | C28: 189150 | D28: 19912309 | E28: 11349000 | F28: 101420 | G28: 10676745 | H28: 6085200 | I28: 290570 | J28: 30589054 | K28: 17434200 | L28: 108433 | M28: 11415022 | N28: 6505980 | O28: 84278 | P28: 8872162.5 | Q28: 5056680 | R28: 192711 | S28: 20287184 | T28: 11562660 | U28: 297583 | V28: 31327330 | W28: 17854980 | X28: 185698 | Y28: 19548908 | Z28: 11141880 | AA28: 483281 | AB28: 50876238 | AC28: 28996860
B29: 39661 | C29: 190466 | D29: 19865636 | E29: 11427960 | F29: 101671 | G29: 10604302 | H29: 6100260 | I29: 292137 | J29: 30469938 | K29: 17528220 | L29: 109472 | M29: 11417948 | N29: 6568320 | O29: 84832 | P29: 8847991.8 | Q29: 5089920 | R29: 194304 | S29: 20265940 | T29: 11658240 | U29: 299938 | V29: 31283583 | W29: 17996280 | X29: 186503 | Y29: 19452294 | Z29: 11190180 | AA29: 486441 | AB29: 50735878 | AC29: 29186460
B30: 39692 | C30: 221382 | D30: 22842166 | E30: 13279878 | F30: 108164 | G30: 11160690 | H30: 6488553 | I30: 329546 | J30: 34002856 | K30: 19768431 | L30: 108958 | M30: 11244847 | N30: 6537480 | O30: 84560 | P30: 8726888.2 | Q30: 5073600 | R30: 193518 | S30: 19971736 | T30: 11611080 | U30: 330340 | V30: 34087013 | W30: 19817358 | X30: 192724 | Y30: 19887578 | Z30: 11562153 | AA30: 523064 | AB30: 53974591 | AC30: 31379511
B31: 39722 | C31: 230808 | D31: 25958557 | E31: 15225060 | F31: 110075 | G31: 11794176 | H31: 6917450.4 | I31: 340883 | J31: 37752733 | K31: 22142510 | L31: 108604 | M31: 11154003 | N31: 6541980 | O31: 84437 | P31: 8685319.3 | Q31: 5094062.2 | R31: 193041 | S31: 19839322 | T31: 11636042 | U31: 339412 | V31: 37112560 | W31: 21767040 | X31: 194512 | Y31: 20479495 | Z31: 12011513 | AA31: 533924 | AB31: 57592055 | AC31: 33778552
B32: 39753 | C32: 236178 | D32: 25833511 | E32: 15133152 | F32: 111136 | G32: 11797674 | H32: 6911023.4 | I32: 347314 | J32: 37631185 | K32: 22044175 | L32: 108404 | M32: 11222894 | N32: 6574320 | O32: 84286 | P32: 8687151.1 | Q32: 5088893.3 | R32: 192690 | S32: 19910045 | T32: 11663213 | U32: 344582 | V32: 37056405 | W32: 21707472 | X32: 195422 | Y32: 20484825 | Z32: 11999917 | AA32: 540004 | AB32: 57541230 | AC32: 33707389
B33: 39783 | C33: 244815 | D33: 27919985 | E33: 16162567 | F33: 113630 | G33: 12618476 | H33: 7304694.3 | I33: 358445 | J33: 40538460 | K33: 23467261 | L33: 109628 | M33: 12198612 | N33: 7061640 | O33: 84823 | P33: 9180855.6 | Q33: 5314694.6 | R33: 194451 | S33: 21379468 | T33: 12376335 | U33: 354443 | V33: 40118597 | W33: 23224207 | X33: 198453 | Y33: 21799331 | Z33: 12619389 | AA33: 552896 | AB33: 61917928 | AC33: 35843596
B34: Promedio 2008 | C34: 218799.83 | D34: 23722027 | F34: 107682.67 | G34: 11442010 | I34: 326482.5 | J34: 35164038 | L34: 108916.5 | M34: 11442221 | O34: 84536 | P34: 8833394.8 | R34: 193452.5 | S34: 20275616 | U34: 327716.33 | V34: 35164248 | X34: 192218.67 | Y34: 20275405 | AA34: 519935 | AB34: 55439653
B35: 39814 | C35: 249383 | D35: 27220496 | E35: 15637466 | F35: 114748 | G35: 12345448 | H35: 7092138.1 | I35: 364131 | J35: 39565944 | K35: 22729604 | L35: 110901 | M35: 12585070 | N35: 7229794.9 | O35: 85291 | P35: 9314923.1 | Q35: 5351180.5 | R35: 196192 | S35: 21899993 | T35: 12580975 | U35: 360284 | V35: 39805567 | W35: 22867260 | X35: 200039 | Y35: 21660371 | Z35: 12443319 | AA35: 560323 | AB35: 61465938 | AC35: 35310579
B36: 39845 | C36: 251808 | D36: 27265136 | E36: 15606042 | F36: 115183 | G36: 12336813 | H36: 7061355.5 | I36: 366991 | J36: 39601949 | K36: 22667397 | L36: 111775 | M36: 12638213 | N36: 7233871 | O36: 85481 | P36: 9292200.9 | Q36: 5318677.9 | R36: 197256 | S36: 21930414 | T36: 12552549 | U36: 363583 | V36: 39903349 | W36: 22839913 | X36: 200664 | Y36: 21629014 | Z36: 12380033 | AA36: 564247 | AB36: 61532362 | AC36: 35219946
B37: 39873 | C37: 254074 | D37: 27220535 | E37: 15641611 | F37: 115759 | G37: 12374451 | H37: 7110673.6 | I37: 369833 | J37: 39594986 | K37: 22752284 | L37: 112459 | M37: 12578951 | N37: 7228184.6 | O37: 85609 | P37: 9241675.4 | Q37: 5310501.4 | R37: 198068 | S37: 21820626 | T37: 12538686 | U37: 366533 | V37: 39799486 | W37: 22869795 | X37: 201368 | Y37: 21616126 | Z37: 12421175 | AA37: 567901 | AB37: 61415612 | AC37: 35290970
B38: 39904 | C38: 255795 | D38: 27294014 | E38: 15659383 | F38: 116177 | G38: 12344314 | H38: 7082298 | I38: 371972 | J38: 39638328 | K38: 22741681 | L38: 113104 | M38: 12721432 | N38: 7298661.3 | O38: 85787 | P38: 9323589.3 | Q38: 5349218.8 | R38: 198891 | S38: 22045021 | T38: 12647880 | U38: 368899 | V38: 40015446 | W38: 22958044 | X38: 201964 | Y38: 21667903 | Z38: 12431517 | AA38: 570863 | AB38: 61683349 | AC38: 35389561
B39: 39934 | C39: 258094 | D39: 27660890 | E39: 15830183 | F39: 116638 | G39: 12434818 | H39: 7116381.5 | I39: 374732 | J39: 40095708 | K39: 22946564 | L39: 114003 | M39: 13010291 | N39: 7445721.3 | O39: 86085 | P39: 9492169.1 | Q39: 5432318.8 | R39: 200088 | S39: 22502460 | T39: 12878040 | U39: 372097 | V39: 40671181 | W39: 23275904 | X39: 202723 | Y39: 21926987 | Z39: 12548700 | AA39: 574820 | AB39: 62598168 | AC39: 35824604
B40: 39965 | C40: 260086 | D40: 27820048 | E40: 15976445 | F40: 116982 | G40: 12445188 | H40: 7146998.9 | I40: 377068 | J40: 40265236 | K40: 23123444 | L40: 114983 | M40: 13290784 | N40: 7632606.4 | O40: 86441 | P40: 9557654.4 | Q40: 5488751.8 | R40: 201424 | S40: 22848438 | T40: 13121358 | U40: 375069 | V40: 41110832 | W40: 23609051 | X40: 203423 | Y40: 22002842 | Z40: 12635751 | AA40: 578492 | AB40: 63113674 | AC40: 36244802
B41: 39995 | C41: 261334 | D41: 34828687 | E41: 19913272 | F41: 117124 | G41: 15571257 | H41: 8902853.2 | I41: 378458 | J41: 50399944 | K41: 28816125 | L41: 116028 | M41: 16635501 | N41: 9511333.8 | O41: 86710 | P41: 11890388 | Q41: 6798319.4 | R41: 202738 | S41: 28525890 | T41: 16309653 | U41: 377362 | V41: 51464188 | W41: 29424606 | X41: 203834 | Y41: 27461646 | Z41: 15701173 | AA41: 581196 | AB41: 78925834 | AC41: 45125779
B42: 40026 | C42: 261917 | D42: 35023810 | E42: 19952725 | F42: 117348 | G42: 15826174 | H42: 9016017.8 | I42: 379265 | J42: 50849984 | K42: 28968743 | L42: 117514 | M42: 17331276 | N42: 9873459.8 | O42: 87229 | P42: 12204754 | Q42: 6952929.9 | R42: 204743 | S42: 29536030 | T42: 16826390 | U42: 379431 | V42: 52355086 | W42: 29826185 | X42: 204577 | Y42: 28030928 | Z42: 15968948 | AA42: 584008 | AB42: 80386014 | AC42: 45795132
B43: 40057 | C43: 267244 | D43: 36659911 | E43: 21089929 | F43: 117430 | G43: 15541802 | H43: 8940979.5 | I43: 384674 | J43: 52201713 | K43: 30030908 | L43: 118761 | M43: 17183140 | N43: 9885217.8 | O43: 87678 | P43: 12088694 | Q43: 6954455 | R43: 206439 | S43: 29271834 | T43: 16839673 | U43: 386005 | V43: 53843051 | W43: 30975147 | X43: 205108 | Y43: 27630497 | Z43: 15895434 | AA43: 591113 | AB43: 81473547 | AC43: 46870581
B44: 40087 | C44: 273548 | D44: 37398149 | E44: 21514109 | F44: 118419 | G44: 15908973 | H44: 9151987.3 | I44: 391967 | J44: 53307122 | K44: 30666096 | L44: 120250 | M44: 17754357 | N44: 10213585 | O44: 88090 | P44: 12213741 | Q44: 7026223.8 | R44: 208340 | S44: 29968098 | T44: 17239809 | U44: 393798 | V44: 55152506 | W44: 31727694 | X44: 206509 | Y44: 28122715 | Z44: 16178211 | AA44: 600307 | AB44: 83275221 | AC44: 47905905
B45: 40118 | C45: 275060 | D45: 36645982 | E45: 20985331 | F45: 118547 | G45: 15729190 | H45: 9007325.1 | I45: 393607 | J45: 52375172 | K45: 29992656 | L45: 121468 | M45: 17662445 | N45: 10114404 | O45: 88421 | P45: 12177401 | Q45: 6973391.8 | R45: 209889 | S45: 29839845 | T45: 17087795 | U45: 396528 | V45: 54308427 | W45: 31099735 | X45: 206968 | Y45: 27906591 | Z45: 15980717 | AA45: 603496 | AB45: 82215018 | AC45: 47080452
...

Sheet DINAMICA APS
A1: PERIODO | B1: (Varios elementos) | I1: PERIODO | J1: (Varios elementos) | O1: PERIODO | P1: (Varios elementos)
A3: Etiquetas de fila | B3: Suma de APS VEJEZ MUJER n | C3: Suma de APS VEJEZ HOMBRE n | D3: Suma de APS INVALIDEZ MUJER N | E3: Suma de APS INVALIDEZ HOMBRE N | F3: Suma de APS TOTAL MUJER N | G3: Suma de APS TOTAL HOMBRE N | I3: Etiquetas de fila | J3: Suma de APS VEJEZ MUJER nom | K3: Suma de APS VEJEZ HOMBRE nom | L3: Suma de APS INVALIDEZ MUJER nom | M3: Suma de APS INVALIDEZ HOMBRE nom | O3: Etiquetas de fila | P3: Suma de PBSV_MUJER REAL | Q3: Suma de PBSV_HOMBRE REAL | R3: Suma de PBSI_MUJER REAL | S3: Suma de PBSI_HOMBRE REAL
A4: 2022 | B4: 327413 | C4: 190531 | D4: 137530 | E4: 139864 | F4: 464943 | G4: 330395 | I4: 2022 | J4: 69469277 | K4: 40636216 | L4: 22985157 | M4: 22214073 | O4: 2022 | P4: 69114843 | Q4: 40428576 | R4: 22868011 | S4: 22101174
A5: oct | B5: 109393 | C5: 63815 | D5: 45739 | E5: 46381 | F5: 155132 | G5: 110196 | I5: oct | J5: 23196046 | K5: 13590242 | L5: 7659976.5 | M5: 7378442.3 | O5: oct | P5: 22907040 | Q5: 13420918 | R5: 7564538.8 | S5: 7286512.4
A6: nov | B6: 109031 | C6: 63526 | D6: 45910 | E6: 46666 | F6: 154941 | G6: 110192 | I6: nov | J6: 23133194 | K6: 13546987 | L6: 7675227.2 | M6: 7413824.5 | O6: nov | P6: 23067766 | Q6: 13508672 | R6: 7653519.1 | S6: 7392855.8
A7: dic | B7: 108989 | C7: 63190 | D7: 45881 | E7: 46817 | F7: 154870 | G7: 110007 | I7: dic | J7: 23140038 | K7: 13498987 | L7: 7649953.3 | M7: 7421805.9 | O7: dic | P7: 23140038 | Q7: 13498987 | R7: 7649953.3 | S7: 7421805.9
A11: PERIODO | B11: (Varios elementos)
A13: Etiquetas de fila | B13: Suma de APS VEJEZ MUJER n | C13: Suma de APS VEJEZ HOMBRE n | D13: Suma de APS INVALIDEZ MUJER N | E13: Suma de APS INVALIDEZ HOMBRE N | F13: Suma de APS TOTAL MUJER N | G13: Suma de APS TOTAL HOMBRE N
A14: 2022 | B14: 2017877 | C14: 1478761 | D14: 540602 | E14: 538156 | F14: 2558479 | G14: 2016917
A17: PERIODO | B17: (Varios elementos)
A19: Etiquetas de fila | B19: Promedio de APS VEJEZ MUJER n | C19: Promedio de APS VEJEZ HOMBRE n | D19: Promedio de APS INVALIDEZ MUJER N | E19: Promedio de APS INVALIDEZ HOMBRE N | F19: Promedio de APS TOTAL MUJER N | G19: Promedio de APS TOTAL HOMBRE N
A20: 2022 | B20: 168156.42 | C20: 123230.08 | D20: 45050.167 | E20: 44846.333 | F20: 213206.58 | G20: 168076.42
A23: PERIODO | B23: (Varios elementos)
A25: Etiquetas de fila | B25: Suma de APS VEJEZ MUJER nom | C25: Suma de APS VEJEZ HOMBRE nom | D25: Suma de APS INVALIDEZ MUJER nom | E25: Suma de APS INVALIDEZ HOMBRE nom | F25: Suma de APS TOTAL MUJER nom | G25: Suma de APS TOTAL HOMBRE nom
A26: 2022 | B26: 3.6244601e+08 | C26: 2.505165e+08 | D26: 89129737 | E26: 84667893 | F26: 4.5157575e+08 | G26: 3.3518439e+08
A29: PERIODO | B29: (Varios elementos)
A31: Etiquetas de fila | B31: Promedio de APS VEJEZ MUJER nom | C31: Promedio de APS VEJEZ HOMBRE nom | D31: Promedio de APS INVALIDEZ MUJER nom | E31: Promedio de APS INVALIDEZ HOMBRE nom | F31: Promedio de APS TOTAL MUJER nom | G31: Promedio de APS TOTAL HOMBRE nom
A32: 2022 | B32: 30203834 | C32: 20876375 | D32: 7427478.1 | E32: 7055657.8 | F32: 37631312 | G32: 27932033
A35: PERIODO | B35: (Varios elementos)
A37: Etiquetas de fila | B37: Suma de PBSV_MUJER REAL | C37: Suma de PBSV_HOMBRE REAL | D37: Suma de PBSI_MUJER REAL | E37: Suma de PBSI_HOMBRE REAL
A38: 2022 | B38: 3.4085177e+08 | C38: 2.344632e+08 | D38: 85046490 | E38: 80830616
A42: PERIODO | B42: (Varios elementos)
A44: Etiquetas de fila | B44: Promedio de PBSV_MUJER REAL | C44: Promedio de PBSV_HOMBRE REAL | D44: Promedio de PBSI_MUJER REAL | E44: Promedio de PBSI_HOMBRE REAL
A45: 2022 | B45: 28404314 | C45: 19538600 | D45: 7087207.5 | E45: 6735884.7
A51: Etiquetas de fila | B51: Promedio de APS VEJEZ MUJER n | C51: Promedio de APS VEJEZ HOMBRE n | D51: Promedio de APS INVALIDEZ MUJER N | E51: Promedio de APS INVALIDEZ HOMBRE N
A52: 2008 | B52: 2920.6667 | C52: 1116 | D52: 286.33333 | E52: 290.33333
A53: 2009 | B53: 35080.083 | C53: 24939.75 | D53: 2213.8333 | E53: 1769.75
A54: 2010 | B54: 184671.58 | C54: 128661.83 | D54: 8050.9167 | E54: 5922.9167
A55: 2011 | B55: 232153.67 | C55: 168868.75 | D55: 12883.083 | E55: 9283.4167
A56: 2012 | B56: 279628 | C56: 203893.75 | D56: 19231.417 | E56: 14584.75
A57: 2013 | B57: 327092.08 | C57: 237763.33 | D57: 26607.083 | E57: 21058.833
A58: 2014 | B58: 354831.83 | C58: 258135.42 | D58: 33075.25 | E58: 26998.167
A59: 2015 | B59: 385388.58 | C59: 279293.17 | D59: 35497.583 | E59: 29292.083
A60: 2016 | B60: 409696.25 | C60: 297461.08 | D60: 35477.75 | E60: 29444.667
A61: 2017 | B61: 434014.42 | C61: 315115.08 | D61: 35236.417 | E61: 29440.417
A62: 2018 | B62: 472783.58 | C62: 343894.42 | D62: 35802.167 | E62: 30349.5
A63: 2019 | B63: 513930.5 | C63: 376625 | D63: 36751.75 | E63: 31642.25
... A90: dic | B90: 108989 | C90: 63190 | D90: 45881 | E90: 46817
A94: Etiquetas de fila | B94: Promedio de PBSV_MUJER REAL | C94: Promedio de PBSV_HOMBRE REAL | D94: Promedio de PBSI_MUJER REAL | E94: Promedio de PBSI_HOMBRE REAL
A95: 2008 | B95: 156325.61 | C95: 77435.604 | D95: 15483.202 | E95: 15243.679
...

Sheet 1.4
B2: PAGOS APORTE PREVISIONAL SOLIDARIO (APS)
B4: Resumen trimestral de beneficios pagados, por tipo de beneficio y sexo
B5: (julio 2023 a septiembre 2023)
D7: APS Vejez | G7: APS Invalidez | J7: APS Total
B8: Periodo | C8: Sexo Beneficiarios | D8: N° | E8: Monto nominal M$ * | F8: Monto real M$ ** | G8: N° | H8: Monto nominal M$ * | I8: Monto real M$ ** | J8: N° | K8: Monto nominal M$ * | L8: Monto real M$ **
B9: 45108 | C9: Mujeres | D9: 107603 | E9: 25329300 | F9: 25528060 | G9: 47071 | H9: 8333096.5 | I9: 8398486.8 | J9: 154674 | K9: 33662396 | L9: 33926547
C10: Hombres | D10: 61709 | E10: 14707933 | F10: 14823347 | G10: 49165 | H10: 8270074.9 | I10: 8334970.7 | J10: 110874 | K10: 22978008 | L10: 23158318
C11: Total | D11: 169312 | E11: 40037232 | F11: 40351407 | G11: 96236 | H11: 16603171 | I11: 16733458 | J11: 265548 | K11: 56640404 | L11: 57084865
B12: 45139 | C12: Mujeres | D12: 107495 | E12: 25328349 | F12: 25498683 | G12: 47164 | H12: 8347020.6 | I12: 8403154.5 | J12: 154659 | K12: 33675370 | L12: 33901838
C13: Hombres | D13: 61425 | E13: 14670727 | F13: 14769388 | G13: 49448 | H13: 8312011.6 | I13: 8367910.1 | J13: 110873 | K13: 22982738 | L13: 23137298
C14: Total | D14: 168920 | E14: 39999076 | F14: 40268071 | G14: 96612 | H14: 16659032 | I14: 16771065 | J14: 265532 | K14: 56658108 | L14: 57039136
B15: 45170 | C15: Mujeres | D15: 107346 | E15: 25293121 | F15: 25293121 | G15: 47248 | H15: 8349348.3 | I15: 8349348.3 | J15: 154594 | K15: 33642470 | L15: 33642470
C16: Hombres | D16: 61168 | E16: 14619374 | F16: 14619374 | G16: 49763 | H16: 8344374.8 | I16: 8344374.8 | J16: 110931 | K16: 22963749 | L16: 22963749
C17: Total | D17: 168514 | E17: 39912496 | F17: 39912496 | G17: 97011 | H17: 16693723 | I17: 16693723 | J17: 265525 | K17: 56606219 | L17: 56606219
B18: Fuente: Elaboración propia con datos de la Superintendencia de Pensiones
B19: Nota 1: La Pensión Garantizada Universal (PGU) es un nuevo beneficio generado a partir de la ley 21.419 del 29-01-2022. El concepto de PGU No Contributiva o Contributiva está relacionado con la calidad de la persona que está recibiendo el beneficio, si es No Contributiva quiere decir que no estaba afiliado a un sistema previsional (D.L. 3.500 o antiguo Sistema de Reparto) ni recibe pensión de sobrevivencia, si es Contributiva quiere decir que si estaba afiliado a un sistema previsional o que recibe una pensión de sobrevivencia. De manera automática, en febrero 2022, los PBS de Vejez pasaron a ser PGU No Contributiva y los APS Vejez Subsidio Definido, los Beneficio artículo 9° bis y los APS Vejez con una Pensión Final Garantizada inferior o igual al monto de la PGU pasaron a ser PGU Contributiva (Fuente: Superintendencia de Pensiones). Nota 2: Para los APS de Vejez, en aquellos casos en que este beneficio superaba el monto de la PGU se mantuvo el beneficio.
B20: * Montos nominales de cada periodo de pago. ** Montos deflactados a septiembre 2023
B22: Serie resumen de pagos de beneficios acumulado, por tipo de beneficio y sexo
B23: (julio 2008 a septiembre 2023)
C25: APS Vejez | L25: APS Invalidez | U25: APS Total
C26: Mujeres | F26: Hombres | I26: Total | L26: Mujeres | O26: Hombres | R26: Total | U26: Mujeres | X26: Hombres | AA26: Total
B27: Periodo | C27: N° Beneficios | D27: Monto real M$ * | E27: Monto nominal M$** | F27: N° Beneficios | G27: Monto real M$ * | H27: Monto nominal M$** | I27: N° Beneficios | J27: Monto real M$ * | K27: Monto nominal M$** | L27: N° Beneficios | M27: Monto real M$ * | N27: Monto nominal M$** | O27: N° Beneficios | P27: Monto real M$ * | Q27: Monto nominal M$** | R27: N° Beneficios | S27: Monto real M$ * | T27: Monto nominal M$** | U27: N° Beneficios | V27: Monto real M$ * | W27: Monto nominal M$** | X27: N° Beneficios | Y27: Monto real M$ * | Z27: Monto nominal M$** | AA27: N° Beneficios | AB27: Monto real M$ * | AC27: Monto nominal M$**
B28: 39630
B29: 39661
B30: 39692
B31: 39722 | C31: 2444 | D31: 657365.14 | E31: 385553.92 | F31: 955 | G31: 326838.35 | H31: 191695.3 | I31: 3399 | J31: 984203.49 | K31: 577249.22 | L31: 217 | M31: 60234.082 | N31: 35328.138 | O31: 229 | P31: 61248.516 | Q31: 35923.118 | R31: 446 | S31: 121482.6 | T31: 71251.256 | U31: 2661 | V31: 717599.22 | W31: 420882.06 | X31: 1184 | Y31: 388086.86 | Z31: 227618.42 | AA31: 3845 | AB31: 1105686.1 | AC31: 648500.47
B32: 39753 | C32: 3067 | D32: 329411.92 | E32: 192967.99 | F32: 1159 | G32: 146218.4 | H32: 85654.067 | I32: 4226 | J32: 475630.31 | K32: 278622.06 | L32: 290 | M32: 35030.578 | N32: 20520.752 | O32: 294 | P32: 33520.768 | Q32: 19636.312 | R32: 584 | S32: 68551.346 | T32: 40157.064 | U32: 3357 | V32: 364442.49 | W32: 213488.74 | X32: 1453 | Y32: 179739.17 | Z32: 105290.38 | AA32: 4810 | AB32: 544181.66 | AC32: 318779.12
B33: 39783 | C33: 3251 | D33: 343011.09 | E33: 198565.28 | F33: 1234 | G33: 186026.16 | H33: 107688.46 | I33: 4485 | J33: 529037.25 | K33: 306253.75 | L33: 352 | M33: 36515.178 | N33: 21138.228 | O33: 348 | P33: 34943.56 | Q33: 20228.436 | R33: 700 | S33: 71458.738 | T33: 41366.664 | U33: 3603 | V33: 379526.27 | W33: 219703.51 | X33: 1582 | Y33: 220969.72 | Z33: 127916.9 | AA33: 5185 | AB33: 600495.99 | AC33: 347620.41
B34: Promedio 2008 | C34: 2920.6667 | D34: 443262.72 | F34: 1116 | G34: 219694.3 | I34: 4036.6667 | J34: 662957.02 | L34: 286.33333 | M34: 43926.613 | O34: 290.33333 | P34: 43237.615 | R34: 576.66667 | S34: 87164.227 | U34: 3207 | V34: 487189.33 | X34: 1406.3333 | Y34: 262931.92 | AA34: 4613.3333 | AB34: 750121.25
