Workbook

Sheet Indice General
B1: Subsecretaría de Previsión Social Dirección de Estudios Previsionales
B9: Informe trimestral del Pilar No Contributivo
B10: Trimestre EFM 2023
B12: I. Pago de Beneficios del Pilar No Contributivo
B13: 1. Total de beneficios pagados del Pilar No Contributivo
B14: 2. Pagos Pensión Garantizada Universal (PGU)
B15: 3. Pagos Pensión Básica Solidaria (PBS)
B16: 4. Pagos Aporte Previsional Solidario (APS)
B17: II. Estado de solicitudes
B18: 1. Solicitudes del Pilar No Contributivo a nivel nacional
B19: 2. Solicitudes a nivel regional y comunal
B20: 3. Solicitudes concedidas del Pilar No Contributivo a nivel nacional
... B29: 3. Subsidio a la Cotización de Trabajadores Jóvenes

Sheet I. Beneficios pagados
B1: Subsecretaría de Previsión Social Dirección de Estudios Previsionales
B9: I. Pago de Beneficios del Pilar No Contributivo
B10: Trimestre EFM 2023
B12: 1. Total de beneficios pagados del Pilar No Contributivo
B13: i. Resumen trimestral de beneficios pagados, por tipo y sexo
B14: ii. Serie resumen de pagos de beneficios acumulados, por tipo de beneficio
B15: 2. Pagos Pensión Garantizada Universal (PGU)
B16: i. Resumen trimestral de beneficios pagados, por tipo de beneficio y sexo
B17: ii. Serie resumen de pagos de beneficios acumulado, por tipo de beneficio y sexo
B18: 3. Pagos Pensión Básica Solidaria (PBS)
B19: i. Resumen trimestral de beneficios pagados, por tipo de beneficio y sexo
B20: ii. Serie resumen de pagos de beneficios acumulado, por tipo de beneficio y sexo
... B23: ii. Serie resumen de pagos de beneficios acumulado, por tipo y sexo

Sheet dinamica pgu
A1: PERIODO | B1: (Varios elementos)
A3: Etiquetas de fila
A4: oct
A5: Suma de PGU_NC_Mujer_n | B5: 322141
A6: Suma de PGU_NC_hombre_N | B6: 109963
A7: Suma de PGU_C_Mujer_N | B7: 686334
A8: Suma de PGU_C_hombre_N | B8: 563950
A9: nov
A10: Suma de PGU_NC_Mujer_n | B10: 327443
A11: Suma de PGU_NC_hombre_N | B11: 121585
A12: Suma de PGU_C_Mujer_N | B12: 704099
A13: Suma de PGU_C_hombre_N | B13: 584193
A14: dic
A15: Suma de PGU_NC_Mujer_n | B15: 329180
A16: Suma de PGU_NC_hombre_N | B16: 125728
A17: Suma de PGU_C_Mujer_N | B17: 717919
A18: Suma de PGU_C_hombre_N | B18: 594890
A22: PERIODO | B22: (Varios elementos)
A24: Etiquetas de fila
A25: oct
A26: Suma de PGU_NC_Mujer_Nom | B26: 62098940
A27: Suma de PGU_NC_hombre_Nom | B27: 21312758
A28: Suma de PGU_C_Mujer_Nom | B28: 1.3198656e+08
A29: Suma de PGU_C_hombre_Nom | B29: 1.0801488e+08
A30: nov
A31: Suma de PGU_NC_Mujer_Nom | B31: 63080933
A32: Suma de PGU_NC_hombre_Nom | B32: 23564397
A33: Suma de PGU_C_Mujer_Nom | B33: 1.3523624e+08
A34: Suma de PGU_C_hombre_Nom | B34: 1.115372e+08
A35: dic
A36: Suma de PGU_NC_Mujer_Nom | B36: 63417032
A37: Suma de PGU_NC_hombre_Nom | B37: 24368203
A38: Suma de PGU_C_Mujer_Nom | B38: 1.3763622e+08
A39: Suma de PGU_C_hombre_Nom | B39: 1.1328694e+08
A43: PERIODO | B43: (Varios elementos)
A45: Etiquetas de fila
A46: oct
A47: Suma de PGU_NC_Mujer_REAL | B47: 61325232
A48: Suma de PGU_NC_hombre_REAL | B48: 21047217
A49: Suma de PGU_C_Mujer_REAL | B49: 1.303421e+08
...

Sheet N PBS
A3: Etiquetas de fila | B3: Promedio de PBS VEJEZ MUJER | C3: Promedio de PBS VEJEZ HOMBRE | D3: Promedio de PBS INVALIDEZ MUJER | E3: Promedio de PBS INVALIDEZ HOMBRE | F3: Promedio de PBS TOTAL MUJER | G3: Promedio de PBS TOTAL HOMBRE
A4: 2008 | B4: 218799.83 | C4: 107682.67 | D4: 108916.5 | E4: 84536 | F4: 327716.33 | G4: 192218.67
A5: 2009 | B5: 262267.25 | C5: 117026.58 | D5: 116205.08 | E5: 86817.667 | F5: 378472.33 | G5: 203844.25
A6: 2010 | B6: 284569.67 | C6: 119969.58 | D6: 125529.75 | E6: 89731.417 | F6: 410099.42 | G6: 209701
A7: 2011 | B7: 286982.92 | C7: 118668.92 | D7: 125674.58 | E7: 89317.917 | F7: 412657.5 | G7: 207986.83
A8: 2012 | B8: 288232.25 | C8: 116683.83 | D8: 120025.92 | E8: 85446.25 | F8: 408258.17 | G8: 202130.08
A9: 2013 | B9: 288720.25 | C9: 114312 | D9: 112605.08 | E9: 79812.917 | F9: 401325.33 | G9: 194124.92
A10: 2014 | B10: 288530.42 | C10: 111136.17 | D10: 107377.17 | E10: 75527.833 | F10: 395907.58 | G10: 186664
A11: 2015 | B11: 289070.58 | C11: 110162 | D11: 105105.42 | E11: 74655.333 | F11: 394176 | G11: 184817.33
A12: 2016 | B12: 290373 | C12: 108843.42 | D12: 105459.83 | E12: 75532.583 | F12: 395832.83 | G12: 184376
A13: 2017 | B13: 291754 | C13: 107694.83 | D13: 105581.83 | E13: 76434.167 | F13: 397335.83 | G13: 184129
A14: 2018 | B14: 295171.83 | C14: 107077.42 | D14: 105559.42 | E14: 77417 | F14: 400731.25 | G14: 184494.42
A15: 2019 | B15: 299821.5 | C15: 106705.25 | D15: 104899.17 | E15: 77850.417 | F15: 404720.67 | G15: 184555.67
... A42: dic | B42: 0 | C42: 0 | D42: 103979 | E42: 81605 | F42: 103979 | G42: 81605

Sheet MONTOS PBS
I1: PERIODO | J1: (Varios elementos)
A3: Etiquetas de fila | B3: Promedio de PBSV_MUJER | C3: Promedio de PBSV_HOMBRE | D3: Promedio de PBSI_MUJER | E3: Promedio de PBSI_HOMBRE | F3: Promedio de PBS_MUJER | G3: Promedio de PBS_HOMBRE | I3: Etiquetas de fila | J3: Suma de PBSV_MUJER | K3: Suma de PBSV_HOMBRE | L3: Suma de PBSV_TOTAL | M3: Suma de PBSI_MUJER | N3: Suma de PBSI_HOMBRE | O3: Suma de PBSI_TOTAL | P3: Suma de PBS_MUJER | Q3: Suma de PBS_HOMBRE | R3: Suma de PBS_TOTAL | T3: Etiquetas de fila | U3: Suma de PBSV_MUJER | V3: Suma de PBSV_HOMBRE | W3: Suma de PBSV_TOTAL | X3: Suma de PBSI_MUJER | Y3: Suma de PBSI_HOMBRE | Z3: Suma de PBSI_TOTAL | AA3: Suma de PBS_MUJER | AB3: Suma de PBS_HOMBRE | AC3: Suma de PBS_TOTAL | AE3: Etiquetas de fila | AF3: Suma de PBSV_MUJER | AG3: Suma de PBSV_HOMBRE | AH3: Suma de PBSV_TOTAL | AI3: Suma de PBSI_MUJER | AJ3: Suma de PBSI_HOMBRE | AK3: Suma de PBSI_TOTAL | AL3: Suma de PBS_MUJER | AM3: Suma de PBS_HOMBRE | AN3: Suma de PBS_TOTAL
A4: 2008 | B4: 8.2469269e+09 | C4: 3.9732077e+09 | D4: 3.9696562e+09 | E4: 3.0646136e+09 | F4: 1.2216583e+10 | G4: 7.0378213e+09 | I4: 2022 | J4: 0 | K4: 0 | L4: 0 | M4: 6.0133313e+10 | N4: 4.7149436e+10 | O4: 1.0728275e+11 | P4: 6.0133313e+10 | Q4: 4.7149436e+10 | R4: 1.0728275e+11 | T4: oct | U4: 0 | V4: 0 | W4: 0 | X4: 1.9903687e+10 | Y4: 1.5583475e+10 | Z4: 3.5487162e+10 | AA4: 1.9903687e+10 | AB4: 1.5583475e+10 | AC4: 3.5487162e+10 | AE4: oct | AF4: =+U4/1000 -> 0 | AG4: =+V4/1000 -> 0 | AH4: =+W4/1000 -> 0 | AI4: =+X4/1000 -> 19903687 | AJ4: =+Y4/1000 -> 15583475 | AK4: =+Z4/1000 -> 35487162 | AL4: =+AA4/1000 -> 19903687 | AM4: =+AB4/1000 -> 15583475 | AN4: =+AC4/1000 -> 35487162
A5: 2009 | B5: 1.0831943e+10 | C5: 4.7784934e+09 | D5: 5.149103e+09 | E5: 3.655593e+09 | F5: 1.5981046e+10 | G5: 8.4340864e+09 | I5: oct | J5: 0 | K5: 0 | L5: 0 | M5: 1.9903687e+10 | N5: 1.5583475e+10 | O5: 3.5487162e+10 | P5: 1.9903687e+10 | Q5: 1.5583475e+10 | R5: 3.5487162e+10 | T5: nov | U5: 0 | V5: 0 | W5: 0 | X5: 2.0075789e+10 | Y5: 1.5749774e+10 | Z5: 3.5825563e+10 | AA5: 2.0075789e+10 | AB5: 1.5749774e+10 | AC5: 3.5825563e+10 | AE5: nov | AF5: =+U5/1000 -> 0 | AG5: =+V5/1000 -> 0 | AH5: =+W5/1000 -> 0 | AI5: =+X5/1000 -> 20075789 | AJ5: =+Y5/1000 -> 15749774 | AK5: =+Z5/1000 -> 35825563 | AL5: =+AA5/1000 -> 20075789 | AM5: =+AB5/1000 -> 15749774 | AN5: =+AC5/1000 -> 35825563
A6: 2010 | B6: 1.3095568e+10 | C6: 5.5029662e+09 | D6: 5.9733298e+09 | E6: 4.1819318e+09 | F6: 1.9068897e+10 | G6: 9.684898e+09 | I6: nov | J6: 0 | K6: 0 | L6: 0 | M6: 2.0075789e+10 | N6: 1.5749774e+10 | O6: 3.5825563e+10 | P6: 2.0075789e+10 | Q6: 1.5749774e+10 | R6: 3.5825563e+10 | T6: dic | U6: 0 | V6: 0 | W6: 0 | X6: 20153837159 | Y6: 15816186175 | Z6: 35970023334 | AA6: 20153837159 | AB6: 15816186175 | AC6: 35970023334 | AE6: dic | AF6: =+U6/1000 -> 0 | AG6: =+V6/1000 -> 0 | AH6: =+W6/1000 -> 0 | AI6: =+X6/1000 -> 20153837 | AJ6: =+Y6/1000 -> 15816186 | AK6: =+Z6/1000 -> 35970023 | AL6: =+AA6/1000 -> 20153837 | AM6: =+AB6/1000 -> 15816186 | AN6: =+AC6/1000 -> 35970023
A7: 2011 | B7: 1.3994994e+10 | C7: 5.7801079e+09 | D7: 6.2216009e+09 | E7: 4.3734947e+09 | F7: 2.0216595e+10 | G7: 1.0153603e+10 | I7: dic | J7: 0 | K7: 0 | L7: 0 | M7: 20153837159 | N7: 15816186175 | O7: 35970023334 | P7: 20153837159 | Q7: 15816186175 | R7: 35970023334
A8: 2012 | B8: 1.4900592e+10 | C8: 6.0276417e+09 | D8: 6.3053347e+09 | E8: 4.4481809e+09 | F8: 2.1205927e+10 | G8: 1.0475823e+10
A9: 2013 | B9: 1.5464511e+10 | C9: 6.1276381e+09 | D9: 6.1333006e+09 | E9: 4.2916174e+09 | F9: 2.1597811e+10 | G9: 1.0419256e+10
A10: 2014 | B10: 1.6719242e+10 | C10: 6.4430339e+09 | D10: 6.3328754e+09 | E10: 4.3768174e+09 | F10: 2.3052118e+10 | G10: 1.0819851e+10
A11: 2015 | B11: 1.8210703e+10 | C11: 6.9460832e+09 | D11: 6.7614414e+09 | E11: 4.7714308e+09 | F11: 2.4972144e+10 | G11: 1.1717514e+10
A12: 2016 | B12: 1.9783297e+10 | C12: 7.4256197e+09 | D12: 7.3620108e+09 | E12: 5.231601e+09 | F12: 2.7145307e+10 | G12: 1.2657221e+10 | I12: PERIODO | J12: (Varios elementos) | AE12: nominales
A13: 2017 | B13: 2.3013212e+10 | C13: 8.5012643e+09 | D13: 8.4836307e+09 | E13: 6.1043568e+09 | F13: 3.1496842e+10 | G13: 1.4605621e+10 | AF13: vejez | AI13: invalidez | AL13: total
A14: 2018 | B14: 2.4370428e+10 | C14: 8.8423454e+09 | D14: 8.863105e+09 | E14: 6.4518852e+09 | F14: 3.3233533e+10 | G14: 1.5294231e+10 | I14: Etiquetas de fila | J14: Suma de MUJER | K14: Suma de HOMBRE | L14: Suma de TOTAL | M14: Suma de MUJER2 | N14: Suma de HOMBRE2 | O14: Suma de TOTAL2 | P14: Suma de MUJER3 | Q14: Suma de HOMBRE3 | R14: Suma de TOTAL3 | T14: Etiquetas de fila | U14: Suma de MUJER | V14: Suma de HOMBRE | W14: Suma de TOTAL | X14: Suma de MUJER2 | Y14: Suma de HOMBRE2 | Z14: Suma de TOTAL2 | AA14: Suma de MUJER3 | AB14: Suma de HOMBRE3 | AC14: Suma de TOTAL3 | AE14: Etiquetas de fila | AF14: Promedio de MUJER | AG14: Promedio de HOMBRE | AH14: Promedio de TOTAL | AI14: Promedio de MUJER2 | AJ14: Promedio de HOMBRE2 | AK14: Promedio de TOTAL2 | AL14: Promedio de MUJER3 | AM14: Promedio de HOMBRE3 | AN14: Promedio de TOTAL3
A15: 2019 | B15: 2.6689511e+10 | C15: 9.492244e+09 | D15: 9.429656e+09 | E15: 6.9564548e+09 | F15: 3.6119167e+10 | G15: 1.6448699e+10 | I15: 2022 | J15: 0 | K15: 0 | L15: 0 | M15: 60441368879 | N15: 47390715970 | O15: 107832084849 | P15: 60441368879 | Q15: 47390715970 | R15: 107832084849 | T15: oct | U15: 0 | V15: 0 | W15: 0 | X15: 20154801071 | Y15: 15780083599 | Z15: 35934884670 | AA15: 20154801071 | AB15: 15780083599 | AC15: 35934884670 | AE15: oct | AF15: =+U15/1000 -> 0 | AG15: =+V15/1000 -> 0 | AH15: =+W15/1000 -> 0 | AI15: =+X15/1000 -> 20154801 | AJ15: =+Y15/1000 -> 15780084 | AK15: =+Z15/1000 -> 35934885 | AL15: =+AA15/1000 -> 20154801 | AM15: =+AB15/1000 -> 15780084 | AN15: =+AC15/1000 -> 35934885
A16: 2020 | B16: 3.659289e+10 | C16: 1.2913294e+10 | D16: 1.1894674e+10 | E16: 8.9114229e+09 | F16: 4.8487564e+10 | G16: 2.1824717e+10 | I16: oct | J16: 0 | K16: 0 | L16: 0 | M16: 20154801071 | N16: 15780083599 | O16: 35934884670 | P16: 20154801071 | Q16: 15780083599 | R16: 35934884670 | T16: nov | U16: 0 | V16: 0 | W16: 0 | X16: 20132730649 | Y16: 15794446196 | Z16: 35927176845 | AA16: 20132730649 | AB16: 15794446196 | AC16: 35927176845 | AE16: nov | AF16: =+U16/1000 -> 0 | AG16: =+V16/1000 -> 0 | AH16: =+W16/1000 -> 0 | AI16: =+X16/1000 -> 20132731 | AJ16: =+Y16/1000 -> 15794446 | AK16: =+Z16/1000 -> 35927177 | AL16: =+AA16/1000 -> 20132731 | AM16: =+AB16/1000 -> 15794446 | AN16: =+AC16/1000 -> 35927177
A17: 2021 | B17: 4.3453866e+10 | C17: 1.494933e+10 | D17: 1.4114095e+10 | E17: 1.0837333e+10 | F17: 5.7567962e+10 | G17: 2.5786663e+10 | I17: nov | J17: 0 | K17: 0 | L17: 0 | M17: 20132730649 | N17: 15794446196 | O17: 35927176845 | P17: 20132730649 | Q17: 15794446196 | R17: 35927176845 | T17: dic | U17: 0 | V17: 0 | W17: 0 | X17: 20153837159 | Y17: 15816186175 | Z17: 35970023334 | AA17: 20153837159 | AB17: 15816186175 | AC17: 35970023334 | AE17: dic | AF17: =+U17/1000 -> 0 | AG17: =+V17/1000 -> 0 | AH17: =+W17/1000 -> 0 | AI17: =+X17/1000 -> 20153837 | AJ17: =+Y17/1000 -> 15816186 | AK17: =+Z17/1000 -> 35970023 | AL17: =+AA17/1000 -> 20153837 | AM17: =+AB17/1000 -> 15816186 | AN17: =+AC17/1000 -> 35970023
A18: ene | B18: 4.1412765e+10 | C18: 1.4344175e+10 | D18: 1.357545e+10 | E18: 1.0301137e+10 | F18: 5.4988215e+10 | G18: 2.4645311e+10 | I18: dic | J18: 0 | K18: 0 | L18: 0 | M18: 20153837159 | N18: 15816186175 | O18: 35970023334 | P18: 20153837159 | Q18: 15816186175 | R18: 35970023334 | T18: Total general | U18: 0 | V18: 0 | W18: 0 | X18: 2.0147123e+10 | Y18: 1.5796905e+10 | Z18: 35944028283 | AA18: 2.0147123e+10 | AB18: 1.5796905e+10 | AC18: 35944028283
A19: feb | B19: 4.1492133e+10 | C19: 1.4338672e+10 | D19: 1.35569e+10 | E19: 1.0317361e+10 | F19: 5.5049033e+10 | G19: 2.4656033e+10
A20: mar | B20: 4.1689378e+10 | C20: 1.4389108e+10 | D20: 1.3587482e+10 | E20: 1.0363694e+10 | F20: 5.527686e+10 | G20: 2.4752801e+10
A21: abr | B21: 4.1893694e+10 | C21: 1.4448119e+10 | D21: 1.3658161e+10 | E21: 1.0436146e+10 | F21: 5.5551855e+10 | G21: 2.4884265e+10
A22: may | B22: 4.2028716e+10 | C22: 1.4474202e+10 | D22: 1.3650261e+10 | E22: 1.0455982e+10 | F22: 5.5678977e+10 | G22: 2.4930184e+10
A23: jun | B23: 4.2051494e+10 | C23: 1.4454401e+10 | D23: 1.3673345e+10 | E23: 1.0488652e+10 | F23: 5.5724839e+10 | G23: 2.4943053e+10
A24: jul | B24: 4.3968065e+10 | C24: 1.5094747e+10 | D24: 1.4296201e+10 | E24: 1.0984398e+10 | F24: 5.8264265e+10 | G24: 2.6079145e+10
A25: ago | B25: 4.4239653e+10 | C25: 1.5183281e+10 | D25: 1.4359654e+10 | E25: 1.1056169e+10 | F25: 5.8599307e+10 | G25: 2.6239451e+10
A26: sept | B26: 4.4825753e+10 | C26: 1.5361682e+10 | D26: 1.4520122e+10 | E26: 1.1196684e+10 | F26: 5.9345875e+10 | G26: 2.6558366e+10
A27: oct | B27: 4.5558469e+10 | C27: 1.5619781e+10 | D27: 1.4731002e+10 | E27: 1.1378659e+10 | F27: 6.0289471e+10 | G27: 2.6998439e+10
A28: nov | B28: 4.5907806e+10 | C28: 1.5757842e+10 | D28: 1.4819941e+10 | E28: 1.1477734e+10 | F28: 6.0727747e+10 | G28: 2.7235576e+10
A29: dic | B29: 4.6378472e+10 | C29: 1.5925944e+10 | D29: 1.4940627e+10 | E29: 1.159138e+10 | F29: 6.1319099e+10 | G29: 2.7517324e+10
A30: 2022 | B30: 4.0614957e+09 | C30: 1.3943048e+09 | D30: 1.8608107e+10 | E30: 1.4541109e+10 | F30: 2.2669603e+10 | G30: 1.5935414e+10
... A43: Total general | B43: 1.9676256e+10 | C43: 7.3869635e+09 | D43: 8.5253168e+09 | E43: 6.2527955e+09 | F43: 2.8201573e+10 | G43: 1.3639759e+10
A52: Etiquetas de fila | B52: Promedio de PBSV_MUJER | C52: Promedio de PBSV_HOMBRE | D52: Promedio de PBSI_MUJER | E52: Promedio de PBSI_HOMBRE | F52: Promedio de PBS_MUJER | G52: Promedio de PBS_HOMBRE | I52: Etiquetas de fila | J52: Promedio de PBSV_MUJER | K52: Promedio de PBSV_HOMBRE | L52: Promedio de PBSI_MUJER | M52: Promedio de PBSI_HOMBRE | N52: Promedio de PBS_MUJER | O52: Promedio de PBS_HOMBRE
A53: 2008 | B53: 8.2469269e+09 | C53: 3.9732077e+09 | D53: 3.9696562e+09 | E53: 3.0646136e+09 | F53: 1.2216583e+10 | G53: 7.0378213e+09 | I53: 2008 | J53: 8246926.9 | K53: 3973207.7 | L53: 3969656.2 | M53: 3064613.6 | N53: 12216583 | O53: 7037821.3
A54: 2009 | B54: 1.0831943e+10 | C54: 4.7784934e+09 | D54: 5.149103e+09 | E54: 3.655593e+09 | F54: 1.5981046e+10 | G54: 8.4340864e+09 | I54: 2009 | J54: 10831943 | K54: 4778493.4 | L54: 5149103 | M54: 3655593 | N54: 15981046 | O54: 8434086.4
A55: 2010 | B55: 1.3095568e+10 | C55: 5.5029662e+09 | D55: 5.9733298e+09 | E55: 4.1819318e+09 | F55: 1.9068897e+10 | G55: 9.684898e+09 | I55: 2010 | J55: 13095568 | K55: 5502966.2 | L55: 5973329.8 | M55: 4181931.8 | N55: 19068897 | O55: 9684898
A56: 2011 | B56: 1.3994994e+10 | C56: 5.7801079e+09 | D56: 6.2216009e+09 | E56: 4.3734947e+09 | F56: 2.0216595e+10 | G56: 1.0153603e+10 | I56: 2011 | J56: 13994994 | K56: 5780107.9 | L56: 6221600.9 | M56: 4373494.7 | N56: 20216595 | O56: 10153603
A57: 2012 | B57: 1.4900592e+10 | C57: 6.0276417e+09 | D57: 6.3053347e+09 | E57: 4.4481809e+09 | F57: 2.1205927e+10 | G57: 1.0475823e+10 | I57: 2012 | J57: 14900592 | K57: 6027641.7 | L57: 6305334.7 | M57: 4448180.9 | N57: 21205927 | O57: 10475823
A58: 2013 | B58: 1.5464511e+10 | C58: 6.1276381e+09 | D58: 6.1333006e+09 | E58: 4.2916174e+09 | F58: 2.1597811e+10 | G58: 1.0419256e+10 | I58: 2013 | J58: 15464511 | K58: 6127638.1 | L58: 6133300.6 | M58: 4291617.4 | N58: 21597811 | O58: 10419256
A59: 2014 | B59: 1.6719242e+10 | C59: 6.4430339e+09 | D59: 6.3328754e+09 | E59: 4.3768174e+09 | F59: 2.3052118e+10 | G59: 1.0819851e+10 | I59: 2014 | J59: 16719242 | K59: 6443033.9 | L59: 6332875.4 | M59: 4376817.4 | N59: 23052118 | O59: 10819851
A60: 2015 | B60: 1.8210703e+10 | C60: 6.9460832e+09 | D60: 6.7614414e+09 | E60: 4.7714308e+09 | F60: 2.4972144e+10 | G60: 1.1717514e+10 | I60: 2015 | J60: 18210703 | K60: 6946083.2 | L60: 6761441.4 | M60: 4771430.8 | N60: 24972144 | O60: 11717514
A61: 2016 | B61: 1.9783297e+10 | C61: 7.4256197e+09 | D61: 7.3620108e+09 | E61: 5.231601e+09 | F61: 2.7145307e+10 | G61: 1.2657221e+10 | I61: 2016 | J61: 19783297 | K61: 7425619.7 | L61: 7362010.8 | M61: 5231601 | N61: 27145307 | O61: 12657221
...

Sheet 1.1
B2: TOTAL BENEFICIOS PAGADOS DEL PILAR NO CONTRIBUTIVO
B4: Resumen trimestral de beneficios pagados, por tipo de beneficio y sexo
B5: (enero 2023 a marzo 2023)
D7: Mujeres | G7: Hombres | J7: Total
B8: Periodo | C8: Tipo de beneficio | D8: N° | E8: Monto nominal M$ * | F8: Monto real M$ ** | G8: N° | H8: Monto nominal M$ * | I8: Monto real M$ ** | J8: N° | K8: Monto nominal M$ * | L8: Monto real M$ **
B9: enero 2023 | C9: PGU No Contributiva | D9: 331003 | E9: 63933034 | F9: 64586412 | G9: 126303 | H9: 24450261 | I9: 24700136 | J9: 457306 | K9: 88383295 | L9: 89286548
C10: PGU Contributiva | D10: 729835 | E10: 1.3986358e+08 | F10: 1.4129295e+08 | G10: 605454 | H10: 1.1511277e+08 | I10: 1.1628919e+08 | J10: 1335289 | K10: 2.5497635e+08 | L10: 2.5758214e+08
C11: PBS Invalidez | D11: 104230 | E11: 20201882 | F11: 20408339 | G11: 81876 | H11: 15868523 | I11: 16030695 | J11: 186106 | K11: 36070404 | L11: 36439034
C12: APS Vejez | D12: 108797 | E12: 23112170 | F12: 23348370 | G12: 62891 | H12: 13450862 | I12: 13588326 | J12: 171688 | K12: 36563032 | L12: 36936696
C13: APS Invalidez | D13: 46104 | E13: 7667276.8 | F13: 7745634.3 | G13: 47256 | H13: 7473814.7 | I13: 7550195 | J13: 93360 | K13: 15141092 | L13: 15295829
C14: Total Beneficios | D14: 1319969 | E14: 2.5477794e+08 | F14: 2.573817e+08 | G14: 923780 | H14: 1.7635623e+08 | I14: 1.7815854e+08 | J14: 2243749 | K14: 4.3113417e+08 | L14: 4.3554025e+08
B15: febrero 2023 | C15: PGU No Contributiva | D15: 331827 | E15: 68143594 | F15: 68884241 | G15: 127315 | H15: 26162330 | I15: 26446686 | J15: 459142 | K15: 94305924 | L15: 95330927
C16: PGU Contributiva | D16: 737271 | E16: 1.5045957e+08 | F16: 1.520949e+08 | G16: 613433 | H16: 1.2424945e+08 | I16: 1.2559991e+08 | J16: 1350704 | K16: 2.7470903e+08 | L16: 2.7769482e+08
C17: PBS Invalidez | D17: 104475 | E17: 21529707 | F17: 21763711 | G17: 82037 | H17: 16905382 | I17: 17089125 | J17: 186512 | K17: 38435089 | L17: 38852837
C18: APS Vejez | D18: 108645 | E18: 23098113 | F18: 23349164 | G18: 62678 | H18: 13420694 | I18: 13566562 | J18: 171323 | K18: 36518806 | L18: 36915726
C19: APS Invalidez | D19: 46210 | E19: 8237673.4 | F19: 8327208 | G19: 47542 | H19: 8076320.7 | I19: 8164101.5 | J19: 93752 | K19: 16313994 | L19: 16491309
C20: Total Beneficios | D20: 1328428 | E20: 2.7146866e+08 | F20: 2.7441923e+08 | G20: 933005 | H20: 1.8881418e+08 | I20: 1.9086639e+08 | J20: 2261433 | K20: 4.6028284e+08 | L20: 4.6528562e+08
B21: marzo 2023 | C21: PGU No Contributiva | D21: 332837 | E21: 68328243 | F21: 68328243 | G21: 128270 | H21: 26367973 | I21: 26367973 | J21: 461107 | K21: 94696216 | L21: 94696216
C22: PGU Contributiva | D22: 745051 | E22: 1.5199931e+08 | F22: 1.5199931e+08 | G22: 620582 | H22: 1.2565363e+08 | I22: 1.2565363e+08 | J22: 1365633 | K22: 2.7765294e+08 | L22: 2.7765294e+08
C23: PBS Invalidez | D23: 104804 | E23: 21596972 | F23: 21596972 | G23: 82313 | H23: 16962286 | I23: 16962286 | J23: 187117 | K23: 38559258 | L23: 38559258
C24: APS Vejez | D24: 108598 | E24: 23099682 | F24: 23099682 | G24: 62593 | H24: 13421795 | I24: 13421795 | J24: 171191 | K24: 36521477 | L24: 36521477
C25: APS Invalidez | D25: 46381 | E25: 8260461.9 | F25: 8260461.9 | G25: 47964 | H25: 8133304 | I25: 8133304 | J25: 94345 | K25: 16393766 | L25: 16393766
C26: Total Beneficios | D26: 1337671 | E26: 2.7328467e+08 | F26: 2.7328467e+08 | G26: 941722 | H26: 1.9053899e+08 | I26: 1.9053899e+08 | J26: 2279393 | K26: 4.6382366e+08 | L26: 4.6382366e+08
B27: Fuente: Elaboración propia con datos de la Superintendencia de Pensiones
B28: Nota 1: La Pensión Garantizada Universal (PGU) es un nuevo beneficio generado a partir de la ley 21.419 del 29-01-2022. El concepto de PGU No Contributiva o Contributiva está relacionado con la calidad de la persona que está recibiendo el beneficio, si es No Contributiva quiere decir que no estaba afiliado a un sistema previsional (D.L. 3.500 o antiguo Sistema de Reparto) ni recibe pensión de sobrevivencia, si es Contributiva quiere decir que si estaba afiliado a un sistema previsional o que recibe una pensión de sobrevivencia. De manera automática, en febrero 2022, los PBS de Vejez pasaron a ser PGU No Contributiva y los APS Vejez Subsidio Definido, los Beneficio artículo 9° bis y los APS Vejez con una Pensión Final Garantizada inferior o igual al monto de la PGU pasaron a ser PGU Contributiva (Fuente: Superintendencia de Pensiones). Nota 2: Para los APS de Vejez, en aquellos casos en que este beneficio superaba el monto de la PGU se mantuvo el beneficio.
B29: * Montos nominales de cada periodo de pago. ** Montos deflactados a marzo 2023
B31: Serie resumen de pagos (monto real M$) de beneficios acumulados, por tipo de beneficio
B32: (enero 2020 a marzo 2023)
C34: PGU No Contributiva | G34: PGU Contributiva | K34: PBS Vejez | O34: PBS Invalidez | S34: APS Vejez | W34: APS Invalidez | AA34: Nbis | AE34: Total Beneficios
C35: N° Beneficios promedio | E35: Monto promedio M$* | G35: N° Beneficios promedio | I35: Monto promedio M$* | K35: N° Beneficios promedio | M35: Monto promedio M$* | O35: N° Beneficios promedio | Q35: Monto promedio M$* | S35: N° Beneficios promedio | U35: Monto promedio M$* | W35: N° Beneficios promedio | Y35: Monto promedio M$* | AA35: N° Beneficios promedio | AC35: Monto promedio M$* | AE35: N° Beneficios promedio | AG35: Monto promedio M$*
B36: Periodo | C36: N | D36: % | E36: N | F36: % | G36: N | H36: % | I36: N | J36: % | K36: N | L36: % | M36: N | N36: % | O36: N | P36: % | Q36: N | R36: % | S36: N | T36: % | U36: N | V36: % | W36: N | X36: % | Y36: N | Z36: % | AA36: N | AB36: % | AC36: N | AD36: % | AE36: N | AF36: % | AG36: N | AH36: %
B37: 39630 | K37: 290570 | L37: 0.60124441 | M37: 30163620 | N37: 0.60124441 | O37: 192711 | P37: 0.39875559 | Q37: 20005030 | R37: 0.39875559 | AE37: 483281 | AF37: 1 | AG37: 50168650 | AH37: 1
B38: 39661 | K38: 292137 | L38: 0.60055999 | M38: 30046161 | N38: 0.60055999 | O38: 194304 | P38: 0.39944001 | Q38: 19984080 | R38: 0.39944001 | AE38: 486441 | AF38: 1 | AG38: 50030242 | AH38: 1
B39: 39692 | K39: 329546 | L39: 0.63002998 | M39: 33529943 | N39: 0.62997894 | O39: 193518 | P39: 0.36997002 | Q39: 19693968 | R39: 0.37002106 | AE39: 523064 | AF39: 1 | AG39: 53223911 | AH39: 1
B40: 39722 | K40: 340883 | L40: 0.63388369 | M40: 37227667 | N40: 0.64317182 | O40: 193041 | P40: 0.3589664 | Q40: 19563397 | R40: 0.33799124 | S40: 3399 | T40: 0.0063205577 | U40: 970515.16 | V40: 0.016767314 | W40: 446 | X40: 0.00082935238 | Y40: 119793.02 | Z40: 0.0020696299 | AE40: 537769 | AF40: 1 | AG40: 57881372 | AH40: 1
B41: 39753 | K41: 347314 | L41: 0.63749096 | M41: 37107809 | N41: 0.64785948 | O41: 192690 | P41: 0.35368034 | Q41: 19633136 | R41: 0.34277187 | S41: 4226 | T41: 0.0077567757 | U41: 469015.24 | V41: 0.0081884642 | W41: 584 | X41: 0.0010719255 | Y41: 67597.932 | Z41: 0.0011801818 | AE41: 544814 | AF41: 1 | AG41: 57277559 | AH41: 1
B42: 39783 | K42: 358445 | L42: 0.64228132 | M42: 39974650 | N42: 0.64842422 | O42: 194451 | P42: 0.34842792 | Q42: 21082122 | R42: 0.34197068 | S42: 4485 | T42: 0.0080364678 | U42: 521679.39 | V42: 0.0084621016 | W42: 700 | X42: 0.0012542982 | Y42: 70464.889 | Z42: 0.0011430029 | AE42: 558081 | AF42: 1 | AG42: 61648916 | AH42: 1
B43: Promedio 2008 | K43: 326482.5 | L43: 0.6224069 | M43: 34674975 | N43: 0.62580848 | O43: 193452.5 | P43: 0.36879824 | Q43: 19993622 | R43: 0.36084174 | S43: 4036.6667 | T43: 0.0076955095 | U43: 653736.6 | V43: 0.011798535 | W43: 576.66667 | X43: 0.0010993585 | Y43: 85951.945 | Z43: 0.0015512471 | AE43: 524548.33 | AF43: 1 | AG43: 55408286 | AH43: 1
B44: 39814 | K44: 364131 | L44: 0.64167332 | M44: 39015660 | N44: 0.63183868 | O44: 196192 | P44: 0.34573044 | Q44: 21595408 | R44: 0.34972659 | S44: 6199 | T44: 0.010923906 | U44: 998048.25 | V44: 0.016162881 | W44: 949 | X44: 0.0016723322 | Y44: 140284.74 | Z44: 0.0022718397 | AE44: 567471 | AF44: 1 | AG44: 61749401 | AH44: 1
B45: 39845 | K45: 366991 | L45: 0.64091253 | M45: 39051164 | N45: 0.63378798 | O45: 197256 | P45: 0.34448758 | Q45: 21625405 | R45: 0.35097345 | S45: 7180 | T45: 0.012539141 | U45: 782323.47 | V45: 0.012696861 | W45: 1180 | X45: 0.0020607502 | Y45: 156608.3 | Z45: 0.0025417029 | AE45: 572607 | AF45: 1 | AG45: 61615501 | AH45: 1
...

Sheet 1.2
B2: PAGOS PENSIÓN GARANTIZADA UNIVERSAL (PGU)
B5: Resumen trimestral de beneficios pagados, por tipo de beneficio y sexo
B6: (enero 2023 a marzo 2023)
D8: PGU No Contributiva | G8: PGU Contributiva | J8: PGU Total
B9: Periodo | C9: Sexo Beneficiarios | D9: N° | E9: Monto nominal M$ * | F9: Monto real M$ ** | G9: N° | H9: Monto nominal M$ * | I9: Monto real M$ ** | J9: N° | K9: Monto nominal M$ * | L9: Monto real M$ **
B10: enero 2023 | C10: Mujeres | D10: 331003 | E10: 63933034 | F10: 64586412 | G10: 729835 | H10: 1.3986358e+08 | I10: 1.4129295e+08 | J10: 1060838 | K10: 2.0379661e+08 | L10: 2.0587936e+08
C11: Hombres | D11: 126303 | E11: 24450261 | F11: 24700136 | G11: 605454 | H11: 1.1511277e+08 | I11: 1.1628919e+08 | J11: 731757 | K11: 1.3956303e+08 | L11: 1.4098933e+08
C12: Total | D12: 457306 | E12: 88383295 | F12: 89286548 | G12: 1335289 | H12: 2.5497635e+08 | I12: 2.5758214e+08 | J12: 1792595 | K12: 3.4335965e+08 | L12: 3.4686869e+08
B13: febrero 2023 | C13: Mujeres | D13: 331827 | E13: 68143594 | F13: 68884241 | G13: 737271 | H13: 1.5045957e+08 | I13: 1.520949e+08 | J13: 1069098 | K13: 2.1860317e+08 | L13: 2.2097915e+08
C14: Hombres | D14: 127315 | E14: 26162330 | F14: 26446686 | G14: 613433 | H14: 1.2424945e+08 | I14: 1.2559991e+08 | J14: 740748 | K14: 1.5041178e+08 | L14: 1.520466e+08
C15: Total | D15: 459142 | E15: 94305924 | F15: 95330927 | G15: 1350704 | H15: 2.7470903e+08 | I15: 2.7769482e+08 | J15: 1809846 | K15: 3.6901495e+08 | L15: 3.7302574e+08
B16: marzo 2023 | C16: Mujeres | D16: 332837 | E16: 68328243 | F16: 68328243 | G16: 745051 | H16: 1.5199931e+08 | I16: 1.5199931e+08 | J16: 1077888 | K16: 2.2032755e+08 | L16: 2.2032755e+08
C17: Hombres | D17: 128270 | E17: 26367973 | F17: 26367973 | G17: 620582 | H17: 1.2565363e+08 | I17: 1.2565363e+08 | J17: 748852 | K17: 1.5202161e+08 | L17: 1.5202161e+08
C18: Total | D18: 461107 | E18: 94696216 | F18: 94696216 | G18: 1365633 | H18: 2.7765294e+08 | I18: 2.7765294e+08 | J18: 1826740 | K18: 3.7234916e+08 | L18: 3.7234916e+08
B19: Fuente: Elaboración propia con datos de la Superintendencia de Pensiones
B20: Nota 1: La Pensión Garantizada Universal (PGU) es un nuevo beneficio generado a partir de la ley 21.419 del 29-01-2022. El concepto de PGU No Contributiva o Contributiva está relacionado con la calidad de la persona que está recibiendo el beneficio, si es No Contributiva quiere decir que no estaba afiliado a un sistema previsional (D.L. 3.500 o antiguo Sistema de Reparto) ni recibe pensión de sobrevivencia, si es Contributiva quiere decir que si estaba afiliado a un sistema previsional o que recibe una pensión de sobrevivencia. De manera automática, en febrero 2022, los PBS de Vejez pasaron a ser PGU No Contributiva y los APS Vejez Subsidio Definido, los Beneficio artículo 9° bis y los APS Vejez con una Pensión Final Garantizada inferior o igual al monto de la PGU pasaron a ser PGU Contributiva (Fuente: Superintendencia de Pensiones). Nota 2: Para los APS de Vejez, en aquellos casos en que este beneficio superaba el monto de la PGU se mantuvo el beneficio.
B21: * Montos nominales de cada periodo de pago. ** Montos deflactados a marzo 2023
B23: Serie resumen de pagos (monto real M$) de beneficios acumulado, por tipo de beneficio y sexo
B24: (febrero 2022 a marzo 2023)
C26: PGU No Contributiva | I26: PGU Contributiva | O26: PGU Total
C27: Mujeres | E27: Hombres | G27: Total | I27: Mujeres | K27: Hombres | M27: Total | O27: Mujeres | Q27: Hombres | S27: Total
B28: Periodo | C28: N° Beneficios promedio | D28: Monto promedio M$ * | E28: N° Beneficios promedio | F28: Monto promedio M$ * | G28: N° Beneficios promedio | H28: Monto promedio M$ * | I28: N° Beneficios promedio | J28: Monto promedio M$ * | K28: N° Beneficios promedio | L28: Monto promedio M$ * | M28: N° Beneficios promedio | N28: Monto promedio M$ * | O28: N° Beneficios promedio | P28: Monto promedio M$ * | Q28: N° Beneficios promedio | R28: Monto promedio M$ * | S28: N° Beneficios promedio | T28: Monto promedio M$ *
B29: 44593 | C29: 309683 | D29: 64734164 | E29: 106066 | F29: 22199165 | G29: 415749 | H29: 86933329 | I29: 517361 | J29: 96275366 | K29: 340110 | L29: 65977540 | M29: 857471 | N29: 1.6225291e+08 | O29: 827044 | P29: 1.6100953e+08 | Q29: 446176 | R29: 88176705 | S29: 1273220 | T29: 2.4918623e+08
B30: 44621 | C30: 312946 | D30: 64120560 | E30: 107255 | F30: 22038847 | G30: 420201 | H30: 86159406 | I30: 536699 | J30: 1.1007492e+08 | K30: 361057 | L30: 74127277 | M30: 897756 | N30: 1.842022e+08 | O30: 849645 | P30: 1.7419548e+08 | Q30: 468312 | R30: 96166124 | S30: 1317957 | T30: 2.7036161e+08
B31: 44652 | C31: 314601 | D31: 63502805 | E31: 107763 | F31: 21836908 | G31: 422364 | H31: 85339713 | I31: 552501 | J31: 1.1167813e+08 | K31: 374925 | L31: 75937631 | M31: 927426 | N31: 1.8761576e+08 | O31: 867102 | P31: 1.7518093e+08 | Q31: 482688 | R31: 97774539 | S31: 1349790 | T31: 2.7295547e+08
B32: 44682 | C32: 316872 | D32: 63149512 | E32: 108938 | F32: 21811497 | G32: 425810 | H32: 84961009 | I32: 605836 | J32: 1.2095873e+08 | K32: 477591 | L32: 95598584 | M32: 1083427 | N32: 2.1655731e+08 | O32: 922708 | P32: 1.8410824e+08 | Q32: 586529 | R32: 1.1741008e+08 | S32: 1509237 | T32: 3.0151832e+08
B33: 44713 | C33: 317138 | D33: 62596928 | E33: 109221 | F33: 21665370 | G33: 426359 | H33: 84262298 | I33: 615086 | J33: 1.2162089e+08 | K33: 487043 | L33: 96589823 | M33: 1102129 | N33: 2.1821071e+08 | O33: 932224 | P33: 1.8421782e+08 | Q33: 596264 | R33: 1.1825519e+08 | S33: 1528488 | T33: 3.0247301e+08
B34: 44743 | C34: 317824 | D34: 64863681 | E34: 109691 | F34: 22497989 | G34: 427515 | H34: 87361670 | I34: 621791 | J34: 1.2713736e+08 | K34: 498271 | L34: 1.0218186e+08 | M34: 1120062 | N34: 2.2931921e+08 | O34: 939615 | P34: 1.9200104e+08 | Q34: 607962 | R34: 1.2467985e+08 | S34: 1547577 | T34: 3.1668088e+08
B35: 44774 | C35: 322017 | D35: 64919166 | E35: 110018 | F35: 22294221 | G35: 432035 | H35: 87213387 | I35: 660104 | J35: 1.3294891e+08 | K35: 538150 | L35: 1.0829777e+08 | M35: 1198254 | N35: 2.4124668e+08 | O35: 982121 | P35: 1.9786808e+08 | Q35: 648168 | R35: 1.3059199e+08 | S35: 1630289 | T35: 3.2846007e+08
B36: 44805 | C36: 321661 | D36: 64279098 | E36: 109838 | F36: 22066063 | G36: 431499 | H36: 86345160 | I36: 679141 | J36: 1.3546771e+08 | K36: 553055 | L36: 1.099908e+08 | M36: 1232196 | N36: 2.4545851e+08 | O36: 1000802 | P36: 1.9974681e+08 | Q36: 662893 | R36: 1.3205686e+08 | S36: 1663695 | T36: 3.3180367e+08
B37: 44835 | C37: 322141 | D37: 64036495 | E37: 109963 | F37: 21977740 | G37: 432104 | H37: 86014235 | I37: 686334 | J37: 1.3610469e+08 | K37: 563950 | L37: 1.1138507e+08 | M37: 1250284 | N37: 2.4748975e+08 | O37: 1008475 | P37: 2.0014118e+08 | Q37: 673913 | R37: 1.3336281e+08 | S37: 1682388 | T37: 3.3350399e+08
B38: 44866 | C38: 327443 | D38: 64420866 | E38: 121585 | F38: 24064940 | G38: 449028 | H38: 88485807 | I38: 704099 | J38: 1.3810886e+08 | K38: 584193 | L38: 1.1390642e+08 | M38: 1288292 | N38: 2.5201528e+08 | O38: 1031542 | P38: 2.0252973e+08 | Q38: 705778 | R38: 1.3797136e+08 | S38: 1737320 | T38: 3.4050108e+08
B39: 44896 | C39: 329180 | D39: 64580931 | E39: 125728 | F39: 24815435 | G39: 454908 | H39: 89396366 | I39: 717919 | J39: 1.4016227e+08 | K39: 594890 | L39: 1.153661e+08 | M39: 1312809 | N39: 2.5552837e+08 | O39: 1047099 | P39: 2.047432e+08 | Q39: 720618 | R39: 1.4018154e+08 | S39: 1767717 | T39: 3.4492474e+08
B40: Promedio 2022 | C40: 319227.82 | D40: 64109473 | E40: 111460.55 | F40: 22478925 | G40: 430688.36 | H40: 86588398 | I40: 626988.27 | J40: 1.2459435e+08 | K40: 488475.91 | L40: 97214443 | M40: 1115464.2 | N40: 2.2180879e+08 | O40: 946216.09 | P40: 1.8870382e+08 | Q40: 599936.45 | R40: 1.1969337e+08 | S40: 1546152.5 | T40: 3.0839719e+08
B41: 44927 | C41: 331003 | D41: 64586412 | E41: 126303 | F41: 24700136 | G41: 457306 | H41: 89286548 | I41: 729835 | J41: 1.4129295e+08 | K41: 605454 | L41: 1.1628919e+08 | M41: 1335289 | N41: 2.5758214e+08 | O41: 1060838 | P41: 2.0587936e+08 | Q41: 731757 | R41: 1.4098933e+08 | S41: 1792595 | T41: 3.4686869e+08
B42: 44958 | C42: 331827 | D42: 68884241 | E42: 127315 | F42: 26446686 | G42: 459142 | H42: 95330927 | I42: 737271 | J42: 1.520949e+08 | K42: 613433 | L42: 1.2559991e+08 | M42: 1350704 | N42: 2.7769482e+08 | O42: 1069098 | P42: 2.2097915e+08 | Q42: 740748 | R42: 1.520466e+08 | S42: 1809846 | T42: 3.7302574e+08
B43: 44986 | C43: 332837 | D43: 68328243 | E43: 128270 | F43: 26367973 | G43: 461107 | H43: 94696216 | I43: 745051 | J43: 1.5199931e+08 | K43: 620582 | L43: 1.2565363e+08 | M43: 1365633 | N43: 2.7765294e+08 | O43: 1077888 | P43: 2.2032755e+08 | Q43: 748852 | R43: 1.5202161e+08 | S43: 1826740 | T43: 3.7234916e+08
B44: Promedio al Primer trimestre 2023 | C44: 331889 | D44: 67266299 | E44: 127296 | F44: 25838265 | G44: 459185 | H44: 93104564 | I44: 737385.67 | J44: 1.4846239e+08 | K44: 613156.33 | L44: 1.2251425e+08 | M44: 1350542 | N44: 2.7097663e+08 | O44: 1069274.7 | P44: 2.1572869e+08 | Q44: 740452.33 | R44: 1.4835251e+08 | S44: 1809727 | T44: 3.640812e+08
B45: Fuente: Elaboración propia con datos de la Superintendencia de Pensiones
B46: * Montos deflactados a marzo 2023

Sheet 1.3
B2: PAGOS PENSIÓN BÁSICA SOLIDARIA (PBS)
B4: Resumen trimestral de beneficios pagados, por tipo de beneficio y sexo
B5: (enero 2023 a marzo 2023)
D7: PBS Invalidez
B8: Periodo | C8: Sexo Beneficiarios | D8: N° | E8: Monto nominal M$ * | F8: Monto real M$ **
B9: enero 2023 | C9: Mujeres | D9: 104230 | E9: 20201882 | F9: 20408339
C10: Hombres | D10: 81876 | E10: 15868523 | F10: 16030695
C11: Total | D11: 186106 | E11: 36070404 | F11: 36439034
B12: febrero 2023 | C12: Mujeres | D12: 104475 | E12: 21529707 | F12: 21763711
C13: Hombres | D13: 82037 | E13: 16905382 | F13: 17089125
C14: Total | D14: 186512 | E14: 38435089 | F14: 38852837
B15: marzo 2023 | C15: Mujeres | D15: 104804 | E15: 21596972 | F15: 21596972
C16: Hombres | D16: 82313 | E16: 16962286 | F16: 16962286
C17: Total | D17: 187117 | E17: 38559258 | F17: 38559258
B18: Fuente: Elaboración propia con datos de la Superintendencia de Pensiones
B19: Nota 1: La Pensión Garantizada Universal (PGU) es un nuevo beneficio generado a partir de la ley 21.419 del 29-01-2022. El concepto de PGU No Contributiva o Contributiva está relacionado con la calidad de la persona que está recibiendo el beneficio, si es No Contributiva quiere decir que no estaba afiliado a un sistema previsional (D.L. 3.500 o antiguo Sistema de Reparto) ni recibe pensión de sobrevivencia, si es Contributiva quiere decir que si estaba afiliado a un sistema previsional o que recibe una pensión de sobrevivencia. De manera automática, en febrero 2022, los PBS de Vejez pasaron a ser PGU No Contributiva y los APS Vejez Subsidio Definido, los Beneficio artículo 9° bis y los APS Vejez con una Pensión Final Garantizada inferior o igual al monto de la PGU pasaron a ser PGU Contributiva (Fuente: Superintendencia de Pensiones). Nota 2: Para los APS de Vejez, en aquellos casos en que este beneficio superaba el monto de la PGU se mantuvo el beneficio.
B20: * Montos nominales de cada periodo de pago. ** Montos deflactados a marzo 2023
B22: Serie resumen de pagos (monto real M$) de beneficios acumulado, por tipo de beneficio y sexo
B23: (enero 2020 a marzo 2023)
C25: PBS Vejez | I25: PBS Invalidez | O25: PBS Total
C26: Mujeres | E26: Hombres | G26: Total | I26: Mujeres | K26: Hombres | M26: Total | O26: Mujeres | Q26: Hombres | S26: Total
B27: Periodo | C27: N° Beneficios promedio | D27: Monto promedio M$ * | E27: N° Beneficios promedio | F27: Monto promedio M$ * | G27: N° Beneficios promedio | H27: Monto promedio M$ * | I27: N° Beneficios promedio | J27: Monto promedio M$ * | K27: N° Beneficios promedio | L27: Monto promedio M$ * | M27: N° Beneficios promedio | N27: Monto promedio M$ * | O27: N° Beneficios promedio | P27: Monto promedio M$ * | Q27: N° Beneficios promedio | R27: Monto promedio M$ * | S27: N° Beneficios promedio | T27: Monto promedio M$ *
B28: 39630 | C28: 189150 | D28: 19635368 | E28: 101420 | F28: 10528253 | G28: 290570 | H28: 30163620 | I28: 108433 | J28: 11256261 | K28: 84278 | L28: 8748768.3 | M28: 192711 | N28: 20005030 | O28: 297583 | P28: 30891629 | Q28: 185698 | R28: 19277021 | S28: 483281 | T28: 50168650
B29: 39661 | C29: 190466 | D29: 19589344 | E29: 101671 | F29: 10456817 | G29: 292137 | H29: 30046161 | I29: 109472 | J29: 11259147 | K29: 84832 | L29: 8724933.7 | M29: 194304 | N29: 19984080 | O29: 299938 | P29: 30848491 | Q29: 186503 | R29: 19181751 | S29: 486441 | T29: 50030242
B30: 39692 | C30: 221382 | D30: 22524476 | E30: 108164 | F30: 11005467 | G30: 329546 | H30: 33529943 | I30: 108958 | J30: 11088454 | K30: 84560 | L30: 8605514.5 | M30: 193518 | N30: 19693968 | O30: 330340 | P30: 33612930 | Q30: 192724 | R30: 19610981 | S30: 523064 | T30: 53223911
B31: 39722 | C31: 230808 | D31: 25597525 | E31: 110075 | F31: 11630142 | G31: 340883 | H31: 37227667 | I31: 108604 | J31: 10998873 | K31: 84437 | L31: 8564523.6 | M31: 193041 | N31: 19563397 | O31: 339412 | P31: 36596398 | Q31: 194512 | R31: 20194666 | S31: 533924 | T31: 56791064
B32: 39753 | C32: 236178 | D32: 25474218 | E32: 111136 | F32: 11633592 | G32: 347314 | H32: 37107809 | I32: 108404 | J32: 11066806 | K32: 84286 | L32: 8566330 | M32: 192690 | N32: 19633136 | O32: 344582 | P32: 36541024 | Q32: 195422 | R32: 20199922 | S32: 540004 | T32: 56740945
B33: 39783 | C33: 244815 | D33: 27531673 | E33: 113630 | F33: 12442978 | G33: 358445 | H33: 39974650 | I33: 109628 | J33: 12028953 | K33: 84823 | L33: 9053168.1 | M33: 194451 | N33: 21082122 | O33: 354443 | P33: 39560626 | Q33: 198453 | R33: 21496146 | S33: 552896 | T33: 61056772
B34: Promedio 2008 | C34: 218799.83 | D34: 23392101 | E34: 107682.67 | F34: 11282875 | G34: 326482.5 | H34: 34674975 | I34: 108916.5 | J34: 11283082 | K34: 84536 | L34: 8710539.7 | M34: 193452.5 | N34: 19993622 | O34: 327716.33 | P34: 34675183 | Q34: 192218.67 | R34: 19993414 | S34: 519935 | T34: 54668597
B35: 39814 | C35: 249383 | D35: 26841913 | E35: 114748 | F35: 12173747 | G35: 364131 | H35: 39015660 | I35: 110901 | J35: 12410037 | K35: 85291 | L35: 9185370.9 | M35: 196192 | N35: 21595408 | O35: 360284 | P35: 39251950 | Q35: 200039 | R35: 21359118 | S35: 560323 | T35: 60611068
B36: 39845 | C36: 251808 | D36: 26885932 | E36: 115183 | F36: 12165232 | G36: 366991 | H36: 39051164 | I36: 111775 | J36: 12462440 | K36: 85481 | L36: 9162964.8 | M36: 197256 | N36: 21625405 | O36: 363583 | P36: 39348372 | Q36: 200664 | R36: 21328197 | S36: 564247 | T36: 60676569
B37: 39873 | C37: 254074 | D37: 26841952 | E37: 115759 | F37: 12202347 | G37: 369833 | H37: 39044298 | I37: 112459 | J37: 12404002 | K37: 85609 | L37: 9113142 | M37: 198068 | N37: 21517144 | O37: 366533 | P37: 39245954 | Q37: 201368 | R37: 21315489 | S37: 567901 | T37: 60561443
B38: 39904 | C38: 255795 | D38: 26914408 | E38: 116177 | F38: 12172629 | G38: 371972 | H38: 39087038 | I38: 113104 | J38: 12544502 | K38: 85787 | L38: 9193916.6 | M38: 198891 | N38: 21738418 | O38: 368899 | P38: 39458910 | Q38: 201964 | R38: 21366546 | S38: 570863 | T38: 60825456
B39: 39934 | C39: 258094 | D39: 27276182 | E39: 116638 | F39: 12261874 | G39: 374732 | H39: 39538056 | I39: 114003 | J39: 12829343 | K39: 86085 | L39: 9360151.8 | M39: 200088 | N39: 22189495 | O39: 372097 | P39: 40105525 | Q39: 202723 | R39: 21622026 | S39: 574820 | T39: 61727551
B40: 39965 | C40: 260086 | D40: 27433126 | E40: 116982 | F40: 12272100 | G40: 377068 | H40: 39705226 | I40: 114983 | J40: 13105936 | K40: 86441 | L40: 9424726.3 | M40: 201424 | N40: 22530662 | O40: 375069 | P40: 40539062 | Q40: 203423 | R40: 21696826 | S40: 578492 | T40: 62235888
B41: 39995 | C41: 261334 | D41: 34344289 | E41: 117124 | F41: 15354692 | G41: 378458 | H41: 49698981 | I41: 116028 | J41: 16404134 | K41: 86710 | L41: 11725017 | M41: 202738 | N41: 28129151 | O41: 377362 | P41: 50748423 | Q41: 203834 | R41: 27079708 | S41: 581196 | T41: 77828132
B42: 40026 | C42: 261917 | D42: 34536698 | E42: 117348 | F42: 15606063 | G42: 379265 | H42: 50142761 | I42: 117514 | J42: 17090232 | K42: 87229 | L42: 12035010 | M42: 204743 | N42: 29125242 | O42: 379431 | P42: 51626930 | Q42: 204577 | R42: 27641073 | S42: 584008 | T42: 79268003
B43: 40057 | C43: 267244 | D43: 36150044 | E43: 117430 | F43: 15325647 | G43: 384674 | H43: 51475690 | I43: 118761 | J43: 16944156 | K43: 87678 | L43: 11920564 | M43: 206439 | N43: 28864721 | O43: 386005 | P43: 53094200 | Q43: 205108 | R43: 27246211 | S43: 591113 | T43: 80340411
B44: 40087 | C44: 273548 | D44: 36878015 | E44: 118419 | F44: 15687711 | G44: 391967 | H44: 52565726 | I44: 120250 | J44: 17507429 | K44: 88090 | L44: 12043872 | M44: 208340 | N44: 29551301 | O44: 393798 | P44: 54385444 | Q44: 206509 | R44: 27731583 | S44: 600307 | T44: 82117027
B45: 40118 | C45: 275060 | D45: 36136309 | E45: 118547 | F45: 15510429 | G45: 393607 | H45: 51646737 | I45: 121468 | J45: 17416795 | K45: 88421 | L45: 12008037 | M45: 209889 | N45: 29424832 | O45: 396528 | P45: 53553104 | Q45: 206968 | R45: 27518466 | S45: 603496 | T45: 81071570
...

Sheet DINAMICA APS
A1: PERIODO | B1: (Varios elementos) | I1: PERIODO | J1: (Varios elementos) | O1: PERIODO | P1: (Varios elementos)
A3: Etiquetas de fila | B3: Suma de APS VEJEZ MUJER n | C3: Suma de APS VEJEZ HOMBRE n | D3: Suma de APS INVALIDEZ MUJER N | E3: Suma de APS INVALIDEZ HOMBRE N | F3: Suma de APS TOTAL MUJER N | G3: Suma de APS TOTAL HOMBRE N | I3: Etiquetas de fila | J3: Suma de APS VEJEZ MUJER nom | K3: Suma de APS VEJEZ HOMBRE nom | L3: Suma de APS INVALIDEZ MUJER nom | M3: Suma de APS INVALIDEZ HOMBRE nom | O3: Etiquetas de fila | P3: Suma de PBSV_MUJER REAL | Q3: Suma de PBSV_HOMBRE REAL | R3: Suma de PBSI_MUJER REAL | S3: Suma de PBSI_HOMBRE REAL
A4: 2022 | B4: 327413 | C4: 190531 | D4: 137530 | E4: 139864 | F4: 464943 | G4: 330395 | I4: 2022 | J4: 69469277 | K4: 40636216 | L4: 22985157 | M4: 22214073 | O4: 2022 | P4: 69114843 | Q4: 40428576 | R4: 22868011 | S4: 22101174
A5: oct | B5: 109393 | C5: 63815 | D5: 45739 | E5: 46381 | F5: 155132 | G5: 110196 | I5: oct | J5: 23196046 | K5: 13590242 | L5: 7659976.5 | M5: 7378442.3 | O5: oct | P5: 22907040 | Q5: 13420918 | R5: 7564538.8 | S5: 7286512.4
A6: nov | B6: 109031 | C6: 63526 | D6: 45910 | E6: 46666 | F6: 154941 | G6: 110192 | I6: nov | J6: 23133194 | K6: 13546987 | L6: 7675227.2 | M6: 7413824.5 | O6: nov | P6: 23067766 | Q6: 13508672 | R6: 7653519.1 | S6: 7392855.8
A7: dic | B7: 108989 | C7: 63190 | D7: 45881 | E7: 46817 | F7: 154870 | G7: 110007 | I7: dic | J7: 23140038 | K7: 13498987 | L7: 7649953.3 | M7: 7421805.9 | O7: dic | P7: 23140038 | Q7: 13498987 | R7: 7649953.3 | S7: 7421805.9
A11: PERIODO | B11: (Varios elementos)
A13: Etiquetas de fila | B13: Suma de APS VEJEZ MUJER n | C13: Suma de APS VEJEZ HOMBRE n | D13: Suma de APS INVALIDEZ MUJER N | E13: Suma de APS INVALIDEZ HOMBRE N | F13: Suma de APS TOTAL MUJER N | G13: Suma de APS TOTAL HOMBRE N
A14: 2022 | B14: 2017877 | C14: 1478761 | D14: 540602 | E14: 538156 | F14: 2558479 | G14: 2016917
A17: PERIODO | B17: (Varios elementos)
A19: Etiquetas de fila | B19: Promedio de APS VEJEZ MUJER n | C19: Promedio de APS VEJEZ HOMBRE n | D19: Promedio de APS INVALIDEZ MUJER N | E19: Promedio de APS INVALIDEZ HOMBRE N | F19: Promedio de APS TOTAL MUJER N | G19: Promedio de APS TOTAL HOMBRE N
A20: 2022 | B20: 168156.42 | C20: 123230.08 | D20: 45050.167 | E20: 44846.333 | F20: 213206.58 | G20: 168076.42
A23: PERIODO | B23: (Varios elementos)
A25: Etiquetas de fila | B25: Suma de APS VEJEZ MUJER nom | C25: Suma de APS VEJEZ HOMBRE nom | D25: Suma de APS INVALIDEZ MUJER nom | E25: Suma de APS INVALIDEZ HOMBRE nom | F25: Suma de APS TOTAL MUJER nom | G25: Suma de APS TOTAL HOMBRE nom
A26: 2022 | B26: 3.6244601e+08 | C26: 2.505165e+08 | D26: 89129737 | E26: 84667893 | F26: 4.5157575e+08 | G26: 3.3518439e+08
A29: PERIODO | B29: (Varios elementos)
A31: Etiquetas de fila | B31: Promedio de APS VEJEZ MUJER nom | C31: Promedio de APS VEJEZ HOMBRE nom | D31: Promedio de APS INVALIDEZ MUJER nom | E31: Promedio de APS INVALIDEZ HOMBRE nom | F31: Promedio de APS TOTAL MUJER nom | G31: Promedio de APS TOTAL HOMBRE nom
A32: 2022 | B32: 30203834 | C32: 20876375 | D32: 7427478.1 | E32: 7055657.8 | F32: 37631312 | G32: 27932033
A35: PERIODO | B35: (Varios elementos)
A37: Etiquetas de fila | B37: Suma de PBSV_MUJER REAL | C37: Suma de PBSV_HOMBRE REAL | D37: Suma de PBSI_MUJER REAL | E37: Suma de PBSI_HOMBRE REAL
A38: 2022 | B38: 3.4085177e+08 | C38: 2.344632e+08 | D38: 85046490 | E38: 80830616
A42: PERIODO | B42: (Varios elementos)
A44: Etiquetas de fila | B44: Promedio de PBSV_MUJER REAL | C44: Promedio de PBSV_HOMBRE REAL | D44: Promedio de PBSI_MUJER REAL | E44: Promedio de PBSI_HOMBRE REAL
A45: 2022 | B45: 28404314 | C45: 19538600 | D45: 7087207.5 | E45: 6735884.7
A51: Etiquetas de fila | B51: Promedio de APS VEJEZ MUJER n | C51: Promedio de APS VEJEZ HOMBRE n | D51: Promedio de APS INVALIDEZ MUJER N | E51: Promedio de APS INVALIDEZ HOMBRE N
A52: 2008 | B52: 2920.6667 | C52: 1116 | D52: 286.33333 | E52: 290.33333
A53: 2009 | B53: 35080.083 | C53: 24939.75 | D53: 2213.8333 | E53: 1769.75
A54: 2010 | B54: 184671.58 | C54: 128661.83 | D54: 8050.9167 | E54: 5922.9167
A55: 2011 | B55: 232153.67 | C55: 168868.75 | D55: 12883.083 | E55: 9283.4167
A56: 2012 | B56: 279628 | C56: 203893.75 | D56: 19231.417 | E56: 14584.75
A57: 2013 | B57: 327092.08 | C57: 237763.33 | D57: 26607.083 | E57: 21058.833
A58: 2014 | B58: 354831.83 | C58: 258135.42 | D58: 33075.25 | E58: 26998.167
A59: 2015 | B59: 385388.58 | C59: 279293.17 | D59: 35497.583 | E59: 29292.083
A60: 2016 | B60: 409696.25 | C60: 297461.08 | D60: 35477.75 | E60: 29444.667
A61: 2017 | B61: 434014.42 | C61: 315115.08 | D61: 35236.417 | E61: 29440.417
A62: 2018 | B62: 472783.58 | C62: 343894.42 | D62: 35802.167 | E62: 30349.5
A63: 2019 | B63: 513930.5 | C63: 376625 | D63: 36751.75 | E63: 31642.25
... A90: dic | B90: 108989 | C90: 63190 | D90: 45881 | E90: 46817
A94: Etiquetas de fila | B94: Promedio de PBSV_MUJER REAL | C94: Promedio de PBSV_HOMBRE REAL | D94: Promedio de PBSI_MUJER REAL | E94: Promedio de PBSI_HOMBRE REAL
A95: 2008 | B95: 156325.61 | C95: 77435.604 | D95: 15483.202 | E95: 15243.679
...

Sheet 1.4
B2: PAGOS APORTE PREVISIONAL SOLIDARIO (APS)
B4: Resumen trimestral de beneficios pagados, por tipo y sexo
B5: (enero 2023 a marzo 2023)
D7: APS Vejez | G7: APS Invalidez | J7: APS Total
B8: Periodo | C8: Sexo Beneficiarios | D8: N° | E8: Monto nominal M$ * | F8: Monto real M$ ** | G8: N° | H8: Monto nominal M$ * | I8: Monto real M$ ** | J8: N° | K8: Monto nominal M$ * | L8: Monto real M$ **
B9: 44927 | C9: Mujeres | D9: 108797 | E9: 23112170 | F9: 23348370 | G9: 46104 | H9: 7667276.8 | I9: 7745634.3 | J9: 154901 | K9: 30779447 | L9: 31094004
C10: Hombres | D10: 62891 | E10: 13450862 | F10: 13588326 | G10: 47256 | H10: 7473814.7 | I10: 7550195 | J10: 110147 | K10: 20924676 | L10: 21138521
C11: Total | D11: 171688 | E11: 36563032 | F11: 36936696 | G11: 93360 | H11: 15141092 | I11: 15295829 | J11: 265048 | K11: 51704123 | L11: 52232525
B12: 44958 | C12: Mujeres | D12: 108645 | E12: 23098113 | F12: 23349164 | G12: 46210 | H12: 8237673.4 | I12: 8327208 | J12: 154855 | K12: 31335786 | L12: 31676372
C13: Hombres | D13: 62678 | E13: 13420694 | F13: 13566562 | G13: 47542 | H13: 8076320.7 | I13: 8164101.5 | J13: 110220 | K13: 21497014 | L13: 21730664
C14: Total | D14: 171323 | E14: 36518806 | F14: 36915726 | G14: 93752 | H14: 16313994 | I14: 16491309 | J14: 265075 | K14: 52832800 | L14: 53407036
B15: 44986 | C15: Mujeres | D15: 108598 | E15: 23099682 | F15: 23099682 | G15: 46381 | H15: 8260461.9 | I15: 8260461.9 | J15: 154979 | K15: 31360144 | L15: 31360144
C16: Hombres | D16: 62593 | E16: 13421795 | F16: 13421795 | G16: 47964 | H16: 8133304 | I16: 8133304 | J16: 110557 | K16: 21555099 | L16: 21555099
C17: Total | D17: 171191 | E17: 36521477 | F17: 36521477 | G17: 94345 | H17: 16393766 | I17: 16393766 | J17: 265536 | K17: 52915243 | L17: 52915243
B18: Fuente: Elaboración propia con datos de la Superintendencia de Pensiones
B19: Nota 1: La Pensión Garantizada Universal (PGU) es un nuevo beneficio generado a partir de la ley 21.419 del 29-01-2022. El concepto de PGU No Contributiva o Contributiva está relacionado con la calidad de la persona que está recibiendo el beneficio, si es No Contributiva quiere decir que no estaba afiliado a un sistema previsional (D.L. 3.500 o antiguo Sistema de Reparto) ni recibe pensión de sobrevivencia, si es Contributiva quiere decir que si estaba afiliado a un sistema previsional o que recibe una pensión de sobrevivencia. De manera automática, en febrero 2022, los PBS de Vejez pasaron a ser PGU No Contributiva y los APS Vejez Subsidio Definido, los Beneficio artículo 9° bis y los APS Vejez con una Pensión Final Garantizada inferior o igual al monto de la PGU pasaron a ser PGU Contributiva (Fuente: Superintendencia de Pensiones). Nota 2: Para los APS de Vejez, en aquellos casos en que este beneficio superaba el monto de la PGU se mantuvo el beneficio.
B20: * Montos nominales de cada periodo de pago. ** Montos deflactados a marzo 2023
B22: Serie resumen de pagos (monto real M$) de beneficios acumulado, por tipo y sexo
B23: (enero 2020 a marzo 2023)
C25: APS Vejez | I25: APS Invalidez | O25: APS Total
C26: Mujeres | E26: Hombres | G26: Total | I26: Mujeres | K26: Hombres | M26: Total | O26: Mujeres | Q26: Hombres | S26: Total
B27: Periodo | C27: N° Beneficios promedio | D27: Monto promedio M$ * | E27: N° Beneficios promedio | F27: Monto promedio M$ * | G27: N° Beneficios promedio | H27: Monto promedio M$ * | I27: N° Beneficios promedio | J27: Monto promedio M$ * | K27: N° Beneficios promedio | L27: Monto promedio M$ * | M27: N° Beneficios promedio | N27: Monto promedio M$ * | O27: N° Beneficios promedio | P27: Monto promedio M$ * | Q27: N° Beneficios promedio | R27: Monto promedio M$ * | S27: N° Beneficios promedio | T27: Monto promedio M$ *
B28: 39630
B29: 39661
B30: 39692
B31: 39722 | C31: 2444 | D31: 648222.49 | E31: 955 | F31: 322292.67 | G31: 3399 | H31: 970515.16 | I31: 217 | J31: 59396.345 | K31: 229 | L31: 60396.67 | M31: 446 | N31: 119793.02 | O31: 2661 | P31: 707618.84 | Q31: 1184 | R31: 382689.34 | S31: 3845 | T31: 1090308.2
B32: 39753 | C32: 3067 | D32: 324830.45 | E32: 1159 | F32: 144184.79 | G32: 4226 | H32: 469015.24 | I32: 290 | J32: 34543.372 | K32: 294 | L32: 33054.56 | M32: 584 | N32: 67597.932 | O32: 3357 | P32: 359373.82 | Q32: 1453 | R32: 177239.35 | S32: 4810 | T32: 536613.17
B33: 39783 | C33: 3251 | D33: 338240.49 | E33: 1234 | F33: 183438.91 | G33: 4485 | H33: 521679.39 | I33: 352 | J33: 36007.324 | K33: 348 | L33: 34457.564 | M33: 700 | N33: 70464.889 | O33: 3603 | P33: 374247.81 | Q33: 1582 | R33: 217896.47 | S33: 5185 | T33: 592144.28
B34: Promedio 2008 | C34: 2920.6667 | D34: 437097.81 | E34: 1116 | F34: 216638.79 | G34: 4036.6667 | H34: 653736.6 | I34: 286.33333 | J34: 43315.68 | K34: 290.33333 | L34: 42636.265 | M34: 576.66667 | N34: 85951.945 | O34: 3207 | P34: 480413.49 | Q34: 1406.3333 | R34: 259275.05 | S34: 4613.3333 | T34: 739688.54
B35: 39814 | C35: 4434 | D35: 663521 | E35: 1765 | F35: 334527.25 | G35: 6199 | H35: 998048.25 | I35: 468 | J35: 65293.925 | K35: 481 | L35: 74990.814 | M35: 949 | N35: 140284.74 | O35: 4902 | P35: 728814.92 | Q35: 2246 | R35: 409518.07 | S35: 7148 | T35: 1138333
B36: 39845 | C36: 5048 | D36: 512980.24 | E36: 2132 | F36: 269343.24 | G36: 7180 | H36: 782323.47 | I36: 596 | J36: 81174.641 | K36: 584 | L36: 75433.658 | M36: 1180 | N36: 156608.3 | O36: 5644 | P36: 594154.88 | Q36: 2716 | R36: 344776.89 | S36: 8360 | T36: 938931.77
B37: 39873 | C37: 5703 | D37: 567469.5 | E37: 2584 | F37: 346679.3 | G37: 8287 | H37: 914148.8 | I37: 787 | J37: 106349.65 | K37: 703 | L37: 81413.263 | M37: 1490 | N37: 187762.92 | O37: 6490 | P37: 673819.16 | Q37: 3287 | R37: 428092.56 | S37: 9777 | T37: 1101911.7
B38: 39904 | C38: 6499 | D38: 815091.05 | E38: 3131 | F38: 483912.06 | G38: 9630 | H38: 1299003.1 | I38: 1119 | J38: 187820.7 | K38: 922 | L38: 136991.07 | M38: 2041 | N38: 324811.77 | O38: 7618 | P38: 1002911.8 | Q38: 4053 | R38: 620903.13 | S38: 11671 | T38: 1623814.9
B39: 39934 | C39: 7208 | D39: 749849.28 | E39: 3842 | F39: 570615.27 | G39: 11050 | H39: 1320464.6 | I39: 1372 | J39: 178067.46 | K39: 1125 | L39: 143887.49 | M39: 2497 | N39: 321954.95 | O39: 8580 | P39: 927916.75 | Q39: 4967 | R39: 714502.76 | S39: 13547 | T39: 1642419.5
B40: 39965 | C40: 7817 | D40: 755293.27 | E40: 4373 | F40: 525001.09 | G40: 12190 | H40: 1280294.4 | I40: 1674 | J40: 211125.78 | K40: 1346 | L40: 162185.77 | M40: 3020 | N40: 373311.55 | O40: 9491 | P40: 966419.05 | Q40: 5719 | R40: 687186.85 | S40: 15210 | T40: 1653605.9
B41: 39995 | C41: 8395 | D41: 1095393.8 | E41: 4882 | F41: 731647.93 | G41: 13277 | H41: 1827041.7 | I41: 2118 | J41: 383541.09 | K41: 1670 | L41: 298361.59 | M41: 3788 | N41: 681902.68 | O41: 10513 | P41: 1478934.9 | Q41: 6552 | R41: 1030009.5 | S41: 17065 | T41: 2508944.4
B42: 40026 | C42: 9052 | D42: 1275761.2 | E42: 5603 | F42: 1002673.7 | G42: 14655 | H42: 2278434.9 | I42: 2469 | J42: 398970.95 | K42: 1969 | L42: 311285.01 | M42: 4438 | N42: 710255.97 | O42: 11521 | P42: 1674732.2 | Q42: 7572 | R42: 1313958.7 | S42: 19093 | T42: 2988690.9
B43: 40057 | C43: 12193 | D43: 1641569 | E43: 15010 | F43: 1696568.3 | G43: 27203 | H43: 3338137.3 | I43: 2777 | J43: 412814.87 | K43: 2203 | L43: 319529.11 | M43: 4980 | N43: 732343.98 | O43: 14970 | P43: 2054383.8 | Q43: 17213 | R43: 2016097.4 | S43: 32183 | T43: 4070481.2
B44: 40087 | C44: 98877 | D44: 8075439.2 | E44: 70157 | F44: 5101603.2 | G44: 169034 | H44: 13177042 | I44: 3876 | J44: 741073.67 | K44: 3042 | L44: 556305.7 | M44: 6918 | N44: 1297379.4 | O44: 102753 | P44: 8816512.8 | Q44: 73199 | R44: 5657908.9 | S44: 175952 | T44: 14474422
B45: 40118 | C45: 118191 | D45: 4889824.6 | E45: 85364 | F45: 3650599.9 | G45: 203555 | H45: 8540424.4 | I45: 4342 | J45: 652977.74 | K45: 3394 | L45: 498331.52 | M45: 7736 | N45: 1151309.3 | O45: 122533 | P45: 5542802.3 | Q45: 88758 | R45: 4148931.4 | S45: 211291 | T45: 9691733.7
...

Sheet Hoja2
A3: -> region_codigo | B3: = | C3: 1
C5: estado_solicitud
A6: comuna | B6: A | C6: C | D6: D | E6: R | F6: T | G6: Total
A8: ALTO HOSPICIO | B8: 32 | C8: 8631 | D8: 1 | E8: 1938 | F8: 329 | G8: 10931
A9: CAMIÑA | B9: 0 | C9: 192 | D9: 0 | E9: 38 | F9: 4 | G9: 234
A10: COLCHANE | B10: 2 | C10: 137 | D10: 0 | E10: 25 | F10: 3 | G10: 167
A11: HUARA | B11: 6 | C11: 476 | D11: 1 | E11: 103 | F11: 14 | G11: 600
A12: IQUIQUE | B12: 90 | C12: 26648 | D12: 11 | E12: 6786 | F12: 678 | G12: 34213
A13: PICA | B13: 2 | C13: 876 | D13: 0 | E13: 200 | F13: 26 | G13: 1104
A14: POZO ALMONTE | B14: 9 | C14: 1589 | D14: 0 | E14: 403 | F14: 50 | G14: 2051
A15: Total | B15: =SUM(B8:B14) -> 141 | C15: =SUM(C8:C14) -> 38549 | D15: =SUM(D8:D14) -> 13 | E15: =SUM(E8:E14) -> 9493 | F15: =SUM(F8:F14) -> 1104 | G15: =SUM(G8:G14) -> 49300
A21: -> region_codigo = 2
B23: estado_solicitud
A24: comuna | B24: A | C24: C | D24: D | E24: R | F24: T | G24: Total
A26: ANTOFAGASTA | B26: 137 | C26: 41859 | D26: 18 | E26: 10946 | F26: 1282 | G26: 54242
A27: CALAMA | B27: 30 | C27: 14670 | D27: 8 | E27: 3983 | F27: 498 | G27: 19189
A28: MARIA ELENA | B28: 0 | C28: 414 | D28: 0 | E28: 130 | F28: 12 | G28: 556
A29: MEJILLONES | B29: 3 | C29: 1165 | D29: 1 | E29: 377 | F29: 59 | G29: 1605
A30: OLLAGUE | B30: 0 | C30: 37 | D30: 0 | E30: 5 | F30: 1 | G30: 43
A31: SAN PEDRO DE ATACAMA | B31: 1 | C31: 680 | D31: 0 | E31: 145 | F31: 25 | G31: 851
A32: SIERRA GORDA | B32: 0 | C32: 98 | D32: 0 | E32: 29 | F32: 2 | G32: 129
A33: TALTAL | B33: 4 | C33: 1885 | D33: 0 | E33: 570 | F33: 63 | G33: 2522
A34: TOCOPILLA | B34: 11 | C34: 4223 | D34: 7 | E34: 1046 | F34: 126 | G34: 5413
A36: Total | B36: =SUM(B26:B35) -> 186 | C36: =SUM(C26:C35) -> 65031 | D36: =SUM(D26:D35) -> 34 | E36: =SUM(E26:E35) -> 17231 | F36: =SUM(F26:F35) -> 2068 | G36: =SUM(G26:G35) -> 84550
A42: -> region_codigo | B42: = | C42: 3
C44: estado_solicitud
A45: comuna | C45: A | D45: C | E45: D | F45: R | G45: T | H45: Total
A47: ALTO DEL CARMEN | C47: 1 | D47: 962 | E47: 0 | F47: 159 | G47: 31 | H47: 1153
A48: CALDERA | C48: 9 | D48: 2524 | E48: 1 | F48: 499 | G48: 92 | H48: 3125
A49: CHAÑARAL | C49: 5 | D49: 2246 | E49: 3 | F49: 497 | G49: 44 | H49: 2795
A50: COPIAPO | C50: 67 | D50: 20329 | E50: 7 | F50: 4285 | G50: 511 | H50: 25199
A51: DIEGO DE ALMAGRO | C51: 6 | D51: 1399 | E51: 1 | F51: 380 | G51: 25 | H51: 1811
A52: FREIRINA | C52: 4 | D52: 1169 | E52: 0 | F52: 197 | G52: 13 | H52: 1383
A53: HUASCO | C53: 2 | D53: 1687 | E53: 1 | F53: 361 | G53: 43 | H53: 2094
A54: TIERRA AMARILLA | C54: 4 | D54: 1565 | E54: 1 | F54: 299 | G54: 40 | H54: 1909
A55: VALLENAR | C55: 34 | D55: 9905 | E55: 3 | F55: 1871 | G55: 198 | H55: 12011
A57: Total | C57: 132 | D57: 41786 | E57: 17 | F57: 8548 | G57: 997 | H57: 51480
A63: -> region_codigo | B63: = | C63: 4
C65: estado_solicitud
A66: comuna | B66: A | C66: C | D66: D | E66: R | F66: T | G66: Total
...

Sheet II. Estado de Solicitudes
B1: Subsecretaría de Previsión Social Dirección de Estudios Previsionales
B9: II. Estado de solicitudes
B10: Trimestre EFM 2023
B12: 1. Solicitudes del Pilar No Contributivo a nivel nacional
B13: i. Resumen trimestral de número y estado de solicitudes, según tipo de beneficio y sexo
B14: ii. Serie resumen de solicitudes de beneficios, por tipo de beneficio y sexo
B15: 2. Solicitudes del Pilar No Contributivo a nivel regional y comunal
B16: i. Resumen trimestral de solicitudes por región, según tipo de beneficio y sexo
B17: ii. Número de solicitudes trimestrales por comuna, según tipo de beneficio y sexo
B18: Región de Tarapacá
B19: Región de Antofagasta
B20: Región de Atacama
... B61: ii. Serie resumen de tasas de concesión de solicitudes por tipo de beneficio y sexo

Sheet 2.1
B2: SOLICITUDES DEL PILAR NO CONTRIBUTIVO A NIVEL NACIONAL
B4: Resumen trimestral de número y estado de solicitudes, según tipo de beneficio y sexo
B5: (enero 2023 a marzo 2023)
B7: Tipo de beneficio | C7: Sexo Beneficiarios | D7: Estado de las solicitudes
D8: Anuladas | F8: Concedidas | H8: Desistidas | J8: Rechazadas | L8: En Trámite | N8: Total Solicitudes
D9: N° | E9: % | F9: N° | G9: % | H9: N° | I9: % | J9: N° | K9: % | L9: N° | M9: % | N9: N° | O9: %
B10: PGU No Contributiva | C10: Mujeres | D10: 9 | E10: =D10/$N10 -> 0.00080551329 | F10: 7118 | G10: =F10/$N10 -> 0.63707151 | H10: 19 | I10: =H10/$N10 -> 0.0017005281 | J10: 10 | K10: =J10/$N10 -> 0.00089501477 | L10: 4017 | M10: =L10/$N10 -> 0.35952743 | N10: 11173 | O10: =N10/$N10 -> 1
C11: Hombres | D11: 4 | E11: =D11/$N11 -> 0.00026413101 | F11: 9059 | G11: =F11/$N11 -> 0.5981907 | H11: 3 | I11: =H11/$N11 -> 0.00019809826 | J11: 16 | K11: =J11/$N11 -> 0.001056524 | L11: 6062 | M11: =L11/$N11 -> 0.40029054 | N11: 15144 | O11: =N11/$N11 -> 1
