Workbook

Sheet Indice General
B1: Subsecretaría de Previsión Social Dirección de Estudios Previsionales
B9: Informe trimestral del Pilar No Contributivo
B10: Trimestre OND 2022
B12: I. Pago de Beneficios del Pilar No Contributivo
B13: 1. Total de beneficios pagados del Pilar No Contributivo
B14: 2. Pagos Pensión Básica Solidaria (PBS)
B15: 3. Pagos Pensión Garantizada Universal (PGU)
B16: 4. Pagos Aporte Previsional Solidario (APS)
B17: 5. Pagos Beneficio del artículo 9° bis (Nbis)
B18: II. Estado de solicitudes
B19: 1. Estado de las solicitudes del Pilar No Contributivo
B20: 2. Solicitudes del Pilar No Contributivo a nivel nacional
... B32: 3. Subsidio a la Cotización de Trabajadores Jóvenes

Sheet I. Beneficios pagados
B1: Subsecretaría de Previsión Social Dirección de Estudios Previsionales
B9: I. Pago de Beneficios del Pilar No Contributivo
B10: Trimestre OND 2022
B12: 1. Total de beneficios pagados del Pilar No Contributivo
B13: i. Resumen trimestral de beneficios pagados en T4 2022, por tipo y sexo
B14: ii. Resumen anual de beneficios pagados en 2022, por tipo y sexo
B15: iii. Serie resumen de pagos de beneficios acumulados, por tipo
B16: 2. Pagos Pensión Básica Solidaria (PBS)
B17: i. Resumen trimestral de beneficios pagados en T4 2022, por tipo y sexo
B18: ii. Resumen anual de beneficios pagados en 2022, por tipo y sexo
B19: iii. Serie resumen de pagos de beneficios acumulado, por tipo y sexo
B20: 3. Pagos Pensión Garantizada Universal (PGU)
... B31: iii. Serie resumen de pagos de beneficios acumulado, por tipo y sexo

Sheet dinamica pgu
A1: PERIODO | B1: (Varios elementos)
A3: Etiquetas de fila
A4: oct
A5: Suma de PGU_NC_Mujer_n | B5: 322141
A6: Suma de PGU_NC_hombre_N | B6: 109963
A7: Suma de PGU_C_Mujer_N | B7: 686334
A8: Suma de PGU_C_hombre_N | B8: 563950
A9: nov
A10: Suma de PGU_NC_Mujer_n | B10: 327443
A11: Suma de PGU_NC_hombre_N | B11: 121585
A12: Suma de PGU_C_Mujer_N | B12: 704099
A13: Suma de PGU_C_hombre_N | B13: 584193
A14: dic
A15: Suma de PGU_NC_Mujer_n | B15: 329180
A16: Suma de PGU_NC_hombre_N | B16: 125728
A17: Suma de PGU_C_Mujer_N | B17: 717919
A18: Suma de PGU_C_hombre_N | B18: 594890
A22: PERIODO | B22: (Varios elementos)
A24: Etiquetas de fila
A25: oct
A26: Suma de PGU_NC_Mujer_Nom | B26: 62098940
A27: Suma de PGU_NC_hombre_Nom | B27: 21312758
A28: Suma de PGU_C_Mujer_Nom | B28: 1.3198656e+08
A29: Suma de PGU_C_hombre_Nom | B29: 1.0801488e+08
A30: nov
A31: Suma de PGU_NC_Mujer_Nom | B31: 63080933
A32: Suma de PGU_NC_hombre_Nom | B32: 23564397
A33: Suma de PGU_C_Mujer_Nom | B33: 1.3523624e+08
A34: Suma de PGU_C_hombre_Nom | B34: 1.115372e+08
A35: dic
A36: Suma de PGU_NC_Mujer_Nom | B36: 63417032
A37: Suma de PGU_NC_hombre_Nom | B37: 24368203
A38: Suma de PGU_C_Mujer_Nom | B38: 1.3763622e+08
A39: Suma de PGU_C_hombre_Nom | B39: 1.1328694e+08
A43: PERIODO | B43: (Varios elementos)
A45: Etiquetas de fila
A46: oct
A47: Suma de PGU_NC_Mujer_REAL | B47: 61325232
A48: Suma de PGU_NC_hombre_REAL | B48: 21047217
A49: Suma de PGU_C_Mujer_REAL | B49: 1.303421e+08
...

Sheet N PBS
A3: Etiquetas de fila | B3: Promedio de PBS VEJEZ MUJER | C3: Promedio de PBS VEJEZ HOMBRE | D3: Promedio de PBS INVALIDEZ MUJER | E3: Promedio de PBS INVALIDEZ HOMBRE | F3: Promedio de PBS TOTAL MUJER | G3: Promedio de PBS TOTAL HOMBRE
A4: 2008 | B4: 218799.83 | C4: 107682.67 | D4: 108916.5 | E4: 84536 | F4: 327716.33 | G4: 192218.67
A5: 2009 | B5: 262267.25 | C5: 117026.58 | D5: 116205.08 | E5: 86817.667 | F5: 378472.33 | G5: 203844.25
A6: 2010 | B6: 284569.67 | C6: 119969.58 | D6: 125529.75 | E6: 89731.417 | F6: 410099.42 | G6: 209701
A7: 2011 | B7: 286982.92 | C7: 118668.92 | D7: 125674.58 | E7: 89317.917 | F7: 412657.5 | G7: 207986.83
A8: 2012 | B8: 288232.25 | C8: 116683.83 | D8: 120025.92 | E8: 85446.25 | F8: 408258.17 | G8: 202130.08
A9: 2013 | B9: 288720.25 | C9: 114312 | D9: 112605.08 | E9: 79812.917 | F9: 401325.33 | G9: 194124.92
A10: 2014 | B10: 288530.42 | C10: 111136.17 | D10: 107377.17 | E10: 75527.833 | F10: 395907.58 | G10: 186664
A11: 2015 | B11: 289070.58 | C11: 110162 | D11: 105105.42 | E11: 74655.333 | F11: 394176 | G11: 184817.33
A12: 2016 | B12: 290373 | C12: 108843.42 | D12: 105459.83 | E12: 75532.583 | F12: 395832.83 | G12: 184376
A13: 2017 | B13: 291754 | C13: 107694.83 | D13: 105581.83 | E13: 76434.167 | F13: 397335.83 | G13: 184129
A14: 2018 | B14: 295171.83 | C14: 107077.42 | D14: 105559.42 | E14: 77417 | F14: 400731.25 | G14: 184494.42
A15: 2019 | B15: 299821.5 | C15: 106705.25 | D15: 104899.17 | E15: 77850.417 | F15: 404720.67 | G15: 184555.67
... A42: dic | B42: 0 | C42: 0 | D42: 103979 | E42: 81605 | F42: 103979 | G42: 81605

Sheet MONTOS PBS
I1: PERIODO | J1: (Varios elementos)
A3: Etiquetas de fila | B3: Promedio de PBSV_MUJER | C3: Promedio de PBSV_HOMBRE | D3: Promedio de PBSI_MUJER | E3: Promedio de PBSI_HOMBRE | F3: Promedio de PBS_MUJER | G3: Promedio de PBS_HOMBRE | I3: Etiquetas de fila | J3: Suma de PBSV_MUJER | K3: Suma de PBSV_HOMBRE | L3: Suma de PBSV_TOTAL | M3: Suma de PBSI_MUJER | N3: Suma de PBSI_HOMBRE | O3: Suma de PBSI_TOTAL | P3: Suma de PBS_MUJER | Q3: Suma de PBS_HOMBRE | R3: Suma de PBS_TOTAL | T3: Etiquetas de fila | U3: Suma de PBSV_MUJER | V3: Suma de PBSV_HOMBRE | W3: Suma de PBSV_TOTAL | X3: Suma de PBSI_MUJER | Y3: Suma de PBSI_HOMBRE | Z3: Suma de PBSI_TOTAL | AA3: Suma de PBS_MUJER | AB3: Suma de PBS_HOMBRE | AC3: Suma de PBS_TOTAL | AE3: Etiquetas de fila | AF3: Suma de PBSV_MUJER | AG3: Suma de PBSV_HOMBRE | AH3: Suma de PBSV_TOTAL | AI3: Suma de PBSI_MUJER | AJ3: Suma de PBSI_HOMBRE | AK3: Suma de PBSI_TOTAL | AL3: Suma de PBS_MUJER | AM3: Suma de PBS_HOMBRE | AN3: Suma de PBS_TOTAL
A4: 2008 | B4: 8.2469269e+09 | C4: 3.9732077e+09 | D4: 3.9696562e+09 | E4: 3.0646136e+09 | F4: 1.2216583e+10 | G4: 7.0378213e+09 | I4: 2022 | J4: 0 | K4: 0 | L4: 0 | M4: 6.0133313e+10 | N4: 4.7149436e+10 | O4: 1.0728275e+11 | P4: 6.0133313e+10 | Q4: 4.7149436e+10 | R4: 1.0728275e+11 | T4: oct | U4: 0 | V4: 0 | W4: 0 | X4: 1.9903687e+10 | Y4: 1.5583475e+10 | Z4: 3.5487162e+10 | AA4: 1.9903687e+10 | AB4: 1.5583475e+10 | AC4: 3.5487162e+10 | AE4: oct | AF4: =+U4/1000 -> 0 | AG4: =+V4/1000 -> 0 | AH4: =+W4/1000 -> 0 | AI4: =+X4/1000 -> 19903687 | AJ4: =+Y4/1000 -> 15583475 | AK4: =+Z4/1000 -> 35487162 | AL4: =+AA4/1000 -> 19903687 | AM4: =+AB4/1000 -> 15583475 | AN4: =+AC4/1000 -> 35487162
A5: 2009 | B5: 1.0831943e+10 | C5: 4.7784934e+09 | D5: 5.149103e+09 | E5: 3.655593e+09 | F5: 1.5981046e+10 | G5: 8.4340864e+09 | I5: oct | J5: 0 | K5: 0 | L5: 0 | M5: 1.9903687e+10 | N5: 1.5583475e+10 | O5: 3.5487162e+10 | P5: 1.9903687e+10 | Q5: 1.5583475e+10 | R5: 3.5487162e+10 | T5: nov | U5: 0 | V5: 0 | W5: 0 | X5: 2.0075789e+10 | Y5: 1.5749774e+10 | Z5: 3.5825563e+10 | AA5: 2.0075789e+10 | AB5: 1.5749774e+10 | AC5: 3.5825563e+10 | AE5: nov | AF5: =+U5/1000 -> 0 | AG5: =+V5/1000 -> 0 | AH5: =+W5/1000 -> 0 | AI5: =+X5/1000 -> 20075789 | AJ5: =+Y5/1000 -> 15749774 | AK5: =+Z5/1000 -> 35825563 | AL5: =+AA5/1000 -> 20075789 | AM5: =+AB5/1000 -> 15749774 | AN5: =+AC5/1000 -> 35825563
A6: 2010 | B6: 1.3095568e+10 | C6: 5.5029662e+09 | D6: 5.9733298e+09 | E6: 4.1819318e+09 | F6: 1.9068897e+10 | G6: 9.684898e+09 | I6: nov | J6: 0 | K6: 0 | L6: 0 | M6: 2.0075789e+10 | N6: 1.5749774e+10 | O6: 3.5825563e+10 | P6: 2.0075789e+10 | Q6: 1.5749774e+10 | R6: 3.5825563e+10 | T6: dic | U6: 0 | V6: 0 | W6: 0 | X6: 20153837159 | Y6: 15816186175 | Z6: 35970023334 | AA6: 20153837159 | AB6: 15816186175 | AC6: 35970023334 | AE6: dic | AF6: =+U6/1000 -> 0 | AG6: =+V6/1000 -> 0 | AH6: =+W6/1000 -> 0 | AI6: =+X6/1000 -> 20153837 | AJ6: =+Y6/1000 -> 15816186 | AK6: =+Z6/1000 -> 35970023 | AL6: =+AA6/1000 -> 20153837 | AM6: =+AB6/1000 -> 15816186 | AN6: =+AC6/1000 -> 35970023
A7: 2011 | B7: 1.3994994e+10 | C7: 5.7801079e+09 | D7: 6.2216009e+09 | E7: 4.3734947e+09 | F7: 2.0216595e+10 | G7: 1.0153603e+10 | I7: dic | J7: 0 | K7: 0 | L7: 0 | M7: 20153837159 | N7: 15816186175 | O7: 35970023334 | P7: 20153837159 | Q7: 15816186175 | R7: 35970023334
A8: 2012 | B8: 1.4900592e+10 | C8: 6.0276417e+09 | D8: 6.3053347e+09 | E8: 4.4481809e+09 | F8: 2.1205927e+10 | G8: 1.0475823e+10
A9: 2013 | B9: 1.5464511e+10 | C9: 6.1276381e+09 | D9: 6.1333006e+09 | E9: 4.2916174e+09 | F9: 2.1597811e+10 | G9: 1.0419256e+10
A10: 2014 | B10: 1.6719242e+10 | C10: 6.4430339e+09 | D10: 6.3328754e+09 | E10: 4.3768174e+09 | F10: 2.3052118e+10 | G10: 1.0819851e+10
A11: 2015 | B11: 1.8210703e+10 | C11: 6.9460832e+09 | D11: 6.7614414e+09 | E11: 4.7714308e+09 | F11: 2.4972144e+10 | G11: 1.1717514e+10
A12: 2016 | B12: 1.9783297e+10 | C12: 7.4256197e+09 | D12: 7.3620108e+09 | E12: 5.231601e+09 | F12: 2.7145307e+10 | G12: 1.2657221e+10 | I12: PERIODO | J12: (Varios elementos) | AE12: nominales
A13: 2017 | B13: 2.3013212e+10 | C13: 8.5012643e+09 | D13: 8.4836307e+09 | E13: 6.1043568e+09 | F13: 3.1496842e+10 | G13: 1.4605621e+10 | AF13: vejez | AI13: invalidez | AL13: total
A14: 2018 | B14: 2.4370428e+10 | C14: 8.8423454e+09 | D14: 8.863105e+09 | E14: 6.4518852e+09 | F14: 3.3233533e+10 | G14: 1.5294231e+10 | I14: Etiquetas de fila | J14: Suma de MUJER | K14: Suma de HOMBRE | L14: Suma de TOTAL | M14: Suma de MUJER2 | N14: Suma de HOMBRE2 | O14: Suma de TOTAL2 | P14: Suma de MUJER3 | Q14: Suma de HOMBRE3 | R14: Suma de TOTAL3 | T14: Etiquetas de fila | U14: Suma de MUJER | V14: Suma de HOMBRE | W14: Suma de TOTAL | X14: Suma de MUJER2 | Y14: Suma de HOMBRE2 | Z14: Suma de TOTAL2 | AA14: Suma de MUJER3 | AB14: Suma de HOMBRE3 | AC14: Suma de TOTAL3 | AE14: Etiquetas de fila | AF14: Promedio de MUJER | AG14: Promedio de HOMBRE | AH14: Promedio de TOTAL | AI14: Promedio de MUJER2 | AJ14: Promedio de HOMBRE2 | AK14: Promedio de TOTAL2 | AL14: Promedio de MUJER3 | AM14: Promedio de HOMBRE3 | AN14: Promedio de TOTAL3
A15: 2019 | B15: 2.6689511e+10 | C15: 9.492244e+09 | D15: 9.429656e+09 | E15: 6.9564548e+09 | F15: 3.6119167e+10 | G15: 1.6448699e+10 | I15: 2022 | J15: 0 | K15: 0 | L15: 0 | M15: 60441368879 | N15: 47390715970 | O15: 107832084849 | P15: 60441368879 | Q15: 47390715970 | R15: 107832084849 | T15: oct | U15: 0 | V15: 0 | W15: 0 | X15: 20154801071 | Y15: 15780083599 | Z15: 35934884670 | AA15: 20154801071 | AB15: 15780083599 | AC15: 35934884670 | AE15: oct | AF15: =+U15/1000 -> 0 | AG15: =+V15/1000 -> 0 | AH15: =+W15/1000 -> 0 | AI15: =+X15/1000 -> 20154801 | AJ15: =+Y15/1000 -> 15780084 | AK15: =+Z15/1000 -> 35934885 | AL15: =+AA15/1000 -> 20154801 | AM15: =+AB15/1000 -> 15780084 | AN15: =+AC15/1000 -> 35934885
A16: 2020 | B16: 3.659289e+10 | C16: 1.2913294e+10 | D16: 1.1894674e+10 | E16: 8.9114229e+09 | F16: 4.8487564e+10 | G16: 2.1824717e+10 | I16: oct | J16: 0 | K16: 0 | L16: 0 | M16: 20154801071 | N16: 15780083599 | O16: 35934884670 | P16: 20154801071 | Q16: 15780083599 | R16: 35934884670 | T16: nov | U16: 0 | V16: 0 | W16: 0 | X16: 20132730649 | Y16: 15794446196 | Z16: 35927176845 | AA16: 20132730649 | AB16: 15794446196 | AC16: 35927176845 | AE16: nov | AF16: =+U16/1000 -> 0 | AG16: =+V16/1000 -> 0 | AH16: =+W16/1000 -> 0 | AI16: =+X16/1000 -> 20132731 | AJ16: =+Y16/1000 -> 15794446 | AK16: =+Z16/1000 -> 35927177 | AL16: =+AA16/1000 -> 20132731 | AM16: =+AB16/1000 -> 15794446 | AN16: =+AC16/1000 -> 35927177
A17: 2021 | B17: 4.3453866e+10 | C17: 1.494933e+10 | D17: 1.4114095e+10 | E17: 1.0837333e+10 | F17: 5.7567962e+10 | G17: 2.5786663e+10 | I17: nov | J17: 0 | K17: 0 | L17: 0 | M17: 20132730649 | N17: 15794446196 | O17: 35927176845 | P17: 20132730649 | Q17: 15794446196 | R17: 35927176845 | T17: dic | U17: 0 | V17: 0 | W17: 0 | X17: 20153837159 | Y17: 15816186175 | Z17: 35970023334 | AA17: 20153837159 | AB17: 15816186175 | AC17: 35970023334 | AE17: dic | AF17: =+U17/1000 -> 0 | AG17: =+V17/1000 -> 0 | AH17: =+W17/1000 -> 0 | AI17: =+X17/1000 -> 20153837 | AJ17: =+Y17/1000 -> 15816186 | AK17: =+Z17/1000 -> 35970023 | AL17: =+AA17/1000 -> 20153837 | AM17: =+AB17/1000 -> 15816186 | AN17: =+AC17/1000 -> 35970023
A18: ene | B18: 4.1412765e+10 | C18: 1.4344175e+10 | D18: 1.357545e+10 | E18: 1.0301137e+10 | F18: 5.4988215e+10 | G18: 2.4645311e+10 | I18: dic | J18: 0 | K18: 0 | L18: 0 | M18: 20153837159 | N18: 15816186175 | O18: 35970023334 | P18: 20153837159 | Q18: 15816186175 | R18: 35970023334 | T18: Total general | U18: 0 | V18: 0 | W18: 0 | X18: 2.0147123e+10 | Y18: 1.5796905e+10 | Z18: 35944028283 | AA18: 2.0147123e+10 | AB18: 1.5796905e+10 | AC18: 35944028283
A19: feb | B19: 4.1492133e+10 | C19: 1.4338672e+10 | D19: 1.35569e+10 | E19: 1.0317361e+10 | F19: 5.5049033e+10 | G19: 2.4656033e+10
A20: mar | B20: 4.1689378e+10 | C20: 1.4389108e+10 | D20: 1.3587482e+10 | E20: 1.0363694e+10 | F20: 5.527686e+10 | G20: 2.4752801e+10
A21: abr | B21: 4.1893694e+10 | C21: 1.4448119e+10 | D21: 1.3658161e+10 | E21: 1.0436146e+10 | F21: 5.5551855e+10 | G21: 2.4884265e+10
A22: may | B22: 4.2028716e+10 | C22: 1.4474202e+10 | D22: 1.3650261e+10 | E22: 1.0455982e+10 | F22: 5.5678977e+10 | G22: 2.4930184e+10
A23: jun | B23: 4.2051494e+10 | C23: 1.4454401e+10 | D23: 1.3673345e+10 | E23: 1.0488652e+10 | F23: 5.5724839e+10 | G23: 2.4943053e+10
A24: jul | B24: 4.3968065e+10 | C24: 1.5094747e+10 | D24: 1.4296201e+10 | E24: 1.0984398e+10 | F24: 5.8264265e+10 | G24: 2.6079145e+10
A25: ago | B25: 4.4239653e+10 | C25: 1.5183281e+10 | D25: 1.4359654e+10 | E25: 1.1056169e+10 | F25: 5.8599307e+10 | G25: 2.6239451e+10
A26: sept | B26: 4.4825753e+10 | C26: 1.5361682e+10 | D26: 1.4520122e+10 | E26: 1.1196684e+10 | F26: 5.9345875e+10 | G26: 2.6558366e+10
A27: oct | B27: 4.5558469e+10 | C27: 1.5619781e+10 | D27: 1.4731002e+10 | E27: 1.1378659e+10 | F27: 6.0289471e+10 | G27: 2.6998439e+10
A28: nov | B28: 4.5907806e+10 | C28: 1.5757842e+10 | D28: 1.4819941e+10 | E28: 1.1477734e+10 | F28: 6.0727747e+10 | G28: 2.7235576e+10
A29: dic | B29: 4.6378472e+10 | C29: 1.5925944e+10 | D29: 1.4940627e+10 | E29: 1.159138e+10 | F29: 6.1319099e+10 | G29: 2.7517324e+10
A30: 2022 | B30: 4.0614957e+09 | C30: 1.3943048e+09 | D30: 1.8608107e+10 | E30: 1.4541109e+10 | F30: 2.2669603e+10 | G30: 1.5935414e+10
... A43: Total general | B43: 1.9676256e+10 | C43: 7.3869635e+09 | D43: 8.5253168e+09 | E43: 6.2527955e+09 | F43: 2.8201573e+10 | G43: 1.3639759e+10
A52: Etiquetas de fila | B52: Promedio de PBSV_MUJER | C52: Promedio de PBSV_HOMBRE | D52: Promedio de PBSI_MUJER | E52: Promedio de PBSI_HOMBRE | F52: Promedio de PBS_MUJER | G52: Promedio de PBS_HOMBRE | I52: Etiquetas de fila | J52: Promedio de PBSV_MUJER | K52: Promedio de PBSV_HOMBRE | L52: Promedio de PBSI_MUJER | M52: Promedio de PBSI_HOMBRE | N52: Promedio de PBS_MUJER | O52: Promedio de PBS_HOMBRE
A53: 2008 | B53: 8.2469269e+09 | C53: 3.9732077e+09 | D53: 3.9696562e+09 | E53: 3.0646136e+09 | F53: 1.2216583e+10 | G53: 7.0378213e+09 | I53: 2008 | J53: 8246926.9 | K53: 3973207.7 | L53: 3969656.2 | M53: 3064613.6 | N53: 12216583 | O53: 7037821.3
A54: 2009 | B54: 1.0831943e+10 | C54: 4.7784934e+09 | D54: 5.149103e+09 | E54: 3.655593e+09 | F54: 1.5981046e+10 | G54: 8.4340864e+09 | I54: 2009 | J54: 10831943 | K54: 4778493.4 | L54: 5149103 | M54: 3655593 | N54: 15981046 | O54: 8434086.4
A55: 2010 | B55: 1.3095568e+10 | C55: 5.5029662e+09 | D55: 5.9733298e+09 | E55: 4.1819318e+09 | F55: 1.9068897e+10 | G55: 9.684898e+09 | I55: 2010 | J55: 13095568 | K55: 5502966.2 | L55: 5973329.8 | M55: 4181931.8 | N55: 19068897 | O55: 9684898
A56: 2011 | B56: 1.3994994e+10 | C56: 5.7801079e+09 | D56: 6.2216009e+09 | E56: 4.3734947e+09 | F56: 2.0216595e+10 | G56: 1.0153603e+10 | I56: 2011 | J56: 13994994 | K56: 5780107.9 | L56: 6221600.9 | M56: 4373494.7 | N56: 20216595 | O56: 10153603
A57: 2012 | B57: 1.4900592e+10 | C57: 6.0276417e+09 | D57: 6.3053347e+09 | E57: 4.4481809e+09 | F57: 2.1205927e+10 | G57: 1.0475823e+10 | I57: 2012 | J57: 14900592 | K57: 6027641.7 | L57: 6305334.7 | M57: 4448180.9 | N57: 21205927 | O57: 10475823
A58: 2013 | B58: 1.5464511e+10 | C58: 6.1276381e+09 | D58: 6.1333006e+09 | E58: 4.2916174e+09 | F58: 2.1597811e+10 | G58: 1.0419256e+10 | I58: 2013 | J58: 15464511 | K58: 6127638.1 | L58: 6133300.6 | M58: 4291617.4 | N58: 21597811 | O58: 10419256
A59: 2014 | B59: 1.6719242e+10 | C59: 6.4430339e+09 | D59: 6.3328754e+09 | E59: 4.3768174e+09 | F59: 2.3052118e+10 | G59: 1.0819851e+10 | I59: 2014 | J59: 16719242 | K59: 6443033.9 | L59: 6332875.4 | M59: 4376817.4 | N59: 23052118 | O59: 10819851
A60: 2015 | B60: 1.8210703e+10 | C60: 6.9460832e+09 | D60: 6.7614414e+09 | E60: 4.7714308e+09 | F60: 2.4972144e+10 | G60: 1.1717514e+10 | I60: 2015 | J60: 18210703 | K60: 6946083.2 | L60: 6761441.4 | M60: 4771430.8 | N60: 24972144 | O60: 11717514
A61: 2016 | B61: 1.9783297e+10 | C61: 7.4256197e+09 | D61: 7.3620108e+09 | E61: 5.231601e+09 | F61: 2.7145307e+10 | G61: 1.2657221e+10 | I61: 2016 | J61: 19783297 | K61: 7425619.7 | L61: 7362010.8 | M61: 5231601 | N61: 27145307 | O61: 12657221
...

Sheet 1.1
B2: TOTAL BENEFICIOS PAGADOS DEL PILAR NO CONTRIBUTIVO
B4: Resumen trimestral de beneficios pagados, por tipo y sexo
B5: (octubre 2022 a diciembre 2022)
D7: Mujeres | G7: Hombres | J7: Ambos
B8: Periodo | C8: Tipo de beneficio | D8: N° | E8: Monto nominal M$ * | F8: Monto real M$ ** | G8: N° | H8: Monto nominal M$ * | I8: Monto real M$ ** | J8: N° | K8: Monto nominal M$ * | L8: Monto real M$ **
B9: octubre 2022 | C9: PBS Vejez
C10: PBS Invalidez | D10: 103979 | E10: 20154801 | F10: =+[1]PBS!$AF$181 -> 20409083 | G10: 81414 | H10: 15780084 | I10: =+[1]PBS!$AG$181 -> 15979172 | J10: 185393 | K10: 35934885 | L10: =+[1]PBS!$AH$181 -> 36388256
C11: PGU No Contributiva | D11: 322141 | E11: 62098940 | F11: =+[1]PGU_desagr!$AB$18 -> 62882408 | G11: 109963 | H11: 21312758 | I11: =+[1]PGU_desagr!$AC$18 -> 21581650 | J11: 432104 | K11: 83411698 | L11: =+[1]PGU_desagr!$AD$18 -> 84464058
C12: PGU Contributiva | D12: 686334 | E12: 1.3198656e+08 | F12: =+[1]PGU_desagr!$AE$18 -> 1.3365176e+08 | G12: 563950 | H12: 1.0801488e+08 | I12: =+[1]PGU_desagr!$AF$18 -> 1.0937765e+08 | J12: 1250284 | K12: 2.4000144e+08 | L12: =+[1]PGU_desagr!$AG$18 -> 2.4302941e+08
C13: APS Vejez | D13: 109393 | E13: 23196046 | F13: 23488697 | G13: 63815 | H13: 13590242 | I13: 13761703 | J13: 173208 | K13: 36786288 | L13: 37250400
C14: APS Invalidez | D14: 45739 | E14: 7659976.5 | F14: 7756618.3 | G14: 46381 | H14: 7378442.3 | I14: 7471532.2 | J14: 92120 | K14: 15038419 | L14: 15228150
C15: Nbis
C16: Total Beneficios | D16: =SUM(D9:D15) -> 1267586 | E16: =SUM(E9:E15) -> 2.4509632e+08 | F16: =SUM(F9:F15) -> 2.4818857e+08 | G16: =SUM(G9:G15) -> 865523 | H16: =SUM(H9:H15) -> 1.6607641e+08 | I16: =SUM(I9:I15) -> 1.681717e+08 | J16: =SUM(J9:J15) -> 2133109 | K16: =SUM(K9:K15) -> 4.1117273e+08 | L16: =SUM(L9:L15) -> 4.1636028e+08
B17: noviembre 2022 | C17: PBS Vejez
C18: PBS Invalidez | D18: 103866 | E18: 20132731 | F18: =+[1]PBS!$AF$182 -> 20189834 | G18: 81490 | H18: 15794446 | I18: =+[1]PBS!$AG$182 -> 15839245 | J18: 185356 | K18: 35927177 | L18: =+[1]PBS!$AH$182 -> 36029079
C19: PGU No Contributiva | D19: 327443 | E19: 63080933 | F19: =+[1]PGU_desagr!$AB$19 -> 63259852 | G19: 121585 | H19: 23564397 | I19: =+[1]PGU_desagr!$AC$19 -> 23631234 | J19: 449028 | K19: 86645330 | L19: =+[1]PGU_desagr!$AD$19 -> 86891086
C20: PGU Contributiva | D20: 704099 | E20: 1.3523624e+08 | F20: =+[1]PGU_desagr!$AE$19 -> 1.3561981e+08 | G20: 584193 | H20: 1.115372e+08 | I20: =+[1]PGU_desagr!$AF$19 -> 1.1185356e+08 | J20: 1288292 | K20: 2.4677344e+08 | L20: =+[1]PGU_desagr!$AG$19 -> 2.4747337e+08
C21: APS Vejez | D21: 109031 | E21: 23133194 | F21: =+[1]APS!$AA$183 -> 23198807 | G21: 63526 | H21: 13546987 | I21: =+[1]APS!$AB$183 -> 13585411 | J21: 172557 | K21: 36680181 | L21: =+[1]APS!$AC$183 -> 36784218
C22: APS Invalidez | D22: 45910 | E22: 7675227.2 | F22: =+[1]APS!$AD$183 -> 7696996.8 | G22: 46666 | H22: 7413824.5 | I22: =+[1]APS!$AE$183 -> 7434852.7 | J22: 92576 | K22: 15089052 | L22: =+[1]APS!$AF$183 -> 15131849
C23: Nbis
C24: Total Beneficios | D24: =SUM(D17:D23) -> 1290349 | E24: =SUM(E17:E23) -> 2.4925832e+08 | F24: =SUM(F17:F23) -> 2.4996531e+08 | G24: =SUM(G17:G23) -> 897460 | H24: =SUM(H17:H23) -> 1.7185686e+08 | I24: =SUM(I17:I23) -> 1.723443e+08 | J24: =SUM(J17:J23) -> 2187809 | K24: =SUM(K17:K23) -> 4.2111518e+08 | L24: =SUM(L17:L23) -> 4.2230961e+08
B25: diciembre 2022 | C25: PBS Vejez
C26: PBS Invalidez | D26: 103979 | E26: 20153837 | F26: =+[1]PBS!$AF$183 -> 20153837 | G26: 81605 | H26: 15816186 | I26: =+[1]PBS!$AG$183 -> 15816186 | J26: 185584 | K26: 35970023 | L26: =+[1]PBS!$AH$183 -> 35970023
C27: PGU No Contributiva | D27: 329180 | E27: 63417032 | F27: =+[1]PGU_desagr!$AB$20 -> 63417032 | G27: 125728 | H27: 24368203 | I27: =+[1]PGU_desagr!$AC$20 -> 24368203 | J27: 454908 | K27: 87785234 | L27: =+[1]PGU_desagr!$AD$20 -> 87785234
C28: PGU Contributiva | D28: 717919 | E28: 1.3763622e+08 | F28: =+[1]PGU_desagr!$AE$20 -> 1.3763622e+08 | G28: 594890 | H28: 1.1328694e+08 | I28: =+[1]PGU_desagr!$AF$20 -> 1.1328694e+08 | J28: 1312809 | K28: 2.5092316e+08 | L28: =+[1]PGU_desagr!$AG$20 -> 2.5092316e+08
C29: APS Vejez | D29: 108989 | E29: 23140038 | F29: =+[1]APS!$AA$184 -> 23140038 | G29: 63190 | H29: 13498987 | I29: =+[1]APS!$AB$184 -> 13498987 | J29: 172179 | K29: 36639025 | L29: =+[1]APS!$AC$184 -> 36639025
C30: APS Invalidez | D30: 45881 | E30: 7649953.3 | F30: =+[1]APS!$AD$184 -> 7649953.3 | G30: 46817 | H30: 7421805.9 | I30: =+[1]APS!$AE$184 -> 7421805.9 | J30: 92698 | K30: 15071759 | L30: =+[1]APS!$AF$184 -> 15071759
C31: Nbis
C32: Total Beneficios | D32: =SUM(D25:D31) -> 1305948 | E32: =SUM(E25:E31) -> 2.5199708e+08 | F32: =SUM(F25:F31) -> 2.5199708e+08 | G32: =SUM(G25:G31) -> 912230 | H32: =SUM(H25:H31) -> 1.7439212e+08 | I32: =SUM(I25:I31) -> 1.7439212e+08 | J32: =SUM(J25:J31) -> 2218178 | K32: =SUM(K25:K31) -> 4.263892e+08 | L32: =SUM(L25:L31) -> 4.263892e+08
B33: Fuente: Elaboración propia con datos del IPS
B34: Nota: Las cifras son provisorias.
B35: * Montos nominales de cada periodo de pago. ** Montos deflactados a diciembre de 2022.
B37: Resumen anual de beneficios pagados, por tipo y sexo
B38: (enero 2022 a diciembre 2022)
D40: Mujeres | G40: Hombres | J40: Ambos
B41: Periodo | C41: Tipo de beneficio | D41: N° promedio mensual | E41: Monto nominal M$ * | F41: Monto real M$ ** | G41: N° promedio mensual | H41: Monto nominal M$ * | I41: Monto real M$ ** | J41: N° promedio mensual | K41: Monto nominal M$ * | L41: Monto real M$ **
B42: Año 2022 | C42: PBS Vejez | D42: 309032 | E42: 54315079 | F42: 60530406 | G42: 105909 | H42: 18646278 | I42: 20779990 | J42: 414941 | K42: 72961356 | L42: 81310395
C43: PBS Invalidez | D43: 103357.58 | E43: 2.3401777e+08 | F43: 242022236 | G43: 80758.083 | H43: 1.8285215e+08 | I43: 188463669 | J43: 184115.67 | K43: 4.1686992e+08 | L43: 430485905
C44: PGU No Contributiva | D44: 319227.82 | E44: 6.6356017e+08 | F44: 6.9249478e+08 | G44: 111460.55 | H44: 2.3284578e+08 | I44: 2.4281182e+08 | J44: 430688.36 | K44: 8.9640595e+08 | L44: 9.353066e+08
C45: PGU Contributiva | D45: 626988.27 | E45: 1.2940434e+09 | F45: 1.3458375e+09 | G45: 488475.91 | H45: 1.0117751e+09 | I45: 1.0500865e+09 | J45: 1115464.2 | K45: 2.3058184e+09 | L45: 2.3959241e+09
...

Sheet 1.2
B2: PAGOS PENSIÓN BÁSICA SOLIDARIA (PBS)
B4: Resumen trimestral de beneficios pagados, por tipo y sexo
B5: (octubre 2022 a diciembre 2022)
D7: PBS Vejez | G7: PBS Invalidez | J7: PBS Total
B8: Periodo | C8: Sexo Beneficiarios | D8: N° | E8: Monto nominal M$ * | F8: Monto real M$ ** | G8: N° | H8: Monto nominal M$ * | I8: Monto real M$ ** | J8: N° | K8: Monto nominal M$ * | L8: Monto real M$ **
B9: octubre 2022 | C9: Mujeres | G9: 103979 | H9: =+[1]PBS!$S$181/1000 -> 20154801 | I9: =+[1]PBS!$AF$181 -> 20409083 | J9: 103979 | K9: 20154801 | L9: 20409083
C10: Hombres | G10: 81414 | H10: =+[1]PBS!$R$181/1000 -> 15780084 | I10: =+[1]PBS!$AG$181 -> 15979172 | J10: 81414 | K10: 15780084 | L10: 15979172
C11: Ambos | G11: 185393 | H11: =+[1]PBS!$T$181/1000 -> 35934885 | I11: =+[1]PBS!$AH$181 -> 36388256 | J11: 185393 | K11: 35934885 | L11: 36388256
B12: noviembre 2022 | C12: Mujeres | G12: 103866 | H12: =+[1]PBS!$S$182/1000 -> 20132731 | I12: =+[1]PBS!$AF$182 -> 20189834 | J12: 103866 | K12: 20132731 | L12: 20189834
C13: Hombres | G13: 81490 | H13: =+[1]PBS!$R$182/1000 -> 15794446 | I13: =+[1]PBS!$AG$182 -> 15839245 | J13: 81490 | K13: 15794446 | L13: 15839245
C14: Ambos | G14: 185356 | H14: =+[1]PBS!$T$182/1000 -> 35927177 | I14: =+[1]PBS!$AH$182 -> 36029079 | J14: 185356 | K14: 35927177 | L14: 36029079
B15: diciembre 2022 | C15: Mujeres | G15: 103979 | H15: =+[1]PBS!$S$183/1000 -> 20153837 | I15: =+[1]PBS!$AF$183 -> 20153837 | J15: 103979 | K15: 20153837 | L15: 20153837
C16: Hombres | G16: 81605 | H16: =+[1]PBS!$R$183/1000 -> 15816186 | I16: =+[1]PBS!$AG$183 -> 15816186 | J16: 81605 | K16: 15816186 | L16: 15816186
C17: Ambos | G17: 185584 | H17: =+[1]PBS!$T$183/1000 -> 35970023 | I17: =+[1]PBS!$AH$183 -> 35970023 | J17: 185584 | K17: 35970023 | L17: 35970023
B18: Fuente: Elaboración propia con datos del IPS
B19: Nota: Las cifras son provisorias.
B20: * Montos nominales de cada periodo de pago. ** Montos deflactados a diciembre de 2022.
B22: Resumen anual de beneficios pagados, por tipo y sexo
B23: (enero 2022 a diciembre 2022)
D25: PBS Vejez * | G25: PBS Invalidez | J25: PBS Total
B26: Periodo | C26: Sexo Beneficiarios | D26: N° promedio mensual | E26: Monto nominal M$ ** | F26: Monto real M$ *** | G26: N° promedio mensual | H26: Monto nominal M$ ** | I26: Monto real M$ *** | J26: N° promedio mensual | K26: Monto nominal M$ ** | L26: Monto real M$ ***
B27: Año 2022 | C27: Mujeres | D27: 309032 | E27: 54315079 | F27: 60530406 | G27: 103357.58 | H27: 2.3401777e+08 | I27: 2.4558417e+08 | J27: 129110.25 | K27: 2.8833285e+08 | L27: 3.0611457e+08
C28: Hombres | D28: 105909 | E28: 18646278 | F28: 20779990 | G28: 80758.083 | H28: 1.8285215e+08 | I28: 1.9186996e+08 | J28: 89583.833 | K28: 2.0149843e+08 | L28: 2.1264995e+08
C29: Ambos | D29: 414941 | E29: 72961356 | F29: 81310395 | G29: 184115.67 | H29: 4.1686992e+08 | I29: 4.3745412e+08 | J29: 218694.08 | K29: 4.8983128e+08 | L29: 5.1876452e+08
B30: Fuente: Elaboración propia con datos del IPS
B31: Nota: Las cifras son provisorias
B32: * PBS Vejez sólo se pagó hasta enero de 2022, luego pasó a ser PGU No Contributiva, por lo que para los promedios se considera sólo la cantidad de meses en las que el beneficio estuvo vigente. **Montos nominales de cada periodo de pago. *** Montos deflactados a diciembre de 2022
B34: Serie resumen de pagos de beneficios acumulado, por tipo y sexo
B35: (enero 2020 a diciembre 2022)
C37: PBS Vejez | G37: PBS Invalidez | K37: PBS Total
C38: Mujeres | E38: Hombres | G38: Mujeres | I38: Hombres | K38: Mujeres | M38: Hombres
B39: Periodo | C39: N° Beneficios promedio | D39: Monto promedio M$ * | E39: N° Beneficios promedio | F39: Monto promedio M$ * | G39: N° Beneficios promedio | H39: Monto promedio M$ * | I39: N° Beneficios promedio | J39: Monto promedio M$ * | K39: N° Beneficios promedio | L39: Monto promedio M$ * | M39: N° Beneficios promedio | N39: Monto promedio M$ *
B40: Promedio 2020 | C40: 302635 | D40: 54856999 | E40: 105719.42 | F40: 19360776 | G40: 104028.33 | H40: 17833070 | I40: 77987.167 | J40: 13359506 | K40: 406663.33 | L40: 72690069 | M40: 183706.58 | N40: 32720282
B41: 44197 | C41: 303535 | D41: 59662587 | E41: 104773 | F41: 20665381 | G41: 102915 | H41: 19557894 | I41: 78093 | J41: 14840653 | K41: 406450 | L41: 79220482 | M41: 182866 | N41: 35506034
B42: 44228 | C42: 303509 | D42: 59556011 | E42: 104543 | F42: 20581109 | G42: 102585 | H42: 19458987 | I42: 78054 | J42: 14809093 | K42: 406094 | L42: 79014998 | M42: 182597 | N42: 35390202
B43: 44256 | C43: 303836 | D43: 59392429 | E43: 104524 | F43: 20499324 | G43: 102435 | H43: 19357295 | I43: 78131 | J43: 14764551 | K43: 406271 | L43: 78749724 | M43: 182655 | N43: 35263875
B44: 44287 | C44: 304229 | D44: 59236060 | E44: 104568 | F44: 20429081 | G44: 102581 | H44: 19312111 | I44: 78384 | J44: 14756306 | K44: 406810 | L44: 78548171 | M44: 182952 | N44: 35185387
B45: 44317 | C45: 304427 | D45: 59108949 | E45: 104477 | F45: 20356437 | G45: 102248 | H45: 19197649 | I45: 78324 | J45: 14705234 | K45: 406675 | L45: 78306599 | M45: 182801 | N45: 35061670
B46: 44348 | C46: 304385 | D46: 59046792 | E46: 104256 | F46: 20296211 | G46: 102342 | H46: 19199488 | I46: 78508 | J46: 14727687 | K46: 406727 | L46: 78246280 | M46: 182764 | N46: 35023898
B47: 44378 | C47: 304412 | D47: 60751025 | E47: 104136 | F47: 20856532 | G47: 102344 | H47: 19753174 | I47: 78636 | J47: 15177231 | K47: 406756 | L47: 80504199 | M47: 182772 | N47: 36033763
...

Sheet DINAMICA APS
A1: PERIODO | B1: (Varios elementos) | I1: PERIODO | J1: (Varios elementos) | O1: PERIODO | P1: (Varios elementos)
A3: Etiquetas de fila | B3: Suma de APS VEJEZ MUJER n | C3: Suma de APS VEJEZ HOMBRE n | D3: Suma de APS INVALIDEZ MUJER N | E3: Suma de APS INVALIDEZ HOMBRE N | F3: Suma de APS TOTAL MUJER N | G3: Suma de APS TOTAL HOMBRE N | I3: Etiquetas de fila | J3: Suma de APS VEJEZ MUJER nom | K3: Suma de APS VEJEZ HOMBRE nom | L3: Suma de APS INVALIDEZ MUJER nom | M3: Suma de APS INVALIDEZ HOMBRE nom | O3: Etiquetas de fila | P3: Suma de PBSV_MUJER REAL | Q3: Suma de PBSV_HOMBRE REAL | R3: Suma de PBSI_MUJER REAL | S3: Suma de PBSI_HOMBRE REAL
A4: 2022 | B4: 327413 | C4: 190531 | D4: 137530 | E4: 139864 | F4: 464943 | G4: 330395 | I4: 2022 | J4: 69469277 | K4: 40636216 | L4: 22985157 | M4: 22214073 | O4: 2022 | P4: 69114843 | Q4: 40428576 | R4: 22868011 | S4: 22101174
A5: oct | B5: 109393 | C5: 63815 | D5: 45739 | E5: 46381 | F5: 155132 | G5: 110196 | I5: oct | J5: 23196046 | K5: 13590242 | L5: 7659976.5 | M5: 7378442.3 | O5: oct | P5: 22907040 | Q5: 13420918 | R5: 7564538.8 | S5: 7286512.4
A6: nov | B6: 109031 | C6: 63526 | D6: 45910 | E6: 46666 | F6: 154941 | G6: 110192 | I6: nov | J6: 23133194 | K6: 13546987 | L6: 7675227.2 | M6: 7413824.5 | O6: nov | P6: 23067766 | Q6: 13508672 | R6: 7653519.1 | S6: 7392855.8
A7: dic | B7: 108989 | C7: 63190 | D7: 45881 | E7: 46817 | F7: 154870 | G7: 110007 | I7: dic | J7: 23140038 | K7: 13498987 | L7: 7649953.3 | M7: 7421805.9 | O7: dic | P7: 23140038 | Q7: 13498987 | R7: 7649953.3 | S7: 7421805.9
A11: PERIODO | B11: (Varios elementos)
A13: Etiquetas de fila | B13: Suma de APS VEJEZ MUJER n | C13: Suma de APS VEJEZ HOMBRE n | D13: Suma de APS INVALIDEZ MUJER N | E13: Suma de APS INVALIDEZ HOMBRE N | F13: Suma de APS TOTAL MUJER N | G13: Suma de APS TOTAL HOMBRE N
A14: 2022 | B14: 2017877 | C14: 1478761 | D14: 540602 | E14: 538156 | F14: 2558479 | G14: 2016917
A17: PERIODO | B17: (Varios elementos)
A19: Etiquetas de fila | B19: Promedio de APS VEJEZ MUJER n | C19: Promedio de APS VEJEZ HOMBRE n | D19: Promedio de APS INVALIDEZ MUJER N | E19: Promedio de APS INVALIDEZ HOMBRE N | F19: Promedio de APS TOTAL MUJER N | G19: Promedio de APS TOTAL HOMBRE N
A20: 2022 | B20: 168156.42 | C20: 123230.08 | D20: 45050.167 | E20: 44846.333 | F20: 213206.58 | G20: 168076.42
A23: PERIODO | B23: (Varios elementos)
A25: Etiquetas de fila | B25: Suma de APS VEJEZ MUJER nom | C25: Suma de APS VEJEZ HOMBRE nom | D25: Suma de APS INVALIDEZ MUJER nom | E25: Suma de APS INVALIDEZ HOMBRE nom | F25: Suma de APS TOTAL MUJER nom | G25: Suma de APS TOTAL HOMBRE nom
A26: 2022 | B26: 3.6244601e+08 | C26: 2.505165e+08 | D26: 89129737 | E26: 84667893 | F26: 4.5157575e+08 | G26: 3.3518439e+08
A29: PERIODO | B29: (Varios elementos)
A31: Etiquetas de fila | B31: Promedio de APS VEJEZ MUJER nom | C31: Promedio de APS VEJEZ HOMBRE nom | D31: Promedio de APS INVALIDEZ MUJER nom | E31: Promedio de APS INVALIDEZ HOMBRE nom | F31: Promedio de APS TOTAL MUJER nom | G31: Promedio de APS TOTAL HOMBRE nom
A32: 2022 | B32: 30203834 | C32: 20876375 | D32: 7427478.1 | E32: 7055657.8 | F32: 37631312 | G32: 27932033
A35: PERIODO | B35: (Varios elementos)
A37: Etiquetas de fila | B37: Suma de PBSV_MUJER REAL | C37: Suma de PBSV_HOMBRE REAL | D37: Suma de PBSI_MUJER REAL | E37: Suma de PBSI_HOMBRE REAL
A38: 2022 | B38: 3.4085177e+08 | C38: 2.344632e+08 | D38: 85046490 | E38: 80830616
A42: PERIODO | B42: (Varios elementos)
A44: Etiquetas de fila | B44: Promedio de PBSV_MUJER REAL | C44: Promedio de PBSV_HOMBRE REAL | D44: Promedio de PBSI_MUJER REAL | E44: Promedio de PBSI_HOMBRE REAL
A45: 2022 | B45: 28404314 | C45: 19538600 | D45: 7087207.5 | E45: 6735884.7
A51: Etiquetas de fila | B51: Promedio de APS VEJEZ MUJER n | C51: Promedio de APS VEJEZ HOMBRE n | D51: Promedio de APS INVALIDEZ MUJER N | E51: Promedio de APS INVALIDEZ HOMBRE N
A52: 2008 | B52: 2920.6667 | C52: 1116 | D52: 286.33333 | E52: 290.33333
A53: 2009 | B53: 35080.083 | C53: 24939.75 | D53: 2213.8333 | E53: 1769.75
A54: 2010 | B54: 184671.58 | C54: 128661.83 | D54: 8050.9167 | E54: 5922.9167
A55: 2011 | B55: 232153.67 | C55: 168868.75 | D55: 12883.083 | E55: 9283.4167
A56: 2012 | B56: 279628 | C56: 203893.75 | D56: 19231.417 | E56: 14584.75
A57: 2013 | B57: 327092.08 | C57: 237763.33 | D57: 26607.083 | E57: 21058.833
A58: 2014 | B58: 354831.83 | C58: 258135.42 | D58: 33075.25 | E58: 26998.167
A59: 2015 | B59: 385388.58 | C59: 279293.17 | D59: 35497.583 | E59: 29292.083
A60: 2016 | B60: 409696.25 | C60: 297461.08 | D60: 35477.75 | E60: 29444.667
A61: 2017 | B61: 434014.42 | C61: 315115.08 | D61: 35236.417 | E61: 29440.417
A62: 2018 | B62: 472783.58 | C62: 343894.42 | D62: 35802.167 | E62: 30349.5
A63: 2019 | B63: 513930.5 | C63: 376625 | D63: 36751.75 | E63: 31642.25
... A90: dic | B90: 108989 | C90: 63190 | D90: 45881 | E90: 46817
A94: Etiquetas de fila | B94: Promedio de PBSV_MUJER REAL | C94: Promedio de PBSV_HOMBRE REAL | D94: Promedio de PBSI_MUJER REAL | E94: Promedio de PBSI_HOMBRE REAL
A95: 2008 | B95: 156325.61 | C95: 77435.604 | D95: 15483.202 | E95: 15243.679
...

Sheet 1.3
B2: PAGOS PENSIÓN GARANTIZADA UNIVERSAL (PGU)
B5: Resumen trimestral de beneficios pagados, por tipo y sexo
B6: (octubre 2022 a diciembre 2022)
D8: PGU No Contributiva | G8: PGU Contributiva | J8: PGU Total
B9: Periodo | C9: Sexo Beneficiarios | D9: N° | E9: Monto nominal M$ * | F9: Monto real M$ ** | G9: N° | H9: Monto nominal M$ * | I9: Monto real M$ ** | J9: N° | K9: Monto nominal M$ * | L9: Monto real M$ **
B10: octubre 2022 | C10: Mujeres | D10: =+[1]PGU_desagr!$C$18 -> 322141 | E10: =+[1]PGU_desagr!$O$18/1000 -> 62098940 | F10: =+[1]PGU_desagr!$AB$18 -> 62882408 | G10: =+[1]PGU_desagr!$F$18 -> 686334 | H10: =+[1]PGU_desagr!$R$18/1000 -> 1.3198656e+08 | I10: =+[1]PGU_desagr!$AE$18 -> 1.3365176e+08 | J10: =+[1]PGU_desagr!$I$18 -> 1008475 | K10: =+[1]PGU_desagr!$U$18/1000 -> 1.940855e+08 | L10: =+[1]PGU_desagr!$AH$18 -> 1.9653417e+08
C11: Hombres | D11: =+[1]PGU_desagr!$D$18 -> 109963 | E11: =+[1]PGU_desagr!$P$18/1000 -> 21312758 | F11: =+[1]PGU_desagr!$AC$18 -> 21581650 | G11: =+[1]PGU_desagr!$G$18 -> 563950 | H11: =+[1]PGU_desagr!$S$18/1000 -> 1.0801488e+08 | I11: =+[1]PGU_desagr!$AF$18 -> 1.0937765e+08 | J11: =+[1]PGU_desagr!$J$18 -> 673913 | K11: =+[1]PGU_desagr!$V$18/1000 -> 1.2932764e+08 | L11: =+[1]PGU_desagr!$AI$18 -> 1.309593e+08
C12: Ambos | D12: =+[1]PGU_desagr!$E$18 -> 432104 | E12: =+[1]PGU_desagr!$Q$18/1000 -> 83411698 | F12: =+[1]PGU_desagr!$AD$18 -> 84464058 | G12: =+[1]PGU_desagr!$H$18 -> 1250284 | H12: =+[1]PGU_desagr!$T$18/1000 -> 2.4000144e+08 | I12: =+[1]PGU_desagr!$AG$18 -> 2.4302941e+08 | J12: =+[1]PGU_desagr!$K$18 -> 1682388 | K12: =+[1]PGU_desagr!$W$18/1000 -> 3.2341314e+08 | L12: =+[1]PGU_desagr!$AJ$18 -> 3.2749347e+08
B13: noviembre 2022 | C13: Mujeres | D13: =+[1]PGU_desagr!$C$19 -> 327443 | E13: =+[1]PGU_desagr!$O$19/1000 -> 63080933 | F13: =+[1]PGU_desagr!$AB$19 -> 63259852 | G13: =+[1]PGU_desagr!$F$19 -> 704099 | H13: =+[1]PGU_desagr!$R$19/1000 -> 1.3523624e+08 | I13: =+[1]PGU_desagr!$AE$19 -> 1.3561981e+08 | J13: =+[1]PGU_desagr!$I$19 -> 1031542 | K13: =+[1]PGU_desagr!$U$19/1000 -> 1.9831717e+08 | L13: =+[1]PGU_desagr!$AH$19 -> 1.9887967e+08
C14: Hombres | D14: =+[1]PGU_desagr!$D$19 -> 121585 | E14: =+[1]PGU_desagr!$P$19/1000 -> 23564397 | F14: =+[1]PGU_desagr!$AC$19 -> 23631234 | G14: =+[1]PGU_desagr!$G$19 -> 584193 | H14: =+[1]PGU_desagr!$S$19/1000 -> 1.115372e+08 | I14: =+[1]PGU_desagr!$AF$19 -> 1.1185356e+08 | J14: =+[1]PGU_desagr!$J$19 -> 705778 | K14: =+[1]PGU_desagr!$V$19/1000 -> 1.351016e+08 | L14: =+[1]PGU_desagr!$AI$19 -> 1.3548479e+08
C15: Ambos | D15: =+[1]PGU_desagr!$E$19 -> 449028 | E15: =+[1]PGU_desagr!$Q$19/1000 -> 86645330 | F15: =+[1]PGU_desagr!$AD$19 -> 86891086 | G15: =+[1]PGU_desagr!$H$19 -> 1288292 | H15: =+[1]PGU_desagr!$T$19/1000 -> 2.4677344e+08 | I15: =+[1]PGU_desagr!$AG$19 -> 2.4747337e+08 | J15: =+[1]PGU_desagr!$K$19 -> 1737320 | K15: =+[1]PGU_desagr!$W$19/1000 -> 3.3341877e+08 | L15: =+[1]PGU_desagr!$AJ$19 -> 3.3436446e+08
B16: diciembre 2022 | C16: Mujeres | D16: =+[1]PGU_desagr!$C$20 -> 329180 | E16: =+[1]PGU_desagr!$O$20/1000 -> 63417032 | F16: =+[1]PGU_desagr!$AB$20 -> 63417032 | G16: =+[1]PGU_desagr!$F$20 -> 717919 | H16: =+[1]PGU_desagr!$R$20/1000 -> 1.3763622e+08 | I16: =+[1]PGU_desagr!$AE$20 -> 1.3763622e+08 | J16: =+[1]PGU_desagr!$I$20 -> 1047099 | K16: =+[1]PGU_desagr!$U$20/1000 -> 2.0105325e+08 | L16: =+[1]PGU_desagr!$AH$20 -> 2.0105325e+08
C17: Hombres | D17: =+[1]PGU_desagr!$D$20 -> 125728 | E17: =+[1]PGU_desagr!$P$20/1000 -> 24368203 | F17: =+[1]PGU_desagr!$AC$20 -> 24368203 | G17: =+[1]PGU_desagr!$G$20 -> 594890 | H17: =+[1]PGU_desagr!$S$20/1000 -> 1.1328694e+08 | I17: =+[1]PGU_desagr!$AF$20 -> 1.1328694e+08 | J17: =+[1]PGU_desagr!$J$20 -> 720618 | K17: =+[1]PGU_desagr!$V$20/1000 -> 1.3765514e+08 | L17: =+[1]PGU_desagr!$AI$20 -> 1.3765514e+08
C18: Ambos | D18: =+[1]PGU_desagr!$E$20 -> 454908 | E18: =+[1]PGU_desagr!$Q$20/1000 -> 87785234 | F18: =+[1]PGU_desagr!$AD$20 -> 87785234 | G18: =+[1]PGU_desagr!$H$20 -> 1312809 | H18: =+[1]PGU_desagr!$T$20/1000 -> 2.5092316e+08 | I18: =+[1]PGU_desagr!$AG$20 -> 2.5092316e+08 | J18: =+[1]PGU_desagr!$K$20 -> 1767717 | K18: =+[1]PGU_desagr!$W$20/1000 -> 3.3870839e+08 | L18: =+[1]PGU_desagr!$AJ$20 -> 3.3870839e+08
B19: Fuente: Elaboración propia con datos del IPS
B20: Nota 1: La Pensión Garantizada Universal (PGU) es un nuevo beneficio generado a partir de la ley 21.419 del 29-01-2022. El concepto de PGU No Contributiva o Contributiva está relacionado con la calidad de la persona que está recibiendo el beneficio, si es No Contributiva quiere decir que no estaba afiliado a un sistema previsional (D.L. 3.500 o antiguo Sistema de Reparto) ni recibe pensión de sobrevivencia, si es Contributiva quiere decir que si estaba afiliado a un sistema previsional o que recibe una pensión de sobrevivencia. De manera automática, en febrero 2022, los PBS de Vejez pasaron a ser PGU No Contributiva y los APS Vejez Subsidio Definido, los Beneficio artículo 9° bis y los APS Vejez con una Pensión Final Garantizada inferior o igual al monto de la PGU pasaron a ser PGU Contributiva (Fuente: Superintendencia de Pensiones).
B21: Nota 2: Las cifras son provisorias
B22: * Montos nominales de cada periodo de pago. ** Montos deflactados a diciembre de 2022
B24: Resumen anual de beneficios pagados, por tipo y sexo
B25: (febrero 2022 a diciembre 2022)
D27: PGU No Contributiva | G27: PGU Contributiva | J27: PGU Total
B28: Periodo | C28: Sexo Beneficiarios | D28: N° promedio mensual | E28: Monto nominal M$ * | F28: Monto real M$ ** | G28: N° promedio mensual | H28: Monto nominal M$ * | I28: Monto real M$ ** | J28: N° promedio mensual | K28: Monto nominal M$ * | L28: Monto real M$ **
B29: Año 2022 | C29: Mujeres | D29: 319227.82 | E29: 6.6356017e+08 | F29: 6.9249478e+08 | G29: 626988.27 | H29: 1.2940434e+09 | I29: 1.3458375e+09 | J29: 946216.09 | K29: 1.9576035e+09 | L29: 2.0383323e+09
C30: Hombres | D30: 111460.55 | E30: 2.3284578e+08 | F30: 2.4281182e+08 | G30: 488475.91 | H30: 1.0117751e+09 | I30: 1.0500865e+09 | J30: 599936.45 | K30: 1.2446209e+09 | L30: 1.2928983e+09
C31: Ambos | D31: 430688.36 | E31: 8.9640595e+08 | F31: 9.353066e+08 | G31: 1115464.2 | H31: 2.3058184e+09 | I31: 2.3959241e+09 | J31: 1546152.5 | K31: 3.2022244e+09 | L31: 3.3312307e+09
B32: Fuente: Elaboración propia con datos del IPS
B33: Nota: Las cifras son provisorias
B34: * Montos nominales de cada periodo de pago. ** Montos deflactados a diciembre de 2022
B36: Serie resumen de pagos de beneficios acumulado, por tipo y sexo
B37: (febrero 2022 a diciembre 2022)
C39: PGU No Contributiva | G39: PGU Contributiva | K39: PGU Total
C40: Mujeres | E40: Hombres | G40: Mujeres | I40: Hombres | K40: Mujeres | M40: Hombres
B41: Periodo | C41: N° Beneficios promedio | D41: Monto promedio M$ * | E41: N° Beneficios promedio | F41: Monto promedio M$ * | G41: N° Beneficios promedio | H41: Monto promedio M$ * | I41: N° Beneficios promedio | J41: Monto promedio M$ * | K41: N° Beneficios promedio | L41: Monto promedio M$ * | M41: N° Beneficios promedio | N41: Monto promedio M$ *
B42: 44593 | C42: 309683 | D42: 63567503 | E42: 106066 | F42: 21799084 | G42: 517361 | H42: 94540259 | I42: 340110 | J42: 64788470 | K42: 827044 | L42: 1.5810776e+08 | M42: 446176 | N42: 86587555
B43: 44621 | C43: 312946 | D43: 62964957 | E43: 107255 | F43: 21641655 | G43: 536699 | H43: 1.0809112e+08 | I43: 361057 | J43: 72791331 | K43: 849645 | L43: 1.7105607e+08 | M43: 468312 | N43: 94432986
B44: 44652 | C44: 314601 | D44: 62358336 | E44: 107763 | F44: 21443356 | G44: 552501 | H44: 1.0966543e+08 | I44: 374925 | J44: 74569058 | K44: 867102 | L44: 1.7202376e+08 | M44: 482688 | N44: 96012414
B45: 44682 | C45: 316872 | D45: 62011410 | E45: 108938 | F45: 21418403 | G45: 605836 | H45: 1.1877877e+08 | I45: 477591 | J45: 93875675 | K45: 922708 | L45: 1.8079018e+08 | M45: 586529 | N45: 1.1529408e+08
B46: 44713 | C46: 317138 | D46: 61468785 | E46: 109221 | F46: 21274909 | G46: 615086 | H46: 1.19429e+08 | I46: 487043 | J46: 94849049 | K46: 932224 | L46: 1.8089778e+08 | M46: 596264 | N46: 1.1612396e+08
B47: 44743 | C47: 317824 | D47: 63694686 | E47: 109691 | F47: 22092523 | G47: 621791 | H47: 1.2484604e+08 | I47: 498271 | J47: 1.003403e+08 | K47: 939615 | L47: 1.8854073e+08 | M47: 607962 | N47: 1.2243282e+08
B48: 44774 | C48: 322017 | D48: 63749171 | E48: 110018 | F48: 21892427 | G48: 660104 | H48: 1.3055286e+08 | I48: 538150 | J48: 1.0634599e+08 | K48: 982121 | L48: 1.9430203e+08 | M48: 648168 | N48: 1.2823842e+08
...

Sheet 1.4
B2: PAGOS APORTE PREVISIONAL SOLIDARIO (APS)
B4: Resumen trimestral de beneficios pagados, por tipo y sexo
B5: (octubre 2022 a diciembre 2022)
D7: APS Vejez | G7: APS Invalidez | J7: APS Total
B8: Periodo | C8: Sexo Beneficiarios | D8: N° | E8: Monto nominal M$ * | F8: Monto real M$ ** | G8: N° | H8: Monto nominal M$ * | I8: Monto real M$ ** | J8: N° | K8: Monto nominal M$ * | L8: Monto real M$ **
B9: octubre 2022 | C9: Mujeres | D9: 109393 | E9: =+[1]APS!$P$182/1000 -> 23196046 | F9: =+[1]APS!$AA$182 -> 23488697 | G9: =+[1]APS!$G$182 -> 45739 | H9: =+[1]APS!$S$182/1000 -> 7659976.5 | I9: =+[1]APS!$AD$182 -> 7756618.3 | J9: =+[1]APS!$J$182 -> 155132 | K9: =+[1]APS!$V$182/1000 -> 30856022 | L9: =+[1]APS!$AG$182 -> 31245316
C10: Hombres | D10: 63815 | E10: =+[1]APS!$O$182/1000 -> 13590242 | F10: =+[1]APS!$AB$182 -> 13761703 | G10: =+[1]APS!$F$182 -> 46381 | H10: =+[1]APS!$R$182/1000 -> 7378442.3 | I10: =+[1]APS!$AE$182 -> 7471532.2 | J10: =+[1]APS!$I$182 -> 110196 | K10: =+[1]APS!$U$182/1000 -> 20968684 | L10: =+[1]APS!$AH$182 -> 21233235
C11: Ambos | D11: 173208 | E11: =+[1]APS!$Q$182/1000 -> 36786288 | F11: =+[1]APS!$AC$182 -> 37250400 | G11: =+[1]APS!$H$182 -> 92120 | H11: =+[1]APS!$T$182/1000 -> 15038419 | I11: =+[1]APS!$AF$182 -> 15228150 | J11: =+[1]APS!$K$182 -> 265328 | K11: =+[1]APS!$W$182/1000 -> 51824706 | L11: =+[1]APS!$AI$182 -> 52478551
B12: noviembre 2022 | C12: Mujeres | D12: 109031 | E12: =+[1]APS!$P$183/1000 -> 23133194 | F12: =+[1]APS!$AA$183 -> 23198807 | G12: =+[1]APS!$G$183 -> 45910 | H12: =+[1]APS!$S$183/1000 -> 7675227.2 | I12: =+[1]APS!$AD$183 -> 7696996.8 | J12: =+[1]APS!$J$183 -> 154941 | K12: =+[1]APS!$V$183/1000 -> 30808421 | L12: =+[1]APS!$AG$183 -> 30895804
C13: Hombres | D13: 63526 | E13: =+[1]APS!$O$183/1000 -> 13546987 | F13: =+[1]APS!$AB$183 -> 13585411 | G13: =+[1]APS!$F$183 -> 46666 | H13: =+[1]APS!$R$183/1000 -> 7413824.5 | I13: =+[1]APS!$AE$183 -> 7434852.7 | J13: =+[1]APS!$I$183 -> 110192 | K13: =+[1]APS!$U$183/1000 -> 20960812 | L13: =+[1]APS!$AH$183 -> 21020264
C14: Ambos | D14: 172557 | E14: =+[1]APS!$Q$183/1000 -> 36680181 | F14: =+[1]APS!$AC$183 -> 36784218 | G14: =+[1]APS!$H$183 -> 92576 | H14: =+[1]APS!$T$183/1000 -> 15089052 | I14: =+[1]APS!$AF$183 -> 15131849 | J14: =+[1]APS!$K$183 -> 265133 | K14: =+[1]APS!$W$183/1000 -> 51769232 | L14: =+[1]APS!$AI$183 -> 51916068
B15: diciembre 2022 | C15: Mujeres | D15: 108989 | E15: =+[1]APS!$P$184/1000 -> 23140038 | F15: =+[1]APS!$AA$184 -> 23140038 | G15: =+[1]APS!$G$184 -> 45881 | H15: =+[1]APS!$S$184/1000 -> 7649953.3 | I15: =+[1]APS!$AD$184 -> 7649953.3 | J15: =+[1]APS!$J$184 -> 154870 | K15: =+[1]APS!$V$184/1000 -> 30789991 | L15: =+[1]APS!$AG$184 -> 30789991
C16: Hombres | D16: 63190 | E16: =+[1]APS!$O$184/1000 -> 13498987 | F16: =+[1]APS!$AB$184 -> 13498987 | G16: =+[1]APS!$F$184 -> 46817 | H16: =+[1]APS!$R$184/1000 -> 7421805.9 | I16: =+[1]APS!$AE$184 -> 7421805.9 | J16: =+[1]APS!$I$184 -> 110007 | K16: =+[1]APS!$U$184/1000 -> 20920793 | L16: =+[1]APS!$AH$184 -> 20920793
C17: Ambos | D17: 172179 | E17: =+[1]APS!$Q$184/1000 -> 36639025 | F17: =+[1]APS!$AC$184 -> 36639025 | G17: =+[1]APS!$H$184 -> 92698 | H17: =+[1]APS!$T$184/1000 -> 15071759 | I17: =+[1]APS!$AF$184 -> 15071759 | J17: =+[1]APS!$K$184 -> 264877 | K17: =+[1]APS!$W$184/1000 -> 51710784 | L17: =+[1]APS!$AI$184 -> 51710784
B18: Fuente: Elaboración propia con datos del IPS
B19: Nota: Las cifras son provisorias
B20: * Montos nominales de cada periodo de pago. ** Montos deflactados a diciembre de 2022
B22: Resumen anual de beneficios pagados, por tipo y sexo
B23: (enero 2022 a diciembre 2022)
D25: APS Vejez | G25: APS Invalidez | J25: APS Total
B26: Periodo | C26: Sexo Beneficiarios | D26: N° promedio mensual | E26: Monto nominal M$ * | F26: Monto real M$ ** | G26: N° promedio mensual | H26: Monto nominal M$ * | I26: Monto real M$ ** | J26: N° promedio mensual | K26: Monto nominal M$ * | L26: Monto real M$ **
B27: Año 2022 | C27: Mujeres | D27: 168156.42 | E27: 3.6244601e+08 | F27: 3.8604321e+08 | G27: 45050.167 | H27: 89129737 | I27: 93534966 | J27: 213206.58 | K27: 4.5157575e+08 | L27: 4.7957817e+08
C28: Hombres | D28: 123230.08 | E28: 2.505165e+08 | F28: 2.6808536e+08 | G28: 44846.333 | H28: 84667893 | I28: 88806431 | J28: 168076.42 | K28: 3.3518439e+08 | L28: 3.5689179e+08
C29: Ambos | D29: 291386.5 | E29: 6.1296251e+08 | F29: 6.5412857e+08 | G29: 89896.5 | H29: 1.7379763e+08 | I29: 1.823414e+08 | J29: 381283 | K29: 7.8676014e+08 | L29: 8.3646996e+08
B30: Fuente: Elaboración propia con datos del IPS
B31: Nota: Las cifras son provisorias
B32: * Montos nominales de cada periodo de pago. ** Montos deflactados a diciembre de 2022
B34: Serie resumen de pagos de beneficios acumulado, por tipo y sexo
B35: (enero 2020 a diciembre 2022)
C37: APS Vejez | G37: APS Invalidez | K37: APS Total
C38: Mujeres | E38: Hombres | G38: Mujeres | I38: Hombres | K38: Mujeres | M38: Hombres
B39: Periodo | C39: N° Beneficios promedio | D39: Monto promedio M$ * | E39: N° Beneficios promedio | F39: Monto promedio M$ * | G39: N° Beneficios promedio | H39: Monto promedio M$ * | I39: N° Beneficios promedio | J39: Monto promedio M$ * | K39: N° Beneficios promedio | L39: Monto promedio M$ * | M39: N° Beneficios promedio | N39: Monto promedio M$ *
B40: Promedio 2020 | C40: =+[1]APS!$D$189 -> 569814.17 | D40: 78109549 | E40: 419795.08 | F40: 54038961 | G40: =+[1]APS!$G$189 -> 38063.25 | H40: 6106010 | I40: 33240.167 | J40: 5190963.9 | K40: 607877.42 | L40: 84215559 | M40: 453035.25 | N40: 59229925
B41: 44197 | C41: 600842 | D41: 91766146 | E41: 443662 | F41: 63835170 | G41: 38683 | H41: 6861931.7 | I41: 34228 | J41: 5894347.5 | K41: 639525 | L41: 98628077 | M41: 477890 | N41: 69729517
B42: 44228 | C42: 605436 | D42: 91855518 | E42: 447257 | F42: 63902819 | G42: 38750 | H42: 6847110.4 | I42: 34279 | J42: 5883751.7 | K42: 644186 | L42: 98702629 | M42: 481536 | N42: 69786570
B43: 44256 | C43: 610095 | D43: 92402342 | E43: 450099 | F43: 64066934 | G43: 38777 | H43: 6824656.1 | I43: 34317 | J43: 5870827.2 | K43: 648872 | L43: 99226999 | M43: 484416 | N43: 69937761
B44: 44287 | C44: 615165 | D44: 92937319 | E44: 453554 | F44: 64244968 | G44: 39434 | H44: 6863197.5 | I44: 35231 | J44: 5946494.8 | K44: 654599 | L44: 99800517 | M44: 488785 | N44: 70191463
B45: 44317 | C45: 619925 | D45: 93507275 | E45: 456843 | F45: 64510062 | G45: 40665 | H45: 6950552.7 | I45: 36858 | J45: 6071862.3 | K45: 660590 | L45: 1.0045783e+08 | M45: 493701 | N45: 70581925
B46: 44348 | C46: 624280 | D46: 94300916 | E46: 459648 | F46: 64932561 | G46: 41406 | H46: 7016135.5 | I46: 37901 | J46: 6176730.4 | K46: 665686 | L46: 1.0131705e+08 | M46: 497549 | N46: 71109291
B47: 44378 | C47: 628233 | D47: 98785632 | E47: 462542 | F47: 68109609 | G47: 41969 | H47: 7302821.3 | I47: 38877 | J47: 6499178.7 | K47: 670202 | L47: 1.0608845e+08 | M47: 501419 | N47: 74608787
...

Sheet 1.5
B2: Pagos Beneficio del artículo 9° bis (Nbis)
B5: Resumen trimestral de beneficios pagados, por tipo y sexo
B6: (octubre 2022 a diciembre 2022)
B8: No aplica, los pagos de este beneficio se realizaron hasta enero de 2022, luego pasaron a PGU
B11: Resumen anual de beneficios pagados, por tipo y sexo
B12: (enero 2022 a diciembre 2022)
D14: Nbis *
B15: Periodo | C15: Sexo Beneficiarios | D15: N° promedio mensual | E15: Monto nominal M$ ** | F15: Monto real M$ ***
B16: Año 2022 | C16: Mujeres | D16: 3 | E16: 183.096 | F16: 204.04785
C17: Hombres | D17: 13 | E17: 851.881 | F17: 949.36257
C18: Ambos | D18: 16 | E18: 1034.977 | F18: 1153.4104
B19: Fuente: Elaboración propia con datos del IPS
B20: Nota: Las cifras son provisorias
B21: * Nbis sólo se pagó hasta enero de 2022, luego pasó a ser PGU No Contributiva, por lo que para los promedios se considera sólo la cantidad de meses en las que el beneficio estuvo vigente. **Montos nominales de cada periodo de pago. *** Montos deflactados a diciembre de 2022
B23: Serie resumen de pagos de beneficios acumulado, por tipo y sexo
B24: (febrero 2020 a diciembre 2022)
C26: Nbis *
C27: Mujeres | E27: Hombres
B28: Periodo | C28: N° Beneficios promedio | D28: Monto promedio M$ ** | E28: N° Beneficios promedio | F28: Monto promedio M$ **
B29: Promedio 2020 | C29: =+[1]Nbis!$D$55 -> 2.0909091 | D29: 181.42384 | E29: 2.1428571 | F29: 219.49577
B30: 44197 | C30: 3 | D30: 420.12212 | E30: 3 | F30: 259.58897
B31: 44228 | C31: 2 | D31: 249.2296 | E31: 2 | F31: 215.74013
B32: 44256 | C32: 2 | D32: 247.58266 | E32: 4 | F32: 226.7952
B33: 44287 | C33: 2 | D33: 246.5268 | E33: 4 | F33: 432.83634
B34: 44317 | C34: 3 | D34: 260.73408 | E34: 5 | F34: 477.22761
B35: 44348 | C35: 3 | D35: 259.30585 | E35: 6 | F35: 677.08251
B36: 44378 | C36: 2 | D36: 145.81473 | E36: 7 | F36: 762.96218
B37: 44409 | C37: 2 | D37: 145.20366 | E37: 6 | F37: 712.67188
B38: 44440 | C38: 2 | D38: 142.04655 | E38: 6 | F38: 684.17016
B39: 44470 | C39: 2 | D39: 138.99032 | E39: 10 | F39: 993.69467
B40: 44501 | C40: 2 | D40: 135.95678 | E40: 11 | F40: 855.83187
B41: 44531 | C41: 2 | D41: 131.92408 | E41: 13 | F41: 1052.7863
B42: Promedio 2021 | C42: =+[1]Nbis!$D$56 -> 2.25 | D42: 210.28644 | E42: =+[1]Nbis!$C$56 -> 6.4166667 | F42: 612.61565
B43: 44562 | C43: =+[1]Nbis!$D$34 -> 3 | D43: 204.04785 | E43: =+[1]Nbis!$C$34 -> 13 | F43: 949.36257
B44: 44593
B45: 44621
B46: 44652
B47: 44682
B48: 44713
B49: 44743
...

Sheet Hoja2
A3: -> region_codigo | B3: = | C3: 1
C5: estado_solicitud
A6: comuna | B6: A | C6: C | D6: D | E6: R | F6: T | G6: Total
A8: ALTO HOSPICIO | B8: 32 | C8: 8631 | D8: 1 | E8: 1938 | F8: 329 | G8: 10931
A9: CAMIÑA | B9: 0 | C9: 192 | D9: 0 | E9: 38 | F9: 4 | G9: 234
A10: COLCHANE | B10: 2 | C10: 137 | D10: 0 | E10: 25 | F10: 3 | G10: 167
A11: HUARA | B11: 6 | C11: 476 | D11: 1 | E11: 103 | F11: 14 | G11: 600
A12: IQUIQUE | B12: 90 | C12: 26648 | D12: 11 | E12: 6786 | F12: 678 | G12: 34213
A13: PICA | B13: 2 | C13: 876 | D13: 0 | E13: 200 | F13: 26 | G13: 1104
A14: POZO ALMONTE | B14: 9 | C14: 1589 | D14: 0 | E14: 403 | F14: 50 | G14: 2051
A15: Total | B15: =SUM(B8:B14) -> 141 | C15: =SUM(C8:C14) -> 38549 | D15: =SUM(D8:D14) -> 13 | E15: =SUM(E8:E14) -> 9493 | F15: =SUM(F8:F14) -> 1104 | G15: =SUM(G8:G14) -> 49300
A21: -> region_codigo = 2
B23: estado_solicitud
A24: comuna | B24: A | C24: C | D24: D | E24: R | F24: T | G24: Total
A26: ANTOFAGASTA | B26: 137 | C26: 41859 | D26: 18 | E26: 10946 | F26: 1282 | G26: 54242
A27: CALAMA | B27: 30 | C27: 14670 | D27: 8 | E27: 3983 | F27: 498 | G27: 19189
A28: MARIA ELENA | B28: 0 | C28: 414 | D28: 0 | E28: 130 | F28: 12 | G28: 556
A29: MEJILLONES | B29: 3 | C29: 1165 | D29: 1 | E29: 377 | F29: 59 | G29: 1605
A30: OLLAGUE | B30: 0 | C30: 37 | D30: 0 | E30: 5 | F30: 1 | G30: 43
A31: SAN PEDRO DE ATACAMA | B31: 1 | C31: 680 | D31: 0 | E31: 145 | F31: 25 | G31: 851
A32: SIERRA GORDA | B32: 0 | C32: 98 | D32: 0 | E32: 29 | F32: 2 | G32: 129
A33: TALTAL | B33: 4 | C33: 1885 | D33: 0 | E33: 570 | F33: 63 | G33: 2522
A34: TOCOPILLA | B34: 11 | C34: 4223 | D34: 7 | E34: 1046 | F34: 126 | G34: 5413
A36: Total | B36: =SUM(B26:B35) -> 186 | C36: =SUM(C26:C35) -> 65031 | D36: =SUM(D26:D35) -> 34 | E36: =SUM(E26:E35) -> 17231 | F36: =SUM(F26:F35) -> 2068 | G36: =SUM(G26:G35) -> 84550
A42: -> region_codigo | B42: = | C42: 3
C44: estado_solicitud
A45: comuna | C45: A | D45: C | E45: D | F45: R | G45: T | H45: Total
A47: ALTO DEL CARMEN | C47: 1 | D47: 962 | E47: 0 | F47: 159 | G47: 31 | H47: 1153
A48: CALDERA | C48: 9 | D48: 2524 | E48: 1 | F48: 499 | G48: 92 | H48: 3125
A49: CHAÑARAL | C49: 5 | D49: 2246 | E49: 3 | F49: 497 | G49: 44 | H49: 2795
A50: COPIAPO | C50: 67 | D50: 20329 | E50: 7 | F50: 4285 | G50: 511 | H50: 25199
A51: DIEGO DE ALMAGRO | C51: 6 | D51: 1399 | E51: 1 | F51: 380 | G51: 25 | H51: 1811
A52: FREIRINA | C52: 4 | D52: 1169 | E52: 0 | F52: 197 | G52: 13 | H52: 1383
A53: HUASCO | C53: 2 | D53: 1687 | E53: 1 | F53: 361 | G53: 43 | H53: 2094
A54: TIERRA AMARILLA | C54: 4 | D54: 1565 | E54: 1 | F54: 299 | G54: 40 | H54: 1909
A55: VALLENAR | C55: 34 | D55: 9905 | E55: 3 | F55: 1871 | G55: 198 | H55: 12011
A57: Total | C57: 132 | D57: 41786 | E57: 17 | F57: 8548 | G57: 997 | H57: 51480
A63: -> region_codigo | B63: = | C63: 4
C65: estado_solicitud
A66: comuna | B66: A | C66: C | D66: D | E66: R | F66: T | G66: Total
...

Sheet II. Estado de Solicitudes
B1: Subsecretaría de Previsión Social Dirección de Estudios Previsionales
B9: II. Estado de solicitudes
B10: Trimestre OND 2022
B12: 1. Estado de las solicitudes del Pilar No Contributivo
B13: i. Resumen anual de estado de las solicitudes de beneficios del Pilar No Contributivo
B14: ii. Serie resumen por año del estado de las solicitudes por tipo de beneficio
B15: 2. Solicitudes del Pilar No Contributivo a nivel nacional
B16: i. Resumen trimestral de número y estado de solicitudes en T4 2022, según tipo y sexo
B17: ii. Resumen anual de número y estado de solicitudes en 2022, por tipo y sexo
B18: iii. Serie resumen de solicitudes de beneficios, por tipo y sexo
B19: 3. Solicitudes del Pilar No Contributivo a nivel regional y comunal
B20: i. Resumen trimestral de solicitudes por región en T4 2022, según tipo y sexo
... B73: iii. Serie resumen de tasas de concesión de solicitudes por tipo y sexo

Sheet 2.1
B2: ESTADO DE LAS SOLICITUDES DEL PILAR NO CONTRIBUTIVO
B4: Resumen anual de estado de las solicitudes de beneficios del Pilar No Contributivo
B5: (enero 2022 a diciembre 2022)
B7: Tipo de Beneficio | C7: Concedidas | E7: Suspendidas | G7: Extintas | I7: Total Solicitudes
C8: N° | D8: % | E8: N° | F8: % | G8: N° | H8: % | I8: N° | J8: %
B9: PBS Vejez | C9: 4474 | D9: =+C9/$I9 -> 0.91699119 | E9: 53 | F9: =+E9/$I9 -> 0.010862882 | G9: 3828 | H9: =+G9/$I9 -> 0.78458701 | I9: 4879 | J9: =+I9/$I9 -> 1
B10: PBS Invalidez | C10: 9283 | D10: =+C10/$I10 -> 0.25502747 | E10: 1260 | F10: =+E10/$I10 -> 0.034615385 | G10: 10252 | H10: =+G10/$I10 -> 0.28164835 | I10: 36400 | J10: =+I10/$I10 -> 1
B11: PGU No Contributiva | C11: 61292 | D11: =+C11/$I11 -> 0.71298784 | E11: 1251 | F11: =+E11/$I11 -> 0.014552434 | G11: 29767 | H11: =+G11/$I11 -> 0.34626883 | I11: 85965 | J11: =+I11/$I11 -> 1
B12: PGU Contributiva | C12: 372682 | D12: =+C12/$I12 -> 0.76852742 | E12: 619 | F12: =+E12/$I12 -> 0.0012764729 | G12: 41180 | H12: =+G12/$I12 -> 0.084919473 | I12: 484930 | J12: =+I12/$I12 -> 1
B13: APS Vejez | C13: 20511 | D13: =+C13/$I13 -> 0.93359126 | E13: =351+229 -> 580 | F13: =+E13/$I13 -> 0.026399636 | G13: =14666+7811 -> 22477 | H13: =+G13/$I13 -> 1.0230769 | I13: 21970 | J13: =+I13/$I13 -> 1
B14: APS Invalidez | C14: 14797 | D14: =+C14/$I14 -> 0.76104511 | E14: 431 | F14: =+E14/$I14 -> 0.022167361 | G14: 6508 | H14: =+G14/$I14 -> 0.33472201 | I14: 19443 | J14: =+I14/$I14 -> 1
B15: Total Beneficios | C15: 483039 | D15: =+C15/$I15 -> 0.73905846 | E15: =SUM(E9:E14) -> 4194 | F15: =+E15/$I15 -> 0.0064168963 | G15: =SUM(G9:G14) -> 114012 | H15: =+G15/$I15 -> 0.17444043 | I15: 653587 | J15: =+I15/$I15 -> 1
B16: Fuente: Elaboración propia con datos del IPS Nota: El estado final de las solicitudes puede cambiar entre periodos, dado que se incluyen solicitudes en trámite.
B18: Serie resumen por año del estado de las solicitudes por tipo de beneficio
B19: (julio 2008 a diciembre 2022)
B21: Estado Solicitudes | C21: Tipo beneficios | D21: Periodo
D22: 2008 | F22: 2009 | H22: 2010 | J22: 2011 | L22: 2012 | N22: 2013 | P22: 2014 | R22: 2015 | T22: 2016 | V22: 2017 | X22: 2018 | Z22: 2019 | AB22: 2020 | AD22: 2021 | AF22: 2022
D23: N° | E23: % | F23: N° | G23: % | H23: N° | I23: % | J23: N° | K23: % | L23: N° | M23: % | N23: N° | O23: % | P23: N° | Q23: % | R23: N° | S23: % | T23: N° | U23: % | V23: N° | W23: % | X23: N° | Y23: % | Z23: N° | AA23: % | AB23: N° | AC23: % | AD23: N° | AE23: % | AF23: N° | AG23: %
B24: Concedidas | C24: PBS Vejez | D24: 83064 | E24: =IFERROR(D24/D$45,0) -> 0.99000036 | F24: 57810 | G24: =IFERROR(F24/F$45,0) -> 0.97727964 | H24: 36125 | I24: =IFERROR(H24/H$45,0) -> 0.88687305 | J24: 29976 | K24: =IFERROR(J24/J$45,0) -> 0.80119741 | L24: 29369 | M24: =IFERROR(L24/L$45,0) -> 0.86098326 | N24: 29479 | O24: =IFERROR(N24/N$45,0) -> 0.90100251 | P24: 32567 | Q24: =IFERROR(P24/P$45,0) -> 0.82674147 | R24: 26363 | S24: =IFERROR(R24/R$45,0) -> 0.84926873 | T24: 24913 | U24: =IFERROR(T24/T$45,0) -> 0.81189506 | V24: 26161 | W24: =IFERROR(V24/V$45,0) -> 0.81681654 | X24: 28351 | Y24: =IFERROR(X24/X$45,0) -> 0.89812146 | Z24: 26756 | AA24: =IFERROR(Z24/Z$45,0) -> 0.89987556 | AB24: 27128 | AC24: =IFERROR(AB24/AB$45,0) -> 0.88996785 | AD24: 35508 | AE24: =IFERROR(AD24/AD$45,0) -> 0.85247161 | AF24: 4474 | AG24: =IFERROR(AF24/AF$45,0) -> 0.91699119
C25: PBS Invalidez | D25: 21142 | E25: =IFERROR(D25/D$46,0) -> 0.57318693 | F25: 21206 | G25: =IFERROR(F25/F$46,0) -> 0.59805968 | H25: 13245 | I25: =IFERROR(H25/H$46,0) -> 0.53050026 | J25: 10364 | K25: =IFERROR(J25/J$46,0) -> 0.49498519 | L25: 10380 | M25: =IFERROR(L25/L$46,0) -> 0.52975401 | N25: 9014 | O25: =IFERROR(N25/N$46,0) -> 0.52923908 | P25: 9988 | Q25: =IFERROR(P25/P$46,0) -> 0.56837193 | R25: 11711 | S25: =IFERROR(R25/R$46,0) -> 0.63108261 | T25: 11810 | U25: =IFERROR(T25/T$46,0) -> 0.65270255 | V25: 11910 | W25: =IFERROR(V25/V$46,0) -> 0.64957731 | X25: 10990 | Y25: =IFERROR(X25/X$46,0) -> 0.64666078 | Z25: 10802 | AA25: =IFERROR(Z25/Z$46,0) -> 0.64927571 | AB25: 9792 | AC25: =IFERROR(AB25/AB$46,0) -> 0.65245203 | AD25: 16018 | AE25: =IFERROR(AD25/AD$46,0) -> 0.59394119 | AF25: 9283 | AG25: =IFERROR(AF25/AF$46,0) -> 0.25502747
