Workbook

Sheet Indice General
B1: Subsecretaría de Previsión Social Dirección de Estudios Previsionales
B9: Informe trimestral del Pilar No Contributivo
B10: Trimestre OND 2023
B12: I. Pago de Beneficios del Pilar No Contributivo
B13: 1. Total de beneficios pagados del Pilar No Contributivo a nivel nacional
B14: 2. Total de beneficios pagados del Pilar No Contributivo a nivel regional
B15: 3. Pagos Pensión Garantizada Universal (PGU)
B16: 4. Pagos Pensión Básica Solidaria (PBS)
B17: 5. Pagos Aporte Previsional Solidario (APS)
B18: 6. Beneficios suspendidos y extintos del Pilar No Contributivo
B20: II. Estado de solicitudes
B21: 1. Solicitudes del Pilar No Contributivo a nivel nacional
... B34: 3. Subsidio a la Cotización de Trabajadores Jóvenes

Sheet I. Beneficios pagados
B1: Subsecretaría de Previsión Social Dirección de Estudios Previsionales
B9: I. Pago de Beneficios del Pilar No Contributivo
B10: Trimestre OND 2023
B12: 1. Total de beneficios pagados del Pilar No Contributivo a nivel nacional
B13: i. Resumen trimestral de beneficios pagados, por tipo de beneficio y sexo
B14: ii. Resumen anual de beneficios pagados, por tipo de beneficio y sexo
B15: iii. Serie resumen de pagos de beneficios acumulados, por tipo de beneficio
B17: 2. Total de beneficios pagados del Pilar No Contributivo a nivel regional
B18: i. Resumen trimestral de beneficios pagados, por región, tipo de beneficio y sexo
B20: 3. Pagos Pensión Garantizada Universal (PGU)
B21: i. Resumen trimestral de beneficios pagados, por tipo de beneficio y sexo
B22: ii. Resumen anual de beneficios pagados, por tipo de beneficio y sexo
... B37: ii. Beneficios extinguidos por año, por tipo de beneficio

Sheet dinamica pgu
A1: PERIODO | B1: (Varios elementos)
A3: Etiquetas de fila
A4: oct
A5: Suma de PGU_NC_Mujer_n | B5: 322141
A6: Suma de PGU_NC_hombre_N | B6: 109963
A7: Suma de PGU_C_Mujer_N | B7: 686334
A8: Suma de PGU_C_hombre_N | B8: 563950
A9: nov
A10: Suma de PGU_NC_Mujer_n | B10: 327443
A11: Suma de PGU_NC_hombre_N | B11: 121585
A12: Suma de PGU_C_Mujer_N | B12: 704099
A13: Suma de PGU_C_hombre_N | B13: 584193
A14: dic
A15: Suma de PGU_NC_Mujer_n | B15: 329180
A16: Suma de PGU_NC_hombre_N | B16: 125728
A17: Suma de PGU_C_Mujer_N | B17: 717919
A18: Suma de PGU_C_hombre_N | B18: 594890
A22: PERIODO | B22: (Varios elementos)
A24: Etiquetas de fila
A25: oct
A26: Suma de PGU_NC_Mujer_Nom | B26: 62098940
A27: Suma de PGU_NC_hombre_Nom | B27: 21312758
A28: Suma de PGU_C_Mujer_Nom | B28: 1.3198656e+08
A29: Suma de PGU_C_hombre_Nom | B29: 1.0801488e+08
A30: nov
A31: Suma de PGU_NC_Mujer_Nom | B31: 63080933
A32: Suma de PGU_NC_hombre_Nom | B32: 23564397
A33: Suma de PGU_C_Mujer_Nom | B33: 1.3523624e+08
A34: Suma de PGU_C_hombre_Nom | B34: 1.115372e+08
A35: dic
A36: Suma de PGU_NC_Mujer_Nom | B36: 63417032
A37: Suma de PGU_NC_hombre_Nom | B37: 24368203
A38: Suma de PGU_C_Mujer_Nom | B38: 1.3763622e+08
A39: Suma de PGU_C_hombre_Nom | B39: 1.1328694e+08
A43: PERIODO | B43: (Varios elementos)
A45: Etiquetas de fila
A46: oct
A47: Suma de PGU_NC_Mujer_REAL | B47: 61325232
A48: Suma de PGU_NC_hombre_REAL | B48: 21047217
A49: Suma de PGU_C_Mujer_REAL | B49: 1.303421e+08
...

Sheet N PBS
A3: Etiquetas de fila | B3: Promedio de PBS VEJEZ MUJER | C3: Promedio de PBS VEJEZ HOMBRE | D3: Promedio de PBS INVALIDEZ MUJER | E3: Promedio de PBS INVALIDEZ HOMBRE | F3: Promedio de PBS TOTAL MUJER | G3: Promedio de PBS TOTAL HOMBRE
A4: 2008 | B4: 218799.83 | C4: 107682.67 | D4: 108916.5 | E4: 84536 | F4: 327716.33 | G4: 192218.67
A5: 2009 | B5: 262267.25 | C5: 117026.58 | D5: 116205.08 | E5: 86817.667 | F5: 378472.33 | G5: 203844.25
A6: 2010 | B6: 284569.67 | C6: 119969.58 | D6: 125529.75 | E6: 89731.417 | F6: 410099.42 | G6: 209701
A7: 2011 | B7: 286982.92 | C7: 118668.92 | D7: 125674.58 | E7: 89317.917 | F7: 412657.5 | G7: 207986.83
A8: 2012 | B8: 288232.25 | C8: 116683.83 | D8: 120025.92 | E8: 85446.25 | F8: 408258.17 | G8: 202130.08
A9: 2013 | B9: 288720.25 | C9: 114312 | D9: 112605.08 | E9: 79812.917 | F9: 401325.33 | G9: 194124.92
A10: 2014 | B10: 288530.42 | C10: 111136.17 | D10: 107377.17 | E10: 75527.833 | F10: 395907.58 | G10: 186664
A11: 2015 | B11: 289070.58 | C11: 110162 | D11: 105105.42 | E11: 74655.333 | F11: 394176 | G11: 184817.33
A12: 2016 | B12: 290373 | C12: 108843.42 | D12: 105459.83 | E12: 75532.583 | F12: 395832.83 | G12: 184376
A13: 2017 | B13: 291754 | C13: 107694.83 | D13: 105581.83 | E13: 76434.167 | F13: 397335.83 | G13: 184129
A14: 2018 | B14: 295171.83 | C14: 107077.42 | D14: 105559.42 | E14: 77417 | F14: 400731.25 | G14: 184494.42
A15: 2019 | B15: 299821.5 | C15: 106705.25 | D15: 104899.17 | E15: 77850.417 | F15: 404720.67 | G15: 184555.67
... A42: dic | B42: 0 | C42: 0 | D42: 103979 | E42: 81605 | F42: 103979 | G42: 81605

Sheet MONTOS PBS
I1: PERIODO | J1: (Varios elementos)
A3: Etiquetas de fila | B3: Promedio de PBSV_MUJER | C3: Promedio de PBSV_HOMBRE | D3: Promedio de PBSI_MUJER | E3: Promedio de PBSI_HOMBRE | F3: Promedio de PBS_MUJER | G3: Promedio de PBS_HOMBRE | I3: Etiquetas de fila | J3: Suma de PBSV_MUJER | K3: Suma de PBSV_HOMBRE | L3: Suma de PBSV_TOTAL | M3: Suma de PBSI_MUJER | N3: Suma de PBSI_HOMBRE | O3: Suma de PBSI_TOTAL | P3: Suma de PBS_MUJER | Q3: Suma de PBS_HOMBRE | R3: Suma de PBS_TOTAL | T3: Etiquetas de fila | U3: Suma de PBSV_MUJER | V3: Suma de PBSV_HOMBRE | W3: Suma de PBSV_TOTAL | X3: Suma de PBSI_MUJER | Y3: Suma de PBSI_HOMBRE | Z3: Suma de PBSI_TOTAL | AA3: Suma de PBS_MUJER | AB3: Suma de PBS_HOMBRE | AC3: Suma de PBS_TOTAL | AE3: Etiquetas de fila | AF3: Suma de PBSV_MUJER | AG3: Suma de PBSV_HOMBRE | AH3: Suma de PBSV_TOTAL | AI3: Suma de PBSI_MUJER | AJ3: Suma de PBSI_HOMBRE | AK3: Suma de PBSI_TOTAL | AL3: Suma de PBS_MUJER | AM3: Suma de PBS_HOMBRE | AN3: Suma de PBS_TOTAL
A4: 2008 | B4: 8.2469269e+09 | C4: 3.9732077e+09 | D4: 3.9696562e+09 | E4: 3.0646136e+09 | F4: 1.2216583e+10 | G4: 7.0378213e+09 | I4: 2022 | J4: 0 | K4: 0 | L4: 0 | M4: 6.0133313e+10 | N4: 4.7149436e+10 | O4: 1.0728275e+11 | P4: 6.0133313e+10 | Q4: 4.7149436e+10 | R4: 1.0728275e+11 | T4: oct | U4: 0 | V4: 0 | W4: 0 | X4: 1.9903687e+10 | Y4: 1.5583475e+10 | Z4: 3.5487162e+10 | AA4: 1.9903687e+10 | AB4: 1.5583475e+10 | AC4: 3.5487162e+10 | AE4: oct | AF4: =+U4/1000 -> 0 | AG4: =+V4/1000 -> 0 | AH4: =+W4/1000 -> 0 | AI4: =+X4/1000 -> 19903687 | AJ4: =+Y4/1000 -> 15583475 | AK4: =+Z4/1000 -> 35487162 | AL4: =+AA4/1000 -> 19903687 | AM4: =+AB4/1000 -> 15583475 | AN4: =+AC4/1000 -> 35487162
A5: 2009 | B5: 1.0831943e+10 | C5: 4.7784934e+09 | D5: 5.149103e+09 | E5: 3.655593e+09 | F5: 1.5981046e+10 | G5: 8.4340864e+09 | I5: oct | J5: 0 | K5: 0 | L5: 0 | M5: 1.9903687e+10 | N5: 1.5583475e+10 | O5: 3.5487162e+10 | P5: 1.9903687e+10 | Q5: 1.5583475e+10 | R5: 3.5487162e+10 | T5: nov | U5: 0 | V5: 0 | W5: 0 | X5: 2.0075789e+10 | Y5: 1.5749774e+10 | Z5: 3.5825563e+10 | AA5: 2.0075789e+10 | AB5: 1.5749774e+10 | AC5: 3.5825563e+10 | AE5: nov | AF5: =+U5/1000 -> 0 | AG5: =+V5/1000 -> 0 | AH5: =+W5/1000 -> 0 | AI5: =+X5/1000 -> 20075789 | AJ5: =+Y5/1000 -> 15749774 | AK5: =+Z5/1000 -> 35825563 | AL5: =+AA5/1000 -> 20075789 | AM5: =+AB5/1000 -> 15749774 | AN5: =+AC5/1000 -> 35825563
A6: 2010 | B6: 1.3095568e+10 | C6: 5.5029662e+09 | D6: 5.9733298e+09 | E6: 4.1819318e+09 | F6: 1.9068897e+10 | G6: 9.684898e+09 | I6: nov | J6: 0 | K6: 0 | L6: 0 | M6: 2.0075789e+10 | N6: 1.5749774e+10 | O6: 3.5825563e+10 | P6: 2.0075789e+10 | Q6: 1.5749774e+10 | R6: 3.5825563e+10 | T6: dic | U6: 0 | V6: 0 | W6: 0 | X6: 20153837159 | Y6: 15816186175 | Z6: 35970023334 | AA6: 20153837159 | AB6: 15816186175 | AC6: 35970023334 | AE6: dic | AF6: =+U6/1000 -> 0 | AG6: =+V6/1000 -> 0 | AH6: =+W6/1000 -> 0 | AI6: =+X6/1000 -> 20153837 | AJ6: =+Y6/1000 -> 15816186 | AK6: =+Z6/1000 -> 35970023 | AL6: =+AA6/1000 -> 20153837 | AM6: =+AB6/1000 -> 15816186 | AN6: =+AC6/1000 -> 35970023
A7: 2011 | B7: 1.3994994e+10 | C7: 5.7801079e+09 | D7: 6.2216009e+09 | E7: 4.3734947e+09 | F7: 2.0216595e+10 | G7: 1.0153603e+10 | I7: dic | J7: 0 | K7: 0 | L7: 0 | M7: 20153837159 | N7: 15816186175 | O7: 35970023334 | P7: 20153837159 | Q7: 15816186175 | R7: 35970023334
A8: 2012 | B8: 1.4900592e+10 | C8: 6.0276417e+09 | D8: 6.3053347e+09 | E8: 4.4481809e+09 | F8: 2.1205927e+10 | G8: 1.0475823e+10
A9: 2013 | B9: 1.5464511e+10 | C9: 6.1276381e+09 | D9: 6.1333006e+09 | E9: 4.2916174e+09 | F9: 2.1597811e+10 | G9: 1.0419256e+10
A10: 2014 | B10: 1.6719242e+10 | C10: 6.4430339e+09 | D10: 6.3328754e+09 | E10: 4.3768174e+09 | F10: 2.3052118e+10 | G10: 1.0819851e+10
A11: 2015 | B11: 1.8210703e+10 | C11: 6.9460832e+09 | D11: 6.7614414e+09 | E11: 4.7714308e+09 | F11: 2.4972144e+10 | G11: 1.1717514e+10
A12: 2016 | B12: 1.9783297e+10 | C12: 7.4256197e+09 | D12: 7.3620108e+09 | E12: 5.231601e+09 | F12: 2.7145307e+10 | G12: 1.2657221e+10 | I12: PERIODO | J12: (Varios elementos) | AE12: nominales
A13: 2017 | B13: 2.3013212e+10 | C13: 8.5012643e+09 | D13: 8.4836307e+09 | E13: 6.1043568e+09 | F13: 3.1496842e+10 | G13: 1.4605621e+10 | AF13: vejez | AI13: invalidez | AL13: total
A14: 2018 | B14: 2.4370428e+10 | C14: 8.8423454e+09 | D14: 8.863105e+09 | E14: 6.4518852e+09 | F14: 3.3233533e+10 | G14: 1.5294231e+10 | I14: Etiquetas de fila | J14: Suma de MUJER | K14: Suma de HOMBRE | L14: Suma de TOTAL | M14: Suma de MUJER2 | N14: Suma de HOMBRE2 | O14: Suma de TOTAL2 | P14: Suma de MUJER3 | Q14: Suma de HOMBRE3 | R14: Suma de TOTAL3 | T14: Etiquetas de fila | U14: Suma de MUJER | V14: Suma de HOMBRE | W14: Suma de TOTAL | X14: Suma de MUJER2 | Y14: Suma de HOMBRE2 | Z14: Suma de TOTAL2 | AA14: Suma de MUJER3 | AB14: Suma de HOMBRE3 | AC14: Suma de TOTAL3 | AE14: Etiquetas de fila | AF14: Promedio de MUJER | AG14: Promedio de HOMBRE | AH14: Promedio de TOTAL | AI14: Promedio de MUJER2 | AJ14: Promedio de HOMBRE2 | AK14: Promedio de TOTAL2 | AL14: Promedio de MUJER3 | AM14: Promedio de HOMBRE3 | AN14: Promedio de TOTAL3
A15: 2019 | B15: 2.6689511e+10 | C15: 9.492244e+09 | D15: 9.429656e+09 | E15: 6.9564548e+09 | F15: 3.6119167e+10 | G15: 1.6448699e+10 | I15: 2022 | J15: 0 | K15: 0 | L15: 0 | M15: 60441368879 | N15: 47390715970 | O15: 107832084849 | P15: 60441368879 | Q15: 47390715970 | R15: 107832084849 | T15: oct | U15: 0 | V15: 0 | W15: 0 | X15: 20154801071 | Y15: 15780083599 | Z15: 35934884670 | AA15: 20154801071 | AB15: 15780083599 | AC15: 35934884670 | AE15: oct | AF15: =+U15/1000 -> 0 | AG15: =+V15/1000 -> 0 | AH15: =+W15/1000 -> 0 | AI15: =+X15/1000 -> 20154801 | AJ15: =+Y15/1000 -> 15780084 | AK15: =+Z15/1000 -> 35934885 | AL15: =+AA15/1000 -> 20154801 | AM15: =+AB15/1000 -> 15780084 | AN15: =+AC15/1000 -> 35934885
A16: 2020 | B16: 3.659289e+10 | C16: 1.2913294e+10 | D16: 1.1894674e+10 | E16: 8.9114229e+09 | F16: 4.8487564e+10 | G16: 2.1824717e+10 | I16: oct | J16: 0 | K16: 0 | L16: 0 | M16: 20154801071 | N16: 15780083599 | O16: 35934884670 | P16: 20154801071 | Q16: 15780083599 | R16: 35934884670 | T16: nov | U16: 0 | V16: 0 | W16: 0 | X16: 20132730649 | Y16: 15794446196 | Z16: 35927176845 | AA16: 20132730649 | AB16: 15794446196 | AC16: 35927176845 | AE16: nov | AF16: =+U16/1000 -> 0 | AG16: =+V16/1000 -> 0 | AH16: =+W16/1000 -> 0 | AI16: =+X16/1000 -> 20132731 | AJ16: =+Y16/1000 -> 15794446 | AK16: =+Z16/1000 -> 35927177 | AL16: =+AA16/1000 -> 20132731 | AM16: =+AB16/1000 -> 15794446 | AN16: =+AC16/1000 -> 35927177
A17: 2021 | B17: 4.3453866e+10 | C17: 1.494933e+10 | D17: 1.4114095e+10 | E17: 1.0837333e+10 | F17: 5.7567962e+10 | G17: 2.5786663e+10 | I17: nov | J17: 0 | K17: 0 | L17: 0 | M17: 20132730649 | N17: 15794446196 | O17: 35927176845 | P17: 20132730649 | Q17: 15794446196 | R17: 35927176845 | T17: dic | U17: 0 | V17: 0 | W17: 0 | X17: 20153837159 | Y17: 15816186175 | Z17: 35970023334 | AA17: 20153837159 | AB17: 15816186175 | AC17: 35970023334 | AE17: dic | AF17: =+U17/1000 -> 0 | AG17: =+V17/1000 -> 0 | AH17: =+W17/1000 -> 0 | AI17: =+X17/1000 -> 20153837 | AJ17: =+Y17/1000 -> 15816186 | AK17: =+Z17/1000 -> 35970023 | AL17: =+AA17/1000 -> 20153837 | AM17: =+AB17/1000 -> 15816186 | AN17: =+AC17/1000 -> 35970023
A18: ene | B18: 4.1412765e+10 | C18: 1.4344175e+10 | D18: 1.357545e+10 | E18: 1.0301137e+10 | F18: 5.4988215e+10 | G18: 2.4645311e+10 | I18: dic | J18: 0 | K18: 0 | L18: 0 | M18: 20153837159 | N18: 15816186175 | O18: 35970023334 | P18: 20153837159 | Q18: 15816186175 | R18: 35970023334 | T18: Total general | U18: 0 | V18: 0 | W18: 0 | X18: 2.0147123e+10 | Y18: 1.5796905e+10 | Z18: 35944028283 | AA18: 2.0147123e+10 | AB18: 1.5796905e+10 | AC18: 35944028283
A19: feb | B19: 4.1492133e+10 | C19: 1.4338672e+10 | D19: 1.35569e+10 | E19: 1.0317361e+10 | F19: 5.5049033e+10 | G19: 2.4656033e+10
A20: mar | B20: 4.1689378e+10 | C20: 1.4389108e+10 | D20: 1.3587482e+10 | E20: 1.0363694e+10 | F20: 5.527686e+10 | G20: 2.4752801e+10
A21: abr | B21: 4.1893694e+10 | C21: 1.4448119e+10 | D21: 1.3658161e+10 | E21: 1.0436146e+10 | F21: 5.5551855e+10 | G21: 2.4884265e+10
A22: may | B22: 4.2028716e+10 | C22: 1.4474202e+10 | D22: 1.3650261e+10 | E22: 1.0455982e+10 | F22: 5.5678977e+10 | G22: 2.4930184e+10
A23: jun | B23: 4.2051494e+10 | C23: 1.4454401e+10 | D23: 1.3673345e+10 | E23: 1.0488652e+10 | F23: 5.5724839e+10 | G23: 2.4943053e+10
A24: jul | B24: 4.3968065e+10 | C24: 1.5094747e+10 | D24: 1.4296201e+10 | E24: 1.0984398e+10 | F24: 5.8264265e+10 | G24: 2.6079145e+10
A25: ago | B25: 4.4239653e+10 | C25: 1.5183281e+10 | D25: 1.4359654e+10 | E25: 1.1056169e+10 | F25: 5.8599307e+10 | G25: 2.6239451e+10
A26: sept | B26: 4.4825753e+10 | C26: 1.5361682e+10 | D26: 1.4520122e+10 | E26: 1.1196684e+10 | F26: 5.9345875e+10 | G26: 2.6558366e+10
A27: oct | B27: 4.5558469e+10 | C27: 1.5619781e+10 | D27: 1.4731002e+10 | E27: 1.1378659e+10 | F27: 6.0289471e+10 | G27: 2.6998439e+10
A28: nov | B28: 4.5907806e+10 | C28: 1.5757842e+10 | D28: 1.4819941e+10 | E28: 1.1477734e+10 | F28: 6.0727747e+10 | G28: 2.7235576e+10
A29: dic | B29: 4.6378472e+10 | C29: 1.5925944e+10 | D29: 1.4940627e+10 | E29: 1.159138e+10 | F29: 6.1319099e+10 | G29: 2.7517324e+10
A30: 2022 | B30: 4.0614957e+09 | C30: 1.3943048e+09 | D30: 1.8608107e+10 | E30: 1.4541109e+10 | F30: 2.2669603e+10 | G30: 1.5935414e+10
... A43: Total general | B43: 1.9676256e+10 | C43: 7.3869635e+09 | D43: 8.5253168e+09 | E43: 6.2527955e+09 | F43: 2.8201573e+10 | G43: 1.3639759e+10
A52: Etiquetas de fila | B52: Promedio de PBSV_MUJER | C52: Promedio de PBSV_HOMBRE | D52: Promedio de PBSI_MUJER | E52: Promedio de PBSI_HOMBRE | F52: Promedio de PBS_MUJER | G52: Promedio de PBS_HOMBRE | I52: Etiquetas de fila | J52: Promedio de PBSV_MUJER | K52: Promedio de PBSV_HOMBRE | L52: Promedio de PBSI_MUJER | M52: Promedio de PBSI_HOMBRE | N52: Promedio de PBS_MUJER | O52: Promedio de PBS_HOMBRE
A53: 2008 | B53: 8.2469269e+09 | C53: 3.9732077e+09 | D53: 3.9696562e+09 | E53: 3.0646136e+09 | F53: 1.2216583e+10 | G53: 7.0378213e+09 | I53: 2008 | J53: 8246926.9 | K53: 3973207.7 | L53: 3969656.2 | M53: 3064613.6 | N53: 12216583 | O53: 7037821.3
A54: 2009 | B54: 1.0831943e+10 | C54: 4.7784934e+09 | D54: 5.149103e+09 | E54: 3.655593e+09 | F54: 1.5981046e+10 | G54: 8.4340864e+09 | I54: 2009 | J54: 10831943 | K54: 4778493.4 | L54: 5149103 | M54: 3655593 | N54: 15981046 | O54: 8434086.4
A55: 2010 | B55: 1.3095568e+10 | C55: 5.5029662e+09 | D55: 5.9733298e+09 | E55: 4.1819318e+09 | F55: 1.9068897e+10 | G55: 9.684898e+09 | I55: 2010 | J55: 13095568 | K55: 5502966.2 | L55: 5973329.8 | M55: 4181931.8 | N55: 19068897 | O55: 9684898
A56: 2011 | B56: 1.3994994e+10 | C56: 5.7801079e+09 | D56: 6.2216009e+09 | E56: 4.3734947e+09 | F56: 2.0216595e+10 | G56: 1.0153603e+10 | I56: 2011 | J56: 13994994 | K56: 5780107.9 | L56: 6221600.9 | M56: 4373494.7 | N56: 20216595 | O56: 10153603
A57: 2012 | B57: 1.4900592e+10 | C57: 6.0276417e+09 | D57: 6.3053347e+09 | E57: 4.4481809e+09 | F57: 2.1205927e+10 | G57: 1.0475823e+10 | I57: 2012 | J57: 14900592 | K57: 6027641.7 | L57: 6305334.7 | M57: 4448180.9 | N57: 21205927 | O57: 10475823
A58: 2013 | B58: 1.5464511e+10 | C58: 6.1276381e+09 | D58: 6.1333006e+09 | E58: 4.2916174e+09 | F58: 2.1597811e+10 | G58: 1.0419256e+10 | I58: 2013 | J58: 15464511 | K58: 6127638.1 | L58: 6133300.6 | M58: 4291617.4 | N58: 21597811 | O58: 10419256
A59: 2014 | B59: 1.6719242e+10 | C59: 6.4430339e+09 | D59: 6.3328754e+09 | E59: 4.3768174e+09 | F59: 2.3052118e+10 | G59: 1.0819851e+10 | I59: 2014 | J59: 16719242 | K59: 6443033.9 | L59: 6332875.4 | M59: 4376817.4 | N59: 23052118 | O59: 10819851
A60: 2015 | B60: 1.8210703e+10 | C60: 6.9460832e+09 | D60: 6.7614414e+09 | E60: 4.7714308e+09 | F60: 2.4972144e+10 | G60: 1.1717514e+10 | I60: 2015 | J60: 18210703 | K60: 6946083.2 | L60: 6761441.4 | M60: 4771430.8 | N60: 24972144 | O60: 11717514
A61: 2016 | B61: 1.9783297e+10 | C61: 7.4256197e+09 | D61: 7.3620108e+09 | E61: 5.231601e+09 | F61: 2.7145307e+10 | G61: 1.2657221e+10 | I61: 2016 | J61: 19783297 | K61: 7425619.7 | L61: 7362010.8 | M61: 5231601 | N61: 27145307 | O61: 12657221
...

Sheet 1.1
B2: TOTAL DE BENEFICIOS PAGADOS DEL PILAR NO CONTRIBUTIVO A NIVEL NACIONAL
B4: Resumen trimestral de beneficios pagados, por tipo de beneficio y sexo
B5: (octubre 2023 a diciembre 2023)
D7: Mujeres | G7: Hombres | J7: Total
B8: Periodo | C8: Tipo de beneficio | D8: N° beneficiarios | E8: Monto nominal (M$)3 | F8: Monto real (M$)4 | G8: N° beneficiarios | H8: Monto nominal (M$)3 | I8: Monto real (M$)4 | J8: N° beneficiarios | K8: Monto nominal (M$)3 | L8: Monto real (M$)4
B9: 45200 | C9: PGU No Contributiva1 | D9: 344866 | E9: 70556341 | F9: 70700999 | G9: 139504 | H9: 28629001 | I9: 28687697 | J9: 484370 | K9: 99185342 | L9: 99388697
C10: PGU Contributiva1 | D10: 801418 | E10: 162703789 | F10: 1.6303737e+08 | G10: 670939 | H10: 1.3496986e+08 | I10: 1.3524659e+08 | J10: 1472357 | K10: 2.9767365e+08 | L10: 2.9828396e+08
C11: PBS Invalidez | D11: 107612 | E11: 22173725 | F11: 22219187 | G11: 84447 | H11: 17401883 | I11: 17437561 | J11: 192059 | K11: 39575608 | L11: 39656748
C12: APS Vejez1 | D12: 106548 | E12: 25173158 | F12: 25224769 | G12: 60882 | H12: 14578037 | I12: 14607926 | J12: 167430 | K12: 39751195 | L12: 39832695
C13: APS Invalidez | D13: 47288 | E13: 8347977.7 | F13: 8365093.1 | G13: 49876 | H13: 8352880.7 | I13: 8370006.2 | J13: 97164 | K13: 16700858 | L13: 16735099
C14: Total Beneficios2 | D14: 1407732 | E14: 2.8895499e+08 | F14: 2.8954742e+08 | G14: 1005648 | H14: 2.0393167e+08 | I14: 2.0434978e+08 | J14: 2413380 | K14: 4.9288666e+08 | L14: 4.938972e+08
B15: 45231 | C15: PGU No Contributiva1 | D15: 343086 | E15: 70221852 | F15: 69844858 | G15: 139023 | H15: 28559853 | I15: 28406526 | J15: 482109 | K15: 98781705 | L15: 98251384
C16: PGU Contributiva1 | D16: 810512 | E16: 1.6459531e+08 | F16: 1.6371166e+08 | G16: 678035 | H16: 1.3635304e+08 | I16: 1.3562101e+08 | J16: 1488547 | K16: 3.0094835e+08 | L16: 2.9933267e+08
C17: PBS Invalidez | D17: 107578 | E17: 22167675 | F17: 22048666 | G17: 84680 | H17: 17450456 | I17: 17356771 | J17: 192258 | K17: 39618131 | L17: 39405437
C18: APS Vejez1 | D18: 106386 | E18: 25126472 | F18: 24991578 | G18: 60624 | H18: 14517267 | I18: 14439329 | J18: 167010 | K18: 39643740 | L18: 39430908
C19: APS Invalidez | D19: 47294 | E19: 8334109.4 | F19: 8289366.8 | G19: 49989 | H19: 8356257.6 | I19: 8311396.1 | J19: 97283 | K19: 16690367 | L19: 16600763
C20: Total Beneficios2 | D20: 1414856 | E20: 2.9044542e+08 | F20: 2.8888613e+08 | G20: 1012351 | H20: 2.0523687e+08 | I20: 2.0413504e+08 | J20: 2427207 | K20: 4.9568229e+08 | L20: 4.9302117e+08
B21: 45261 | C21: PGU No Contributiva1 | D21: 339811 | E21: 69796632 | F21: 69796632 | G21: 131135 | H21: 26987353 | I21: 26987353 | J21: 470946 | K21: 96783985 | L21: 96783985
C22: PGU Contributiva1 | D22: 818807 | E22: 1.6633464e+08 | F22: 1.6633464e+08 | G22: 690945 | H22: 1.390067e+08 | I22: 1.390067e+08 | J22: 1509752 | K22: 3.0534134e+08 | L22: 3.0534134e+08
C23: PBS Invalidez | D23: 107857 | E23: 22224555 | F23: 22224555 | G23: 84948 | H23: 17505535 | I23: 17505535 | J23: 192805 | K23: 39730090 | L23: 39730090
C24: APS Vejez1 | D24: 105880 | E24: 25039244 | F24: 25039244 | G24: 60307 | H24: 14450349 | I24: 14450349 | J24: 166187 | K24: 39489594 | L24: 39489594
C25: APS Invalidez | D25: 47405 | E25: 8339131.6 | F25: 8339131.6 | G25: 50164 | H25: 8365112.5 | I25: 8365112.5 | J25: 97569 | K25: 16704244 | L25: 16704244
C26: Total Beneficios2 | D26: 1419760 | E26: 2.917342e+08 | F26: 2.917342e+08 | G26: 1017499 | H26: 2.0631505e+08 | I26: 2.0631505e+08 | J26: 2437259 | K26: 4.9804925e+08 | L26: 4.9804925e+08
B27: Fuente: Elaboración propia con datos de la Superintendencia de Pensiones
B28: 1 La Pensión Garantizada Universal (PGU) es un nuevo beneficio generado a partir de la ley 21.419 del 29-01-2022. El concepto de PGU No Contributiva o Contributiva está relacionado con la calidad de la persona que está recibiendo el beneficio, si es No Contributiva quiere decir que no estaba afiliado a un sistema previsional (D.L. 3.500 o antiguo Sistema de Reparto) ni recibe pensión de sobrevivencia, si es Contributiva quiere decir que sí estaba afiliado a un sistema previsional o que recibe una pensión de sobrevivencia. De manera automática, en febrero 2022, los PBS de Vejez pasaron a ser PGU No Contributiva y los APS Vejez Subsidio Definido, los Beneficio artículo 9° bis y los APS Vejez con una Pensión Final Garantizada inferior o igual al monto de la PGU pasaron a ser PGU Contributiva. En los casos en que el APS Vejez con una Pensión Final Garantizada tuviera un monto superior a la PGU, se mantuvo el pago del beneficio.
B29: 2 A diciembre de 2023 se encuentran vigentes 89.472 beneficios Ex PASIS de Vejez y 92.738 Ex PASIS de Invalidez. 3 Montos nominales de cada periodo de pago. 4 Montos deflactados a diciembre 2023.
B31: Resumen anual de beneficios pagados, por tipo de beneficio y sexo
B32: (enero 2023 a diciembre 2023)
D34: Mujeres | G34: Hombres | J34: Ambos
B35: Periodo | C35: Tipo de beneficio | D35: N° promedio beneficiarios3 | E35: Monto nominal (M$)4 | F35: Monto real (M$)5 | G35: N° promedio beneficiarios3 | H35: Monto nominal (M$)4 | I35: Monto real (M$)5 | J35: N° promedio beneficiarios3 | K35: Monto nominal (M$)4 | L35: Monto real (M$)5
B36: Año 2023 | C36: PGU No Contributiva1 | D36: 338941.42 | E36: 8.2990264e+08 | F36: 8.4122591e+08 | G36: 133932.08 | H36: 3.2881759e+08 | I36: 3.3325394e+08 | J36: 472873.5 | K36: 1.1587202e+09 | L36: 1.1744799e+09
C37: PGU Contributiva1 | D37: 777918.17 | E37: 1.8892604e+09 | F37: 1.9145926e+09 | G37: 650208.25 | H37: 1.5652586e+09 | I37: 1.5862021e+09 | J37: 1428126.4 | K37: 3.454519e+09 | L37: 3.5007947e+09
C38: PBS Invalidez | D38: 106021.08 | E38: 2.6088347e+08 | F38: 2.6444117e+08 | G38: 83341.5 | H38: 2.0508402e+08 | I38: 2.078794e+08 | J38: 189362.58 | K38: 4.6596748e+08 | L38: 4.7232057e+08
C39: APS Vejez1 | D39: 107656.58 | E39: 2.9213166e+08 | F39: 2.9607842e+08 | G39: 61733.75 | H39: 1.693076e+08 | I39: 1.7159906e+08 | J39: 169390.33 | K39: 4.6143926e+08 | L39: 4.6767749e+08
C40: APS Invalidez | D40: 46872.083 | E40: 99131586 | F40: 1.0048947e+08 | G40: 48903.25 | H40: 98307682 | I40: 99645254 | J40: 95775.333 | K40: 1.9743927e+08 | L40: 2.0013473e+08
C41: Total Beneficios2 | D41: 1377409.3 | E41: 3.3713098e+09 | F41: 3.4168276e+09 | G41: 978118.83 | H41: 2.3667755e+09 | I41: 2.3985797e+09 | J41: 2355528.2 | K41: 5.7380852e+09 | L41: 5.8154073e+09
B42: Fuente: Elaboración propia con datos de la Superintendencia de Pensiones
B43: 1 La Pensión Garantizada Universal (PGU) es un nuevo beneficio generado a partir de la ley 21.419 del 29-01-2022. El concepto de PGU No Contributiva o Contributiva está relacionado con la calidad de la persona que está recibiendo el beneficio, si es No Contributiva quiere decir que no estaba afiliado a un sistema previsional (D.L. 3.500 o antiguo Sistema de Reparto) ni recibe pensión de sobrevivencia, si es Contributiva quiere decir que sí estaba afiliado a un sistema previsional o que recibe una pensión de sobrevivencia. De manera automática, en febrero 2022, los PBS de Vejez pasaron a ser PGU No Contributiva y los APS Vejez Subsidio Definido, los Beneficio artículo 9° bis y los APS Vejez con una Pensión Final Garantizada inferior o igual al monto de la PGU pasaron a ser PGU Contributiva. En los casos en que el APS Vejez con una Pensión Final Garantizada tuviera un monto superior a la PGU, se mantuvo el pago del beneficio.
B44: 2 A diciembre de 2023 se encuentran vigentes 89.472 beneficios Ex PASIS de Vejez y 92.738 Ex PASIS de Invalidez. 3 Promedio mensual de beneficiarios del año. 4 Montos nominales de cada periodo de pago. 5 Montos deflactados a diciembre 2023
B46: Serie resumen de pagos de beneficios acumulados, por tipo de beneficio
...

Sheet 1.2
B2: TOTAL DE BENEFICIOS PAGADOS DEL PILAR NO CONTRIBUTIVO A NIVEL REGIONAL
B4: Resumen trimestral de beneficios pagados, por región, tipo de beneficio y sexo
B5: (octubre 2023 a diciembre 2023)
B7: Región | C7: Tipo de beneficio | D7: Mujeres | G7: Hombres | J7: Total
D8: N° promedio beneficiarios3 | E8: Monto total (M$)4 | F8: Monto promedio por beneficiario ($)5 | G8: N° promedio beneficiarios3 | H8: Monto total (M$)4 | I8: Monto promedio por beneficiario ($)5 | J8: N° promedio beneficiarios3 | K8: Monto total (M$)4 | L8: Monto promedio por beneficiario ($)5
B9: Región de Arica y Parinacota | C9: PGU No Contributiva1 | D9: 3362 | E9: 2064921.7 | F9: 204731.48 | G9: 1444 | H9: 886848.64 | I9: 204720.37 | J9: 4806 | K9: 2951770.4 | L9: 204728.14
C10: PGU Contributiva1 | D10: 10114.667 | E10: 6158628.8 | F10: 202960.35 | G10: 8450.3333 | H10: 5100433.1 | I10: 201192.58 | J10: 18565 | K10: 11259062 | L10: 202155.7
C11: APS Vejez1 | D11: 1321 | E11: 936963.07 | F11: 236427.72 | G11: 748 | H11: 535732.11 | I11: 238739.8 | J11: 2069 | K11: 1472695.2 | L11: 237263.6
C12: PBS Invalidez | D12: 1141.6667 | E12: 705228.66 | F12: 205906.18 | G12: 1155 | H12: 713599.6 | I12: 205945.05 | J12: 2296.6667 | K12: 1418828.3 | L12: 205925.73
C13: APS Invalidez | D13: 465.66667 | E13: 238494.67 | F13: 170719.16 | G13: 565.66667 | H13: 275711.5 | I13: 162469.95 | J13: 1031.3333 | K13: 514206.17 | L13: 166194.63
C14: Total2 | D14: 16405 | E14: 10104237 | F14: 205308.08 | G14: 12363 | H14: 7512325 | I14: 202548.6 | J14: 28768 | K14: 17616562 | L14: 204122.2
B15: Región de Tarapacá | C15: PGU No Contributiva1 | D15: 3727.6667 | E15: 2294191.5 | F15: 205149.92 | G15: 1636.3333 | H15: 1005551.3 | I15: 204838.32 | J15: 5364 | K15: 3299742.9 | L15: 205054.86
B16: Región de Tarapacá | C16: PGU Contributiva1 | D16: 10913.333 | E16: 6643196.6 | F16: 202907.65 | G16: 9961 | H16: 5973702.1 | I16: 199903.03 | J16: 20874.333 | K16: 12616899 | L16: 201473.88
B17: Región de Tarapacá | C17: APS Vejez1 | D17: 1627.3333 | E17: 1156573.7 | F17: 236905.72 | G17: 875.66667 | H17: 629058.74 | I17: 239458.98 | J17: 2503 | K17: 1785632.5 | L17: 237798.97
B18: Región de Tarapacá | C18: PBS Invalidez | D18: 1388 | E18: 857547.8 | F18: 205943.28 | G18: 1171.6667 | H18: 723432.27 | I18: 205812.88 | J18: 2559.6667 | K18: 1580980.1 | L18: 205883.59
B19: Región de Tarapacá | C19: APS Invalidez | D19: 665.66667 | E19: 344895.56 | F19: 172706.84 | G19: 772 | H19: 374912.04 | I19: 161879.12 | J19: 1437.6667 | K19: 719807.6 | L19: 166892.56
B20: Región de Tarapacá | C20: Total2 | D20: 18322 | E20: 11296405 | F20: 205516.23 | G20: 14416.667 | H20: 8706656.5 | I20: 201309.98 | J20: 32738.667 | K20: 20003062 | L20: 203663.98
B21: Región de Antofagasta | C21: PGU No Contributiva1 | D21: 7025.6667 | E21: 4325277.1 | F21: 205213.13 | G21: 2213.6667 | H21: 1354141.7 | I21: 203906.29 | J21: 9239.3333 | K21: 5679418.8 | L21: 204900.02
B22: Región de Antofagasta | C22: PGU Contributiva1 | D22: 19999.333 | E22: 12149542 | F22: 202499.11 | G22: 16666.333 | H22: 9708162.6 | I22: 194167.14 | J22: 36665.667 | K22: 21857704 | L22: 198711.82
B23: Región de Antofagasta | C23: APS Vejez1 | D23: 2536.3333 | E23: 1791120.2 | F23: 235394.95 | G23: 1093 | H23: 791872.9 | I23: 241498.29 | J23: 3629.3333 | K23: 2582993.1 | L23: 237233.01
B24: Región de Antofagasta | C24: PBS Invalidez | D24: 2065.6667 | E24: 1275809.4 | F24: 205875.33 | G24: 1552 | H24: 958442.35 | I24: 205851.02 | J24: 3617.6667 | K24: 2234251.8 | L24: 205864.9
B25: Región de Antofagasta | C25: APS Invalidez | D25: 819 | E25: 416601.39 | F25: 169556.94 | G25: 856.33333 | H25: 418654.09 | I25: 162963.83 | J25: 1675.3333 | K25: 835255.48 | L25: 166186.92
B26: Región de Antofagasta | C26: Total2 | D26: 32446 | E26: 19958350 | F26: 205041.71 | G26: 22381.333 | H26: 13231274 | I26: 197058.17 | J26: 54827.333 | K26: 33189623 | L26: 201782.71
... B110: Total Nacional | C110: Total2 | D110: 1414116 | E110: 8.7016775e+08 | F110: 205114.66 | G110: 1011832.7 | H110: 6.1479987e+08 | I110: 202536.74 | J110: 2425948.7 | K110: 1.4849676e+09 | L110: 204039.44
B111: Fuente: Elaboración propia con datos de la Superintendencia de Pensiones
B112: 1 La Pensión Garantizada Universal (PGU) es un nuevo beneficio generado a partir de la ley 21.419 del 29-01-2022. El concepto de PGU No Contributiva o Contributiva está relacionado con la calidad de la persona que está recibiendo el beneficio, si es No Contributiva quiere decir que no estaba afiliado a un sistema previsional (D.L. 3.500 o antiguo Sistema de Reparto) ni recibe pensión de sobrevivencia, si es Contributiva quiere decir que sí estaba afiliado a un sistema previsional o que recibe una pensión de sobrevivencia. De manera automática, en febrero 2022, los PBS de Vejez pasaron a ser PGU No Contributiva y los APS Vejez Subsidio Definido, los Beneficio artículo 9° bis y los APS Vejez con una Pensión Final Garantizada inferior o igual al monto de la PGU pasaron a ser PGU Contributiva. En los casos en que el APS Vejez con una Pensión Final Garantizada tuviera un monto superior a la PGU, se mantuvo el pago del beneficio.
B113: 2 A diciembre de 2023 se encuentran vigentes 89.472 beneficios Ex PASIS de Vejez y 92.738 Ex PASIS de Invalidez. 3 Promedio mensual de beneficiarios en el trimestre. 4 Monto total pagado en el trimestre en pesos a diciembre de 2023. 5 Monto promedio mensual pagado por beneficiario en el trimestre, en pesos a diciembre de 2023.

Sheet 1.3
B2: PAGOS PENSIÓN GARANTIZADA UNIVERSAL (PGU)
B4: Resumen trimestral de beneficios pagados, por tipo de beneficio y sexo
B5: (octubre 2023 a diciembre 2023)
D7: PGU No Contributiva1 | G7: PGU Contributiva1 | J7: PGU Total1
B8: Periodo | C8: Sexo Beneficiarios | D8: N° beneficiarios | E8: Monto nominal (M$)2 | F8: Monto real (M$)3 | G8: N° beneficiarios | H8: Monto nominal (M$)2 | I8: Monto real (M$)3 | J8: N° beneficiarios | K8: Monto nominal (M$)2 | L8: Monto real (M$)3
B9: 45200 | C9: Mujeres | D9: 344866 | E9: 70556341 | F9: 70700999 | G9: 801418 | H9: 162703789 | I9: 1.6303737e+08 | J9: 1146284 | K9: 2.3326013e+08 | L9: 2.3373837e+08
C10: Hombres | D10: 139504 | E10: 28629001 | F10: 28687697 | G10: 670939 | H10: 1.3496986e+08 | I10: 1.3524659e+08 | J10: 810443 | K10: 1.6359887e+08 | L10: 1.6393428e+08
C11: Total | D11: 484370 | E11: 99185342 | F11: 99388697 | G11: 1472357 | H11: 2.9767365e+08 | I11: 2.9828396e+08 | J11: 1956727 | K11: 3.96859e+08 | L11: 3.9767266e+08
B12: 45231 | C12: Mujeres | D12: 343086 | E12: 70221852 | F12: 69844858 | G12: 810512 | H12: 1.6459531e+08 | I12: 1.6371166e+08 | J12: 1153598 | K12: 2.3481716e+08 | L12: 2.3355652e+08
C13: Hombres | D13: 139023 | E13: 28559853 | F13: 28406526 | G13: 678035 | H13: 1.3635304e+08 | I13: 1.3562101e+08 | J13: 817058 | K13: 1.6491289e+08 | L13: 1.6402754e+08
C14: Total | D14: 482109 | E14: 98781705 | F14: 98251384 | G14: 1488547 | H14: 3.0094835e+08 | I14: 2.9933267e+08 | J14: 1970656 | K14: 3.9973005e+08 | L14: 3.9758406e+08
B15: 45261 | C15: Mujeres | D15: 339811 | E15: 69796632 | F15: 69796632 | G15: 818807 | H15: 1.6633464e+08 | I15: 1.6633464e+08 | J15: 1158618 | K15: 2.3613127e+08 | L15: 2.3613127e+08
C16: Hombres | D16: 131135 | E16: 26987353 | F16: 26987353 | G16: 690945 | H16: 1.390067e+08 | I16: 1.390067e+08 | J16: 822080 | K16: 1.6599405e+08 | L16: 1.6599405e+08
C17: Total | D17: 470946 | E17: 96783985 | F17: 96783985 | G17: 1509752 | H17: 3.0534134e+08 | I17: 3.0534134e+08 | J17: 1980698 | K17: 4.0212532e+08 | L17: 4.0212532e+08
B18: Fuente: Elaboración propia con datos de la Superintendencia de Pensiones
B19: 1 La Pensión Garantizada Universal (PGU) es un nuevo beneficio generado a partir de la ley 21.419 del 29-01-2022. El concepto de PGU No Contributiva o Contributiva está relacionado con la calidad de la persona que está recibiendo el beneficio, si es No Contributiva quiere decir que no estaba afiliado a un sistema previsional (D.L. 3.500 o antiguo Sistema de Reparto) ni recibe pensión de sobrevivencia, si es Contributiva quiere decir que sí estaba afiliado a un sistema previsional o que recibe una pensión de sobrevivencia. De manera automática, en febrero 2022, los PBS de Vejez pasaron a ser PGU No Contributiva y los APS Vejez Subsidio Definido, los Beneficio artículo 9° bis y los APS Vejez con una Pensión Final Garantizada inferior o igual al monto de la PGU pasaron a ser PGU Contributiva. En los casos en que el APS Vejez con una Pensión Final Garantizada tuviera un monto superior a la PGU, se mantuvo el pago del beneficio.
B20: 2 Montos nominales de cada periodo de pago. 3 Montos deflactados a diciembre 2023
B23: Resumen anual de beneficios pagados, por tipo de beneficio y sexo
B24: (enero 2023 a diciembre 2023)
D26: PGU No Contributiva1 | G26: PGU Contributiva1 | J26: PGU Total1
B27: Periodo | C27: Sexo Beneficiarios | D27: N° promedio beneficiarios2 | E27: Monto nominal (M$)3 | F27: Monto real (M$)4 | G27: N° promedio beneficiarios2 | H27: Monto nominal (M$)3 | I27: Monto real (M$)4 | J27: N° promedio beneficiarios2 | K27: Monto nominal (M$)3 | L27: Monto real (M$)4
B28: Año 2023 | C28: Mujeres | D28: 338941.42 | E28: 8.2990264e+08 | F28: 8.4122591e+08 | G28: 777918.17 | H28: 1.8892604e+09 | I28: 1.9145926e+09 | J28: 1116859.6 | K28: 2.719163e+09 | L28: 2.7558185e+09
C29: Hombres | D29: 133932.08 | E29: 3.2881759e+08 | F29: 3.3325394e+08 | G29: 650208.25 | H29: 1.5652586e+09 | I29: 1.5862021e+09 | J29: 784140.33 | K29: 1.8940762e+09 | L29: 1.919456e+09
C30: Ambos | D30: 472873.5 | E30: 1.1587202e+09 | F30: 1.1744799e+09 | G30: 1428126.4 | H30: 3.454519e+09 | I30: 3.5007947e+09 | J30: 1900999.9 | K30: 4.6132392e+09 | L30: 4.6752746e+09
B31: Fuente: Elaboración propia con datos de la Superintendencia de Pensiones
B32: 1 La Pensión Garantizada Universal (PGU) es un nuevo beneficio generado a partir de la ley 21.419 del 29-01-2022. El concepto de PGU No Contributiva o Contributiva está relacionado con la calidad de la persona que está recibiendo el beneficio, si es No Contributiva quiere decir que no estaba afiliado a un sistema previsional (D.L. 3.500 o antiguo Sistema de Reparto) ni recibe pensión de sobrevivencia, si es Contributiva quiere decir que sí estaba afiliado a un sistema previsional o que recibe una pensión de sobrevivencia. De manera automática, en febrero 2022, los PBS de Vejez pasaron a ser PGU No Contributiva y los APS Vejez Subsidio Definido, los Beneficio artículo 9° bis y los APS Vejez con una Pensión Final Garantizada inferior o igual al monto de la PGU pasaron a ser PGU Contributiva. En los casos en que el APS Vejez con una Pensión Final Garantizada tuviera un monto superior a la PGU, se mantuvo el pago del beneficio.
B33: 2 Promedio mensual de beneficiarios del año.
B34: 3 Montos nominales de cada periodo de pago. 4 Montos deflactados a diciembre de 2023
B37: Serie resumen de pagos de beneficios acumulado, por tipo de beneficio y sexo
B38: (febrero 2022 a diciembre 2023)
C40: PGU No Contributiva1 | L40: PGU Contributiva1 | U40: PGU Total1
C41: Mujeres | F41: Hombres | I41: Total | L41: Mujeres | O41: Hombres | R41: Total | U41: Mujeres | X41: Hombres | AA41: Total
B42: Periodo | C42: N° Beneficiarios | D42: Monto real (M$)2 | E42: Monto nominal (M$)3 | F42: N° Beneficiarios | G42: Monto real (M$)2 | H42: Monto nominal (M$)3 | I42: N° Beneficiarios | J42: Monto real (M$)2 | K42: Monto nominal (M$)3 | L42: N° Beneficiarios | M42: Monto real (M$)2 | N42: Monto nominal (M$)3 | O42: N° Beneficiarios | P42: Monto real (M$)2 | Q42: Monto nominal (M$)3 | R42: N° Beneficiarios | S42: Monto real (M$)2 | T42: Monto nominal (M$)3 | U42: N° Beneficiarios | V42: Monto real (M$)2 | W42: Monto nominal (M$)3 | X42: N° Beneficiarios | Y42: Monto real (M$)2 | Z42: Monto nominal (M$)3 | AA42: N° Beneficiarios | AB42: Monto real (M$)2 | AC42: Monto nominal (M$)3
B43: 44593 | C43: 309683 | D43: 66071873 | E43: 57205361 | F43: 106066 | G43: 22657903 | H43: 19617327 | I43: 415749 | J43: 88729776 | K43: 76822687 | L43: 517361 | M43: 98264863 | N43: 85078214 | O43: 340110 | P43: 67340943 | Q43: 58304128 | R43: 857471 | S43: 1.6560581e+08 | T43: 1.4338234e+08 | U43: 827044 | V43: 1.6433674e+08 | W43: 1.4228357e+08 | X43: 446176 | Y43: 89998846 | Z43: 77921454 | AA43: 1273220 | AB43: 2.5433558e+08 | AC43: 2.2020503e+08
B44: 44621 | C44: 312946 | D44: 65445589 | E44: 57713942 | F44: 107255 | G44: 22494272 | H44: 19836831 | I44: 420201 | J44: 87939861 | K44: 77550774 | L44: 536699 | M44: 1.1234958e+08 | N44: 99076767 | O44: 361057 | P44: 75659092 | Q44: 66720837 | R44: 897756 | S44: 1.8800867e+08 | T44: 1.657976e+08 | U44: 849645 | V44: 1.7779517e+08 | W44: 1.5679071e+08 | X44: 468312 | Y44: 98153363 | Z44: 86557668 | AA44: 1317957 | AB44: 2.7594854e+08 | AC44: 2.4334838e+08
B45: 44652 | C45: 314601 | D45: 64815068 | E45: 57957137 | F45: 107763 | G45: 22288160 | H45: 19929902 | I45: 422364 | J45: 87103228 | K45: 77887039 | L45: 552501 | M45: 1.1398592e+08 | N45: 1.0192533e+08 | O45: 374925 | P45: 77506856 | Q45: 69306036 | R45: 927426 | S45: 1.9149277e+08 | T45: 1.7123137e+08 | U45: 867102 | V45: 1.7880098e+08 | W45: 1.5988247e+08 | X45: 482688 | Y45: 99795016 | Z45: 89235939 | AA45: 1349790 | AB45: 2.78596e+08 | AC45: 2.4911841e+08
B46: 44682 | C46: 316872 | D46: 64454475 | E46: 58325654 | F46: 108938 | G46: 22262224 | H46: 20145363 | I46: 425810 | J46: 86716699 | K46: 78471017 | L46: 605836 | M46: 1.234583e+08 | N46: 1.1171894e+08 | O46: 477591 | P46: 97574096 | Q46: 88296010 | R46: 1083427 | S46: 2.2103239e+08 | T46: 2.0001495e+08 | U46: 922708 | V46: 1.8791277e+08 | W46: 1.700446e+08 | X46: 586529 | Y46: 1.1983632e+08 | Z46: 1.0844137e+08 | AA46: 1509237 | AB46: 3.0774909e+08 | AC46: 2.7848597e+08
B47: 44713 | C47: 317138 | D47: 63890472 | E47: 58354483 | F47: 109221 | G47: 22113077 | H47: 20197021 | I47: 426359 | J47: 86003549 | K47: 78551504 | L47: 615086 | M47: 1.2413414e+08 | N47: 1.1337815e+08 | O47: 487043 | P47: 98585818 | Q47: 90043543 | R47: 1102129 | S47: 2.2271996e+08 | T47: 2.034217e+08 | U47: 932224 | V47: 1.8802461e+08 | W47: 1.7173264e+08 | X47: 596264 | Y47: 1.206989e+08 | Z47: 1.1024056e+08 | AA47: 1528488 | AB47: 3.0872351e+08 | AC47: 2.819732e+08
B48: 44743 | C48: 317824 | D48: 66204066 | E48: 61298892 | F48: 109691 | G48: 22962903 | H48: 21261541 | I48: 427515 | J48: 89166969 | K48: 82560433 | L48: 621791 | M48: 1.2976461e+08 | N48: 1.2015012e+08 | O48: 498271 | P48: 1.0429341e+08 | Q48: 96566129 | R48: 1120062 | S48: 2.3405802e+08 | T48: 2.1671625e+08 | U48: 939615 | V48: 1.9596867e+08 | W48: 1.8144901e+08 | X48: 607962 | Y48: 1.2725631e+08 | Z48: 1.1782767e+08 | AA48: 1547577 | AB48: 3.2322498e+08 | AC48: 2.9927668e+08
B49: 44774 | C49: 322017 | D49: 66260698 | E49: 62094245 | F49: 110018 | G49: 22754923 | H49: 21324100 | I49: 432035 | J49: 89015621 | K49: 83418344 | L49: 660104 | M49: 1.3569626e+08 | N49: 1.2716371e+08 | O49: 538150 | P49: 1.105357e+08 | Q49: 1.0358525e+08 | R49: 1198254 | S49: 2.4623196e+08 | T49: 2.3074897e+08 | U49: 982121 | V49: 2.0195695e+08 | W49: 1.8925796e+08 | X49: 648168 | Y49: 1.3329063e+08 | Z49: 1.2490935e+08 | AA49: 1630289 | AB49: 3.3524758e+08 | AC49: 3.1416731e+08
...

Sheet 1.4
B2: PAGOS PENSIÓN BÁSICA SOLIDARIA (PBS)
B4: Resumen trimestral de beneficios pagados, por tipo de beneficio y sexo
B5: (octubre 2023 a diciembre 2023)
D7: PBS Invalidez1
B8: Periodo | C8: Sexo Beneficiarios | D8: N° beneficiarios | E8: Monto nominal (M$)2 | F8: Monto real (M$)3
B9: 45200 | C9: Mujeres | D9: 107612 | E9: 22173725 | F9: 22219187
C10: Hombres | D10: 84447 | E10: 17401883 | F10: 17437561
C11: Total | D11: 192059 | E11: 39575608 | F11: 39656748
B12: 45231 | C12: Mujeres | D12: 107578 | E12: 22167675 | F12: 22048666
C13: Hombres | D13: 84680 | E13: 17450456 | F13: 17356771
C14: Total | D14: 192258 | E14: 39618131 | F14: 39405437
B15: 45261 | C15: Mujeres | D15: 107857 | E15: 22224555 | F15: 22224555
C16: Hombres | D16: 84948 | E16: 17505535 | F16: 17505535
C17: Total | D17: 192805 | E17: 39730090 | F17: 39730090
B18: Fuente: Elaboración propia con datos de la Superintendencia de Pensiones
B19: 1 De manera automática, en febrero 2022, los PBS de Vejez pasaron a ser PGU No Contributiva y los APS Vejez Subsidio Definido, los Beneficio artículo 9° bis y los APS Vejez con una Pensión Final Garantizada inferior o igual al monto de la PGU pasaron a ser PGU Contributiva. En los casos en que el APS Vejez con una Pensión Final Garantizada tuviera un monto superior a la PGU, se mantuvo el pago del beneficio.
B20: 2 Montos nominales de cada periodo de pago. 3 Montos deflactados a diciembre 2023
B22: Resumen anual de beneficios pagados, por tipo de beneficio y sexo
B23: (enero 2023 a diciembre 2023)
D25: PBS Invalidez1
B26: Periodo | C26: Sexo Beneficiarios | D26: N° promedio beneficiarios2 | E26: Monto nominal (M$)3 | F26: Monto real (M$)4
B27: Año 2023 | C27: Mujeres | D27: 106021.08 | E27: 2.6088347e+08 | F27: 2.6444117e+08
C28: Hombres | D28: 83341.5 | E28: 2.0508402e+08 | F28: 2.078794e+08
C29: Ambos | D29: 189362.58 | E29: 4.6596748e+08 | F29: 4.7232057e+08
B30: Fuente: Elaboración propia con datos de la Superintendencia de Pensiones
B31: 1 De manera automática, en febrero 2022, los PBS de Vejez pasaron a ser PGU No Contributiva y los APS Vejez Subsidio Definido, los Beneficio artículo 9° bis y los APS Vejez con una Pensión Final Garantizada inferior o igual al monto de la PGU pasaron a ser PGU Contributiva. En los casos en que el APS Vejez con una Pensión Final Garantizada tuviera un monto superior a la PGU, se mantuvo el pago del beneficio.
B32: 2 Promedio mensual de beneficiarios del año.
B33: 3 Montos nominales de cada periodo de pago. 4 Montos deflactados a diciembre de 2023
B35: Serie resumen de pagos de beneficios acumulado, por tipo de beneficio y sexo
B36: (julio 2008 a diciembre 2023)
C38: PBS Vejez1 | L38: PBS Invalidez | U38: PBS Total
C39: Mujeres | F39: Hombres | I39: Total | L39: Mujeres | O39: Hombres | R39: Total | U39: Mujeres | X39: Hombres | AA39: Total
B40: Periodo | C40: N° Beneficiarios | D40: Monto real (M$)2 | E40: Monto nominal (M$)3 | F40: N° Beneficiarios | G40: Monto real (M$)2 | H40: Monto nominal (M$)3 | I40: N° Beneficiarios | J40: Monto real (M$)2 | K40: Monto nominal (M$)3 | L40: N° Beneficiarios | M40: Monto real (M$)2 | N40: Monto nominal (M$)3 | O40: N° Beneficiarios | P40: Monto real (M$)2 | Q40: Monto nominal (M$)3 | R40: N° Beneficiarios | S40: Monto real (M$)2 | T40: Monto nominal (M$)3 | U40: N° Beneficiarios | V40: Monto real (M$)2 | W40: Monto nominal (M$)3 | X40: N° Beneficiarios | Y40: Monto real (M$)2 | Z40: Monto nominal (M$)3 | AA40: N° Beneficiarios | AB40: Monto real (M$)2 | AC40: Monto nominal (M$)3
B41: 39630 | C41: 189150 | D41: 20041126 | E41: 11349000 | F41: 101420 | G41: 10745815 | H41: 6085200 | I41: 290570 | J41: 30786941 | K41: 17434200 | L41: 108433 | M41: 11488868 | N41: 6505980 | O41: 84278 | P41: 8929558.5 | Q41: 5056680 | R41: 192711 | S41: 20418427 | T41: 11562660 | U41: 297583 | V41: 31529994 | W41: 17854980 | X41: 185698 | Y41: 19675374 | Z41: 11141880 | AA41: 483281 | AB41: 51205368 | AC41: 28996860
B42: 39661 | C42: 190466 | D42: 19994151 | E42: 11427960 | F42: 101671 | G42: 10672904 | H42: 6100260 | I42: 292137 | J42: 30667055 | K42: 17528220 | L42: 109472 | M42: 11491813 | N42: 6568320 | O42: 84832 | P42: 8905231.4 | Q42: 5089920 | R42: 194304 | S42: 20397045 | T42: 11658240 | U42: 299938 | V42: 31485964 | W42: 17996280 | X42: 186503 | Y42: 19578135 | Z42: 11190180 | AA42: 486441 | AB42: 51064099 | AC42: 29186460
B43: 39692 | C43: 221382 | D43: 22989937 | E43: 13279878 | F43: 108164 | G43: 11232891 | H43: 6488553 | I43: 329546 | J43: 34222828 | K43: 19768431 | L43: 108958 | M43: 11317593 | N43: 6537480 | O43: 84560 | P43: 8783344.4 | Q43: 5073600 | R43: 193518 | S43: 20100937 | T43: 11611080 | U43: 330340 | V43: 34307529 | W43: 19817358 | X43: 192724 | Y43: 20016235 | Z43: 11562153 | AA43: 523064 | AB43: 54323765 | AC43: 31379511
B44: 39722 | C44: 230808 | D44: 26126489 | E44: 15225060 | F44: 110075 | G44: 11870475 | H44: 6917450.4 | I44: 340883 | J44: 37996964 | K44: 22142510 | L44: 108604 | M44: 11226161 | N44: 6541980 | O44: 84437 | P44: 8741506.5 | Q44: 5094062.2 | R44: 193041 | S44: 19967667 | T44: 11636042 | U44: 339412 | V44: 37352650 | W44: 21767040 | X44: 194512 | Y44: 20611982 | Z44: 12011513 | AA44: 533924 | AB44: 57964631 | AC44: 33778552
B45: 39753 | C45: 236178 | D45: 26000633 | E45: 15133152 | F45: 111136 | G45: 11873996 | H45: 6911023.4 | I45: 347314 | J45: 37874629 | K45: 22044175 | L45: 108404 | M45: 11295498 | N45: 6574320 | O45: 84286 | P45: 8743350.3 | Q45: 5088893.3 | R45: 192690 | S45: 20038848 | T45: 11663213 | U45: 344582 | V45: 37296131 | W45: 21707472 | X45: 195422 | Y45: 20617346 | Z45: 11999917 | AA45: 540004 | AB45: 57913477 | AC45: 33707389
B46: 39783 | C46: 244815 | D46: 28100605 | E46: 16162567 | F46: 113630 | G46: 12700107 | H46: 7304694.3 | I46: 358445 | J46: 40800713 | K46: 23467261 | L46: 109628 | M46: 12277528 | N46: 7061640 | O46: 84823 | P46: 9240248.7 | Q46: 5314694.6 | R46: 194451 | S46: 21517776 | T46: 12376335 | U46: 354443 | V46: 40378133 | W46: 23224207 | X46: 198453 | Y46: 21940356 | Z46: 12619389 | AA46: 552896 | AB46: 62318489 | AC46: 35843596
B47: Promedio 2008 | C47: 218799.83 | D47: 23875490 | F47: 107682.67 | G47: 11516031 | I47: 326482.5 | J47: 35391522 | L47: 108916.5 | M47: 11516243 | O47: 84536 | P47: 8890540 | R47: 193452.5 | S47: 20406783 | U47: 327716.33 | V47: 35391733 | X47: 192218.67 | Y47: 20406571 | AA47: 519935 | AB47: 55798305
...

Sheet DINAMICA APS
A1: PERIODO | B1: (Varios elementos) | I1: PERIODO | J1: (Varios elementos) | O1: PERIODO | P1: (Varios elementos)
A3: Etiquetas de fila | B3: Suma de APS VEJEZ MUJER n | C3: Suma de APS VEJEZ HOMBRE n | D3: Suma de APS INVALIDEZ MUJER N | E3: Suma de APS INVALIDEZ HOMBRE N | F3: Suma de APS TOTAL MUJER N | G3: Suma de APS TOTAL HOMBRE N | I3: Etiquetas de fila | J3: Suma de APS VEJEZ MUJER nom | K3: Suma de APS VEJEZ HOMBRE nom | L3: Suma de APS INVALIDEZ MUJER nom | M3: Suma de APS INVALIDEZ HOMBRE nom | O3: Etiquetas de fila | P3: Suma de PBSV_MUJER REAL | Q3: Suma de PBSV_HOMBRE REAL | R3: Suma de PBSI_MUJER REAL | S3: Suma de PBSI_HOMBRE REAL
A4: 2022 | B4: 327413 | C4: 190531 | D4: 137530 | E4: 139864 | F4: 464943 | G4: 330395 | I4: 2022 | J4: 69469277 | K4: 40636216 | L4: 22985157 | M4: 22214073 | O4: 2022 | P4: 69114843 | Q4: 40428576 | R4: 22868011 | S4: 22101174
A5: oct | B5: 109393 | C5: 63815 | D5: 45739 | E5: 46381 | F5: 155132 | G5: 110196 | I5: oct | J5: 23196046 | K5: 13590242 | L5: 7659976.5 | M5: 7378442.3 | O5: oct | P5: 22907040 | Q5: 13420918 | R5: 7564538.8 | S5: 7286512.4
A6: nov | B6: 109031 | C6: 63526 | D6: 45910 | E6: 46666 | F6: 154941 | G6: 110192 | I6: nov | J6: 23133194 | K6: 13546987 | L6: 7675227.2 | M6: 7413824.5 | O6: nov | P6: 23067766 | Q6: 13508672 | R6: 7653519.1 | S6: 7392855.8
A7: dic | B7: 108989 | C7: 63190 | D7: 45881 | E7: 46817 | F7: 154870 | G7: 110007 | I7: dic | J7: 23140038 | K7: 13498987 | L7: 7649953.3 | M7: 7421805.9 | O7: dic | P7: 23140038 | Q7: 13498987 | R7: 7649953.3 | S7: 7421805.9
A11: PERIODO | B11: (Varios elementos)
A13: Etiquetas de fila | B13: Suma de APS VEJEZ MUJER n | C13: Suma de APS VEJEZ HOMBRE n | D13: Suma de APS INVALIDEZ MUJER N | E13: Suma de APS INVALIDEZ HOMBRE N | F13: Suma de APS TOTAL MUJER N | G13: Suma de APS TOTAL HOMBRE N
A14: 2022 | B14: 2017877 | C14: 1478761 | D14: 540602 | E14: 538156 | F14: 2558479 | G14: 2016917
A17: PERIODO | B17: (Varios elementos)
A19: Etiquetas de fila | B19: Promedio de APS VEJEZ MUJER n | C19: Promedio de APS VEJEZ HOMBRE n | D19: Promedio de APS INVALIDEZ MUJER N | E19: Promedio de APS INVALIDEZ HOMBRE N | F19: Promedio de APS TOTAL MUJER N | G19: Promedio de APS TOTAL HOMBRE N
A20: 2022 | B20: 168156.42 | C20: 123230.08 | D20: 45050.167 | E20: 44846.333 | F20: 213206.58 | G20: 168076.42
A23: PERIODO | B23: (Varios elementos)
A25: Etiquetas de fila | B25: Suma de APS VEJEZ MUJER nom | C25: Suma de APS VEJEZ HOMBRE nom | D25: Suma de APS INVALIDEZ MUJER nom | E25: Suma de APS INVALIDEZ HOMBRE nom | F25: Suma de APS TOTAL MUJER nom | G25: Suma de APS TOTAL HOMBRE nom
A26: 2022 | B26: 3.6244601e+08 | C26: 2.505165e+08 | D26: 89129737 | E26: 84667893 | F26: 4.5157575e+08 | G26: 3.3518439e+08
A29: PERIODO | B29: (Varios elementos)
A31: Etiquetas de fila | B31: Promedio de APS VEJEZ MUJER nom | C31: Promedio de APS VEJEZ HOMBRE nom | D31: Promedio de APS INVALIDEZ MUJER nom | E31: Promedio de APS INVALIDEZ HOMBRE nom | F31: Promedio de APS TOTAL MUJER nom | G31: Promedio de APS TOTAL HOMBRE nom
A32: 2022 | B32: 30203834 | C32: 20876375 | D32: 7427478.1 | E32: 7055657.8 | F32: 37631312 | G32: 27932033
A35: PERIODO | B35: (Varios elementos)
A37: Etiquetas de fila | B37: Suma de PBSV_MUJER REAL | C37: Suma de PBSV_HOMBRE REAL | D37: Suma de PBSI_MUJER REAL | E37: Suma de PBSI_HOMBRE REAL
A38: 2022 | B38: 3.4085177e+08 | C38: 2.344632e+08 | D38: 85046490 | E38: 80830616
A42: PERIODO | B42: (Varios elementos)
A44: Etiquetas de fila | B44: Promedio de PBSV_MUJER REAL | C44: Promedio de PBSV_HOMBRE REAL | D44: Promedio de PBSI_MUJER REAL | E44: Promedio de PBSI_HOMBRE REAL
A45: 2022 | B45: 28404314 | C45: 19538600 | D45: 7087207.5 | E45: 6735884.7
A51: Etiquetas de fila | B51: Promedio de APS VEJEZ MUJER n | C51: Promedio de APS VEJEZ HOMBRE n | D51: Promedio de APS INVALIDEZ MUJER N | E51: Promedio de APS INVALIDEZ HOMBRE N
A52: 2008 | B52: 2920.6667 | C52: 1116 | D52: 286.33333 | E52: 290.33333
A53: 2009 | B53: 35080.083 | C53: 24939.75 | D53: 2213.8333 | E53: 1769.75
A54: 2010 | B54: 184671.58 | C54: 128661.83 | D54: 8050.9167 | E54: 5922.9167
A55: 2011 | B55: 232153.67 | C55: 168868.75 | D55: 12883.083 | E55: 9283.4167
A56: 2012 | B56: 279628 | C56: 203893.75 | D56: 19231.417 | E56: 14584.75
A57: 2013 | B57: 327092.08 | C57: 237763.33 | D57: 26607.083 | E57: 21058.833
A58: 2014 | B58: 354831.83 | C58: 258135.42 | D58: 33075.25 | E58: 26998.167
A59: 2015 | B59: 385388.58 | C59: 279293.17 | D59: 35497.583 | E59: 29292.083
A60: 2016 | B60: 409696.25 | C60: 297461.08 | D60: 35477.75 | E60: 29444.667
A61: 2017 | B61: 434014.42 | C61: 315115.08 | D61: 35236.417 | E61: 29440.417
A62: 2018 | B62: 472783.58 | C62: 343894.42 | D62: 35802.167 | E62: 30349.5
A63: 2019 | B63: 513930.5 | C63: 376625 | D63: 36751.75 | E63: 31642.25
... A90: dic | B90: 108989 | C90: 63190 | D90: 45881 | E90: 46817
A94: Etiquetas de fila | B94: Promedio de PBSV_MUJER REAL | C94: Promedio de PBSV_HOMBRE REAL | D94: Promedio de PBSI_MUJER REAL | E94: Promedio de PBSI_HOMBRE REAL
A95: 2008 | B95: 156325.61 | C95: 77435.604 | D95: 15483.202 | E95: 15243.679
...

Sheet 1.5
B2: PAGOS APORTE PREVISIONAL SOLIDARIO (APS)
B4: Resumen trimestral de beneficios pagados, por tipo de beneficio y sexo
B5: (octubre 2023 a diciembre 2023)
D7: APS Vejez1 | G7: APS Invalidez | J7: APS Total
B8: Periodo | C8: Sexo Beneficiarios | D8: N° beneficiarios | E8: Monto nominal (M$)2 | F8: Monto real (M$)3 | G8: N° beneficiarios | H8: Monto nominal (M$)2 | I8: Monto real (M$)3 | J8: N° beneficiarios | K8: Monto nominal (M$)2 | L8: Monto real (M$)3
B9: 45200 | C9: Mujeres | D9: 106548 | E9: 25173158 | F9: 25224769 | G9: 47288 | H9: 8347977.7 | I9: 8365093.1 | J9: 153836 | K9: 33521136 | L9: 33589862
C10: Hombres | D10: 60882 | E10: 14578037 | F10: 14607926 | G10: 49876 | H10: 8352880.7 | I10: 8370006.2 | J10: 110758 | K10: 22930918 | L10: 22977932
C11: Total | D11: 167430 | E11: 39751195 | F11: 39832695 | G11: 97164 | H11: 16700858 | I11: 16735099 | J11: 264594 | K11: 56452054 | L11: 56567794
B12: 45231 | C12: Mujeres | D12: 106386 | E12: 25126472 | F12: 24991578 | G12: 47294 | H12: 8334109.4 | I12: 8289366.8 | J12: 153680 | K12: 33460582 | L12: 33280945
C13: Hombres | D13: 60624 | E13: 14517267 | F13: 14439329 | G13: 49989 | H13: 8356257.6 | I13: 8311396.1 | J13: 110613 | K13: 22873525 | L13: 22750726
C14: Total | D14: 167010 | E14: 39643740 | F14: 39430908 | G14: 97283 | H14: 16690367 | I14: 16600763 | J14: 264293 | K14: 56334107 | L14: 56031670
B15: 45261 | C15: Mujeres | D15: 105880 | E15: 25039244 | F15: 25039244 | G15: 47405 | H15: 8339131.6 | I15: 8339131.6 | J15: 153285 | K15: 33378376 | L15: 33378376
C16: Hombres | D16: 60307 | E16: 14450349 | F16: 14450349 | G16: 50164 | H16: 8365112.5 | I16: 8365112.5 | J16: 110471 | K16: 22815462 | L16: 22815462
C17: Total | D17: 166187 | E17: 39489594 | F17: 39489594 | G17: 97569 | H17: 16704244 | I17: 16704244 | J17: 263756 | K17: 56193838 | L17: 56193838
B18: Fuente: Elaboración propia con datos de la Superintendencia de Pensiones
B19: 1 La Pensión Garantizada Universal (PGU) es un nuevo beneficio generado a partir de la ley 21.419 del 29-01-2022. El concepto de PGU No Contributiva o Contributiva está relacionado con la calidad de la persona que está recibiendo el beneficio, si es No Contributiva quiere decir que no estaba afiliado a un sistema previsional (D.L. 3.500 o antiguo Sistema de Reparto) ni recibe pensión de sobrevivencia, si es Contributiva quiere decir que sí estaba afiliado a un sistema previsional o que recibe una pensión de sobrevivencia. De manera automática, en febrero 2022, los PBS de Vejez pasaron a ser PGU No Contributiva y los APS Vejez Subsidio Definido, los Beneficio artículo 9° bis y los APS Vejez con una Pensión Final Garantizada inferior o igual al monto de la PGU pasaron a ser PGU Contributiva. En los casos en que el APS Vejez con una Pensión Final Garantizada tuviera un monto superior a la PGU, se mantuvo el pago del beneficio.
B20: 2 Montos nominales de cada periodo de pago. 3 Montos deflactados a diciembre 2023
B23: Resumen anual de beneficios pagados, por tipo de beneficio y sexo
B24: (enero 2023 a diciembre 2023)
D26: APS Vejez1 | G26: APS Invalidez | J26: APS Total
B27: Periodo | C27: Sexo Beneficiarios | D27: N° promedio beneficiarios2 | E27: Monto nominal (M$)3 | F27: Monto real (M$)4 | G27: N° promedio beneficiarios2 | H27: Monto nominal (M$)3 | I27: Monto real (M$)4 | J27: N° promedio beneficiarios2 | K27: Monto nominal (M$)3 | L27: Monto real (M$)4
B28: Año 2023 | C28: Mujeres | D28: 107656.58 | E28: 2.9213166e+08 | F28: 2.9607842e+08 | G28: 46872.083 | H28: 99131586 | I28: 1.0048947e+08 | J28: 154528.67 | K28: 3.9126324e+08 | L28: 3.965679e+08
C29: Hombres | D29: 61733.75 | E29: 1.693076e+08 | F29: 1.7159906e+08 | G29: 48903.25 | H29: 98307682 | I29: 99645254 | J29: 110637 | K29: 2.6761529e+08 | L29: 2.7124432e+08
C30: Ambos | D30: 169390.33 | E30: 4.6143926e+08 | F30: 4.6767749e+08 | G30: 95775.333 | H30: 1.9743927e+08 | I30: 2.0013473e+08 | J30: 265165.67 | K30: 6.5887853e+08 | L30: 6.6781221e+08
B31: Fuente: Elaboración propia con datos de la Superintendencia de Pensiones
B32: 1 La Pensión Garantizada Universal (PGU) es un nuevo beneficio generado a partir de la ley 21.419 del 29-01-2022. El concepto de PGU No Contributiva o Contributiva está relacionado con la calidad de la persona que está recibiendo el beneficio, si es No Contributiva quiere decir que no estaba afiliado a un sistema previsional (D.L. 3.500 o antiguo Sistema de Reparto) ni recibe pensión de sobrevivencia, si es Contributiva quiere decir que sí estaba afiliado a un sistema previsional o que recibe una pensión de sobrevivencia. De manera automática, en febrero 2022, los PBS de Vejez pasaron a ser PGU No Contributiva y los APS Vejez Subsidio Definido, los Beneficio artículo 9° bis y los APS Vejez con una Pensión Final Garantizada inferior o igual al monto de la PGU pasaron a ser PGU Contributiva. En los casos en que el APS Vejez con una Pensión Final Garantizada tuviera un monto superior a la PGU, se mantuvo el pago del beneficio.
B33: 2 Promedio mensual de beneficiarios del año. 3 Montos nominales de cada periodo de pago. 4 Montos deflactados a diciembre de 2023
B35: Serie resumen de pagos de beneficios acumulado, por tipo de beneficio y sexo
B36: (julio 2008 a diciembre 2023)
C38: APS Vejez1 | L38: APS Invalidez | U38: APS Total
C39: Mujeres | F39: Hombres | I39: Total | L39: Mujeres | O39: Hombres | R39: Total | U39: Mujeres | X39: Hombres | AA39: Total
B40: Periodo | C40: N° beneficiarios | D40: Monto real (M$)2 | E40: Monto nominal (M$)3 | F40: N° beneficiarios | G40: Monto real (M$)2 | H40: Monto nominal (M$)3 | I40: N° beneficiarios | J40: Monto real (M$)2 | K40: Monto nominal (M$)3 | L40: N° beneficiarios | M40: Monto real (M$)2 | N40: Monto nominal (M$)3 | O40: N° beneficiarios | P40: Monto real (M$)2 | Q40: Monto nominal (M$)3 | R40: N° beneficiarios | S40: Monto real (M$)2 | T40: Monto nominal (M$)3 | U40: N° beneficiarios | V40: Monto real (M$)2 | W40: Monto nominal (M$)3 | X40: N° beneficiarios | Y40: Monto real (M$)2 | Z40: Monto nominal (M$)3 | AA40: N° beneficiarios | AB40: Monto real (M$)2 | AC40: Monto nominal (M$)3
B41: 39630
B42: 39661
B43: 39692
B44: 39722 | C44: 2444 | D44: 661617.79 | E44: 385553.92 | F44: 955 | G44: 328952.74 | H44: 191695.3 | I44: 3399 | J44: 990570.52 | K44: 577249.22 | L44: 217 | M44: 60623.75 | N44: 35328.138 | O44: 229 | P44: 61644.746 | Q44: 35923.118 | R44: 446 | S44: 122268.5 | T44: 71251.256 | U44: 2661 | V44: 722241.53 | W44: 420882.06 | X44: 1184 | Y44: 390597.48 | Z44: 227618.42 | AA44: 3845 | AB44: 1112839 | AC44: 648500.47
B45: 39753 | C45: 3067 | D45: 331542.96 | E45: 192967.99 | F45: 1159 | G45: 147164.32 | H45: 85654.067 | I45: 4226 | J45: 478707.27 | K45: 278622.06 | L45: 290 | M45: 35257.199 | N45: 20520.752 | O45: 294 | P45: 33737.621 | Q45: 19636.312 | R45: 584 | S45: 68994.82 | T45: 40157.064 | U45: 3357 | V45: 366800.15 | W45: 213488.74 | X45: 1453 | Y45: 180901.94 | Z45: 105290.38 | AA45: 4810 | AB45: 547702.09 | AC45: 318779.12
B46: 39783 | C46: 3251 | D46: 345230.11 | E46: 198565.28 | F46: 1234 | G46: 187229.61 | H46: 107688.46 | I46: 4485 | J46: 532459.72 | K46: 306253.75 | L46: 352 | M46: 36751.403 | N46: 21138.228 | O46: 348 | P46: 35169.618 | Q46: 20228.436 | R46: 700 | S46: 71921.021 | T46: 41366.664 | U46: 3603 | V46: 381981.51 | W46: 219703.51 | X46: 1582 | Y46: 222399.23 | Z46: 127916.9 | AA46: 5185 | AB46: 604380.74 | AC46: 347620.41
B47: Promedio 2008 | C47: 2920.6667 | D47: 446130.28 | F47: 1116 | G47: 221115.55 | I47: 4036.6667 | J47: 667245.84 | L47: 286.33333 | M47: 44210.784 | O47: 290.33333 | P47: 43517.328 | R47: 576.66667 | S47: 87728.112 | U47: 3207 | V47: 490341.07 | X47: 1406.3333 | Y47: 264632.88 | AA47: 4613.3333 | AB47: 754973.95
B48: 39814 | C48: 4434 | D48: 677232.43 | E48: 386551.68 | F48: 1765 | G48: 341440.14 | H48: 194887.69 | I48: 6199 | J48: 1018672.6 | K48: 581439.38 | L48: 468 | M48: 66643.201 | N48: 38038.701 | O48: 481 | P48: 76540.473 | Q48: 43687.88 | R48: 949 | S48: 143183.67 | T48: 81726.581 | U48: 4902 | V48: 743875.63 | W48: 424590.39 | X48: 2246 | Y48: 417980.62 | Z48: 238575.57 | AA48: 7148 | AB48: 1161856.2 | AC48: 663165.96
...

Sheet Hoja2
A3: -> region_codigo | B3: = | C3: 1
C5: estado_solicitud
A6: comuna | B6: A | C6: C | D6: D | E6: R | F6: T | G6: Total
A8: ALTO HOSPICIO | B8: 32 | C8: 8631 | D8: 1 | E8: 1938 | F8: 329 | G8: 10931
A9: CAMIÑA | B9: 0 | C9: 192 | D9: 0 | E9: 38 | F9: 4 | G9: 234
A10: COLCHANE | B10: 2 | C10: 137 | D10: 0 | E10: 25 | F10: 3 | G10: 167
A11: HUARA | B11: 6 | C11: 476 | D11: 1 | E11: 103 | F11: 14 | G11: 600
