Workbook

Sheet datos
A2: Mes | B2: Diciembre de 2018

Sheet Índice
B1: Subsecretaría de Previsión Social Dirección de Estudios Previsionales
B5: Informe Estadístico Mensual del Pilar Solidario
B7: Introducción
B8: El presente archivo contiene los principales cuadros del Informe Estadístico Mensual del Pilar Solidario del mes de Diciembre de 2021. Correspondiente a:
B10: Estadísticas del Sistema de Pensiones Solidarias
B11: Estadísticas del Bono por Hijo (BxH)
B12: Estadísticas del Subsidio Previsional a los Trabajadores Jóvenes (STJ)

Sheet Índice Pensiones Solidarias
A2: Subsecretaría de Previsión Social
A3: Dirección de Estudios Previsionales
B5: Sistema de Pensiones Solidarias | N5: Volver a Índice
B7: Introducción
B8: El presente archivo contiene los principales cuadros sobre el Sistema de Pensiones Solidarias del Informe Estadístico Mensual del Pilar Solidario del mes diciembre de 2021. Los cuadros entregan información de los beneficios solicitados y concedidos mensualmente a nivel nacional, desde julio de 2008 a diciembre de 2021, asi como también la información de las solicitudes y concesiones a nivel regional y comunal acumulado a diciembre de 2021.
B11: Este archivo contiene información al 28 de enero de 2022.
B13: Nacional
B14: Solicitudes recibidas en el Sistema de Pensiones Solidarias, según mes, desde julio 2008 a diciembre 2021
B15: Concesiones en el Sistema de Pensiones Solidarias, por mes, desde julio 2008 a diciembre 2021
B17: Regional
B18: Solicitudes recibidas en el Sistema de Pensiones Solidarias acumuladas desde julio 2008 a diciembre 2021, según región
B19: Concesiones en el Sistema de Pensiones Solidarias acumuladas desde julio 2008 a diciembre 2021, según región
B21: Solicitudes y Concesiones en el Sistema de Pensiones Solidarias acumulado a diciembre 2021 por región y comuna:
B22: XV Arica y Parinacota
B23: I Tarapaca
... B37: XIII Metropolitana

Sheet Solicitudes Nacional
A2: Subsecretaría de Previsión Social
A3: Dirección de Estudios Previsionales
B5: Número de solicitudes mensuales recibidas en el Sistema de Pensiones Solidarias, según tipo de beneficio, sexo y origen de tramitación del beneficio | S5: Volver Sistema de Pensiones Solidarias
B6: Julio de 2008 a diciembre de 2021
B8: TOTAL SOLICITUDES (no incluye ex Pasis)
B9: PERIODO | C9: TOTAL PBS Y APS | L9: SEXO | N9: ORIGEN DE TRAMITACIÓN DEL BENEFICIO
C10: PBSV | D10: PBSI | E10: TOTAL PBS | F10: APSV | G10: APSI | H10: TOTAL APS | I10: Total PBS + APS | J10: Nbis | K10: Total PBS + APS + Nbis | L10: Femenino | M10: Masculino | N10: En IPS | O10: En AFP | P10: En Cías. de Seguro | Q10: En Municipio | R10: C. Web
B11: Jul a Dic 2008 | C11: 84576 | D11: 37258 | E11: 121834 | F11: 12800 | G11: 6052 | H11: 18852 | I11: 140686 | J11: 0 | K11: 140686 | L11: 108633 | M11: 32053 | N11: 96799 | O11: 1029 | P11: 0 | Q11: 42858 | R11: 0
B12: Total 2009 | C12: 59319 | D12: 35533 | E12: 94852 | F12: 298185 | G12: 11725 | H12: 309910 | I12: 404762 | J12: 0 | K12: 404762 | L12: 256315 | M12: 148447 | N12: 300173 | O12: 30362 | P12: 0 | Q12: 74227 | R12: 0
B13: Total 2010 | C13: 40738 | D13: 24967 | E13: 65705 | F13: 168077 | G13: 11931 | H13: 180008 | I13: 245713 | J13: 0 | K13: 245713 | L13: 152809 | M13: 92904 | N13: 148067 | O13: 32918 | P13: 5334 | Q13: 59394 | R13: 0
B14: Total 2011 | C14: 37423 | D14: 20938 | E14: 58361 | F14: 126076 | G14: 10368 | H14: 136444 | I14: 194805 | J14: 0 | K14: 194805 | L14: 123383 | M14: 71422 | N14: 114406 | O14: 25990 | P14: 11383 | Q14: 43026 | R14: 0
B15: Total 2012 | C15: 34194 | D15: 19594 | E15: 53788 | F15: 130347 | G15: 8226 | H15: 138573 | I15: 192361 | J15: 0 | K15: 192361 | L15: 118837 | M15: 73524 | N15: 126931 | O15: 24058 | P15: 9228 | Q15: 32144 | R15: 0
B16: Total 2013 | C16: 32773 | D16: 17032 | E16: 49805 | F16: 76994 | G16: 7295 | H16: 84289 | I16: 134094 | J16: 0 | K16: 134094 | L16: 82092 | M16: 52002 | N16: 83802 | O16: 22686 | P16: 6357 | Q16: 21249 | R16: 0
B17: Total 2014 | C17: 39393 | D17: 17573 | E17: 56966 | F17: 88545 | G17: 6054 | H17: 94599 | I17: 151565 | J17: 0 | K17: 151565 | L17: 92858 | M17: 58707 | N17: 94144 | O17: 27044 | P17: 6542 | Q17: 23835 | R17: 0
B18: Total 2015 | C18: 31043 | D18: 18557 | E18: 49600 | F18: 88878 | G18: 2501 | H18: 91379 | I18: 140979 | J18: 0 | K18: 140979 | L18: 86238 | M18: 54741 | N18: 84140 | O18: 29604 | P18: 5381 | Q18: 21854 | R18: 0
B19: Total 2016 | C19: 27624 | D19: 18094 | E19: 45718 | F19: 85022 | G19: 2577 | H19: 87599 | I19: 133317 | J19: 0 | K19: 133317 | L19: 82738 | M19: 50579 | N19: 78827 | O19: 29016 | P19: 4531 | Q19: 20905 | R19: 38
B20: Total 2017 | C20: 27467 | D20: 18335 | E20: 45802 | F20: 100168 | G20: 3167 | H20: 103335 | I20: 149137 | J20: 0 | K20: 149137 | L20: 89906 | M20: 59231 | N20: 87059 | O20: 34398 | P20: 4540 | Q20: 22825 | R20: 315
B21: Total 2018 | C21: 27800 | D21: 16994 | E21: 44793 | F21: 120070 | G21: 6272 | H21: 126343 | I21: 171136 | J21: 0 | K21: 171136 | L21: 102497 | M21: 68639 | N21: 98969 | O21: 43515 | P21: 4876 | Q21: 22926 | R21: 850
B22: Enero'19 | C22: 2413 | D22: 1462 | E22: 3875 | F22: 9943 | G22: 565 | H22: 10508 | I22: 14383 | J22: 0 | K22: 14383 | L22: 8587 | M22: 5796 | N22: 8023 | O22: 4044 | P22: 339 | Q22: 1910 | R22: 67
... B61: TOTAL | C61: 533327 | D61: 303579 | E61: 836905 | F61: 1750371 | G61: 110404 | H61: 1860776 | I61: 2697681 | J61: 953 | K61: 2698634 | L61: 1670611 | M61: 1028023 | N61: 1608386 | O61: 473886 | P61: 77608 | Q61: 450200 | R61: 88554
B62: Fuente: Elaboración propia sobre la base de información del IPS.

Sheet Concesiones Nacional
A2: Subsecretaría de Previsión Social
A3: Dirección de Estudios Previsionales
B5: Número de beneficios concedidos mensuales en el Sistema de Pensiones Solidarias, según tipo de beneficio, sexo y origen de tramitación del beneficio | S5: Volver Sistema de Pensiones Solidarias
B6: ='Solicitudes Nacional'!B6:Q6 -> Julio de 2008 a diciembre de 2021
B8: TOTAL CONCEDIDAS (no incluye ex Pasis)
B9: MES | C9: TOTAL PBS Y APS | L9: SEXO | N9: ORIGEN DE TRAMITACIÓN DEL BENEFICIO
C10: PBSV | D10: PBSI | E10: TOTAL PBS | F10: APSV | G10: APSI | H10: TOTAL APS | I10: Total PBS+APS | J10: Nbis | K10: Total PBS + APS + Nbis | L10: Femenino | M10: Masculino | N10: En IPS | O10: En AFP | P10: En Cías. de Seguro | Q10: En Municipio | R10: C. Web
B11: Jul a Dic 2008 | C11: 83731 | D11: 21440 | E11: 105171 | F11: 9486 | G11: 1541 | H11: 11027 | I11: 116198 | J11: 0 | K11: 116198 | L11: 89477 | M11: 26721 | N11: 78766 | O11: 988 | P11: 0 | Q11: 36444 | R11: 0
B12: Total 2009 | C12: 57975 | D12: 21272 | E12: 79247 | F12: 277144 | G12: 9873 | H12: 287017 | I12: 366264 | J12: 0 | K12: 366264 | L12: 225377 | M12: 140887 | N12: 273407 | O12: 26670 | P12: 0 | Q12: 66187 | R12: 0
B13: Total 2010 | C13: 36125 | D13: 13245 | E13: 49370 | F13: 137904 | G13: 9915 | H13: 147819 | I13: 197189 | J13: 0 | K13: 197189 | L13: 119677 | M13: 77512 | N13: 120976 | O13: 25694 | P13: 3837 | Q13: 46682 | R13: 0
B14: Total 2011 | C14: 29976 | D14: 10364 | E14: 40340 | F14: 90271 | G14: 8697 | H14: 98968 | I14: 139308 | J14: 0 | K14: 139308 | L14: 84838 | M14: 54470 | N14: 81472 | O14: 19161 | P14: 8015 | Q14: 30660 | R14: 0
B15: Total 2012 | C15: 29369 | D15: 10380 | E15: 39749 | F15: 113369 | G15: 7014 | H15: 120383 | I15: 160132 | J15: 0 | K15: 160132 | L15: 95754 | M15: 64378 | N15: 106541 | O15: 20848 | P15: 7850 | Q15: 24893 | R15: 0
B16: Total 2013 | C16: 29479 | D16: 9014 | E16: 38493 | F16: 65567 | G16: 6048 | H16: 71615 | I16: 110108 | J16: 0 | K16: 110108 | L16: 65748 | M16: 44360 | N16: 68722 | O16: 19387 | P16: 5326 | Q16: 16673 | R16: 0
B17: Total 2014 | C17: 32567 | D17: 9988 | E17: 42555 | F17: 70060 | G17: 5270 | H17: 75330 | I17: 117885 | J17: 0 | K17: 117885 | L17: 70004 | M17: 47881 | N17: 72035 | O17: 22552 | P17: 5134 | Q17: 18164 | R17: 0
B18: Total 2015 | C18: 26363 | D18: 11711 | E18: 38074 | F18: 71190 | G18: 2081 | H18: 73271 | I18: 111345 | J18: 0 | K18: 111345 | L18: 65990 | M18: 45355 | N18: 65223 | O18: 24957 | P18: 4304 | Q18: 16861 | R18: 0
B19: Total 2016 | C19: 22256 | D19: 11810 | E19: 34066 | F19: 65772 | G19: 2218 | H19: 67990 | I19: 102056 | J19: 0 | K19: 102056 | L19: 61350 | M19: 40706 | N19: 59376 | O19: 23640 | P19: 3451 | Q19: 15560 | R19: 29
B20: Total 2017 | C20: 21991 | D20: 11910 | E20: 33901 | F20: 79386 | G20: 2802 | H20: 82188 | I20: 116089 | J20: 0 | K20: 116089 | L20: 67429 | M20: 48660 | N20: 66296 | O20: 28517 | P20: 3602 | Q20: 17423 | R20: 251
B21: Total 2018 | C21: 24873 | D21: 10989 | E21: 35862 | F21: 108927 | G21: 5864 | H21: 114791 | I21: 150653 | J21: 0 | K21: 150653 | L21: 87284 | M21: 63369 | N21: 85791 | O21: 40174 | P21: 4487 | Q21: 19524 | R21: 677
B22: Enero' 19 | C22: 2170 | D22: 954 | E22: 3124 | F22: 9048 | G22: 518 | H22: 9566 | I22: 12690 | J22: 0 | K22: 12690 | L22: 7291 | M22: 5399 | N22: 6946 | O22: 3744 | P22: 306 | Q22: 1640 | R22: 54
... B61: TOTAL | C61: 471813 | D61: 173449 | E61: 645262 | F61: 1491522 | G61: 92867 | H61: 1584389 | I61: 2229651 | J61: 34 | K61: 2229685 | L61: 1337442 | M61: 892243 | N61: 1323786 | O61: 409687 | P61: 63581 | Q61: 361471 | R61: 71160
B62: Fuente: Elaboración propia sobre la base de información del IPS.
B63: Nota: La información estadística reportada del número de solicitudes concesionadas, en trámite, rechazadas y anuladas varía mes a mes por actualización de cifras.
B64: El número de beneficios concesionados no coincide con el número de beneficios pagados por las siguientes razones: •El total acumulado de concesiones de la Reforma Previsional incluye personas fallecidas: El número de personas fallecidas que recibían PBS y APS durante el año 2019 correspondió a: 65.759 El número de personas fallecidas desde julio de 2008 a diciembre 2018 correspondió a: 519.562 •Existen personas a quienes se les ha extinguido o suspendido el beneficio. •El mes de concedida la pensión no necesariamente coincide con el primer mes de pago. Nbis: Beneficio que se incorpora con la Ley N°21.190 para los pensionados por Retiro Programado con Pensión Base mayor a la PMAS, y que cumplen con los requisitos exigidos por ley que acceden a un complemento que aseguro que, ante la baja de los pagos del retiro programado, la pensión final no descienda del valor de una Pensión Básica Solidaria.

Sheet Solicitudes Regiones
A2: Subsecretaría de Previsión Social
A3: Dirección de Estudios Previsionales
B5: Número de solicitudes del Sistema de Pensiones Solidarias según región, tipo de beneficio, sexo y origen de tramitación del beneficio | T5: Volver Sistema de Pensiones Solidarias
B6: Acumuladas de julio de 2008 a diciembre de 2021
B8: TOTAL SOLICITUDES (no incluye ex Pasis)
B9: REGIÓN | C9: TOTAL PBS Y APS | K9: TOTAL | M9: SEXO | O9: ORIGEN DE TRAMITACIÓN DEL BENEFICIO
C10: PBSV | D10: PBSI | E10: TOTAL PBS | F10: APSV | G10: APSI | H10: TOTAL APS | I10: Total PBS + APS | J10: Nbis | K10: Total PBS+APS+Nbis | L10: % de Concesiones | M10: Femenino | N10: Masculino | O10: En IPS | P10: En AFP | Q10: En Cías. de Seguro | R10: En Municipio | S10: C. Web
B11: ARICA Y PARINACOTA | C11: 6332 | D11: 2944 | E11: 9276 | F11: 22732 | G11: 1260 | H11: 23992 | I11: 33268 | J11: 22 | K11: 33290 | L11: 0.012335871 | M11: 19758 | N11: 13532 | O11: 19144 | P11: 6914 | Q11: 1098 | R11: 5172 | S11: 962
B12: TARAPACA | C12: 6544 | D12: 4917 | E12: 11461 | F12: 24801 | G12: 2060 | H12: 26861 | I12: 38322 | J12: 17 | K12: 38339 | L12: 0.014206817 | M12: 23413 | N12: 14926 | O12: 21769 | P12: 6164 | Q12: 1476 | R12: 7532 | S12: 1398
B13: ANTOFAGASTA | C13: 12836 | D13: 6278 | E13: 19114 | F13: 42364 | G13: 2342 | H13: 44706 | I13: 63820 | J13: 36 | K13: 63856 | L13: 0.023662342 | M13: 41662 | N13: 22194 | O13: 43593 | P13: 9894 | Q13: 944 | R13: 7194 | S13: 2231
B14: ATACAMA | C14: 8205 | D14: 4214 | E14: 12419 | F14: 27338 | G14: 1538 | H14: 28876 | I14: 41295 | J14: 31 | K14: 41326 | L14: 0.015313674 | M14: 25265 | N14: 16061 | O14: 24473 | P14: 7765 | Q14: 1192 | R14: 6846 | S14: 1050
B15: COQUIMBO | C15: 24051 | D15: 11581 | E15: 35632 | F15: 80724 | G15: 4462 | H15: 85186 | I15: 120818 | J15: 65 | K15: 120883 | L15: 0.044794144 | M15: 73986 | N15: 46897 | O15: 86403 | P15: 18261 | Q15: 1903 | R15: 11159 | S15: 3155
B16: VALPARAISO | C16: 58556 | D16: 29625 | E16: 88181 | F16: 218279 | G16: 13326 | H16: 231605 | I16: 319786 | J16: 117 | K16: 319903 | L16: 0.11854257 | M16: 200070 | N16: 119833 | O16: 196112 | P16: 62875 | Q16: 7789 | R16: 42754 | S16: 10373
B17: L. G. B. OHIGGINS | C17: 27998 | D17: 17394 | E17: 45392 | F17: 102359 | G17: 7543 | H17: 109902 | I17: 155294 | J17: 34 | K17: 155328 | L17: 0.057558009 | M17: 92828 | N17: 62500 | O17: 88347 | P17: 25511 | Q17: 3906 | R17: 33987 | S17: 3577
B18: MAULE | C18: 38101 | D18: 22635 | E18: 60736 | F18: 119508 | G18: 8269 | H18: 127777 | I18: 188513 | J18: 50 | K18: 188563 | L18: 0.069873499 | M18: 109683 | N18: 78880 | O18: 110054 | P18: 36165 | Q18: 5148 | R18: 33370 | S18: 3825
B19: ÑUBLE | C19: 19864 | D19: 23935 | E19: 43799 | F19: 54822 | G19: 6187 | H19: 61009 | I19: 104808 | J19: 32 | K19: 104840 | L19: 0.038849284 | M19: 63846 | N19: 40994 | O19: 60697 | P19: 17423 | Q19: 2093 | R19: 24627 | S19: 0
B20: BIO-BIO | C20: 51960 | D20: 38734 | E20: 90694 | F20: 165167 | G20: 11072 | H20: 176239 | I20: 266933 | J20: 89 | K20: 267022 | L20: 0.098947097 | M20: 166849 | N20: 100173 | O20: 157538 | P20: 43599 | Q20: 8491 | R20: 57394 | S20: 0
B21: LA ARAUCANIA | C21: 41520 | D21: 26753 | E21: 68273 | F21: 93514 | G21: 6734 | H21: 100248 | I21: 168521 | J21: 40 | K21: 168561 | L21: 0.062461601 | M21: 101475 | N21: 67086 | O21: 108561 | P21: 28746 | Q21: 4427 | R21: 23235 | S21: 3592
B22: LOS RIOS | C22: 14590 | D22: 10102 | E22: 24692 | F22: 42275 | G22: 4195 | H22: 46470 | I22: 71162 | J22: 28 | K22: 71190 | L22: 0.026380013 | M22: 42847 | N22: 28343 | O22: 48970 | P22: 13786 | Q22: 2209 | R22: 4727 | S22: 1496
... B27: Totales | C27: 533327 | D27: 303579 | E27: 836906 | F27: 1750371 | G27: 110404 | H27: 1860775 | I27: 2697681 | J27: 953 | K27: 2698634 | L27: 1 | M27: 1670609 | N27: 1028025 | O27: 1616457 | P27: 473889 | Q27: 77626 | R27: 450214 | S27: 80443
B28: Participación sobre el total | C28: =+C27/$K$27 -> 0.1976285 | D28: =+D27/$K$27 -> 0.11249358 | F28: =+F27/$K$27 -> 0.64861371 | G28: =+G27/$K$27 -> 0.040911068 | K28: =C28+D28+F28+G28 -> 0.99964686 | M28: =+M27/$K$27 -> 0.61905727 | N28: =+N27/$K$27 -> 0.38094273 | O28: =+O27/$K$27 -> 0.59899082 | P28: =+P27/$K$27 -> 0.17560329 | Q28: =+Q27/$K$27 -> 0.028764923 | R28: =+R27/$K$27 -> 0.16683033 | S28: =+S27/$K$27 -> 0.029808785
B29: Fuente: Elaboración propia sobre la base de información del IPS.
B30: Nota: La información estadística reportada del número de solicitudes concesionadas, en trámite, rechazadas y anuladas varía mes a mes por actualización de cifras.

Sheet Concesiones Regiones
A2: Subsecretaría de Previsión Social
A3: Dirección de Estudios Previsionales
B5: Número de concesiones del Sistema de Pensiones Solidarias según región, tipo de beneficio, sexo y origen de tramitación del beneficio | T5: Volver Sistema de Pensiones Solidarias
B6: ='Solicitudes Regiones'!B6:R6 -> Acumuladas de julio de 2008 a diciembre de 2021
B8: TOTAL CONCEDIDAS (no incluye ex Pasis)
B9: REGIÓN | C9: TOTAL PBS Y APS | K9: TOTAL | M9: SEXO | O9: ORIGEN DE TRAMITACIÓN DEL BENEFICIO
C10: PBSV | D10: PBSI | E10: TOTAL PBS | F10: APSV | G10: APSI | H10: TOTAL APS | I10: Total PBS + APS | J10: Nbis | K10: Total PBS+APS+Nbis | L10: % de Concesiones | M10: Femenino | N10: Masculino | O10: En IPS | P10: En AFP | Q10: En Cías. de Seguro | R10: En Municipio | S10: C. Web
B11: ARICA Y PARINACOTA | C11: 5677 | D11: 2054 | E11: 7731 | F11: 19573 | G11: 1069 | H11: 20642 | I11: 28373 | J11: 0 | K11: 28373 | L11: 0.012725116 | M11: 16545 | N11: 11828 | O11: 16280 | P11: 5979 | Q11: 920 | R11: 4457 | S11: 737
B12: TARAPACA | C12: 5518 | D12: 2920 | E12: 8438 | F12: 20167 | G12: 1645 | H12: 21812 | I12: 30250 | J12: 1 | K12: 30251 | L12: 0.013567387 | M12: 17892 | N12: 12359 | O12: 17273 | P12: 5151 | Q12: 1181 | R12: 5621 | S12: 1025
B13: ANTOFAGASTA | C13: 10281 | D13: 3797 | E13: 14078 | F13: 34090 | G13: 1894 | H13: 35984 | I13: 50062 | J13: 1 | K13: 50063 | L13: 0.022452947 | M13: 31608 | N13: 18455 | O13: 33852 | P13: 7934 | Q13: 781 | R13: 5881 | S13: 1615
B14: ATACAMA | C14: 7025 | D14: 2652 | E14: 9677 | F14: 23169 | G14: 1263 | H14: 24432 | I14: 34109 | J14: 0 | K14: 34109 | L14: 0.015297677 | M14: 20194 | N14: 13915 | O14: 19882 | P14: 6694 | Q14: 930 | R14: 5788 | S14: 815
B15: COQUIMBO | C15: 20933 | D15: 7227 | E15: 28160 | F15: 68554 | G15: 3897 | H15: 72451 | I15: 100611 | J15: 4 | K15: 100615 | L15: 0.045125208 | M15: 59390 | N15: 41225 | O15: 71660 | P15: 15855 | Q15: 1486 | R15: 9056 | S15: 2558
B16: VALPARAISO | C16: 51226 | D16: 18893 | E16: 70119 | F16: 182607 | G16: 11158 | H16: 193765 | I16: 263884 | J16: 4 | K16: 263888 | L16: 0.11835214 | M16: 160662 | N16: 103225 | O16: 159832 | P16: 53640 | Q16: 6302 | R16: 35788 | S16: 8326
B17: L. G. B. OHIGGINS | C17: 24283 | D17: 9148 | E17: 33431 | F17: 87625 | G17: 6335 | H17: 93960 | I17: 127391 | J17: 1 | K17: 127392 | L17: 0.057134528 | M17: 72891 | N17: 54501 | O17: 72203 | P17: 22184 | Q17: 3239 | R17: 26961 | S17: 2805
B18: MAULE | C18: 34382 | D18: 12432 | E18: 46814 | F18: 104584 | G18: 6875 | H18: 111459 | I18: 158273 | J18: 2 | K18: 158275 | L18: 0.070985363 | M18: 88937 | N18: 69338 | O18: 92388 | P18: 32245 | Q18: 4254 | R18: 26274 | S18: 3114
B19: ÑUBLE | C19: 18091 | D19: 10523 | E19: 28614 | F19: 48136 | G19: 5387 | H19: 53523 | I19: 82137 | J19: 0 | K19: 82137 | L19: 0.036837939 | M19: 46784 | N19: 35353 | O19: 48470 | P19: 15658 | Q19: 1792 | R19: 16217 | S19: 0
B20: BIO-BIO | C20: 45607 | D20: 19268 | E20: 64875 | F20: 139929 | G20: 9279 | H20: 149208 | I20: 214083 | J20: 3 | K20: 214086 | L20: 0.096016253 | M20: 127178 | N20: 86908 | O20: 127366 | P20: 37123 | Q20: 6847 | R20: 42750 | S20: 0
B21: LA ARAUCANIA | C21: 38003 | D21: 12680 | E21: 50683 | F21: 80830 | G21: 5727 | H21: 86557 | I21: 137240 | J21: 2 | K21: 137242 | L21: 0.061552192 | M21: 78699 | N21: 58543 | O21: 87903 | P21: 25439 | Q21: 3483 | R21: 17633 | S21: 2784
B22: LOS RIOS | C22: 13379 | D22: 6838 | E22: 20217 | F22: 36425 | G22: 3650 | H22: 40075 | I22: 60292 | J22: 1 | K22: 60293 | L22: 0.027041039 | M22: 35184 | N22: 25109 | O22: 41178 | P22: 12139 | Q22: 1807 | R22: 3960 | S22: 1209
... B27: Totales | C27: 471813 | D27: 173449 | E27: 645262 | F27: 1491522 | G27: 92867 | H27: 1584389 | I27: 2229651 | J27: 34 | K27: 2229685 | L27: 1 | M27: 1337440 | N27: 892244 | O27: 1330099 | P27: 409687 | Q27: 63581 | R27: 361471 | S27: 64847
B28: Participación sobre el total | C28: =+C27/$K$27 -> 0.21160523 | D28: =+D27/$K$27 -> 0.077790809 | F28: =+F27/$K$27 -> 0.66893844 | G28: =+G27/$K$27 -> 0.041650278 | K28: =C28+D28+F28+G28 -> 0.99998475 | M28: =+M27/$K$27 -> 0.59983361 | N28: =+N27/$K$27 -> 0.40016594 | O28: =+O27/$K$27 -> 0.59654122 | P28: =+P27/$K$27 -> 0.1837421 | Q28: =+Q27/$K$27 -> 0.028515687 | R28: =+R27/$K$27 -> 0.16211752 | S28: =+S27/$K$27 -> 0.02908348
B29: Fuente: Elaboración propia sobre la base de información del IPS.
B30: Nota: La información estadística reportada del número de solicitudes concesionadas, en trámite, rechazadas y anuladas varía mes a mes por actualización de cifras.

Sheet XV
A2: Subsecretaría de Previsión Social
A3: Dirección de Estudios Previsionales
B5: Número de Solicitudes de Beneficios del Pilar Solidario según tipo de beneficio - XV Región de Arica y Parinacota | M5: Volver Sistema de Pensiones Solidadias
B6: ='Solicitudes Regiones'!$B$6:$R$6 -> Acumuladas de julio de 2008 a diciembre de 2021
B8: Distribución Regional Solicitudes del Pilar Solidario - no incluye ex Pasis
B9: COMUNA | C9: TOTAL PBS Y APS
C10: PBSV | D10: PBSI | E10: Total PBS | F10: % PBS | G10: APSV | H10: APSI | I10: Total APS | J10: %APS | K10: Total PBS+APS | L10: Nbis | M10: Total PBS+APS+Nbis
B11: ARICA | C11: 6173 | D11: 2873 | E11: =C11+D11 -> 9046 | F11: =E11/$E$15 -> 0.97520483 | G11: 22551 | H11: 1257 | I11: =G11+H11 -> 23808 | J11: =I11/$I$15 -> 0.99233078 | K11: =E11+I11 -> 32854 | L11: 22 | M11: =K11+L11 -> 32876
B12: CAMARONES | C12: 29 | D12: 10 | E12: =C12+D12 -> 39 | F12: =E12/$E$15 -> 0.0042043984 | G12: 47 | H12: 1 | I12: =G12+H12 -> 48 | J12: =I12/$I$15 -> 0.0020006669 | K12: =E12+I12 -> 87 | L12: 0 | M12: =K12+L12 -> 87
B13: PUTRE | C13: 91 | D13: 41 | E13: =C13+D13 -> 132 | F13: =E13/$E$15 -> 0.014230272 | G13: 116 | H13: 2 | I13: =G13+H13 -> 118 | J13: =I13/$I$15 -> 0.0049183061 | K13: =E13+I13 -> 250 | L13: 0 | M13: =K13+L13 -> 250
B14: GENERAL LAGOS | C14: 39 | D14: 20 | E14: =C14+D14 -> 59 | F14: =E14/$E$15 -> 0.0063605002 | G14: 18 | H14: 0 | I14: =G14+H14 -> 18 | J14: =I14/$I$15 -> 0.00075025008 | K14: =E14+I14 -> 77 | L14: 0 | M14: =K14+L14 -> 77
B15: Totales | C15: =SUM(C11:C14) -> 6332 | D15: =SUM(D11:D14) -> 2944 | E15: =C15+D15 -> 9276 | F15: =E15/$E$15 -> 1 | G15: =SUM(G11:G14) -> 22732 | H15: =SUM(H11:H14) -> 1260 | I15: =G15+H15 -> 23992 | J15: =I15/$I$15 -> 1 | K15: =E15+I15 -> 33268 | L15: =SUM(L11:L14) -> 22 | M15: =SUM(M11:M14) -> 33290
B16: % respecto del total de solicitudes | C16: =+C15/$M$15 -> 0.19020727 | D16: =+D15/$M$15 -> 0.088434965 | E16: =+E15/$M$15 -> 0.27864223 | G16: =+G15/$K$15 -> 0.68329927 | H16: =+H15/$M$15 -> 0.037849204 | I16: =+I15/$M$15 -> 0.72069691 | K16: =E16+I16 -> 0.99933914 | L16: =+L15/M15 -> 0.00066085912 | M16: =K16+L16 -> 1
B19: Número de Concesiones de Beneficios del Pilar Solidario según tipo de beneficio - XV Región de Arica y Parinacota
B20: ='Solicitudes Regiones'!$B$6:$R$6 -> Acumuladas de julio de 2008 a diciembre de 2021
B22: Concesiones del Pilar Solidario a nivel comunal
B23: COMUNA | C23: TOTAL PBS Y APS
C24: PBSV | D24: PBSI | E24: Total PBS | F24: % PBS | G24: APSV | H24: APSI | I24: Total APS | J24: %APS | K24: Total PBS+APS | L24: Nbis | M24: Total PBS+APS+Nbis
B25: ARICA | C25: 5537 | D25: 2025 | E25: 7562 | F25: =E25/$E$29 -> 0.97813996 | G25: 19419 | H25: 1066 | I25: 20485 | J25: =I25/$I$29 -> 0.99239415 | K25: 28047 | L25: 0 | M25: =K25+L25 -> 28047
B26: CAMARONES | C26: 26 | D26: 4 | E26: 30 | F26: =E26/$E$29 -> 0.0038804812 | G26: 43 | H26: 1 | I26: =G26+H26 -> 44 | J26: =I26/$I$29 -> 0.0021315764 | K26: =E26+I26 -> 74 | L26: 0 | M26: =K26+L26 -> 74
B27: PUTRE | C27: 81 | D27: 18 | E27: 99 | F27: =E27/$E$29 -> 0.012805588 | G27: 96 | H27: 2 | I27: =G27+H27 -> 98 | J27: =I27/$I$29 -> 0.004747602 | K27: =E27+I27 -> 197 | L27: 0 | M27: =K27+L27 -> 197
B28: GENERAL LAGOS | C28: 33 | D28: 7 | E28: 40 | F28: =E28/$E$29 -> 0.0051739749 | G28: 15 | H28: 0 | I28: =G28+H28 -> 15 | J28: =I28/$I$29 -> 0.00072667377 | K28: =E28+I28 -> 55 | L28: 0 | M28: =K28+L28 -> 55
B29: Totales | C29: =SUM(C25:C28) -> 5677 | D29: =SUM(D25:D28) -> 2054 | E29: 7731 | F29: =E29/$E$29 -> 1 | G29: =SUM(G25:G28) -> 19573 | H29: 1069 | I29: =G29+H29 -> 20642 | J29: =I29/$I$29 -> 1 | K29: =E29+I29 -> 28373 | L29: =SUM(L25:L28) -> 0 | M29: =SUM(M25:M28) -> 28373
B30: % respecto del total de concesiones | C30: =+C29/M29 -> 0.20008459 | D30: =+D29/M29 -> 0.072392768 | E30: =+E29/M29 -> 0.27247736 | G30: =+G29/M29 -> 0.68984598 | H30: =+H29/M29 -> 0.037676664 | I30: =+I29/M29 -> 0.72752264 | K30: =+K29/M29 -> 1 | L30: =+L29/M29 -> 0 | M30: =K30+L30 -> 1
B31: Fuente: Elaboración propia sobre la base de información del IPS.
B32: Nota: La información estadística reportada del número de solicitudes concesionadas, en trámite, rechazadas y anuladas varía mes a mes por actualización de cifras.

Sheet I
A2: Subsecretaría de Previsión Social
A3: Dirección de Estudios Previsionales
B5: Número de Solicitudes de Beneficios del Pilar Solidario según tipo de beneficio - I Región de Tarapacá | M5: Volver Sistema de Pensiones Solidadias
B6: ='Solicitudes Regiones'!$B$6:$R$6 -> Acumuladas de julio de 2008 a diciembre de 2021
B8: Distribución Regional Solicitudes del Pilar Solidario - no incluye ex Pasis
B9: COMUNA | C9: TOTAL PBS Y APS
C10: PBSV | D10: PBSI | E10: Total PBS | F10: % PBS | G10: APSV | H10: APSI | I10: Total APS | J10: %APS | K10: Total PBS+APS | L10: Nbis | M10: Total PBS+APS+Nbis
B11: IQUIQUE | C11: 4439 | D11: 2769 | E11: =C11+D11 -> 7208 | F11: =E11/$E$18 -> 0.62891545 | G11: 17789 | H11: 1248 | I11: =G11+H11 -> 19037 | J11: =I11/$I$18 -> 0.70872268 | K11: =E11+I11 -> 26245 | L11: 17 | M11: =K11+L11 -> 26262
B12: ALTO HOSPICIO | C12: 1357 | D12: 1678 | E12: =C12+D12 -> 3035 | F12: =E12/$E$18 -> 0.2648111 | G12: 5057 | H12: 662 | I12: =G12+H12 -> 5719 | J12: =I12/$I$18 -> 0.21291091 | K12: =E12+I12 -> 8754 | L12: 0 | M12: =K12+L12 -> 8754
B13: POZO ALMONTE | C13: 320 | D13: 201 | E13: =C13+D13 -> 521 | F13: =E13/$E$18 -> 0.045458511 | G13: 1004 | H13: 80 | I13: =G13+H13 -> 1084 | J13: =I13/$I$18 -> 0.040355906 | K13: =E13+I13 -> 1605 | L13: 0 | M13: =K13+L13 -> 1605
B14: CAMIÑA | C14: 62 | D14: 43 | E14: =C14+D14 -> 105 | F14: =E14/$E$18 -> 0.0091615042 | G14: 83 | H14: 11 | I14: =G14+H14 -> 94 | J14: =I14/$I$18 -> 0.0034994974 | K14: =E14+I14 -> 199 | L14: 0 | M14: =K14+L14 -> 199
B15: COLCHANE | C15: 60 | D15: 36 | E15: =C15+D15 -> 96 | F15: =E15/$E$18 -> 0.0083762324 | G15: 45 | H15: 5 | I15: =G15+H15 -> 50 | J15: =I15/$I$18 -> 0.0018614348 | K15: =E15+I15 -> 146 | L15: 0 | M15: =K15+L15 -> 146
B16: HUARA | C16: 119 | D16: 88 | E16: =C16+D16 -> 207 | F16: =E16/$E$18 -> 0.018061251 | G16: 277 | H16: 23 | I16: =G16+H16 -> 300 | J16: =I16/$I$18 -> 0.011168609 | K16: =E16+I16 -> 507 | L16: 0 | M16: =K16+L16 -> 507
B17: PICA | C17: 187 | D17: 102 | E17: =C17+D17 -> 289 | F17: =E17/$E$18 -> 0.02521595 | G17: 546 | H17: 31 | I17: =G17+H17 -> 577 | J17: =I17/$I$18 -> 0.021480958 | K17: =E17+I17 -> 866 | L17: 0 | M17: =K17+L17 -> 866
B18: Totales | C18: =SUM(C11:C17) -> 6544 | D18: =SUM(D11:D17) -> 4917 | E18: =C18+D18 -> 11461 | F18: =E18/$E$18 -> 1 | G18: =SUM(G11:G17) -> 24801 | H18: =SUM(H11:H17) -> 2060 | I18: =G18+H18 -> 26861 | J18: =I18/$I$18 -> 1 | K18: =SUM(K11:K17) -> 38322 | L18: =SUM(L11:L17) -> 17 | M18: =K18+L18 -> 38339
B19: % respecto del total de solicitudes | C19: =+C18/M18 -> 0.17068781 | D19: =+D18/M18 -> 0.12825061 | E19: =+E18/M18 -> 0.29893842 | G19: =+G18/M18 -> 0.64688698 | H19: =+H18/M18 -> 0.053731188 | I19: =+I18/M18 -> 0.70061817 | K19: =+K18/M18 -> 0.99955659 | L19: =+L18/M18 -> 0.00044341271 | M19: =K19+L19 -> 1
B21: Número de Concesiones de Beneficios del Pilar Solidario según tipo de beneficio - I Región de Tarapacá
B22: ='Solicitudes Regiones'!$B$6:$R$6 -> Acumuladas de julio de 2008 a diciembre de 2021
B24: Concesiones del Pilar Solidario a nivel comunal
B25: COMUNA | C25: TOTAL PBS Y APS
C26: PBSV | D26: PBSI | E26: Total PBS | F26: % PBS | G26: APSV | H26: APSI | I26: Total APS | J26: %APS | K26: Total PBS+APS | L26: Nbis | M26: Total PBS+APS+Nbis
B27: IQUIQUE | C27: 3704 | D27: 1678 | E27: =C27+D27 -> 5382 | F27: =E27/$E$18 -> 0.46959253 | G27: 14236 | H27: 987 | I27: =G27+H27 -> 15223 | J27: =I27/$I$18 -> 0.56673244 | K27: =E27+I27 -> 20605 | L27: 1 | M27: =K27+L27 -> 20606
B28: ALTO HOSPICIO | C28: 1175 | D28: 990 | E28: =C28+D28 -> 2165 | F28: =E28/$E$18 -> 0.18890149 | G28: 4313 | H28: 537 | I28: =G28+H28 -> 4850 | J28: =I28/$I$18 -> 0.18055918 | K28: =E28+I28 -> 7015 | L28: 0 | M28: =K28+L28 -> 7015
B29: POZO ALMONTE | C29: 264 | D29: 104 | E29: =C29+D29 -> 368 | F29: =E29/$E$18 -> 0.032108891 | G29: 813 | H29: 63 | I29: =G29+H29 -> 876 | J29: =I29/$I$18 -> 0.032612338 | K29: =E29+I29 -> 1244 | L29: 0 | M29: =K29+L29 -> 1244
B30: CAMIÑA | C30: 59 | D30: 23 | E30: =C30+D30 -> 82 | F30: =E30/$E$18 -> 0.0071546985 | G30: 74 | H30: 9 | I30: =G30+H30 -> 83 | J30: =I30/$I$18 -> 0.0030899818 | K30: =E30+I30 -> 165 | L30: 0 | M30: =K30+L30 -> 165
B31: COLCHANE | C31: 56 | D31: 19 | E31: =C31+D31 -> 75 | F31: =E31/$E$18 -> 0.0065439316 | G31: 41 | H31: 5 | I31: =G31+H31 -> 46 | J31: =I31/$I$18 -> 0.00171252 | K31: =E31+I31 -> 121 | L31: 0 | M31: =K31+L31 -> 121
B32: HUARA | C32: 106 | D32: 46 | E32: =C32+D32 -> 152 | F32: =E32/$E$18 -> 0.013262368 | G32: 235 | H32: 23 | I32: =G32+H32 -> 258 | J32: =I32/$I$18 -> 0.0096050035 | K32: =E32+I32 -> 410 | L32: 0 | M32: =K32+L32 -> 410
B33: PICA | C33: 154 | D33: 60 | E33: =C33+D33 -> 214 | F33: =E33/$E$18 -> 0.018672018 | G33: 455 | H33: 21 | I33: =G33+H33 -> 476 | J33: =I33/$I$18 -> 0.017720859 | K33: =E33+I33 -> 690 | L33: 0 | M33: =K33+L33 -> 690
B34: Totales | C34: =SUM(C27:C33) -> 5518 | D34: =SUM(D27:D33) -> 2920 | E34: =C34+D34 -> 8438 | F34: =E34/$E$18 -> 0.73623593 | G34: =SUM(G27:G33) -> 20167 | H34: =SUM(H27:H33) -> 1645 | I34: =G34+H34 -> 21812 | J34: =I34/$I$18 -> 0.81203231 | K34: =SUM(K27:K33) -> 30250 | L34: =SUM(L27:L33) -> 1 | M34: =K34+L34 -> 30251
B35: % respecto del total de concesiones | C35: =+C34/M34 -> 0.18240719 | D35: =+D34/M34 -> 0.096525735 | E35: =+E34/M34 -> 0.27893293 | G35: =+G34/M34 -> 0.66665565 | H35: =+H34/M34 -> 0.054378368 | I35: =+I34/M34 -> 0.72103402 | K35: =+K34/M34 -> 0.99996694 | L35: =+L34/M34 -> 3.3056758e-05 | M35: =K35+L35 -> 1
B36: Fuente: Elaboración propia sobre la base de información del IPS.
B37: Nota: La información estadística reportada del número de solicitudes concesionadas, en trámite, rechazadas y anuladas varía mes a mes por actualización de cifras.

Sheet II
A2: Subsecretaría de Previsión Social
A3: Dirección de Estudios Previsionales
B5: Número de Solicitudes de Beneficios del Pilar Solidario según tipo de beneficio - II Región de Antofagasta | M5: Volver Sistema de Pensiones Solidadias
B6: ='Solicitudes Regiones'!$B$6:$R$6 -> Acumuladas de julio de 2008 a diciembre de 2021
B8: Distribución Regional Solicitudes del Pilar Solidario - no incluye ex Pasis
B9: COMUNA | C9: TOTAL PBS Y APS
C10: PBSV | D10: PBSI | E10: Total PBS | F10: % PBS | G10: APSV | H10: APSI | I10: Total APS | J10: %APS | K10: Total PBS+APS | L10: Nbis | M10: Total PBS+APS+Nbis
B11: ANTOFAGASTA | C11: 7832 | D11: 3974 | E11: =C11+D11 -> 11806 | F11: =E11/$E$20 -> 0.61766245 | G11: 27639 | H11: 1597 | I11: =G11+H11 -> 29236 | J11: =I11/$I$20 -> 0.65396144 | K11: =E11+I11 -> 41042 | L11: 31 | M11: =K11+L11 -> 41073
B12: MEJILLONES | C12: 241 | D12: 99 | E12: =C12+D12 -> 340 | F12: =E12/$E$20 -> 0.017788009 | G12: 821 | H12: 34 | I12: =G12+H12 -> 855 | J12: =I12/$I$20 -> 0.01912495 | K12: =E12+I12 -> 1195 | L12: 0 | M12: =K12+L12 -> 1195
B13: SIERRA GORDA | C13: 23 | D13: 13 | E13: =C13+D13 -> 36 | F13: =E13/$E$20 -> 0.0018834362 | G13: 55 | H13: 5 | I13: =G13+H13 -> 60 | J13: =I13/$I$20 -> 0.0013421017 | K13: =E13+I13 -> 96 | L13: 0 | M13: =K13+L13 -> 96
B14: TALTAL | C14: 379 | D14: 311 | E14: =C14+D14 -> 690 | F14: =E14/$E$20 -> 0.036099194 | G14: 1299 | H14: 69 | I14: =G14+H14 -> 1368 | J14: =I14/$I$20 -> 0.030599919 | K14: =E14+I14 -> 2058 | L14: 1 | M14: =K14+L14 -> 2059
B15: CALAMA | C15: 3204 | D15: 1248 | E15: =C15+D15 -> 4452 | F15: =E15/$E$20 -> 0.23291828 | G15: 9026 | H15: 466 | I15: =G15+H15 -> 9492 | J15: =I15/$I$20 -> 0.21232049 | K15: =E15+I15 -> 13944 | L15: 1 | M15: =K15+L15 -> 13945
B16: OLLAGUE | C16: 16 | D16: 1 | E16: =C16+D16 -> 17 | F16: =E16/$E$20 -> 0.00088940044 | G16: 18 | H16: 0 | I16: =G16+H16 -> 18 | J16: =I16/$I$20 -> 0.00040263052 | K16: =E16+I16 -> 35 | L16: 0 | M16: =K16+L16 -> 35
B17: SAN PEDRO DE ATACAMA | C17: 188 | D17: 54 | E17: =C17+D17 -> 242 | F17: =E17/$E$20 -> 0.012660877 | G17: 412 | H17: 15 | I17: =G17+H17 -> 427 | J17: =I17/$I$20 -> 0.0095512907 | K17: =E17+I17 -> 669 | L17: 0 | M17: =K17+L17 -> 669
B18: TOCOPILLA | C18: 861 | D18: 547 | E18: =C18+D18 -> 1408 | F18: =E18/$E$20 -> 0.073663283 | G18: 2848 | H18: 148 | I18: =G18+H18 -> 2996 | J18: =I18/$I$20 -> 0.067015613 | K18: =E18+I18 -> 4404 | L18: 3 | M18: =K18+L18 -> 4407
B19: MARIA ELENA | C19: 92 | D19: 31 | E19: =C19+D19 -> 123 | F19: =E19/$E$20 -> 0.0064350738 | G19: 246 | H19: 8 | I19: =G19+H19 -> 254 | J19: =I19/$I$20 -> 0.005681564 | K19: =E19+I19 -> 377 | L19: 0 | M19: =K19+L19 -> 377
B20: Totales | C20: =SUM(C11:C19) -> 12836 | D20: =SUM(D11:D19) -> 6278 | E20: =C20+D20 -> 19114 | F20: =E20/$E$20 -> 1 | G20: =SUM(G11:G19) -> 42364 | H20: =SUM(H11:H19) -> 2342 | I20: =G20+H20 -> 44706 | J20: =I20/$I$20 -> 1 | K20: =E20+I20 -> 63820 | L20: =SUM(L11:L19) -> 36 | M20: =K20+L20 -> 63856
B21: % respecto del total de solicitudes | C21: =+C20/M20 -> 0.20101478 | D21: =+D20/M20 -> 0.098314959 | E21: =+E20/M20 -> 0.29932974 | G21: =+G20/M20 -> 0.66343022 | H21: =+H20/M20 -> 0.036676272 | I21: =+I20/M20 -> 0.70010649 | K21: =+K20/M20 -> 0.99943623 | L21: =+L20/M20 -> 0.00056376848 | M21: =K21+L21 -> 1
B23: Número de Concesiones de Beneficios del Pilar Solidario según tipo de beneficio - II Región de Antofagasta
B24: ='Solicitudes Regiones'!$B$6:$R$6 -> Acumuladas de julio de 2008 a diciembre de 2021
B26: Concesiones del Pilar Solidario a nivel comunal
B27: COMUNA | C27: TOTAL PBS Y APS
C28: PBSV | D28: PBSI | E28: Total PBS | F28: % PBS | G28: APSV | H28: APSI | I28: Total APS | J28: %APS | K28: Total PBS+APS | L28: Nbis | M28: Total PBS+APS+Nbis
B29: ANTOFAGASTA | C29: 6306 | D29: 2431 | E29: =D29+C29 -> 8737 | F29: =E29/$E$38 -> 0.62061372 | G29: 22240 | H29: 1305 | I29: =G29+H29 -> 23545 | J29: =I29/$I$38 -> 0.65431859 | K29: =E29+I29 -> 32282 | L29: 1 | M29: =K29+L29 -> 32283
B30: MEJILLONES | C30: 175 | D30: 50 | E30: =D30+C30 -> 225 | F30: =E30/$E$38 -> 0.015982384 | G30: 635 | H30: 28 | I30: =G30+H30 -> 663 | J30: =I30/$I$38 -> 0.018424855 | K30: =E30+I30 -> 888 | L30: 0 | M30: =K30+L30 -> 888
B31: SIERRA GORDA | C31: 20 | D31: 8 | E31: =D31+C31 -> 28 | F31: =E31/$E$38 -> 0.0019889189 | G31: 45 | H31: 4 | I31: =G31+H31 -> 49 | J31: =I31/$I$38 -> 0.0013617163 | K31: =E31+I31 -> 77 | L31: 0 | M31: =K31+L31 -> 77
B32: TALTAL | C32: 302 | D32: 152 | E32: =D32+C32 -> 454 | F32: =E32/$E$38 -> 0.032248899 | G32: 1028 | H32: 49 | I32: =G32+H32 -> 1077 | J32: =I32/$I$38 -> 0.029929969 | K32: =E32+I32 -> 1531 | L32: 0 | M32: =K32+L32 -> 1531
B33: CALAMA | C33: 2537 | D33: 811 | E33: =D33+C33 -> 3348 | F33: =E33/$E$38 -> 0.23781787 | G33: 7233 | H33: 374 | I33: =G33+H33 -> 7607 | J33: =I33/$I$38 -> 0.21139951 | K33: =E33+I33 -> 10955 | L33: 0 | M33: =K33+L33 -> 10955
B34: OLLAGUE | C34: 15 | D34: 1 | E34: =D34+C34 -> 16 | F34: =E34/$E$38 -> 0.0011365251 | G34: 15 | H34: 0 | I34: =G34+H34 -> 15 | J34: =I34/$I$38 -> 0.00041685193 | K34: =E34+I34 -> 31 | L34: 0 | M34: =K34+L34 -> 31
B35: SAN PEDRO DE ATACAMA | C35: 160 | D35: 33 | E35: =D35+C35 -> 193 | F35: =E35/$E$38 -> 0.013709334 | G35: 339 | H35: 11 | I35: =G35+H35 -> 350 | J35: =I35/$I$38 -> 0.0097265451 | K35: =E35+I35 -> 543 | L35: 0 | M35: =K35+L35 -> 543
B36: TOCOPILLA | C36: 700 | D36: 295 | E36: =D36+C36 -> 995 | F36: =E36/$E$38 -> 0.070677653 | G36: 2361 | H36: 117 | I36: =G36+H36 -> 2478 | J36: =I36/$I$38 -> 0.06886394 | K36: =E36+I36 -> 3473 | L36: 0 | M36: =K36+L36 -> 3473
B37: MARIA ELENA | C37: 66 | D37: 16 | E37: =D37+C37 -> 82 | F37: =E37/$E$38 -> 0.005824691 | G37: 194 | H37: 6 | I37: =G37+H37 -> 200 | J37: =I37/$I$38 -> 0.0055580258 | K37: =E37+I37 -> 282 | L37: 0 | M37: =K37+L37 -> 282
B38: Totales | C38: =SUM(C29:C37) -> 10281 | D38: =SUM(D29:D37) -> 3797 | E38: =D38+C38 -> 14078 | F38: =E38/$E$38 -> 1 | G38: =SUM(G29:G37) -> 34090 | H38: =SUM(H29:H37) -> 1894 | I38: =G38+H38 -> 35984 | J38: =I38/$I$38 -> 1 | K38: =SUM(K29:K37) -> 50062 | L38: =SUM(L29:L37) -> 1 | M38: =K38+L38 -> 50063
B39: % respecto del total de concesiones | C39: =+C38/M38 -> 0.20536124 | D39: =+D38/M38 -> 0.075844436 | E39: =+E38/M38 -> 0.28120568 | G39: =+G38/M38 -> 0.68094201 | H39: =+H38/M38 -> 0.037832331 | I39: =+I38/M38 -> 0.71877434 | K39: =+K38/M38 -> 0.99998003 | L39: =+L38/M38 -> 1.9974832e-05 | M39: =K39+L39 -> 1
B40: Fuente: Elaboración propia sobre la base de información del IPS.
B41: Nota: La información estadística reportada del número de solicitudes concesionadas, en trámite, rechazadas y anuladas varía mes a mes por actualización de cifras.
B131: Copiar extraccion TODOS desde casilla A140, luego formatear numeros con punto sindecimales

Sheet III
A2: Subsecretaría de Previsión Social
A3: Dirección de Estudios Previsionales
B5: Número de Solicitudes de Beneficios del Pilar Solidario según tipo de beneficio - III Región de Atacama | M5: Volver Sistema de Pensiones Solidadias
B6: ='Solicitudes Regiones'!$B$6:$R$6 -> Acumuladas de julio de 2008 a diciembre de 2021
B8: Distribución Regional Solicitudes del Pilar Solidario - no incluye ex Pasis
B9: COMUNA | C9: TOTAL PBS Y APS
C10: PBSV | D10: PBSI | E10: Total PBS | F10: % PBS | G10: APSV | H10: APSI | I10: Total APS | J10: %APS | K10: Total PBS+APS | L10: Nbis | M10: Total PBS+APS+Nbis
B11: COPIAPO | C11: 3849 | D11: 1983 | E11: =C11+D11 -> 5832 | F11: =E11/$E$20 -> 0.46960303 | G11: 13482 | H11: 840 | I11: =G11+H11 -> 14322 | J11: =I11/$I$20 -> 0.49598282 | K11: =E11+I11 -> 20154 | L11: 15 | M11: =K11+L11 -> 20169
B12: CALDERA | C12: 446 | D12: 251 | E12: =C12+D12 -> 697 | F12: =E12/$E$20 -> 0.056123681 | G12: 1612 | H12: 98 | I12: =G12+H12 -> 1710 | J12: =I12/$I$20 -> 0.059218728 | K12: =E12+I12 -> 2407 | L12: 3 | M12: =K12+L12 -> 2410
B13: TIERRA AMARILLA | C13: 288 | D13: 208 | E13: =C13+D13 -> 496 | F13: =E13/$E$20 -> 0.039938803 | G13: 1019 | H13: 64 | I13: =G13+H13 -> 1083 | J13: =I13/$I$20 -> 0.037505195 | K13: =E13+I13 -> 1579 | L13: 3 | M13: =K13+L13 -> 1582
B14: CHAÑARAL | C14: 517 | D14: 237 | E14: =C14+D14 -> 754 | F14: =E14/$E$20 -> 0.060713423 | G14: 1441 | H14: 88 | I14: =G14+H14 -> 1529 | J14: =I14/$I$20 -> 0.052950547 | K14: =E14+I14 -> 2283 | L14: 0 | M14: =K14+L14 -> 2283
B15: DIEGO DE ALMAGRO | C15: 324 | D15: 230 | E15: =C15+D15 -> 554 | F15: =E15/$E$20 -> 0.044609067 | G15: 882 | H15: 49 | I15: =G15+H15 -> 931 | J15: =I15/$I$20 -> 0.032241308 | K15: =E15+I15 -> 1485 | L15: 0 | M15: =K15+L15 -> 1485
B16: VALLENAR | C16: 1955 | D16: 939 | E16: =C16+D16 -> 2894 | F16: =E16/$E$20 -> 0.23303003 | G16: 6545 | H16: 289 | I16: =G16+H16 -> 6834 | J16: =I16/$I$20 -> 0.23666713 | K16: =E16+I16 -> 9728 | L16: 5 | M16: =K16+L16 -> 9733
B17: ALTO DEL CARMEN | C17: 215 | D17: 114 | E17: =C17+D17 -> 329 | F17: =E17/$E$20 -> 0.026491666 | G17: 600 | H17: 26 | I17: =G17+H17 -> 626 | J17: =I17/$I$20 -> 0.021678903 | K17: =E17+I17 -> 955 | L17: 0 | M17: =K17+L17 -> 955
B18: FREIRINA | C18: 239 | D18: 113 | E18: =C18+D18 -> 352 | F18: =E18/$E$20 -> 0.028343667 | G18: 726 | H18: 35 | I18: =G18+H18 -> 761 | J18: =I18/$I$20 -> 0.026354066 | K18: =E18+I18 -> 1113 | L18: 1 | M18: =K18+L18 -> 1114
B19: HUASCO | C19: 372 | D19: 139 | E19: =C19+D19 -> 511 | F19: =E19/$E$20 -> 0.04114663 | G19: 1031 | H19: 49 | I19: =G19+H19 -> 1080 | J19: =I19/$I$20 -> 0.037401302 | K19: =E19+I19 -> 1591 | L19: 4 | M19: =K19+L19 -> 1595
B20: Totales | C20: =SUM(C11:C19) -> 8205 | D20: =SUM(D11:D19) -> 4214 | E20: =C20+D20 -> 12419 | F20: =E20/$E$20 -> 1 | G20: =SUM(G11:G19) -> 27338 | H20: =SUM(H11:H19) -> 1538 | I20: =G20+H20 -> 28876 | J20: =I20/$I$20 -> 1 | K20: =E20+I20 -> 41295 | L20: =SUM(L11:L19) -> 31 | M20: =K20+L20 -> 41326
B21: % respecto del total de solicitudes | C21: =+C20/M20 -> 0.19854329 | D21: =+D20/M20 -> 0.1019697 | E21: =+E20/M20 -> 0.30051299 | G21: =+G20/M20 -> 0.66152059 | H21: =+H20/M20 -> 0.03721628 | I21: =+I20/M20 -> 0.69873687 | K21: =+K20/M20 -> 0.99924987 | L21: =+L20/M20 -> 0.00075013309 | M21: =K21+L21 -> 1
B23: Número de concesiones de Beneficios del Pilar Solidario según tipo de beneficio - III Región de Atacama
B24: ='Solicitudes Regiones'!$B$6:$R$6 -> Acumuladas de julio de 2008 a diciembre de 2021
B26: Concesiones del Pilar Solidario a nivel comunal
B27: COMUNA | C27: TOTAL PBS Y APS
C28: PBSV | D28: PBSI | E28: Total PBS | F28: % PBS | G28: APSV | H28: APSI | I28: Total APS | J28: %APS | K28: Total PBS+APS | L28: Nbis | M28: Total PBS+APS+Nbis
B29: COPIAPO | C29: 3315 | D29: 1263 | E29: =C29+D29 -> 4578 | F29: =E29/$E$38 -> 0.4730805 | G29: 11332 | H29: 701 | I29: =G29+H29 -> 12033 | J29: =I29/$I$38 -> 0.49250982 | K29: =E29+I29 -> 16611 | L29: 0 | M29: =K29+L29 -> 16611
B30: CALDERA | C30: 388 | D30: 159 | E30: =C30+D30 -> 547 | F30: =E30/$E$38 -> 0.056525783 | G30: 1361 | H30: 81 | I30: =G30+H30 -> 1442 | J30: =I30/$I$38 -> 0.059020956 | K30: =E30+I30 -> 1989 | L30: 0 | M30: =K30+L30 -> 1989
B31: TIERRA AMARILLA | C31: 251 | D31: 125 | E31: =C31+D31 -> 376 | F31: =E31/$E$38 -> 0.038855017 | G31: 887 | H31: 51 | I31: =G31+H31 -> 938 | J31: =I31/$I$38 -> 0.038392272 | K31: =E31+I31 -> 1314 | L31: 0 | M31: =K31+L31 -> 1314
B32: CHAÑARAL | C32: 430 | D32: 146 | E32: =C32+D32 -> 576 | F32: =E32/$E$38 -> 0.059522579 | G32: 1217 | H32: 54 | I32: =G32+H32 -> 1271 | J32: =I32/$I$38 -> 0.052021938 | K32: =E32+I32 -> 1847 | L32: 0 | M32: =K32+L32 -> 1847
B33: DIEGO DE ALMAGRO | C33: 246 | D33: 126 | E33: =C33+D33 -> 372 | F33: =E33/$E$38 -> 0.038441666 | G33: 742 | H33: 33 | I33: =G33+H33 -> 775 | J33: =I33/$I$38 -> 0.031720694 | K33: =E33+I33 -> 1147 | L33: 0 | M33: =K33+L33 -> 1147
B34: VALLENAR | C34: 1690 | D34: 598 | E34: =C34+D34 -> 2288 | F34: =E34/$E$38 -> 0.23643691 | G34: 5603 | H34: 248 | I34: =G34+H34 -> 5851 | J34: =I34/$I$38 -> 0.23948101 | K34: =E34+I34 -> 8139 | L34: 0 | M34: =K34+L34 -> 8139
B35: ALTO DEL CARMEN | C35: 201 | D35: 66 | E35: =C35+D35 -> 267 | F35: =E35/$E$38 -> 0.027591196 | G35: 521 | H35: 25 | I35: =G35+H35 -> 546 | J35: =I35/$I$38 -> 0.022347741 | K35: =E35+I35 -> 813 | L35: 0 | M35: =K35+L35 -> 813
B36: FREIRINA | C36: 199 | D36: 83 | E36: =C36+D36 -> 282 | F36: =E36/$E$38 -> 0.029141263 | G36: 630 | H36: 25 | I36: =G36+H36 -> 655 | J36: =I36/$I$38 -> 0.026809103 | K36: =E36+I36 -> 937 | L36: 0 | M36: =K36+L36 -> 937
B37: HUASCO | C37: 305 | D37: 86 | E37: =C37+D37 -> 391 | F37: =E37/$E$38 -> 0.040405084 | G37: 876 | H37: 45 | I37: =G37+H37 -> 921 | J37: =I37/$I$38 -> 0.037696464 | K37: =E37+I37 -> 1312 | L37: 0 | M37: =K37+L37 -> 1312
B38: Totales | C38: =SUM(C29:C37) -> 7025 | D38: =SUM(D29:D37) -> 2652 | E38: =C38+D38 -> 9677 | F38: =E38/$E$38 -> 1 | G38: =SUM(G29:G37) -> 23169 | H38: =SUM(H29:H37) -> 1263 | I38: =G38+H38 -> 24432 | J38: =I38/$I$38 -> 1 | K38: =E38+I38 -> 34109 | L38: =SUM(L29:L37) -> 0 | M38: =K38+L38 -> 34109
B39: % respecto del total de concesiones | C39: =+C38/M38 -> 0.20595737 | D39: =+D38/M38 -> 0.07775074 | E39: =+E38/M38 -> 0.28370811 | G39: =+G38/M38 -> 0.67926354 | H39: =+H38/M38 -> 0.03702835 | I39: =+I38/M38 -> 0.71629189 | K39: =+K38/M38 -> 1 | L39: =+L38/M38 -> 0 | M39: =K39+L39 -> 1
B40: Fuente: Elaboración propia sobre la base de información del IPS.
B41: Nota: La información estadística reportada del número de solicitudes concesionadas, en trámite, rechazadas y anuladas varía mes a mes por actualización de cifras.
B131: Copiar extraccion TODOS desde casilla A140, luego formatear numeros con punto sindecimales

Sheet IV
A2: Subsecretaría de Previsión Social
A3: Dirección de Estudios Previsionales
B5: Número de Solicitudes de Beneficios del Pilar Solidario según tipo de beneficio - IV Región de Coquimbo | M5: Volver Sistema de Pensiones Solidadias
B6: ='Solicitudes Regiones'!$B$6:$R$6 -> Acumuladas de julio de 2008 a diciembre de 2021
B8: Distribución Regional Solicitudes del Pilar Solidario - no incluye ex Pasis
B9: COMUNA | C9: TOTAL PBS Y APS
C10: PBSV | D10: PBSI | E10: Total PBS | F10: % PBS | G10: APSV | H10: APSI | I10: Total APS | J10: %APS | K10: Total PBS+APS | L10: Nbis | M10: Total PBS+APS+Nbis
B11: LA SERENA | C11: 5640 | D11: 2790 | E11: =C11+D11 -> 8430 | F11: =E11/$E$26 -> 0.23658509 | G11: 21542 | H11: 1201 | I11: =G11+H11 -> 22743 | J11: =I11/$I$26 -> 0.26698049 | K11: =E11+I11 -> 31173 | L11: 26 | M11: =L11+K11 -> 31199
B12: COQUIMBO | C12: 6495 | D12: 3116 | E12: =C12+D12 -> 9611 | F12: =E12/$E$26 -> 0.26972946 | G12: 23499 | H12: 1260 | I12: =G12+H12 -> 24759 | J12: =I12/$I$26 -> 0.29064635 | K12: =E12+I12 -> 34370 | L12: 17 | M12: =L12+K12 -> 34387
B13: ANDACOLLO | C13: 404 | D13: 242 | E13: =C13+D13 -> 646 | F13: =E13/$E$26 -> 0.018129771 | G13: 1464 | H13: 66 | I13: =G13+H13 -> 1530 | J13: =I13/$I$26 -> 0.017960698 | K13: =E13+I13 -> 2176 | L13: 0 | M13: =L13+K13 -> 2176
B14: LA HIGUERA | C14: 178 | D14: 75 | E14: =C14+D14 -> 253 | F14: =E14/$E$26 -> 0.0071003592 | G14: 435 | H14: 28 | I14: =G14+H14 -> 463 | J14: =I14/$I$26 -> 0.0054351654 | K14: =E14+I14 -> 716 | L14: 0 | M14: =L14+K14 -> 716
B15: PAIHUANO | C15: 134 | D15: 58 | E15: =C15+D15 -> 192 | F15: =E15/$E$26 -> 0.0053884149 | G15: 600 | H15: 20 | I15: =G15+H15 -> 620 | J15: =I15/$I$26 -> 0.0072781913 | K15: =E15+I15 -> 812 | L15: 0 | M15: =L15+K15 -> 812
B16: VICUÑA | C16: 687 | D16: 409 | E16: =C16+D16 -> 1096 | F16: =E16/$E$26 -> 0.030758868 | G16: 3256 | H16: 188 | I16: =G16+H16 -> 3444 | J16: =I16/$I$26 -> 0.040429179 | K16: =E16+I16 -> 4540 | L16: 1 | M16: =L16+K16 -> 4541
B17: ILLAPEL | C17: 1349 | D17: 579 | E17: =C17+D17 -> 1928 | F17: =E17/$E$26 -> 0.054108666 | G17: 4232 | H17: 223 | I17: =G17+H17 -> 4455 | J17: =I17/$I$26 -> 0.052297326 | K17: =E17+I17 -> 6383 | L17: 3 | M17: =L17+K17 -> 6386
B18: CANELA | C18: 513 | D18: 233 | E18: =C18+D18 -> 746 | F18: =E18/$E$26 -> 0.020936237 | G18: 987 | H18: 63 | I18: =G18+H18 -> 1050 | J18: =I18/$I$26 -> 0.012325969 | K18: =E18+I18 -> 1796 | L18: 0 | M18: =L18+K18 -> 1796
B19: LOS VILOS | C19: 787 | D19: 362 | E19: =C19+D19 -> 1149 | F19: =E19/$E$26 -> 0.032246295 | G19: 2416 | H19: 132 | I19: =G19+H19 -> 2548 | J19: =I19/$I$26 -> 0.029911018 | K19: =E19+I19 -> 3697 | L19: 2 | M19: =L19+K19 -> 3699
B20: SALAMANCA | C20: 1182 | D20: 514 | E20: =C20+D20 -> 1696 | F20: =E20/$E$26 -> 0.047597665 | G20: 3360 | H20: 149 | I20: =G20+H20 -> 3509 | J20: =I20/$I$26 -> 0.041192215 | K20: =E20+I20 -> 5205 | L20: 3 | M20: =L20+K20 -> 5208
B21: OVALLE | C21: 4213 | D21: 1816 | E21: =C21+D21 -> 6029 | F21: =E21/$E$26 -> 0.16920184 | G21: 12082 | H21: 706 | I21: =G21+H21 -> 12788 | J21: =I21/$I$26 -> 0.15011856 | K21: =E21+I21 -> 18817 | L21: 7 | M21: =L21+K21 -> 18824
B22: COMBARBALA | C22: 631 | D22: 327 | E22: =C22+D22 -> 958 | F22: =E22/$E$26 -> 0.026885945 | G22: 2063 | H22: 89 | I22: =G22+H22 -> 2152 | J22: =I22/$I$26 -> 0.025262367 | K22: =E22+I22 -> 3110 | L22: 3 | M22: =L22+K22 -> 3113
... B25: RIO HURTADO | C25: 266 | D25: 79 | E25: =C25+D25 -> 345 | F25: =E25/$E$26 -> 0.009682308 | G25: 495 | H25: 21 | I25: =G25+H25 -> 516 | J25: =I25/$I$26 -> 0.0060573334 | K25: =E25+I25 -> 861 | L25: 0 | M25: =L25+K25 -> 861
B26: Totales | C26: =SUM(C11:C25) -> 24051 | D26: =SUM(D11:D25) -> 11581 | E26: =C26+D26 -> 35632 | F26: =E26/$E$26 -> 1 | G26: =SUM(G11:G25) -> 80724 | H26: =SUM(H11:H25) -> 4462 | I26: =G26+H26 -> 85186 | J26: =I26/$I$26 -> 1 | K26: =E26+I26 -> 120818 | L26: =SUM(L11:L25) -> 65 | M26: =L26+K26 -> 120883
B27: % respecto del total de solicitudes | C27: =+C26/M26 -> 0.19896098 | D27: =+D26/M26 -> 0.09580338 | E27: =+E26/M26 -> 0.29476436 | G27: =+G26/M26 -> 0.66778621 | H27: =+H26/M26 -> 0.036911725 | I27: =+I26/M26 -> 0.70469793 | K27: =+K26/M26 -> 0.99946229 | L27: =+L26/M26 -> 0.00053771002 | M27: =K27+L27 -> 1
B29: Número de Concesiones de Beneficios del Pilar Solidario según tipo de beneficio - IV Región de Coquimbo
B30: ='Solicitudes Regiones'!$B$6:$R$6 -> Acumuladas de julio de 2008 a diciembre de 2021
B32: Concesiones del Pilar Solidario a nivel comunal
B33: COMUNA | C33: TOTAL PBS Y APS
C34: PBSV | D34: PBSI | E34: Total PBS | F34: % PBS | G34: APSV | H34: APSI | I34: Total APS | J34: %APS | K34: Total PBS+APS | L34: Nbis | M34: Total PBS+APS+Nbis
B35: LA SERENA | C35: 4746 | D35: 1910 | E35: =C35+D35 -> 6656 | F35: =E35/$E$50 -> 0.23636364 | G35: 17322 | H35: 1052 | I35: =G35+H35 -> 18374 | J35: =I35/$I$50 -> 0.25360589 | K35: =E35+I35 -> 25030 | L35: 2 | M35: =L35+K35 -> 25032
B36: COQUIMBO | C36: 5540 | D36: 1976 | E36: =C36+D36 -> 7516 | F36: =E36/$E$50 -> 0.26690341 | G36: 19656 | H36: 1133 | I36: =G36+H36 -> 20789 | J36: =I36/$I$50 -> 0.28693876 | K36: =E36+I36 -> 28305 | L36: 2 | M36: =L36+K36 -> 28307
B37: ANDACOLLO | C37: 357 | D37: 120 | E37: =C37+D37 -> 477 | F37: =E37/$E$50 -> 0.01693892 | G37: 1320 | H37: 59 | I37: =G37+H37 -> 1379 | J37: =I37/$I$50 -> 0.019033554 | K37: =E37+I37 -> 1856 | L37: 0 | M37: =L37+K37 -> 1856
B38: LA HIGUERA | C38: 164 | D38: 48 | E38: =C38+D38 -> 212 | F38: =E38/$E$50 -> 0.0075284091 | G38: 383 | H38: 26 | I38: =G38+H38 -> 409 | J38: =I38/$I$50 -> 0.0056451947 | K38: =E38+I38 -> 621 | L38: 0 | M38: =L38+K38 -> 621
B39: PAIHUANO | C39: 121 | D39: 37 | E39: =C39+D39 -> 158 | F39: =E39/$E$50 -> 0.0056107955 | G39: 521 | H39: 17 | I39: =G39+H39 -> 538 | J39: =I39/$I$50 -> 0.0074257084 | K39: =E39+I39 -> 696 | L39: 0 | M39: =L39+K39 -> 696
B40: VICUÑA | C40: 596 | D40: 246 | E40: =C40+D40 -> 842 | F40: =E40/$E$50 -> 0.029900568 | G40: 2849 | H40: 169 | I40: =G40+H40 -> 3018 | J40: =I40/$I$50 -> 0.04165574 | K40: =E40+I40 -> 3860 | L40: 0 | M40: =L40+K40 -> 3860
B41: ILLAPEL | C41: 1193 | D41: 339 | E41: =C41+D41 -> 1532 | F41: =E41/$E$50 -> 0.054403409 | G41: 3652 | H41: 193 | I41: =G41+H41 -> 3845 | J41: =I41/$I$50 -> 0.053070351 | K41: =E41+I41 -> 5377 | L41: 0 | M41: =L41+K41 -> 5377
B42: CANELA | C42: 483 | D42: 127 | E42: =C42+D42 -> 610 | F42: =E42/$E$50 -> 0.021661932 | G42: 899 | H42: 58 | I42: =G42+H42 -> 957 | J42: =I42/$I$50 -> 0.013208927 | K42: =E42+I42 -> 1567 | L42: 0 | M42: =L42+K42 -> 1567
B43: LOS VILOS | C43: 701 | D43: 208 | E43: =C43+D43 -> 909 | F43: =E43/$E$50 -> 0.03227983 | G43: 2129 | H43: 110 | I43: =G43+H43 -> 2239 | J43: =I43/$I$50 -> 0.030903645 | K43: =E43+I43 -> 3148 | L43: 0 | M43: =L43+K43 -> 3148
B44: SALAMANCA | C44: 1055 | D44: 306 | E44: =C44+D44 -> 1361 | F44: =E44/$E$50 -> 0.048330966 | G44: 2935 | H44: 124 | I44: =G44+H44 -> 3059 | J44: =I44/$I$50 -> 0.042221639 | K44: =E44+I44 -> 4420 | L44: 0 | M44: =L44+K44 -> 4420
B45: OVALLE | C45: 3764 | D45: 1179 | E45: =C45+D45 -> 4943 | F45: =E45/$E$50 -> 0.17553267 | G45: 10652 | H45: 599 | I45: =G45+H45 -> 11251 | J45: =I45/$I$50 -> 0.15529116 | K45: =E45+I45 -> 16194 | L45: 0 | M45: =L45+K45 -> 16194
B46: COMBARBALA | C46: 577 | D46: 171 | E46: =C46+D46 -> 748 | F46: =E46/$E$50 -> 0.0265625 | G46: 1871 | H46: 81 | I46: =G46+H46 -> 1952 | J46: =I46/$I$50 -> 0.026942347 | K46: =E46+I46 -> 2700 | L46: 0 | M46: =L46+K46 -> 2700
... B49: RIO HURTADO | C49: 247 | D49: 49 | E49: =C49+D49 -> 296 | F49: =E49/$E$50 -> 0.010511364 | G49: 474 | H49: 19 | I49: =G49+H49 -> 493 | J49: =I49/$I$50 -> 0.006804599 | K49: =E49+I49 -> 789 | L49: 0 | M49: =L49+K49 -> 789
...

Sheet V
A2: Subsecretaría de Previsión Social
A3: Dirección de Estudios Previsionales
B5: Número de Solicitudes de Beneficios del Pilar Solidario según tipo de beneficio - V Región de Vaparaíso | M5: Volver Sistema de Pensiones Solidadias
B6: ='Solicitudes Regiones'!$B$6:$R$6 -> Acumuladas de julio de 2008 a diciembre de 2021
B8: Distribución Regional Solicitudes del Pilar Solidario - no incluye ex Pasis
B9: COMUNA | C9: TOTAL PBS Y APS
C10: PBSV | D10: PBSI | E10: Total PBS | F10: % PBS | G10: APSV | H10: APSI | I10: Total APS | J10: %APS | K10: Total PBS+APS | L10: Nbis | M10: Total PBS+APS+Nbis
B11: VALPARAISO | C11: 10094 | D11: 5777 | E11: =C11+D11 -> 15871 | F11: =E11/$E$49 -> 0.17998208 | G11: 37414 | H11: 2579 | I11: =G11+H11 -> 39993 | J11: =I11/$I$49 -> 0.17267762 | K11: =E11+I11 -> 55864 | L11: 21 | M11: =L11+K11 -> 55885
B12: CONCON | C12: 1124 | D12: 503 | E12: =C12+D12 -> 1627 | F12: =E12/$E$49 -> 0.018450687 | G12: 3481 | H12: 185 | I12: =G12+H12 -> 3666 | J12: =I12/$I$49 -> 0.015828674 | K12: =E12+I12 -> 5293 | L12: 6 | M12: =L12+K12 -> 5299
B13: PUCHUNCAVI | C13: 821 | D13: 293 | E13: =C13+D13 -> 1114 | F13: =E13/$E$49 -> 0.012633107 | G13: 2259 | H13: 103 | I13: =G13+H13 -> 2362 | J13: =I13/$I$49 -> 0.010198398 | K13: =E13+I13 -> 3476 | L13: 1 | M13: =L13+K13 -> 3477
B14: VIÑA DEL MAR | C14: 9417 | D14: 3876 | E14: =C14+D14 -> 13293 | F14: =E14/$E$49 -> 0.15074676 | G14: 38709 | H14: 1961 | I14: =G14+H14 -> 40670 | J14: =I14/$I$49 -> 0.1756007 | K14: =E14+I14 -> 53963 | L14: 25 | M14: =L14+K14 -> 53988
B15: ISLA DE PASCUA | C15: 126 | D15: 74 | E15: =C15+D15 -> 200 | F15: =E15/$E$49 -> 0.0022680623 | G15: 364 | H15: 35 | I15: =G15+H15 -> 399 | J15: =I15/$I$49 -> 0.0017227607 | K15: =E15+I15 -> 599 | L15: 0 | M15: =L15+K15 -> 599
B16: LOS ANDES | C16: 1870 | D16: 896 | E16: =C16+D16 -> 2766 | F16: =E16/$E$49 -> 0.031367301 | G16: 8372 | H16: 455 | I16: =G16+H16 -> 8827 | J16: =I16/$I$49 -> 0.038112303 | K16: =E16+I16 -> 11593 | L16: 4 | M16: =L16+K16 -> 11597
B17: RINCONADA | C17: 187 | D17: 115 | E17: =C17+D17 -> 302 | F17: =E17/$E$49 -> 0.003424774 | G17: 1028 | H17: 68 | I17: =G17+H17 -> 1096 | J17: =I17/$I$49 -> 0.0047321949 | K17: =E17+I17 -> 1398 | L17: 0 | M17: =L17+K17 -> 1398
B18: SAN ESTEBAN | C18: 499 | D18: 285 | E18: =C18+D18 -> 784 | F18: =E18/$E$49 -> 0.0088908041 | G18: 2100 | H18: 110 | I18: =G18+H18 -> 2210 | J18: =I18/$I$49 -> 0.0095421083 | K18: =E18+I18 -> 2994 | L18: 0 | M18: =L18+K18 -> 2994
B19: PAPUDO | C19: 212 | D19: 112 | E19: =C19+D19 -> 324 | F19: =E19/$E$49 -> 0.0036742609 | G19: 616 | H19: 56 | I19: =G19+H19 -> 672 | J19: =I19/$I$49 -> 0.0029014918 | K19: =E19+I19 -> 996 | L19: 0 | M19: =L19+K19 -> 996
B20: LA CALERA | C20: 2110 | D20: 1080 | E20: =C20+D20 -> 3190 | F20: =E20/$E$49 -> 0.036175593 | G20: 7034 | H20: 505 | I20: =G20+H20 -> 7539 | J20: =I20/$I$49 -> 0.032551111 | K20: =E20+I20 -> 10729 | L20: 1 | M20: =L20+K20 -> 10730
B21: HIJUELAS | C21: 774 | D21: 482 | E21: =C21+D21 -> 1256 | F21: =E21/$E$49 -> 0.014243431 | G21: 2030 | H21: 193 | I21: =G21+H21 -> 2223 | J21: =I21/$I$49 -> 0.0095982384 | K21: =E21+I21 -> 3479 | L21: 0 | M21: =L21+K21 -> 3479
B22: LA CRUZ | C22: 459 | D22: 207 | E22: =C22+D22 -> 666 | F22: =E22/$E$49 -> 0.0075526474 | G22: 1731 | H22: 136 | I22: =G22+H22 -> 1867 | J22: =I22/$I$49 -> 0.0080611386 | K22: =E22+I22 -> 2533 | L22: 1 | M22: =L22+K22 -> 2534
... B48: VILLA ALEMANA | C48: 3287 | D48: 1957 | E48: =C48+D48 -> 5244 | F48: =E48/$E$49 -> 0.059468593 | G48: 12381 | H48: 759 | I48: =G48+H48 -> 13140 | J48: =I48/$I$49 -> 0.056734526 | K48: =E48+I48 -> 18384 | L48: 8 | M48: =L48+K48 -> 18392
B49: Totales | C49: =SUM(C11:C48) -> 58556 | D49: =SUM(D11:D48) -> 29625 | E49: =C49+D49 -> 88181 | F49: =E49/$E$49 -> 1 | G49: =SUM(G11:G48) -> 218279 | H49: =SUM(H11:H48) -> 13326 | I49: =G49+H49 -> 231605 | J49: =I49/$I$49 -> 1 | K49: =E49+I49 -> 319786 | L49: =SUM(L11:L48) -> 117 | M49: =L49+K49 -> 319903
B50: % respecto del total de solicitudes | C50: =+C49/M49 -> 0.18304298 | D50: =+D49/M49 -> 0.092606196 | E50: =+E49/M49 -> 0.27564918 | G50: =+G49/M49 -> 0.68232871 | H50: =+H49/M49 -> 0.041656377 | I50: =+I49/M49 -> 0.72398508 | K50: =+K49/M49 -> 0.99963426 | L50: =+L49/M49 -> 0.00036573586 | M50: =K50+L50 -> 1
B52: Número de Concesiones de Beneficios del Pilar Solidario según tipo de beneficio - V Región de Vaparaíso
B53: ='Solicitudes Regiones'!$B$6:$R$6 -> Acumuladas de julio de 2008 a diciembre de 2021
B55: Concesiones del Pilar Solidario a nivel comunal
B56: COMUNA | C56: TOTAL PBS Y APS
C57: PBSV | D57: PBSI | E57: Total PBS | F57: % PBS | G57: APSV | H57: APSI | I57: Total APS | J57: %APS | K57: Total PBS+APS | L57: Nbis | M57: Total PBS+APS+Nbis
B58: VALPARAISO | C58: 9073 | D58: 4025 | E58: =C58+D58 -> 13098 | F58: =E58/$E$96 -> 0.18679673 | G58: 31449 | H58: 2222 | I58: =G58+H58 -> 33671 | J58: =I58/$I$96 -> 0.17377235 | K58: =E58+I58 -> 46769 | L58: 0 | M58: =L58+K58 -> 46769
B59: CONCON | C59: 923 | D59: 342 | E59: =C59+D59 -> 1265 | F59: =E59/$E$96 -> 0.018040759 | G59: 2849 | H59: 158 | I59: =G59+H59 -> 3007 | J59: =I59/$I$96 -> 0.015518799 | K59: =E59+I59 -> 4272 | L59: 0 | M59: =L59+K59 -> 4272
B60: PUCHUNCAVI | C60: 679 | D60: 159 | E60: =C60+D60 -> 838 | F60: =E60/$E$96 -> 0.011951112 | G60: 1847 | H60: 93 | I60: =G60+H60 -> 1940 | J60: =I60/$I$96 -> 0.010012128 | K60: =E60+I60 -> 2778 | L60: 0 | M60: =L60+K60 -> 2778
B61: VIÑA DEL MAR | C61: 8323 | D61: 2812 | E61: =C61+D61 -> 11135 | F61: =E61/$E$96 -> 0.15880147 | G61: 31631 | H61: 1694 | I61: =G61+H61 -> 33325 | J61: =I61/$I$96 -> 0.17198668 | K61: =E61+I61 -> 44460 | L61: 2 | M61: =L61+K61 -> 44462
B62: ISLA DE PASCUA | C62: 109 | D62: 52 | E62: =C62+D62 -> 161 | F62: =E62/$E$96 -> 0.0022960966 | G62: 315 | H62: 30 | I62: =G62+H62 -> 345 | J62: =I62/$I$96 -> 0.0017805073 | K62: =E62+I62 -> 506 | L62: 0 | M62: =L62+K62 -> 506
B63: LOS ANDES | C63: 1495 | D63: 483 | E63: =C63+D63 -> 1978 | F63: =E63/$E$96 -> 0.028209187 | G63: 6873 | H63: 391 | I63: =G63+H63 -> 7264 | J63: =I63/$I$96 -> 0.037488711 | K63: =E63+I63 -> 9242 | L63: 0 | M63: =L63+K63 -> 9242
B64: RINCONADA | C64: 167 | D64: 65 | E64: =C64+D64 -> 232 | F64: =E64/$E$96 -> 0.003308661 | G64: 913 | H64: 60 | I64: =G64+H64 -> 973 | J64: =I64/$I$96 -> 0.0050215467 | K64: =E64+I64 -> 1205 | L64: 0 | M64: =L64+K64 -> 1205
B65: SAN ESTEBAN | C65: 396 | D65: 135 | E65: =C65+D65 -> 531 | F65: =E65/$E$96 -> 0.0075728405 | G65: 1753 | H65: 94 | I65: =G65+H65 -> 1847 | J65: =I65/$I$96 -> 0.0095321653 | K65: =E65+I65 -> 2378 | L65: 0 | M65: =L65+K65 -> 2378
B66: PAPUDO | C66: 197 | D66: 69 | E66: =C66+D66 -> 266 | F66: =E66/$E$96 -> 0.003793551 | G66: 538 | H66: 39 | I66: =G66+H66 -> 577 | J66: =I66/$I$96 -> 0.002977834 | K66: =E66+I66 -> 843 | L66: 0 | M66: =L66+K66 -> 843
B67: LA CALERA | C67: 1889 | D67: 687 | E67: =C67+D67 -> 2576 | F67: =E67/$E$96 -> 0.036737546 | G67: 6026 | H67: 416 | I67: =G67+H67 -> 6442 | J67: =I67/$I$96 -> 0.033246458 | K67: =E67+I67 -> 9018 | L67: 0 | M67: =L67+K67 -> 9018
B68: HIJUELAS | C68: 687 | D68: 270 | E68: =C68+D68 -> 957 | F68: =E68/$E$96 -> 0.013648227 | G68: 1733 | H68: 168 | I68: =G68+H68 -> 1901 | J68: =I68/$I$96 -> 0.0098108534 | K68: =E68+I68 -> 2858 | L68: 0 | M68: =L68+K68 -> 2858
B69: LA CRUZ | C69: 401 | D69: 128 | E69: =C69+D69 -> 529 | F69: =E69/$E$96 -> 0.0075443175 | G69: 1484 | H69: 101 | I69: =G69+H69 -> 1585 | J69: =I69/$I$96 -> 0.0081800119 | K69: =E69+I69 -> 2114 | L69: 0 | M69: =L69+K69 -> 2114
... B95: VILLA ALEMANA | C95: 2867 | D95: 1204 | E95: =C95+D95 -> 4071 | F95: =E95/$E$96 -> 0.058058444 | G95: 10361 | H95: 660 | I95: =G95+H95 -> 11021 | J95: =I95/$I$96 -> 0.056878177 | K95: =E95+I95 -> 15092 | L95: 0 | M95: =L95+K95 -> 15092
...

Sheet VI
A2: Subsecretaría de Previsión Social
A3: Dirección de Estudios Previsionales
B5: Número de Solicitudes de Beneficios del Pilar Solidario según tipo de beneficio - VI Región de L.G.B. O'Higgins | M5: Volver Sistema de Pensiones Solidadias
B6: ='Solicitudes Regiones'!$B$6:$R$6 -> Acumuladas de julio de 2008 a diciembre de 2021
B8: Distribución Regional Solicitudes del Pilar Solidario - no incluye ex Pasis
B9: COMUNA | C9: TOTAL PBS Y APS
C10: PBSV | D10: PBSI | E10: Total PBS | F10: % PBS | G10: APSV | H10: APSI | I10: Total APS | J10: %APS | K10: Total PBS+APS | L10: Nbis | M10: Total PBS+APS+Nbis
B11: RANCAGUA | C11: 6376 | D11: 3682 | E11: =C11+D11 -> 10058 | F11: =E11/$E$44 -> 0.2215809 | G11: 23932 | H11: 2167 | I11: =G11+H11 -> 26099 | J11: =I11/$I$44 -> 0.23747521 | K11: =E11+I11 -> 36157 | L11: 14 | M11: =K11+L11 -> 36171
B12: COLTAUCO | C12: 646 | D12: 369 | E12: =C12+D12 -> 1015 | F12: =E12/$E$44 -> 0.022360768 | G12: 2378 | H12: 163 | I12: =G12+H12 -> 2541 | J12: =I12/$I$44 -> 0.023120598 | K12: =E12+I12 -> 3556 | L12: 0 | M12: =K12+L12 -> 3556
B13: GRANEROS | C13: 819 | D13: 414 | E13: =C13+D13 -> 1233 | F13: =E13/$E$44 -> 0.027163377 | G13: 3184 | H13: 236 | I13: =G13+H13 -> 3420 | J13: =I13/$I$44 -> 0.031118633 | K13: =E13+I13 -> 4653 | L13: 1 | M13: =K13+L13 -> 4654
B14: PICHIDEGUA | C14: 833 | D14: 509 | E14: =C14+D14 -> 1342 | F14: =E14/$E$44 -> 0.029564681 | G14: 2550 | H14: 160 | I14: =G14+H14 -> 2710 | J14: =I14/$I$44 -> 0.024658332 | K14: =E14+I14 -> 4052 | L14: 0 | M14: =K14+L14 -> 4052
B15: REQUINOA | C15: 557 | D15: 380 | E15: =C15+D15 -> 937 | F15: =E15/$E$44 -> 0.020642404 | G15: 2730 | H15: 201 | I15: =G15+H15 -> 2931 | J15: =I15/$I$44 -> 0.026669214 | K15: =E15+I15 -> 3868 | L15: 0 | M15: =K15+L15 -> 3868
