Workbook

Sheet datos
A2: Mes | B2: Diciembre de 2018

Sheet Índice
B1: Subsecretaría de Previsión Social Dirección de Estudios Previsionales
B5: Informe Estadístico Mensual de Pensión Garantizada Universal y Pilar Solidario
B7: Introducción
B8: El presente archivo contiene los principales cuadros del Informe Estadístico Mensual de Pensión Garatizada Universal y Pilar Solidario del mes de Junio de 2022. Correspondiente a:
B10: Estadísticas de Pensión Garantizada Universal (PGU) y Sistema de Pensiones Solidarias (SPS)
B11: Estadísticas del Bono por Hijo (BxH)
B12: Estadísticas del Subsidio Previsional a los Trabajadores Jóvenes (STJ)

Sheet Índice PGU y SPS
A2: Subsecretaría de Previsión Social
A3: Dirección de Estudios Previsionales
B5: Pensión Garantizada Universal (PGU) y Sistema de Pensiones Solidarias (SPS) | N5: Volver a Índice
B7: Introducción
B8: El presente archivo contiene los principales cuadros sobre la Pensión Garantizada Universal y el Sistema de Pensiones Solidarias del Informe Estadístico Mensual de PGU y Pilar Solidario del mes junio de 2022. Los cuadros entregan información de los beneficios solicitados y concedidos mensualmente a nivel nacional, desde julio de 2008 a junio de 2022, asi como también la información de las solicitudes y concesiones a nivel regional y comunal acumulado a junio de 2022.
B12: Nacional
B13: Solicitudes recibidas en PGU y SPS, según mes, desde julio 2008 a junio 2022
B14: Concesiones en PGU y SPS, por mes, desde julio 2008 a junio 2022
B16: Regional
B17: Solicitudes recibidas en PGU y SPS acumuladas desde julio 2008 a junio 2022, según región
B18: Concesiones en PGU y SPS acumuladas desde julio 2008 a junio 2022, según región
B20: Solicitudes y Concesiones en PGU y SPS acumulado a junio 2022 por región y comuna:
B21: XV Arica y Parinacota
B22: I Tarapaca
B23: II Antofagasta
... B36: XIII Metropolitana

Sheet Solicitudes Nacional
A2: Subsecretaría de Previsión Social
A3: Dirección de Estudios Previsionales
B5: Número de solicitudes mensuales recibidas en PGU y SPS, según tipo de beneficio, sexo y origen de tramitación del beneficio | S5: Volver Sistema de Pensiones Solidarias
B6: Julio de 2008 a junio de 2022
B8: TOTAL SOLICITUDES (no incluye ex Pasis)
B9: PERIODO | C9: TIPO BENEFICIO | L9: SEXO | N9: ORIGEN DE TRAMITACIÓN DEL BENEFICIO
C10: PBSV/PGU No Contributivo | D10: PBSI | E10: TOTAL PGU No Contributiva / PBS | F10: PGU Contributivo* | G10: APSV | H10: APSI | I10: TOTAL PGU Contributiva / APS | J10: Nbis | K10: Total PGU+PBS+APS | L10: Femenino | M10: Masculino | N10: En IPS | O10: En AFP | P10: En Cías. de Seguro | Q10: En Municipio | R10: C. Web
B11: Jul a Dic 2008 | C11: 83903 | D11: 36885 | E11: 120788 | F11: 11268 | G11: 1362 | H11: 5944 | I11: 18574 | J11: 0 | K11: 139362 | L11: 107640 | M11: 31722 | N11: 95475 | O11: 1029 | P11: 0 | Q11: 42858 | R11: 0
B12: Total 2009 | C12: 59154 | D12: 35458 | E12: 94612 | F12: 279540 | G12: 18581 | H12: 11707 | I12: 309828 | J12: 0 | K12: 404440 | L12: 256079 | M12: 148361 | N12: 299851 | O12: 30362 | P12: 0 | Q12: 74227 | R12: 0
B13: Total 2010 | C13: 40733 | D13: 24967 | E13: 65700 | F13: 133261 | G13: 34785 | H13: 11929 | I13: 179975 | J13: 0 | K13: 245675 | L13: 152798 | M13: 92877 | N13: 148063 | O13: 32918 | P13: 5301 | Q13: 59393 | R13: 0
B14: Total 2011 | C14: 37414 | D14: 20938 | E14: 58352 | F14: 89501 | G14: 36570 | H14: 10368 | I14: 136439 | J14: 0 | K14: 194791 | L14: 123376 | M14: 71415 | N14: 114399 | O14: 25990 | P14: 11377 | Q14: 43025 | R14: 0
B15: Total 2012 | C15: 34111 | D15: 19594 | E15: 53705 | F15: 111445 | G15: 18894 | H15: 8226 | I15: 138565 | J15: 0 | K15: 192270 | L15: 118771 | M15: 73499 | N15: 126850 | O15: 24058 | P15: 9223 | Q15: 32139 | R15: 0
B16: Total 2013 | C16: 32718 | D16: 17032 | E16: 49750 | F16: 65156 | G16: 11833 | H16: 7295 | I16: 84284 | J16: 0 | K16: 134034 | L16: 82046 | M16: 51988 | N16: 83745 | O16: 22686 | P16: 6357 | Q16: 21246 | R16: 0
B17: Total 2014 | C17: 39392 | D17: 17573 | E17: 56965 | F17: 70471 | G17: 18074 | H17: 6054 | I17: 94599 | J17: 0 | K17: 151564 | L17: 92858 | M17: 58706 | N17: 94143 | O17: 27044 | P17: 6542 | Q17: 23835 | R17: 0
B18: Total 2015 | C18: 31042 | D18: 18557 | E18: 49599 | F18: 71608 | G18: 17270 | H18: 2501 | I18: 91379 | J18: 0 | K18: 140978 | L18: 86238 | M18: 54740 | N18: 84139 | O18: 29604 | P18: 5381 | Q18: 21854 | R18: 0
B19: Total 2016 | C19: 30685 | D19: 18094 | E19: 48779 | F19: 81220 | G19: 6212 | H19: 2577 | I19: 90009 | J19: 0 | K19: 138788 | L19: 86383 | M19: 52405 | N19: 84299 | O19: 29016 | P19: 4531 | Q19: 20904 | R19: 38
B20: Total 2017 | C20: 32028 | D20: 18335 | E20: 50363 | F20: 101491 | G20: 2045 | H20: 3167 | I20: 106703 | J20: 0 | K20: 157066 | L20: 95362 | M20: 61704 | N20: 94990 | O20: 34397 | P20: 4540 | Q20: 22824 | R20: 315
B21: Total 2018 | C21: 31567 | D21: 16995 | E21: 48562 | F21: 121449 | G21: 2118 | H21: 6272 | I21: 129839 | J21: 0 | K21: 178401 | L21: 107375 | M21: 71026 | N21: 106236 | O21: 43517 | P21: 4894 | Q21: 22939 | R21: 815
B22: Enero'19 | C22: 2750 | D22: 1462 | E22: 4212 | F22: 10056 | G22: 144 | H22: 565 | I22: 10765 | J22: 0 | K22: 14977 | L22: 9003 | M22: 5974 | N22: 8617 | O22: 4044 | P22: 339 | Q22: 1910 | R22: 67
... B68: TOTAL | C68: 581880 | D68: 321711 | E68: 903591 | F68: 1770337 | G68: 318943 | H68: 121128 | I68: 2210408 | J68: 0 | K68: 3113999 | L68: 1886947 | M68: 1227052 | N68: 1782192 | O68: 528868 | P68: 83360 | Q68: 465944 | R68: 253635
B69: Fuente: Elaboración propia sobre la base de información del IPS.
B70: A contar de la información de Junio-22, el IPS reporta la información en función del tipo de beneficio pagado, por lo tanto, ya no se informa el número de beneficios Nbis y, en el caso del número de beneficios PGU Contributiva, se incluyen los beneficios que fueron concedidos como APSV.
B71: El periodo está determinado por la fecha de solicitud del beneficio.
B72: Las cifras de solicitudes y concesiones anuales varían respecto de informes anteriores, debido al cambio en la fuente de información, el cual incorpora los beneficios de vejez concedidos de oficio a los beneficiarios de PBSI o APSI al momento de cumplir 65 años.

Sheet Concesiones Nacional
A2: Subsecretaría de Previsión Social
A3: Dirección de Estudios Previsionales
B5: Número de beneficios concedidos mensuales en PGU y SPS, según tipo de beneficio, sexo y origen de tramitación del beneficio | S5: Volver Sistema de Pensiones Solidarias
B6: ='Solicitudes Nacional'!B6:Q6 -> Julio de 2008 a junio de 2022
B8: TOTAL CONCEDIDAS (no incluye ex Pasis)
B9: MES | C9: TIPO BENEFICIO | L9: SEXO | N9: ORIGEN DE TRAMITACIÓN DEL BENEFICIO
C10: PBSV/PGU No Contributivo | D10: PBSI | E10: TOTAL PGU No Contributiva / PBS | F10: PGU Contributivo* | G10: APSV | H10: APSI | I10: TOTAL PGU Contributiva / APS | J10: Nbis | K10: Total PGU+PBS+APS | L10: Femenino | M10: Masculino | N10: En IPS | O10: En AFP | P10: En Cías. de Seguro | Q10: En Municipio | R10: C. Web
B11: Jul a Dic 2008 | C11: 83064 | D11: 21142 | E11: 104206 | F11: 9153 | G11: 193 | H11: 1529 | I11: 10875 | J11: 0 | K11: 115081 | L11: 88629 | M11: 26452 | N11: 77649 | O11: 988 | P11: 0 | Q11: 36444 | R11: 0
B12: Total 2009 | C12: 57810 | D12: 21206 | E12: 79016 | F12: 264252 | G12: 12834 | H12: 9856 | I12: 286942 | J12: 0 | K12: 365958 | L12: 225147 | M12: 140811 | N12: 273101 | O12: 26670 | P12: 0 | Q12: 66187 | R12: 0
B13: Total 2010 | C13: 36125 | D13: 13245 | E13: 49370 | F13: 129479 | G13: 8407 | H13: 9914 | I13: 147800 | J13: 0 | K13: 197170 | L13: 119671 | M13: 77499 | N13: 120976 | O13: 25694 | P13: 3818 | Q13: 46682 | R13: 0
B14: Total 2011 | C14: 29976 | D14: 10364 | E14: 40340 | F14: 86298 | G14: 3969 | H14: 8697 | I14: 98964 | J14: 0 | K14: 139304 | L14: 84838 | M14: 54466 | N14: 81473 | O14: 19161 | P14: 8010 | Q14: 30660 | R14: 0
B15: Total 2012 | C15: 29369 | D15: 10380 | E15: 39749 | F15: 109712 | G15: 3652 | H15: 7014 | I15: 120378 | J15: 0 | K15: 160127 | L15: 95751 | M15: 64376 | N15: 106541 | O15: 20848 | P15: 7845 | Q15: 24893 | R15: 0
B16: Total 2013 | C16: 29479 | D16: 9014 | E16: 38493 | F16: 63674 | G16: 1893 | H16: 6048 | I16: 71615 | J16: 0 | K16: 110108 | L16: 65748 | M16: 44360 | N16: 68722 | O16: 19387 | P16: 5326 | Q16: 16673 | R16: 0
B17: Total 2014 | C17: 32567 | D17: 9988 | E17: 42555 | F17: 68708 | G17: 1352 | H17: 5270 | I17: 75330 | J17: 0 | K17: 117885 | L17: 70004 | M17: 47881 | N17: 72035 | O17: 22552 | P17: 5134 | Q17: 18164 | R17: 0
B18: Total 2015 | C18: 26363 | D18: 11711 | E18: 38074 | F18: 70084 | G18: 1106 | H18: 2081 | I18: 73271 | J18: 0 | K18: 111345 | L18: 65990 | M18: 45355 | N18: 65223 | O18: 24957 | P18: 4304 | Q18: 16861 | R18: 0
B19: Total 2016 | C19: 24913 | D19: 11810 | E19: 36723 | F19: 66862 | G19: 896 | H19: 2218 | I19: 69976 | J19: 0 | K19: 106699 | L19: 64506 | M19: 42193 | N19: 64019 | O19: 23640 | P19: 3451 | Q19: 15560 | R19: 29
B20: Total 2017 | C20: 26161 | D20: 11910 | E20: 38071 | F20: 81213 | G20: 1024 | H20: 2802 | I20: 85039 | J20: 0 | K20: 123110 | L20: 72374 | M20: 50736 | N20: 73317 | O20: 28517 | P20: 3602 | Q20: 17423 | R20: 251
B21: Total 2018 | C21: 28351 | D21: 10990 | E21: 39341 | F21: 110834 | G21: 1110 | H21: 5864 | I21: 117808 | J21: 0 | K21: 157149 | L21: 91770 | M21: 65379 | N21: 92287 | O21: 40174 | P21: 4487 | Q21: 19524 | R21: 677
B22: Enero' 19 | C22: 2487 | D22: 954 | E22: 3441 | F22: 9191 | G22: 74 | H22: 518 | I22: 9783 | J22: 0 | K22: 13224 | L22: 7679 | M22: 5545 | N22: 7480 | O22: 3744 | P22: 306 | Q22: 1640 | R22: 54
... B68: TOTAL | C68: 507939 | D68: 179610 | E68: 687549 | F68: 1505208 | G68: 167817 | H68: 100834 | I68: 1773859 | J68: 0 | K68: 2461408 | L68: 1458766 | M68: 1002642 | N68: 1436270 | O68: 446232 | P68: 66536 | Q68: 370356 | R68: 142014
B69: Fuente: Elaboración propia sobre la base de información del IPS.
B70: Notas: La información estadística reportada del número de solicitudes concesionadas, en trámite, rechazadas y anuladas varía mes a mes por actualización de cifras.
B71: El número de beneficios concesionados no coincide con el número de beneficios pagados por las siguientes razones: •El total acumulado de concesiones de la Reforma Previsional incluye personas fallecidas: El número de personas fallecidas que recibían PBS y APS durante el año 2021 correspondió a: 73.607 El número de personas fallecidas desde julio de 2008 a diciembre 2020 correspondió a: 574.175 •Existen personas a quienes se les ha extinguido o suspendido el beneficio. •El mes de concedida la pensión no necesariamente coincide con el primer mes de pago. El periodo está determinado por la fecha de solicitud del beneficio. A contar de la información de Junio-22, el IPS reporta la información en función del tipo de beneficio pagado, por lo tanto, ya no se informa el número de beneficios Nbis y, en el caso del número de beneficios PGU Contributiva, se incluyen los beneficios que fueron concedidos como APSV.

Sheet Solicitudes Regiones
A2: Subsecretaría de Previsión Social
A3: Dirección de Estudios Previsionales
B5: Número de solicitudes de PGU y SPS según región, tipo de beneficio, sexo y origen de tramitación del beneficio | T5: Volver Sistema de Pensiones Solidarias
B6: Julio de 2008 a junio de 2022
B8: TOTAL SOLICITUDES (no incluye ex Pasis)
B9: REGIÓN | C9: TIPO BENEFICIO | M9: SEXO | O9: ORIGEN DE TRAMITACIÓN DEL BENEFICIO
C10: PBSV/PGU No Contributiva | D10: PBSI | E10: TOTAL PGU No Contributiva / PBS | F10: PGU Contributiva | G10: APSV | H10: APSI | I10: TOTAL PGU Contributiva / APS | J10: Nbis | K10: Total PGU+PBS+APS | L10: % de Concesiones | M10: Femenino | N10: Masculino | O10: En IPS | P10: En AFP | Q10: En Cías. de Seguro | R10: En Municipio | S10: C. Web
B11: ARICA Y PARINACOTA | C11: 6795 | D11: 3164 | E11: 9959 | F11: 22468 | G11: 4273 | H11: 1377 | I11: 28118 | J11: 0 | K11: 38077 | L11: 0.012227685 | M11: 22083 | N11: 15994 | O11: 21026 | P11: 7751 | Q11: 1237 | R11: 5324 | S11: 2739
B12: TARAPACA | C12: 7145 | D12: 5282 | E12: 12427 | F12: 24708 | G12: 5520 | H12: 2266 | I12: 32494 | J12: 0 | K12: 44921 | L12: 0.014425502 | M12: 26591 | N12: 18330 | O12: 24744 | P12: 7213 | Q12: 1569 | R12: 7671 | S12: 3724
B13: ANTOFAGASTA | C13: 13907 | D13: 6748 | E13: 20655 | F13: 44036 | G13: 8867 | H13: 2556 | I13: 55459 | J13: 0 | K13: 76114 | L13: 0.024442526 | M13: 47780 | N13: 28334 | O13: 49012 | P13: 11359 | Q13: 1155 | R13: 7273 | S13: 7315
B14: ATACAMA | C14: 8389 | D14: 4293 | E14: 12682 | F14: 27794 | G14: 4548 | H14: 1642 | I14: 33984 | J14: 0 | K14: 46666 | L14: 0.014985875 | M14: 27517 | N14: 19149 | O14: 26397 | P14: 8823 | Q14: 1268 | R14: 7079 | S14: 3099
B15: COQUIMBO | C15: 25719 | D15: 12492 | E15: 38211 | F15: 81896 | G15: 13873 | H15: 4935 | I15: 100704 | J15: 0 | K15: 138915 | L15: 0.044609841 | M15: 83014 | N15: 55901 | O15: 94896 | P15: 20506 | Q15: 2304 | R15: 11638 | S15: 9571
B16: VALPARAISO | C16: 62811 | D16: 31560 | E16: 94371 | F16: 217788 | G16: 42685 | H16: 14639 | I16: 275112 | J16: 0 | K16: 369483 | L16: 0.11865225 | M16: 226234 | N16: 143249 | O16: 215699 | P16: 70231 | Q16: 8370 | R16: 44139 | S16: 31044
B17: L. G. B. OHIGGINS | C17: 29885 | D17: 18476 | E17: 48361 | F17: 103946 | G17: 16973 | H17: 8441 | I17: 129360 | J17: 0 | K17: 177721 | L17: 0.05707163 | M17: 104034 | N17: 73687 | O17: 97520 | P17: 28970 | Q17: 4354 | R17: 35160 | S17: 11717
B18: MAULE | C18: 40610 | D18: 23840 | E18: 64450 | F18: 120432 | G18: 17754 | H18: 9086 | I18: 147272 | J18: 0 | K18: 211722 | L18: 0.067990388 | M18: 121435 | N18: 90287 | O18: 120100 | P18: 40637 | Q18: 5600 | R18: 34546 | S18: 10839
B19: ÑUBLE | C19: 21764 | D19: 25044 | E19: 46808 | F19: 55151 | G19: 8479 | H19: 6744 | I19: 70374 | J19: 0 | K19: 117182 | L19: 0.037630712 | M19: 70639 | N19: 46543 | O19: 65662 | P19: 19111 | Q19: 2196 | R19: 25571 | S19: 4642
B20: BIO-BIO | C20: 55772 | D20: 40832 | E20: 96604 | F20: 164900 | G20: 29874 | H20: 12194 | I20: 206968 | J20: 0 | K20: 303572 | L20: 0.097486223 | M20: 185858 | N20: 117714 | O20: 167161 | P20: 48276 | Q20: 9151 | R20: 59058 | S20: 19926
B21: LA ARAUCANIA | C21: 44317 | D21: 28232 | E21: 72549 | F21: 93751 | G21: 14675 | H21: 7397 | I21: 115823 | J21: 0 | K21: 188372 | L21: 0.060491991 | M21: 111747 | N21: 76625 | O21: 117861 | P21: 31693 | Q21: 4783 | R21: 24371 | S21: 9664
B22: LOS RIOS | C22: 15848 | D22: 10642 | E22: 26490 | F22: 42041 | G22: 7113 | H22: 4526 | I22: 53680 | J22: 0 | K22: 80170 | L22: 0.025745031 | M22: 47573 | N22: 32597 | O22: 53897 | P22: 15209 | Q22: 2271 | R22: 4791 | S22: 4002
... B26: METROPOLITANA | C26: 209608 | D26: 87393 | E26: 297001 | F26: 670086 | G26: 127416 | H26: 36016 | I26: 833518 | J26: 0 | K26: 1130519 | L26: 0.36304411 | M26: 701879 | N26: 428640 | O26: 605749 | P26: 180453 | Q26: 33347 | R26: 186046 | S26: 124924
B27: Totales | C27: 581880 | D27: 321711 | E27: 903591 | F27: 1770337 | G27: 318943 | H27: 121128 | I27: 2210408 | J27: 0 | K27: 3113999 | L27: 1 | M27: 1886947 | N27: 1227052 | O27: 1782192 | P27: 528868 | Q27: 83360 | R27: 465944 | S27: =SUM(S11:S26) -> 253635
B28: Participación sobre el total | C28: =+C27/$K$27 -> 0.1868594 | D28: =+D27/$K$27 -> 0.10331121 | F28: =+F27/$K$27 -> 0.56850917 | G28: =+G27/$K$27 -> 0.10242232 | H28: =+H27/$K$27 -> 0.038897893 | J28: =+J27/$K$27 -> 0 | K28: =C28+D28+F28+G28+H28 -> 1 | M28: =+M27/$K$27 -> 0.6059562 | N28: =+N27/$K$27 -> 0.3940438 | O28: =+O27/$K$27 -> 0.57231618 | P28: =+P27/$K$27 -> 0.16983564 | Q28: =+Q27/$K$27 -> 0.026769437 | R28: =+R27/$K$27 -> 0.14962882 | S28: =+S27/$K$27 -> 0.08144993
B29: Fuente: Elaboración propia sobre la base de información del IPS.
B30: Nota: La información estadística reportada del número de solicitudes concesionadas, en trámite, rechazadas y anuladas varía mes a mes por actualización de cifras.
B31: La información corresponde a la región en que vive el beneficiario.
B32: A contar de la información de Junio-22, el IPS reporta la información en función del tipo de beneficio pagado, por lo tanto, ya no se informa el número de beneficios Nbis y, en el caso del número de beneficios PGU Contributiva, se incluyen los beneficios que fueron concedidos como APSV.

Sheet Concesiones Regiones
A2: Subsecretaría de Previsión Social
A3: Dirección de Estudios Previsionales
B5: Número de concesiones de PGU y SPS según región, tipo de beneficio, sexo y origen de tramitación del beneficio | T5: Volver Sistema de Pensiones Solidarias
B6: ='Solicitudes Regiones'!B6 -> Julio de 2008 a junio de 2022
B8: TOTAL CONCEDIDAS (no incluye ex Pasis)
B9: REGIÓN | C9: TIPO BENEFICIO | M9: SEXO | O9: ORIGEN DE TRAMITACIÓN DEL BENEFICIO
C10: PBSV/PGU No Contributiva | D10: PBSI | E10: TOTAL PGU No Contributiva / PBS | F10: PGU Contributiva | G10: APSV | H10: APSI | I10: TOTAL PGU Contributiva / APS | J10: Nbis | K10: Total PGU+PBS+APS | L10: % de Concesiones | M10: Femenino | N10: Masculino | O10: En IPS | P10: En AFP | Q10: En Cías. de Seguro | R10: En Municipio | S10: C. Web
B11: ARICA Y PARINACOTA | C11: 5945 | D11: 2163 | E11: 8108 | F11: 19200 | G11: 2430 | H11: 1156 | I11: 22786 | J11: 30894 | K11: 30894 | L11: 0.012551353 | M11: 17813 | N11: 13081 | O11: 17336 | P11: 6521 | Q11: 1011 | R11: 4541 | S11: 1485
B12: TARAPACA | C12: 5906 | D12: 3065 | E12: 8971 | F12: 20462 | G12: 2629 | H12: 1798 | I12: 24889 | J12: 33860 | K12: 33860 | L12: 0.013756354 | M12: 19632 | N12: 14228 | O12: 19065 | P12: 5826 | Q12: 1240 | R12: 5705 | S12: 2024
B13: ANTOFAGASTA | C13: 10882 | D13: 3908 | E13: 14790 | F13: 34856 | G13: 4127 | H13: 2043 | I13: 41026 | J13: 55816 | K13: 55816 | L13: 0.022676452 | M13: 34550 | N13: 21266 | O13: 36689 | P13: 8783 | Q13: 875 | R13: 5926 | S13: 3543
B14: ATACAMA | C14: 7020 | D14: 2605 | E14: 9625 | F14: 23430 | G14: 2397 | H14: 1348 | I14: 27175 | J14: 36800 | K14: 36800 | L14: 0.014950792 | M14: 21316 | N14: 15484 | O14: 20822 | P14: 7383 | Q14: 975 | R14: 5925 | S14: 1695
B15: COQUIMBO | C15: 22034 | D15: 7517 | E15: 29551 | F15: 69303 | G15: 7009 | H15: 4263 | I15: 80575 | J15: 110126 | K15: 110126 | L15: 0.044741059 | M15: 64108 | N15: 46018 | O15: 76646 | P15: 17399 | Q15: 1676 | R15: 9310 | S15: 5093
B16: VALPARAISO | C16: 54157 | D16: 19611 | E16: 73768 | F16: 182897 | G16: 20998 | H16: 12128 | I16: 216023 | J16: 289791 | K16: 289791 | L16: 0.11773383 | M16: 174399 | N16: 115392 | O16: 171622 | P16: 58578 | Q16: 6579 | R16: 36508 | S16: 16504
B17: L. G. B. OHIGGINS | C17: 25594 | D17: 9527 | E17: 35121 | F17: 88973 | G17: 8646 | H17: 7017 | I17: 104636 | J17: 139757 | K17: 139757 | L17: 0.056779291 | M17: 79132 | N17: 60625 | O17: 77957 | P17: 24523 | Q17: 3421 | R17: 27679 | S17: 6177
B18: MAULE | C18: 36230 | D18: 12903 | E18: 49133 | F18: 105952 | G18: 9596 | H18: 7498 | I18: 123046 | J18: 172179 | K18: 172179 | L18: 0.069951426 | M18: 95982 | N18: 76197 | O18: 99001 | P18: 35466 | Q18: 4505 | R18: 26954 | S18: 6252
B19: ÑUBLE | C19: 19608 | D19: 10847 | E19: 30455 | F19: 48411 | G19: 4742 | H19: 5791 | I19: 58944 | J19: 89399 | K19: 89399 | L19: 0.036320269 | M19: 50770 | N19: 38629 | O19: 51544 | P19: 16871 | Q19: 1841 | R19: 16686 | S19: 2457
B20: BIO-BIO | C20: 48304 | D20: 20101 | E20: 68405 | F20: 138884 | G20: 16010 | H20: 10125 | I20: 165019 | J20: 233424 | K20: 233424 | L20: 0.094833526 | M20: 137259 | N20: 96165 | O20: 132111 | P20: 40128 | Q20: 7138 | R20: 43632 | S20: 10415
B21: LA ARAUCANIA | C21: 40127 | D21: 13166 | E21: 53293 | F21: 81511 | G21: 7759 | H21: 6214 | I21: 95484 | J21: 148777 | K21: 148777 | L21: 0.06044386 | M21: 84541 | N21: 64236 | O21: 93990 | P21: 27500 | Q21: 3657 | R21: 18258 | S21: 5372
B22: LOS RIOS | C22: 14362 | D22: 7061 | E22: 21423 | F22: 36295 | G22: 4113 | H22: 3896 | I22: 44304 | J22: 65727 | K22: 65727 | L22: 0.026703009 | M22: 38076 | N22: 27651 | O22: 44528 | P22: 13114 | Q22: 1835 | R22: 3996 | S22: 2252
... B26: METROPOLITANA | C26: 182402 | D26: 53814 | E26: 236216 | F26: 568144 | G26: 67863 | H26: 29790 | I26: 665797 | J26: 902013 | K26: 902013 | L26: 0.3664622 | M26: 554698 | N26: 347315 | O26: 496948 | P26: 150849 | Q26: 27112 | R26: 154148 | S26: 72956
B27: Totales | C27: 507939 | D27: 179610 | E27: 687549 | F27: 1505208 | G27: 167817 | H27: 100834 | I27: 1773859 | J27: 2461408 | K27: =SUM(K11:K26) -> 2461408 | L27: =SUM(L11:L26) -> 1 | M27: =SUM(M11:M26) -> 1458766 | N27: =SUM(N11:N26) -> 1002642 | O27: =SUM(O11:O26) -> 1436265 | P27: =SUM(P11:P26) -> 446232 | Q27: =SUM(Q11:Q26) -> 66536 | R27: =SUM(R11:R26) -> 370356 | S27: =SUM(S11:S26) -> 142014
B28: Participación sobre el total | C28: =+C27/$K$27 -> 0.20636116 | D28: =+D27/$K$27 -> 0.07297043 | F28: =+F27/$K$27 -> 0.61152316 | G28: =+G27/$K$27 -> 0.06817927 | H28: =+H27/$K$27 -> 0.040965984 | J28: =+J27/$K$27 -> 1 | K28: =C28+D28+F28+G28+H28 -> 1 | M28: =+M27/$K$27 -> 0.5926551 | N28: =+N27/$K$27 -> 0.4073449 | O28: =+O27/$K$27 -> 0.58351358 | P28: =+P27/$K$27 -> 0.18129136 | Q28: =+Q27/$K$27 -> 0.027031683 | R28: =+R27/$K$27 -> 0.1504651 | S28: =+S27/$K$27 -> 0.057696245
B29: Fuente: Elaboración propia sobre la base de información del IPS.
B30: Nota: La información estadística reportada del número de solicitudes concesionadas, en trámite, rechazadas y anuladas varía mes a mes por actualización de cifras.
B31: La información corresponde a la región en que vive el beneficiario.
B32: A contar de la información de Junio-22, el IPS reporta la información en función del tipo de beneficio pagado, por lo tanto, ya no se informa el número de beneficios Nbis y, en el caso del número de beneficios PGU Contributiva, se incluyen los beneficios que fueron concedidos como APSV.

Sheet XV
A2: Subsecretaría de Previsión Social
A3: Dirección de Estudios Previsionales
B5: Número de Solicitudes de Beneficios de PGU y SPS según tipo de beneficio - XV Región de Arica y Parinacota | M5: Volver Sistema de Pensiones Solidarias
B6: ='Solicitudes Regiones'!$B$6:$R$6 -> Julio de 2008 a junio de 2022
B8: Distribución Regional Solicitudes de PGU y Pilar Solidario - no incluye ex Pasis
B9: COMUNA | C9: TIPO BENEFICIO
C10: PBSV/PGU No Contributivo | D10: PBSI | E10: TOTAL PGU No Contributiva+PBS | F10: % PGU No Contributiva+PBS | G10: PGU Contributivo | H10: APSV | I10: APSI | J10: Total PGU Contributiva+APS | K10: %PGU Contributiva+APS | L10: Nbis | M10: Total PGU+PBS+APS
B11: ARICA | C11: 6628 | D11: 3092 | E11: =C11+D11 -> 9720 | F11: =E11/$E$15 -> 0.97600161 | G11: 22303 | H11: 4243 | I11: 1374 | J11: 27920 | K11: 0.99295825 | L11: 0 | M11: 37640
B12: CAMARONES | C12: 29 | D12: 10 | E12: =C12+D12 -> 39 | F12: =E12/$E$15 -> 0.0039160558 | G12: 44 | H12: 5 | I12: 1 | J12: 50 | K12: 0.0017782204 | L12: 0 | M12: 89
B13: PUTRE | C13: 97 | D13: 42 | E13: =C13+D13 -> 139 | F13: =E13/$E$15 -> 0.013957225 | G13: 101 | H13: 25 | I13: 2 | J13: 128 | K13: 0.0045522441 | L13: 0 | M13: 267
B14: GENERAL LAGOS | C14: 41 | D14: 20 | E14: =C14+D14 -> 61 | F14: =E14/$E$15 -> 0.006125113 | G14: 20 | H14: 0 | I14: 0 | J14: 20 | K14: 0.00071128814 | L14: 0 | M14: 81
B15: Totales | C15: =SUM(C11:C14) -> 6795 | D15: =SUM(D11:D14) -> 3164 | E15: =C15+D15 -> 9959 | F15: =E15/$E$15 -> 1 | G15: =SUM(G11:G14) -> 22468 | H15: =SUM(H11:H14) -> 4273 | I15: =G15+H15 -> 26741 | J15: 28118 | K15: 1 | L15: =SUM(L11:L14) -> 0 | M15: =SUM(M11:M14) -> 38077
B16: % respecto del total de solicitudes | C16: =+C15/$M$15 -> 0.17845418 | D16: =+D15/$M$15 -> 0.083094782 | E16: =+E15/$M$15 -> 0.26154897 | G16: =+G15/$M$15 -> 0.59006749 | H16: =+H15/$M$15 -> 0.11221998 | I16: =+I15/$M$15 -> 0.70228747 | J16: =+J15/$M$15 -> 0.73845103 | K16: =E16+J16 -> 1 | L16: =+L15/M15 -> 0 | M16: =J16+L16+E16 -> 1
B19: Número de Concesiones de Beneficios de PGU y SPS según tipo de beneficio - XV Región de Arica y Parinacota
B20: ='Solicitudes Regiones'!$B$6:$R$6 -> Julio de 2008 a junio de 2022
B22: Concesiones de PGU y Pilar Solidario a nivel comunal
B23: COMUNA | C23: TIPO BENEFICIO
C24: PBSV/PGU No Contributivo | D24: PBSI | E24: TOTAL PGU No Contributiva+PBS | F24: % PGU No Contributiva+PBS | G24: PGU Contributivo | H24: APSV | I24: APSI | J24: Total PGU Contributiva+APS | K24: %PGU Contributiva+APS | L24: Nbis | M24: Total PGU+PBS+APS
B25: ARICA | C25: 5800 | D25: 2133 | E25: 7933 | F25: 0.97841638 | G25: 19056 | H25: 2415 | I25: 1153 | J25: 22624 | K25: 0.99289037 | L25: 0 | M25: 30557
B26: CAMARONES | C26: 26 | D26: 4 | E26: 30 | F26: 0.0037000493 | G26: 40 | H26: 4 | I26: 1 | J26: 45 | K26: 0.0019748969 | L26: 0 | M26: 75
B27: PUTRE | C27: 84 | D27: 18 | E27: 102 | F27: 0.012580168 | G27: 89 | H27: 11 | I27: 2 | J27: 102 | K27: 0.0044764329 | L27: 0 | M27: 204
B28: GENERAL LAGOS | C28: 35 | D28: 8 | E28: 43 | F28: 0.005303404 | G28: 15 | H28: 0 | I28: 0 | J28: 15 | K28: 0.00065829896 | L28: 0 | M28: 58
B29: Totales | C29: =SUM(C25:C28) -> 5945 | D29: =SUM(D25:D28) -> 2163 | E29: =SUM(E25:E28) -> 8108 | F29: =SUM(F25:F28) -> 1 | G29: =SUM(G25:G28) -> 19200 | H29: =SUM(H25:H28) -> 2430 | I29: =SUM(I25:I28) -> 1156 | J29: =SUM(J25:J28) -> 22786 | ... M29: =SUM(M25:M28) -> 30894
B30: % respecto del total de concesiones | C30: =+C29/M29 -> 0.19243219 | D30: =+D29/M29 -> 0.070013595 | E30: =+E29/M29 -> 0.26244578 | G30: =+G29/M29 -> 0.6214799 | H30: =+H29/M29 -> 0.07865605 | I30: =+I29/M29 -> 0.037418269 | J30: =+J29/M29 -> 0.73755422 | K30: =+K29/M29 -> 3.2368745e-05 | L30: =+L29/M29 -> 0 | M30: =J30+L30+E30 -> 1
B31: Fuente: Elaboración propia sobre la base de información del IPS.
B32: Nota: La información estadística reportada del número de solicitudes concesionadas, en trámite, rechazadas y anuladas varía mes a mes por actualización de cifras.

Sheet I
A2: Subsecretaría de Previsión Social
A3: Dirección de Estudios Previsionales
B5: Número de Solicitudes de Beneficios de PGU y SPS según tipo de beneficio - I Región de Tarapacá | M5: Volver Sistema de Pensiones Solidarias
B6: ='Solicitudes Regiones'!$B$6:$R$6 -> Julio de 2008 a junio de 2022
B8: Distribución Regional Solicitudes de PGU y Pilar Solidario - no incluye ex Pasis
B9: COMUNA | C9: TIPO BENEFICIO
C10: PBSV/PGU No Contributivo | D10: PBSI | E10: TOTAL PGU No Contributiva+PBS | F10: % PGU No Contributiva+PBS | G10: PGU Contributivo | H10: APSV | I10: APSI | J10: Total PGU Contributiva+APS | K10: %PGU Contributiva+APS | L10: Nbis | M10: Total PGU+PBS+APS
B11: IQUIQUE | C11: 4840 | D11: 2954 | E11: =C11+D11 -> 7794 | F11: =E11/$E$18 -> 0.62718275 | G11: 17636 | H11: 4262 | I11: 1368 | J11: 23266 | K11: =J11/$J$18 -> 0.71600911 | L11: 0 | M11: =J11+L11+E11 -> 31060
B12: ALTO HOSPICIO | C12: 1496 | D12: 1820 | E12: =C12+D12 -> 3316 | F12: =E12/$E$18 -> 0.26683834 | G12: 5121 | H12: 870 | I12: 741 | J12: 6732 | K12: =J12/$J$18 -> 0.20717671 | L12: 0 | M12: =J12+L12+E12 -> 10048
B13: POZO ALMONTE | C13: 351 | D13: 220 | E13: =C13+D13 -> 571 | F13: =E13/$E$18 -> 0.045948338 | G13: 980 | H13: 232 | I13: 83 | J13: 1295 | K13: =J13/$J$18 -> 0.039853511 | L13: 0 | M13: =J13+L13+E13 -> 1866
B14: CAMIÑA | C14: 68 | D14: 43 | E14: =C14+D14 -> 111 | F14: =E14/$E$18 -> 0.0089321638 | G14: 94 | H14: 4 | I14: 12 | J14: 110 | K14: =J14/$J$18 -> 0.0033852404 | L14: 0 | M14: =J14+L14+E14 -> 221
B15: COLCHANE | C15: 65 | D15: 39 | E15: =C15+D15 -> 104 | F15: =E15/$E$18 -> 0.0083688742 | G15: 48 | H15: 4 | I15: 5 | J15: 57 | K15: =J15/$J$18 -> 0.00175417 | L15: 0 | M15: =J15+L15+E15 -> 161
B16: HUARA | C16: 129 | D16: 93 | E16: =C16+D16 -> 222 | F16: =E16/$E$18 -> 0.017864328 | G16: 258 | H16: 52 | I16: 25 | J16: 335 | K16: =J16/$J$18 -> 0.010309596 | L16: 0 | M16: =J16+L16+E16 -> 557
B17: PICA | C17: 196 | D17: 113 | E17: =C17+D17 -> 309 | F17: =E17/$E$18 -> 0.024865213 | G17: 571 | H17: 96 | I17: 32 | J17: 699 | K17: =J17/$J$18 -> 0.021511664 | L17: 0 | M17: =J17+L17+E17 -> 1008
B18: Totales | C18: =SUM(C11:C17) -> 7145 | D18: =SUM(D11:D17) -> 5282 | E18: =C18+D18 -> 12427 | F18: =E18/$E$18 -> 1 | G18: =SUM(G11:G17) -> 24708 | H18: =SUM(H11:H17) -> 5520 | I18: =G18+H18 -> 30228 | J18: 32494 | K18: =J18/$J$18 -> 1 | L18: =SUM(L11:L17) -> 0 | M18: =SUM(M11:M17) -> 44921
B19: % respecto del total de solicitudes | C19: =+C18/M18 -> 0.15905701 | D19: =+D18/M18 -> 0.1175842 | E19: =+E18/M18 -> 0.27664121 | G19: =+G18/M18 -> 0.55003228 | H19: =+H18/M18 -> 0.12288239 | I19: =+I18/M18 -> 0.67291467 | J19: =+J18/M18 -> 0.72335879 | L19: =+L18/M18 -> 0 | M19: =J19+L19+E19 -> 1
B21: Número de Concesiones de Beneficios de PGU y SPS según tipo de beneficio - I Región de Tarapacá
B22: ='Solicitudes Regiones'!$B$6:$R$6 -> Julio de 2008 a junio de 2022
B24: Concesiones de PGU y Pilar Solidario a nivel comunal
B25: COMUNA | C25: TIPO BENEFICIO
C26: PBSV/PGU No Contributivo | D26: PBSI | E26: TOTAL PGU No Contributiva+PBS | F26: % PGU No Contributiva+PBS | G26: PGU Contributivo | H26: APSV | I26: APSI | J26: Total PGU Contributiva+APS | K26: %PGU Contributiva+APS | L26: Nbis | M26: Total PGU+PBS+APS
B27: IQUIQUE | C27: 3957 | D27: 1746 | E27: =C27+D27 -> 5703 | F27: =E27/$E$18 -> 0.45892009 | G27: 14326 | H27: 1997 | I27: 1076 | J27: =SUM(G27:I27) -> 17399 | K27: =J27/$J$34 -> 0.69906384 | L27: 0 | M27: =J27+L27+E27 -> 23102
B28: ALTO HOSPICIO | C28: 1262 | D28: 1054 | E28: =C28+D28 -> 2316 | F28: =E28/$E$18 -> 0.18636839 | G28: 4477 | H28: 463 | I28: 594 | J28: =SUM(G28:I28) -> 5534 | K28: =J28/$J$34 -> 0.22234722 | L28: 0 | M28: =J28+L28+E28 -> 7850
B29: POZO ALMONTE | C29: 288 | D29: 112 | E29: =C29+D29 -> 400 | F29: =E29/$E$18 -> 0.032187978 | G29: 827 | H29: 103 | I29: 67 | J29: =SUM(G29:I29) -> 997 | K29: =J29/$J$34 -> 0.040057857 | L29: 0 | M29: =J29+L29+E29 -> 1397
B30: CAMIÑA | C30: 63 | D30: 23 | E30: =C30+D30 -> 86 | F30: =E30/$E$18 -> 0.0069204152 | G30: 85 | H30: 1 | I30: 9 | J30: =SUM(G30:I30) -> 95 | K30: =J30/$J$34 -> 0.0038169472 | L30: 0 | M30: =J30+L30+E30 -> 181
B31: COLCHANE | C31: 60 | D31: 20 | E31: =C31+D31 -> 80 | F31: =E31/$E$18 -> 0.0064375956 | G31: 45 | H31: 1 | I31: 5 | J31: =SUM(G31:I31) -> 51 | K31: =J31/$J$34 -> 0.002049098 | L31: 0 | M31: =J31+L31+E31 -> 131
B32: HUARA | C32: 115 | D32: 46 | E32: =C32+D32 -> 161 | F32: =E32/$E$18 -> 0.012955661 | G32: 229 | H32: 25 | I32: 25 | J32: =SUM(G32:I32) -> 279 | K32: =J32/$J$34 -> 0.011209771 | L32: 0 | M32: =J32+L32+E32 -> 440
B33: PICA | C33: 161 | D33: 64 | E33: =C33+D33 -> 225 | F33: =E33/$E$18 -> 0.018105738 | G33: 473 | H33: 39 | I33: 22 | J33: =SUM(G33:I33) -> 534 | K33: =J33/$J$34 -> 0.021455261 | L33: 0 | M33: =J33+L33+E33 -> 759
B34: Totales | C34: =SUM(C27:C33) -> 5906 | D34: =SUM(D27:D33) -> 3065 | E34: =C34+D34 -> 8971 | F34: =E34/$E$18 -> 0.72189587 | G34: =SUM(G27:G33) -> 20462 | H34: =SUM(H27:H33) -> 2629 | I34: =SUM(I27:I33) -> 1798 | J34: =SUM(G34:I34) -> 24889 | K34: =J34/$J$34 -> 1 | L34: =SUM(L27:L33) -> 0 | M34: =J34+L34+E34 -> 33860
B35: % respecto del total de concesiones | C35: =+C34/M34 -> 0.1744241 | D35: =+D34/M34 -> 0.090519787 | E35: =+E34/M34 -> 0.26494389 | G35: =+G34/M34 -> 0.60431187 | H35: =+H34/M34 -> 0.077643237 | I35: =+I34/M34 -> 0.053101004 | J35: =+J34/M34 -> 0.73505611 | L35: =+L34/M34 -> 0 | M35: =J35+L35+E35 -> 1
B36: Fuente: Elaboración propia sobre la base de información del IPS.
B37: Nota: La información estadística reportada del número de solicitudes concesionadas, en trámite, rechazadas y anuladas varía mes a mes por actualización de cifras.

Sheet II
A2: Subsecretaría de Previsión Social
A3: Dirección de Estudios Previsionales
B5: Número de Solicitudes de Beneficios de PGU y SPS según tipo de beneficio - II Región de Antofagasta | M5: Volver Sistema de Pensiones Solidarias
B6: ='Solicitudes Regiones'!$B$6:$R$6 -> Julio de 2008 a junio de 2022
B8: Distribución Regional Solicitudes de PGU y Pilar Solidario - no incluye ex Pasis
B9: COMUNA | C9: TIPO BENEFICIO
C10: PBSV/PGU No Contributivo | D10: PBSI | E10: TOTAL PGU No Contributiva+PBS | F10: % PGU No Contributiva+PBS | G10: PGU Contributivo | H10: APSV | I10: APSI | J10: Total PGU Contributiva+APS | K10: %PGU Contributiva+APS | L10: Nbis | M10: Total PGU+PBS+APS
B11: ANTOFAGASTA | C11: 8434 | D11: 4265 | E11: =C11+D11 -> 12699 | F11: =E11/$E$20 -> 0.61481481 | G11: 28572 | H11: 5888 | I11: 1731 | J11: =SUM(G11:I11) -> 36191 | K11: =J11/$J$20 -> 0.65257217 | L11: 0 | M11: =L11+J11+E11 -> 48890
B12: MEJILLONES | C12: 264 | D12: 113 | E12: =C12+D12 -> 377 | F12: =E12/$E$20 -> 0.018252239 | G12: 816 | H12: 203 | I12: 43 | J12: =SUM(G12:I12) -> 1062 | K12: =J12/$J$20 -> 0.019149281 | L12: 0 | M12: =L12+J12+E12 -> 1439
B13: SIERRA GORDA | C13: 24 | D13: 13 | E13: =C13+D13 -> 37 | F13: =E13/$E$20 -> 0.0017913338 | G13: 51 | H13: 15 | I13: 5 | J13: =SUM(G13:I13) -> 71 | K13: =J13/$J$20 -> 0.001280225 | L13: 0 | M13: =L13+J13+E13 -> 108
B14: TALTAL | C14: 420 | D14: 323 | E14: =C14+D14 -> 743 | F14: =E14/$E$20 -> 0.03597192 | G14: 1253 | H14: 257 | I14: 77 | J14: =SUM(G14:I14) -> 1587 | K14: =J14/$J$20 -> 0.028615734 | L14: 0 | M14: =L14+J14+E14 -> 2330
B15: CALAMA | C15: 3524 | D15: 1365 | E15: =C15+D15 -> 4889 | F15: =E15/$E$20 -> 0.23669814 | G15: 9845 | H15: 1839 | I15: 506 | J15: =SUM(G15:I15) -> 12190 | K15: =J15/$J$20 -> 0.21980202 | L15: 0 | M15: =L15+J15+E15 -> 17079
B16: OLLAGUE | C16: 16 | D16: 1 | E16: =C16+D16 -> 17 | F16: =E16/$E$20 -> 0.00082304527 | G16: 21 | H16: 2 | I16: 1 | J16: =SUM(G16:I16) -> 24 | K16: =J16/$J$20 -> 0.00043275212 | L16: 0 | M16: =L16+J16+E16 -> 41
B17: SAN PEDRO DE ATACAMA | C17: 198 | D17: 59 | E17: =C17+D17 -> 257 | F17: =E17/$E$20 -> 0.012442508 | G17: 432 | H17: 71 | I17: 21 | J17: =SUM(G17:I17) -> 524 | K17: =J17/$J$20 -> 0.0094484214 | L17: 0 | M17: =L17+J17+E17 -> 781
B18: TOCOPILLA | C18: 928 | D18: 575 | E18: =C18+D18 -> 1503 | F18: =E18/$E$20 -> 0.072766885 | G18: 2774 | H18: 530 | I18: 162 | J18: =SUM(G18:I18) -> 3466 | K18: =J18/$J$20 -> 0.062496619 | L18: 0 | M18: =L18+J18+E18 -> 4969
B19: MARIA ELENA | C19: 99 | D19: 34 | E19: =C19+D19 -> 133 | F19: =E19/$E$20 -> 0.0064391189 | G19: 272 | H19: 62 | I19: 10 | J19: =SUM(G19:I19) -> 344 | K19: =J19/$J$20 -> 0.0062027804 | L19: 0 | M19: =L19+J19+E19 -> 477
B20: Totales | C20: =SUM(C11:C19) -> 13907 | D20: =SUM(D11:D19) -> 6748 | E20: =C20+D20 -> 20655 | F20: =E20/$E$20 -> 1 | G20: =SUM(G11:G19) -> 44036 | H20: =SUM(H11:H19) -> 8867 | I20: =SUM(I11:I19) -> 2556 | J20: =SUM(G20:I20) -> 55459 | K20: =J20/$J$20 -> 1 | L20: =SUM(L11:L19) -> 0 | M20: =L20+J20+E20 -> 76114
B21: % respecto del total de solicitudes | C21: =+C20/M20 -> 0.18271277 | D21: =+D20/M20 -> 0.088656489 | E21: =+E20/M20 -> 0.27136926 | G21: =+G20/M20 -> 0.57855322 | H21: =+H20/M20 -> 0.11649631 | I21: =+I20/M20 -> 0.033581207 | J21: =+J20/M20 -> 0.72863074 | L21: =+L20/M20 -> 0 | M21: =J21+L21+E21 -> 1
B23: Número de Concesiones de Beneficios de PGU y SPS según tipo de beneficio - II Región de Antofagasta
B24: ='Solicitudes Regiones'!$B$6:$R$6 -> Julio de 2008 a junio de 2022
B26: Concesiones de PGU y Pilar Solidario a nivel comunal
B27: COMUNA | C27: TIPO BENEFICIO
C28: PBSV/PGU No Contributivo | D28: PBSI | E28: TOTAL PGU No Contributiva+PBS | F28: % PGU No Contributiva+PBS | G28: PGU Contributivo | H28: APSV | I28: APSI | J28: Total PGU Contributiva+APS | K28: %PGU Contributiva+APS | L28: Nbis | M28: Total PGU+PBS+APS
B29: ANTOFAGASTA | C29: 6664 | D29: 2498 | E29: =D29+C29 -> 9162 | F29: =E29/$E$38 -> 0.61947262 | G29: 22635 | H29: 2786 | I29: 1400 | J29: 26821 | K29: =J29/$J$38 -> 0.65375615 | L29: 0 | M29: =L29+J29+E29 -> 35983
B30: MEJILLONES | C30: 190 | D30: 53 | E30: =D30+C30 -> 243 | F30: =E30/$E$38 -> 0.01643002 | G30: 641 | H30: 89 | I30: 34 | J30: 764 | K30: =J30/$J$38 -> 0.018622337 | L30: 0 | M30: =L30+J30+E30 -> 1007
B31: SIERRA GORDA | C31: 21 | D31: 8 | E31: =D31+C31 -> 29 | F31: =E31/$E$38 -> 0.0019607843 | G31: 44 | H31: 8 | I31: 4 | J31: 56 | K31: =J31/$J$38 -> 0.0013649881 | L31: 0 | M31: =L31+J31+E31 -> 85
B32: TALTAL | C32: 329 | D32: 156 | E32: =D32+C32 -> 485 | F32: =E32/$E$38 -> 0.032792427 | G32: 1043 | H32: 102 | I32: 55 | J32: 1200 | K32: =J32/$J$38 -> 0.029249744 | L32: 0 | M32: =L32+J32+E32 -> 1685
B33: CALAMA | C33: 2687 | D33: 837 | E33: =D33+C33 -> 3524 | F33: =E33/$E$38 -> 0.2382691 | G33: 7545 | H33: 833 | I33: 399 | J33: 8777 | K33: =J33/$J$38 -> 0.2139375 | L33: 0 | M33: =L33+J33+E33 -> 12301
B34: OLLAGUE | C34: 15 | D34: 1 | E34: =D34+C34 -> 16 | F34: =E34/$E$38 -> 0.001081812 | G34: 17 | H34: 1 | I34: 1 | J34: 19 | K34: =J34/$J$38 -> 0.00046312095 | L34: 0 | M34: =L34+J34+E34 -> 35
B35: SAN PEDRO DE ATACAMA | C35: 166 | D35: 35 | E35: =D35+C35 -> 201 | F35: =E35/$E$38 -> 0.013590264 | G35: 363 | H35: 33 | I35: 15 | J35: 411 | K35: =J35/$J$38 -> 0.010018037 | L35: 0 | M35: =L35+J35+E35 -> 612
B36: TOCOPILLA | C36: 738 | D36: 303 | E36: =D36+C36 -> 1041 | F36: =E36/$E$38 -> 0.070385396 | G36: 2360 | H36: 243 | I36: 127 | J36: 2730 | K36: =J36/$J$38 -> 0.066543168 | L36: 0 | M36: =L36+J36+E36 -> 3771
B37: MARIA ELENA | C37: 72 | D37: 17 | E37: =D37+C37 -> 89 | F37: =E37/$E$38 -> 0.0060175794 | G37: 208 | H37: 32 | I37: 8 | J37: 248 | K37: =J37/$J$38 -> 0.0060449471 | L37: 0 | M37: =L37+J37+E37 -> 337
B38: Totales | C38: =SUM(C29:C37) -> 10882 | D38: =SUM(D29:D37) -> 3908 | E38: =D38+C38 -> 14790 | F38: =E38/$E$38 -> 1 | G38: =SUM(G29:G37) -> 34856 | H38: =SUM(H29:H37) -> 4127 | I38: =SUM(I29:I37) -> 2043 | J38: =SUM(J29:J37) -> 41026 | K38: =J38/$J$38 -> 1 | L38: =SUM(L29:L37) -> 0 | M38: =L38+J38+E38 -> 55816
B39: % respecto del total de concesiones | C39: =+C38/M38 -> 0.19496202 | D39: =+D38/M38 -> 0.070015766 | E39: =+E38/M38 -> 0.26497778 | G39: =+G38/M38 -> 0.62448044 | H39: =+H38/M38 -> 0.073939372 | I39: =+I38/M38 -> 0.036602408 | J39: =+J38/M38 -> 0.73502222 | L39: =+L38/M38 -> 0 | M39: =J39+L39+E39 -> 1
B40: Fuente: Elaboración propia sobre la base de información del IPS.
B41: Nota: La información estadística reportada del número de solicitudes concesionadas, en trámite, rechazadas y anuladas varía mes a mes por actualización de cifras.
B131: Copiar extraccion TODOS desde casilla A140, luego formatear numeros con punto sindecimales

Sheet III
A2: Subsecretaría de Previsión Social
A3: Dirección de Estudios Previsionales
B5: Número de Solicitudes de Beneficios de PGU y SPS según tipo de beneficio - III Región de Atacama | M5: Volver Sistema de Pensiones Solidarias
B6: ='Solicitudes Regiones'!$B$6:$R$6 -> Julio de 2008 a junio de 2022
B8: Distribución Regional Solicitudes de PGU y Pilar Solidario - no incluye ex Pasis
B9: COMUNA | C9: TIPO BENEFICIO
C10: PBSV/PGU No Contributivo | D10: PBSI | E10: TOTAL PGU No Contributiva+PBS | F10: % PGU No Contributiva+PBS | G10: PGU Contributivo | H10: APSV | I10: APSI | J10: Total PGU Contributiva+APS | K10: %PGU Contributiva+APS | L10: Nbis | M10: Total PGU+PBS+APS
B11: COPIAPO | C11: 3766 | D11: 1966 | E11: =C11+D11 -> 5732 | F11: =E11/$E$20 -> 0.45197918 | G11: 13691 | H11: 2393 | I11: 875 | J11: 16959 | K11: =J11/$J$20 -> 0.49902895 | L11: 0 | M11: =L11+J11+E11 -> 22691
B12: CALDERA | C12: 463 | D12: 255 | E12: =C12+D12 -> 718 | F12: =E12/$E$20 -> 0.056615676 | G12: 1674 | H12: 285 | I12: 107 | J12: 2066 | K12: =J12/$J$20 -> 0.060793315 | L12: 0 | M12: =L12+J12+E12 -> 2784
B13: TIERRA AMARILLA | C13: 290 | D13: 204 | E13: =C13+D13 -> 494 | F13: =E13/$E$20 -> 0.038952847 | G13: 1013 | H13: 173 | I13: 76 | J13: 1262 | K13: =J13/$J$20 -> 0.037135122 | L13: 0 | M13: =L13+J13+E13 -> 1756
B14: CHAÑARAL | C14: 555 | D14: 243 | E14: =C14+D14 -> 798 | F14: =E14/$E$20 -> 0.062923829 | G14: 1386 | H14: 274 | I14: 91 | J14: 1751 | K14: =J14/$J$20 -> 0.051524247 | L14: 0 | M14: =L14+J14+E14 -> 2549
B15: DIEGO DE ALMAGRO | C15: 345 | D15: 239 | E15: =C15+D15 -> 584 | F15: =E15/$E$20 -> 0.046049519 | G15: 890 | H15: 142 | I15: 58 | J15: 1090 | K15: =J15/$J$20 -> 0.032073917 | L15: 0 | M15: =L15+J15+E15 -> 1674
B16: VALLENAR | C16: 2082 | D16: 996 | E16: =C16+D16 -> 3078 | F16: =E16/$E$20 -> 0.2427062 | G16: 6617 | H16: 999 | I16: 312 | J16: 7928 | K16: =J16/$J$20 -> 0.23328625 | L16: 0 | M16: =L16+J16+E16 -> 11006
B17: ALTO DEL CARMEN | C17: 235 | D17: 119 | E17: =C17+D17 -> 354 | F17: =E17/$E$20 -> 0.027913578 | G17: 631 | H17: 51 | I17: 28 | J17: 710 | K17: =J17/$J$20 -> 0.020892185 | L17: 0 | M17: =L17+J17+E17 -> 1064
B18: FREIRINA | C18: 252 | D18: 119 | E18: =C18+D18 -> 371 | F18: =E18/$E$20 -> 0.029254061 | G18: 756 | H18: 100 | I18: 37 | J18: 893 | K18: =J18/$J$20 -> 0.026277072 | L18: 0 | M18: =L18+J18+E18 -> 1264
B19: HUASCO | C19: 401 | D19: 152 | E19: =C19+D19 -> 553 | F19: =E19/$E$20 -> 0.04360511 | G19: 1136 | H19: 131 | I19: 58 | J19: 1325 | K19: =J19/$J$20 -> 0.038988936 | L19: 0 | M19: =L19+J19+E19 -> 1878
B20: Totales | C20: =SUM(C11:C19) -> 8389 | D20: =SUM(D11:D19) -> 4293 | E20: =C20+D20 -> 12682 | F20: =E20/$E$20 -> 1 | G20: =SUM(G11:G19) -> 27794 | H20: =SUM(H11:H19) -> 4548 | I20: =SUM(I11:I19) -> 1642 | J20: =SUM(J11:J19) -> 33984 | K20: =J20/$J$20 -> 1 | L20: =SUM(L11:L19) -> 0 | M20: =L20+J20+E20 -> 46666
B21: % respecto del total de solicitudes | C21: =+C20/M20 -> 0.17976685 | D21: =+D20/M20 -> 0.091994171 | E21: =+E20/M20 -> 0.27176103 | G21: =+G20/M20 -> 0.59559422 | H21: =+H20/M20 -> 0.097458535 | I21: =+I20/M20 -> 0.035186217 | J21: =+J20/M20 -> 0.72823897 | L21: =+L20/M20 -> 0 | M21: =J21+L21+E21 -> 1
B23: Número de concesiones de Beneficios de PGU y SPS según tipo de beneficio - III Región de Atacama
B24: ='Solicitudes Regiones'!$B$6:$R$6 -> Julio de 2008 a junio de 2022
B26: Concesiones de PGU y Pilar Solidario a nivel comunal
B27: COMUNA | C27: TIPO BENEFICIO
C28: PBSV/PGU No Contributivo | D28: PBSI | E28: TOTAL PGU No Contributiva+PBS | F28: % PGU No Contributiva+PBS | G28: PGU Contributivo | H28: APSV | I28: APSI | J28: Total PGU Contributiva+APS | K28: %PGU Contributiva+APS | L28: Nbis | M28: Total PGU+PBS+APS
B29: COPIAPO | C29: 3142 | D29: 1190 | E29: =C29+D29 -> 4332 | F29: =E29/$E$38 -> 0.45007792 | G29: 11395 | H29: 1277 | I29: 733 | J29: 13405 | K29: =J29/$J$38 -> 0.49328427 | L29: 0 | M29: =L29+J29+E29 -> 17737
B30: CALDERA | C30: 392 | D30: 152 | E30: =C30+D30 -> 544 | F30: =E30/$E$38 -> 0.056519481 | G30: 1400 | H30: 148 | I30: 86 | J30: 1634 | K30: =J30/$J$38 -> 0.060128795 | L30: 0 | M30: =L30+J30+E30 -> 2178
B31: TIERRA AMARILLA | C31: 248 | D31: 119 | E31: =C31+D31 -> 367 | F31: =E31/$E$38 -> 0.03812987 | G31: 910 | H31: 90 | I31: 60 | J31: 1060 | K31: =J31/$J$38 -> 0.03900644 | L31: 0 | M31: =L31+J31+E31 -> 1427
B32: CHAÑARAL | C32: 458 | D32: 150 | E32: =C32+D32 -> 608 | F32: =E32/$E$38 -> 0.063168831 | G32: 1221 | H32: 116 | I32: 57 | J32: 1394 | K32: =J32/$J$38 -> 0.051297148 | L32: 0 | M32: =L32+J32+E32 -> 2002
B33: DIEGO DE ALMAGRO | C33: 256 | D33: 136 | E33: =C33+D33 -> 392 | F33: =E33/$E$38 -> 0.040727273 | G33: 770 | H33: 62 | I33: 41 | J33: 873 | K33: =J33/$J$38 -> 0.032125115 | L33: 0 | M33: =L33+J33+E33 -> 1265
B34: VALLENAR | C34: 1772 | D34: 618 | E34: =C34+D34 -> 2390 | F34: =E34/$E$38 -> 0.24831169 | G34: 5612 | H34: 572 | I34: 268 | J34: 6452 | K34: =J34/$J$38 -> 0.2374241 | L34: 0 | M34: =L34+J34+E34 -> 8842
B35: ALTO DEL CARMEN | C35: 217 | D35: 65 | E35: =C35+D35 -> 282 | F35: =E35/$E$38 -> 0.029298701 | G35: 552 | H35: 17 | I35: 25 | J35: 594 | K35: =J35/$J$38 -> 0.021858326 | L35: 0 | M35: =L35+J35+E35 -> 876
B36: FREIRINA | C36: 212 | D36: 85 | E36: =C36+D36 -> 297 | F36: =E36/$E$38 -> 0.030857143 | G36: 657 | H36: 47 | I36: 27 | J36: 731 | K36: =J36/$J$38 -> 0.026899724 | L36: 0 | M36: =L36+J36+E36 -> 1028
B37: HUASCO | C37: 323 | D37: 90 | E37: =C37+D37 -> 413 | F37: =E37/$E$38 -> 0.042909091 | G37: 913 | H37: 68 | I37: 51 | J37: 1032 | K37: =J37/$J$38 -> 0.037976081 | L37: 0 | M37: =L37+J37+E37 -> 1445
B38: Totales | C38: =SUM(C29:C37) -> 7020 | D38: =SUM(D29:D37) -> 2605 | E38: =C38+D38 -> 9625 | F38: =E38/$E$38 -> 1 | G38: =SUM(G29:G37) -> 23430 | H38: =SUM(H29:H37) -> 2397 | I38: =SUM(I29:I37) -> 1348 | J38: =SUM(J29:J37) -> 27175 | K38: =J38/$J$38 -> 1 | L38: =SUM(L29:L37) -> 0 | M38: =L38+J38+E38 -> 36800
B39: % respecto del total de concesiones | C39: =+C38/M38 -> 0.19076087 | D39: =+D38/M38 -> 0.070788043 | E39: =+E38/M38 -> 0.26154891 | G39: =+G38/M38 -> 0.63668478 | H39: =+H38/M38 -> 0.06513587 | I39: =+I38/M38 -> 0.036630435 | J39: =+J38/M38 -> 0.73845109 | L39: =+L38/M38 -> 0 | M39: =J39+L39+E39 -> 1
B40: Fuente: Elaboración propia sobre la base de información del IPS.
B41: Nota: La información estadística reportada del número de solicitudes concesionadas, en trámite, rechazadas y anuladas varía mes a mes por actualización de cifras.
B131: Copiar extraccion TODOS desde casilla A140, luego formatear numeros con punto sindecimales

Sheet IV
A2: Subsecretaría de Previsión Social
A3: Dirección de Estudios Previsionales
B5: Número de Solicitudes de Beneficios de PGU y SPS según tipo de beneficio - IV Región de Coquimbo | M5: Volver Sistema de Pensiones Solidarias
B6: ='Solicitudes Regiones'!$B$6:$R$6 -> Julio de 2008 a junio de 2022
B8: Distribución Regional Solicitudes de PGU y Pilar Solidario - no incluye ex Pasis
B9: COMUNA | C9: TIPO BENEFICIO
C10: PBSV/PGU No Contributivo | D10: PBSI | E10: TOTAL PGU No Contributiva+PBS | F10: % PGU No Contributiva+PBS | G10: PGU Contributivo | H10: APSV | I10: APSI | J10: Total PGU Contributiva+APS | K10: %PGU Contributiva+APS | L10: Nbis | M10: Total PGU+PBS+APS
B11: LA SERENA | C11: 6096 | D11: 3005 | E11: =C11+D11 -> 9101 | F11: =E11/$E$26 -> 0.23817749 | G11: 22117 | H11: 4675 | I11: 1342 | J11: 28134 | K11: =J11/$J$26 -> 0.27937321 | L11: 0 | M11: =L11+J11+E11 -> 37235
B12: COQUIMBO | C12: 6961 | D12: 3413 | E12: =C12+D12 -> 10374 | F12: =E12/$E$26 -> 0.2714925 | G12: 23637 | H12: 4488 | I12: 1394 | J12: 29519 | K12: =J12/$J$26 -> 0.29312639 | L12: 0 | M12: =L12+J12+E12 -> 39893
B13: ANDACOLLO | C13: 431 | D13: 270 | E13: =C13+D13 -> 701 | F13: =E13/$E$26 -> 0.018345503 | G13: 1437 | H13: 181 | I13: 72 | J13: 1690 | K13: =J13/$J$26 -> 0.016781856 | L13: 0 | M13: =L13+J13+E13 -> 2391
B14: LA HIGUERA | C14: 188 | D14: 83 | E14: =C14+D14 -> 271 | F14: =E14/$E$26 -> 0.0070921986 | G14: 438 | H14: 50 | I14: 32 | J14: 520 | K14: =J14/$J$26 -> 0.0051636479 | L14: 0 | M14: =L14+J14+E14 -> 791
B15: PAIHUANO | C15: 144 | D15: 62 | E15: =C15+D15 -> 206 | F15: =E15/$E$26 -> 0.0053911177 | G15: 582 | H15: 101 | I15: 24 | J15: 707 | K15: =J15/$J$26 -> 0.0070205752 | L15: 0 | M15: =L15+J15+E15 -> 913
B16: VICUÑA | C16: 732 | D16: 444 | E16: =C16+D16 -> 1176 | F16: =E16/$E$26 -> 0.030776478 | G16: 3261 | H16: 472 | I16: 211 | J16: 3944 | K16: =J16/$J$26 -> 0.039164283 | L16: 0 | M16: =L16+J16+E16 -> 5120
B17: ILLAPEL | C17: 1435 | D17: 611 | E17: =C17+D17 -> 2046 | F17: =E17/$E$26 -> 0.053544791 | G17: 4120 | H17: 637 | I17: 243 | J17: 5000 | K17: =J17/$J$26 -> 0.049650461 | L17: 0 | M17: =L17+J17+E17 -> 7046
B18: CANELA | C18: 537 | D18: 247 | E18: =C18+D18 -> 784 | F18: =E18/$E$26 -> 0.020517652 | G18: 1027 | H18: 84 | I18: 66 | J18: 1177 | K18: =J18/$J$26 -> 0.011687718 | L18: 0 | M18: =L18+J18+E18 -> 1961
B19: LOS VILOS | C19: 828 | D19: 380 | E19: =C19+D19 -> 1208 | F19: =E19/$E$26 -> 0.031613933 | G19: 2464 | H19: 339 | I19: 146 | J19: 2949 | K19: =J19/$J$26 -> 0.029283842 | L19: 0 | M19: =L19+J19+E19 -> 4157
B20: SALAMANCA | C20: 1251 | D20: 536 | E20: =C20+D20 -> 1787 | F20: =E20/$E$26 -> 0.046766638 | G20: 3380 | H20: 431 | I20: 163 | J20: 3974 | K20: =J20/$J$26 -> 0.039462186 | L20: 0 | M20: =L20+J20+E20 -> 5761
B21: OVALLE | C21: 4495 | D21: 1952 | E21: =C21+D21 -> 6447 | F21: =E21/$E$26 -> 0.16872105 | G21: 12321 | H21: 1750 | I21: 770 | J21: 14841 | K21: =J21/$J$26 -> 0.1473725 | L21: 0 | M21: =L21+J21+E21 -> 21288
B22: COMBARBALA | C22: 682 | D22: 348 | E22: =C22+D22 -> 1030 | F22: =E22/$E$26 -> 0.026955589 | G22: 2103 | H22: 225 | I22: 97 | J22: 2425 | K22: =J22/$J$26 -> 0.024080473 | L22: 0 | M22: =L22+J22+E22 -> 3455
... B25: RIO HURTADO | C25: 279 | D25: 84 | E25: =C25+D25 -> 363 | F25: =E25/$E$26 -> 0.0094998822 | G25: 538 | H25: 34 | I25: 25 | J25: 597 | K25: =J25/$J$26 -> 0.005928265 | L25: 0 | M25: =L25+J25+E25 -> 960
B26: Totales | C26: =SUM(C11:C25) -> 25719 | D26: =SUM(D11:D25) -> 12492 | E26: =C26+D26 -> 38211 | F26: =E26/$E$26 -> 1 | G26: =SUM(G11:G25) -> 81896 | H26: =SUM(H11:H25) -> 13873 | I26: =SUM(I11:I25) -> 4935 | J26: =SUM(J11:J25) -> 100704 | K26: =J26/$J$26 -> 1 | L26: =SUM(L11:L25) -> 0 | M26: =L26+J26+E26 -> 138915
B27: % respecto del total de solicitudes | C27: =+C26/M26 -> 0.18514199 | D27: =+D26/M26 -> 0.089925494 | E27: =+E26/M26 -> 0.27506749 | G27: =+G26/M26 -> 0.58954037 | H27: =+H26/M26 -> 0.099866825 | I27: =+I26/M26 -> 0.035525321 | J27: =+J26/M26 -> 0.72493251 | L27: =+L26/M26 -> 0 | M27: =J27+L27+E27 -> 1
B29: Número de Concesiones de Beneficios de PGU y SPS según tipo de beneficio - IV Región de Coquimbo
B30: ='Solicitudes Regiones'!$B$6:$R$6 -> Julio de 2008 a junio de 2022
B32: Concesiones de PGU y Pilar Solidario a nivel comunal
B33: COMUNA | C33: TIPO BENEFICIO
C34: PBSV/PGU No Contributivo | D34: PBSI | E34: TOTAL PGU No Contributiva+PBS | F34: % PGU No Contributiva+PBS | G34: PGU Contributivo | H34: APSV | I34: APSI | J34: Total PGU Contributiva+APS | K34: %PGU Contributiva+APS | L34: Nbis | M34: Total PGU+PBS+APS
B35: LA SERENA | C35: 5000 | D35: 1973 | E35: =C35+D35 -> 6973 | F35: =E35/$E$50 -> 0.23596494 | G35: 17443 | H35: 2220 | I35: 1157 | J35: 20820 | K35: =J35/$J$50 -> 0.2583928 | L35: 0 | M35: =L35+J35+E35 -> 27793
B36: COQUIMBO | C36: 5833 | D36: 2068 | E36: =C36+D36 -> 7901 | F36: =E36/$E$50 -> 0.26736828 | G36: 19667 | H36: 2367 | I36: 1243 | J36: 23277 | K36: =J36/$J$50 -> 0.28888613 | L36: 0 | M36: =L36+J36+E36 -> 31178
B37: ANDACOLLO | C37: 377 | D37: 123 | E37: =C37+D37 -> 500 | F37: =E37/$E$50 -> 0.016919901 | G37: 1318 | H37: 104 | I37: 64 | J37: 1486 | K37: =J37/$J$50 -> 0.018442445 | L37: 0 | M37: =L37+J37+E37 -> 1986
B38: LA HIGUERA | C38: 170 | D38: 50 | E38: =C38+D38 -> 220 | F38: =E38/$E$50 -> 0.0074447565 | G38: 393 | H38: 26 | I38: 29 | J38: 448 | K38: =J38/$J$50 -> 0.0055600372 | L38: 0 | M38: =L38+J38+E38 -> 668
B39: PAIHUANO | C39: 127 | D39: 37 | E39: =C39+D39 -> 164 | F39: =E39/$E$50 -> 0.0055497276 | G39: 516 | H39: 51 | I39: 20 | J39: 587 | K39: =J39/$J$50 -> 0.0072851381 | L39: 0 | M39: =L39+J39+E39 -> 751
B40: VICUÑA | C40: 629 | D40: 259 | E40: =C40+D40 -> 888 | F40: =E40/$E$50 -> 0.030049745 | G40: 2898 | H40: 245 | I40: 183 | J40: 3326 | K40: =J40/$J$50 -> 0.041278312 | L40: 0 | M40: =L40+J40+E40 -> 4214
B41: ILLAPEL | C41: 1251 | D41: 349 | E41: =C41+D41 -> 1600 | F41: =E41/$E$50 -> 0.054143684 | G41: 3618 | H41: 313 | I41: 208 | J41: 4139 | K41: =J41/$J$50 -> 0.05136829 | L41: 0 | M41: =L41+J41+E41 -> 5739
B42: CANELA | C42: 504 | D42: 132 | E42: =C42+D42 -> 636 | F42: =E42/$E$50 -> 0.021522114 | G42: 939 | H42: 44 | I42: 59 | J42: 1042 | K42: =J42/$J$50 -> 0.012932051 | L42: 0 | M42: =L42+J42+E42 -> 1678
B43: LOS VILOS | C43: 730 | D43: 220 | E43: =C43+D43 -> 950 | F43: =E43/$E$50 -> 0.032147812 | G43: 2181 | H43: 169 | I43: 124 | J43: 2474 | K43: =J43/$J$50 -> 0.030704313 | L43: 0 | M43: =L43+J43+E43 -> 3424
B44: SALAMANCA | C44: 1106 | D44: 322 | E44: =C44+D44 -> 1428 | F44: =E44/$E$50 -> 0.048323238 | G44: 3023 | H44: 179 | I44: 134 | J44: 3336 | K44: =J44/$J$50 -> 0.04140242 | L44: 0 | M44: =L44+J44+E44 -> 4764
B45: OVALLE | C45: 3968 | D45: 1223 | E45: =C45+D45 -> 5191 | F45: =E45/$E$50 -> 0.17566241 | G45: 10860 | H45: 923 | I45: 647 | J45: 12430 | K45: =J45/$J$50 -> 0.15426621 | L45: 0 | M45: =L45+J45+E45 -> 17621
B46: COMBARBALA | C46: 620 | D46: 174 | E46: =C46+D46 -> 794 | F46: =E46/$E$50 -> 0.026868803 | G46: 1861 | H46: 146 | I46: 87 | J46: 2094 | K46: =J46/$J$50 -> 0.02598821 | L46: 0 | M46: =L46+J46+E46 -> 2888
... B49: RIO HURTADO | C49: 260 | D49: 51 | E49: =C49+D49 -> 311 | F49: =E49/$E$50 -> 0.010524179 | G49: 496 | H49: 23 | I49: 23 | J49: 542 | K49: =J49/$J$50 -> 0.0067266522 | L49: 0 | M49: =L49+J49+E49 -> 853
...

Sheet V
A2: Subsecretaría de Previsión Social
A3: Dirección de Estudios Previsionales
B5: Número de Solicitudes de Beneficios de PGU y SPS según tipo de beneficio - V Región de Vaparaíso | M5: Volver Sistema de Pensiones Solidarias
B6: ='Solicitudes Regiones'!$B$6:$R$6 -> Julio de 2008 a junio de 2022
B8: Distribución Regional Solicitudes de PGU y Pilar Solidario - no incluye ex Pasis
B9: COMUNA | C9: TIPO BENEFICIO
C10: PBSV/PGU No Contributivo | D10: PBSI | E10: TOTAL PGU No Contributiva+PBS | F10: % PGU No Contributiva+PBS | G10: PGU Contributivo | H10: APSV | I10: APSI | J10: Total PGU Contributiva+APS | K10: %PGU Contributiva+APS | L10: Nbis | M10: Total PGU+PBS+APS
B11: VALPARAISO | C11: 10839 | D11: 6113 | E11: =C11+D11 -> 16952 | F11: =E11/$E$49 -> 0.17963145 | G11: 36614 | H11: 7498 | I11: 2803 | J11: 46915 | K11: =J11/$J$49 -> 0.17053055 | L11: 0 | M11: =L11+J11+E11 -> 63867
B12: CONCON | C12: 1217 | D12: 529 | E12: =C12+D12 -> 1746 | F12: =E12/$E$49 -> 0.018501446 | G12: 3885 | H12: 756 | I12: 204 | J12: 4845 | K12: =J12/$J$49 -> 0.017611009 | L12: 0 | M12: =L12+J12+E12 -> 6591
B13: PUCHUNCAVI | C13: 873 | D13: 317 | E13: =C13+D13 -> 1190 | F13: =E13/$E$49 -> 0.012609806 | G13: 2359 | H13: 421 | I13: 106 | J13: 2886 | K13: =J13/$J$49 -> 0.010490273 | L13: 0 | M13: =L13+J13+E13 -> 4076
B14: VIÑA DEL MAR | C14: 10055 | D14: 4122 | E14: =C14+D14 -> 14177 | F14: =E14/$E$49 -> 0.15022623 | G14: 38215 | H14: 8942 | I14: 2137 | J14: 49294 | K14: =J14/$J$49 -> 0.17917793 | L14: 0 | M14: =L14+J14+E14 -> 63471
B15: ISLA DE PASCUA | C15: 134 | D15: 77 | E15: =C15+D15 -> 211 | F15: =E15/$E$49 -> 0.0022358564 | G15: 390 | H15: 57 | I15: 39 | J15: 486 | K15: =J15/$J$49 -> 0.0017665533 | L15: 0 | M15: =L15+J15+E15 -> 697
B16: LOS ANDES | C16: 2014 | D16: 953 | E16: =C16+D16 -> 2967 | F16: =E16/$E$49 -> 0.031439743 | G16: 8212 | H16: 1671 | I16: 515 | J16: 10398 | K16: =J16/$J$49 -> 0.037795516 | L16: 0 | M16: =L16+J16+E16 -> 13365
B17: RINCONADA | C17: 208 | D17: 122 | E17: =C17+D17 -> 330 | F17: =E17/$E$49 -> 0.003496837 | G17: 1031 | H17: 130 | I17: 75 | J17: 1236 | K17: =J17/$J$49 -> 0.0044927157 | L17: 0 | M17: =L17+J17+E17 -> 1566
B18: SAN ESTEBAN | C18: 527 | D18: 312 | E18: =C18+D18 -> 839 | F18: =E18/$E$49 -> 0.008890443 | G18: 2077 | H18: 356 | I18: 126 | J18: 2559 | K18: =J18/$J$49 -> 0.0093016662 | L18: 0 | M18: =L18+J18+E18 -> 3398
B19: PAPUDO | C19: 232 | D19: 120 | E19: =C19+D19 -> 352 | F19: =E19/$E$49 -> 0.0037299594 | G19: 656 | H19: 101 | I19: 57 | J19: 814 | K19: =J19/$J$49 -> 0.002958795 | L19: 0 | M19: =L19+J19+E19 -> 1166
B20: LA CALERA | C20: 2235 | D20: 1168 | E20: =C20+D20 -> 3403 | F20: =E20/$E$49 -> 0.036059807 | G20: 6937 | H20: 1159 | I20: 545 | J20: 8641 | K20: =J20/$J$49 -> 0.031409026 | L20: 0 | M20: =L20+J20+E20 -> 12044
B21: HIJUELAS | C21: 835 | D21: 504 | E21: =C21+D21 -> 1339 | F21: =E21/$E$49 -> 0.014188681 | G21: 1995 | H21: 293 | I21: 205 | J21: 2493 | K21: =J21/$J$49 -> 0.0090617639 | L21: 0 | M21: =L21+J21+E21 -> 3832
B22: LA CRUZ | C22: 490 | D22: 223 | E22: =C22+D22 -> 713 | F22: =E22/$E$49 -> 0.0075552871 | G22: 1817 | H22: 269 | I22: 150 | J22: 2236 | K22: =J22/$J$49 -> 0.0081275989 | L22: 0 | M22: =L22+J22+E22 -> 2949
... B48: VILLA ALEMANA | C48: 3565 | D48: 2088 | E48: =C48+D48 -> 5653 | F48: =E48/$E$49 -> 0.059901877 | G48: 12779 | H48: 2439 | I48: 851 | J48: 16069 | K48: =J48/$J$49 -> 0.058408939 | L48: 0 | M48: =L48+J48+E48 -> 21722
B49: Totales | C49: =SUM(C11:C48) -> 62811 | D49: =SUM(D11:D48) -> 31560 | E49: =C49+D49 -> 94371 | F49: =E49/$E$49 -> 1 | G49: =SUM(G11:G48) -> 217788 | H49: =SUM(H11:H48) -> 42685 | I49: =SUM(I11:I48) -> 14639 | J49: =SUM(J11:J48) -> 275112 | K49: =J49/$J$49 -> 1 | L49: =SUM(L11:L48) -> 0 | M49: =L49+J49+E49 -> 369483
B50: % respecto del total de solicitudes | C50: =+C49/M49 -> 0.169997 | D50: =+D49/M49 -> 0.08541665 | E50: =+E49/M49 -> 0.25541365 | G50: =+G49/M49 -> 0.58943984 | H50: =+H49/M49 -> 0.11552629 | I50: =+I49/M49 -> 0.039620226 | J50: =+J49/M49 -> 0.74458635 | L50: =+L49/M49 -> 0 | M50: =J50+L50+E50 -> 1
B52: Número de Concesiones de Beneficios de PGU y SPS según tipo de beneficio - V Región de Vaparaíso
B53: ='Solicitudes Regiones'!$B$6:$R$6 -> Julio de 2008 a junio de 2022
B55: Concesiones de PGU y Pilar Solidario a nivel comunal
B56: COMUNA | C56: TIPO BENEFICIO
C57: PBSV/PGU No Contributivo | D57: PBSI | E57: TOTAL PGU No Contributiva+PBS | F57: % PGU No Contributiva+PBS | G57: PGU Contributivo | H57: APSV | I57: APSI | J57: Total PGU Contributiva+APS | K57: %PGU Contributiva+APS | L57: Nbis | M57: Total PGU+PBS+APS
B58: VALPARAISO | C58: 9611 | D58: 4146 | E58: =C58+D58 -> 13757 | F58: =E58/$E$96 -> 0.18649008 | G58: 31174 | H58: 3753 | I58: 2390 | J58: 37317 | K58: =J58/$J$96 -> 0.17274549 | L58: 0 | M58: =L58+J58+E58 -> 51074
B59: CONCON | C59: 987 | D59: 355 | E59: =C59+D59 -> 1342 | F59: =E59/$E$96 -> 0.01819217 | G59: 2923 | H59: 399 | I59: 170 | J59: 3492 | K59: =J59/$J$96 -> 0.016164945 | L59: 0 | M59: =L59+J59+E59 -> 4834
B60: PUCHUNCAVI | C60: 712 | D60: 165 | E60: =C60+D60 -> 877 | F60: =E60/$E$96 -> 0.011888624 | G60: 1921 | H60: 187 | I60: 94 | J60: 2202 | K60: =J60/$J$96 -> 0.010193359 | L60: 0 | M60: =L60+J60+E60 -> 3079
B61: VIÑA DEL MAR | C61: 8732 | D61: 2918 | E61: =C61+D61 -> 11650 | F61: =E61/$E$96 -> 0.15792756 | G61: 31410 | H61: 4154 | I61: 1826 | J61: 37390 | K61: =J61/$J$96 -> 0.17308342 | L61: 0 | M61: =L61+J61+E61 -> 49040
B62: ISLA DE PASCUA | C62: 115 | D62: 53 | E62: =C62+D62 -> 168 | F62: =E62/$E$96 -> 0.0022774103 | G62: 333 | H62: 29 | I62: 32 | J62: 394 | K62: =J62/$J$96 -> 0.0018238799 | L62: 0 | M62: =L62+J62+E62 -> 562
B63: LOS ANDES | C63: 1585 | D63: 504 | E63: =C63+D63 -> 2089 | F63: =E63/$E$96 -> 0.028318512 | G63: 6798 | H63: 817 | I63: 433 | J63: 8048 | K63: =J63/$J$96 -> 0.037255292 | L63: 0 | M63: =L63+J63+E63 -> 10137
B64: RINCONADA | C64: 181 | D64: 70 | E64: =C64+D64 -> 251 | F64: =E64/$E$96 -> 0.0034025594 | G64: 917 | H64: 73 | I64: 67 | J64: 1057 | K64: =J64/$J$96 -> 0.0048929975 | L64: 0 | M64: =L64+J64+E64 -> 1308
B65: SAN ESTEBAN | C65: 410 | D65: 141 | E65: =C65+D65 -> 551 | F65: =E65/$E$96 -> 0.0074693634 | G65: 1774 | H65: 156 | I65: 106 | J65: 2036 | K65: =J65/$J$96 -> 0.0094249223 | L65: 0 | M65: =L65+J65+E65 -> 2587
B66: PAPUDO | C66: 212 | D66: 71 | E66: =C66+D66 -> 283 | F66: =E66/$E$96 -> 0.0038363518 | G66: 541 | H66: 61 | I66: 39 | J66: 641 | K66: =J66/$J$96 -> 0.0029672766 | L66: 0 | M66: =L66+J66+E66 -> 924
B67: LA CALERA | C67: 1978 | D67: 709 | E67: =C67+D67 -> 2687 | F67: =E67/$E$96 -> 0.036425008 | G67: 6005 | H67: 630 | I67: 445 | J67: 7080 | K67: =J67/$J$96 -> 0.032774288 | L67: 0 | M67: =L67+J67+E67 -> 9767
B68: HIJUELAS | C68: 738 | D68: 279 | E68: =C68+D68 -> 1017 | F68: =E68/$E$96 -> 0.013786466 | G68: 1791 | H68: 122 | I68: 179 | J68: 2092 | K68: =J68/$J$96 -> 0.009684154 | L68: 0 | M68: =L68+J68+E68 -> 3109
B69: LA CRUZ | C69: 419 | D69: 137 | E69: =C69+D69 -> 556 | F69: =E69/$E$96 -> 0.0075371435 | G69: 1511 | H69: 149 | I69: 112 | J69: 1772 | K69: =J69/$J$96 -> 0.0082028303 | L69: 0 | M69: =L69+J69+E69 -> 2328
... B95: VILLA ALEMANA | C95: 3046 | D95: 1249 | E95: =C95+D95 -> 4295 | F95: =E95/$E$96 -> 0.058223078 | G95: 10382 | H95: 1314 | I95: 720 | J95: 12416 | K95: =J95/$J$96 -> 0.057475361 | L95: 0 | M95: =L95+J95+E95 -> 16711
...

Sheet VI
A2: Subsecretaría de Previsión Social
A3: Dirección de Estudios Previsionales
B5: Número de Solicitudes de Beneficios de PGU y SPS según tipo de beneficio - VI Región de L.G.B. O'Higgins | M5: Volver Sistema de Pensiones Solidarias
B6: ='Solicitudes Regiones'!$B$6:$R$6 -> Julio de 2008 a junio de 2022
B8: Distribución Regional Solicitudes de PGU y Pilar Solidario - no incluye ex Pasis
B9: COMUNA | C9: TIPO BENEFICIO
C10: PBSV/PGU No Contributivo | D10: PBSI | E10: TOTAL PGU No Contributiva+PBS | F10: % PGU No Contributiva+PBS | G10: PGU Contributivo | H10: APSV | I10: APSI | J10: Total PGU Contributiva+APS | K10: %PGU Contributiva+APS | L10: Nbis | M10: Total PGU+PBS+APS
B11: RANCAGUA | C11: 6852 | D11: 3930 | E11: =C11+D11 -> 10782 | F11: =E11/$E$44 -> 0.22294824 | G11: 25074 | H11: 4763 | I11: 2409 | J11: 32246 | K11: =J11/$J$44 -> 0.24927335 | L11: 0 | M11: =L11+J11+E11 -> 43028
