Workbook

Sheet datos
A2: Mes | B2: Septiembre de 2018

Sheet Índice
B1: Subsecretaría de Previsión Social Dirección de Estudios Previsionales
B5: Informe Estadístico Mensual del Pilar Solidario
B7: Introducción
B8: El presente archivo contiene los principales cuadros del Informe Estadístico Mensual del Pilar Solidario del mes de noviembre de 2018. Correspondiente a:
B10: Estadísticas del Sistema de Pensiones Solidarias
B11: Estadísticas del Bono por Hijo (BxH)
B12: Estadísticas del Subsidio Previsional a los Trabajadores Jóvenes (STJ)

Sheet Índice Pensiones Solidarias
A2: Subsecretaría de Previsión Social
A3: Dirección de Estudios Previsionales
B5: Sistema de Pensiones Solidarias | N5: Volver a Índice
B7: Introducción
B8: El presente archivo contiene los principales cuadros sobre el Sistema de Pensiones Solidarias del Informe Estadístico Mensual del Pilar Solidario del mes de noviembre de 2018. Los cuadros entregan información de los beneficios solicitados y concedidos mensualmente a nivel nacional, desde julio de 2008 a noviembre de 2018, asi como también la información de las solicitudes y concesiones a nivel regional y comunal acumulado a noviembre de 2018.
B11: Este archivo contiene información al 26 de diciembre de 2018
B13: Nacional
B14: Solicitudes recibidas en el Sistema de Pensiones Solidarias, según mes, desde julio 2008 a noviembre 2018
B15: Concesiones en el Sistema de Pensiones Solidarias, por mes, desde julio 2008 a noviembre 2018
B17: Regional
B18: Solicitudes recibidas en el Sistema de Pensiones Solidarias acumuladas desde julio 2008 a noviembre 2018, según región
B19: Concesiones en el Sistema de Pensiones Solidarias acumuladas desde julio 2008 a noviembre 2018, según región
B21: Solicitudes y Concesiones en el Sistema de Pensiones Solidarias acumulado a noviembre 2018 por región y comuna:
B22: XV Arica y Parinacota
B23: I Tarapaca
... B36: XIII Metropolitana

Sheet Solicitudes Nacional
A2: Subsecretaría de Previsión Social
A3: Dirección de Estudios Previsionales
B5: Número de solicitudes mensuales recibidas en el Sistema de Pensiones Solidarias, según tipo de beneficio, sexo y origen de tramitación del beneficio | Q5: Volver Sistema de Pensiones Solidarias
B6: Julio de 2008 a noviembre 2018
B8: TOTAL SOLICITUDES (no incluye ex Pasis)
B9: PERIODO | C9: TOTAL PBS Y APS | J9: SEXO | L9: ORIGEN DE TRAMITACIÓN DEL BENEFICIO
C10: PBSV | D10: PBSI | E10: TOTAL PBS | F10: APSV | G10: APSI | H10: TOTAL APS | I10: Total PBS + APS | J10: Femenino | K10: Masculino | L10: En IPS | M10: En AFP | N10: En Cías. de Seguro | O10: En Municipio
B11: Jul a Dic 2008 | C11: 84792 | D11: 37698 | E11: 122490 | F11: 13034 | G11: 6193 | H11: 19227 | I11: 141717 | J11: 109234 | K11: 32483 | L11: 97794 | M11: 1045 | N11: 0 | O11: 42878
B12: Total 2009 | C12: 59115 | D12: 35112 | E12: 94227 | F12: 297997 | G12: 11591 | H12: 309588 | I12: 403815 | J12: 255764 | K12: 148051 | L12: 299252 | M12: 30351 | N12: 0 | O12: 74212
B13: Total 2010 | C13: 40711 | D13: 24962 | E13: 65673 | F13: 168085 | G13: 11927 | H13: 180012 | I13: 245685 | J13: 152794 | K13: 92891 | L13: 148053 | M13: 32913 | N13: 5334 | O13: 59385
B14: Total 2011 | C14: 37244 | D14: 20916 | E14: 58160 | F14: 126024 | G14: 10364 | H14: 136388 | I14: 194548 | J14: 123196 | K14: 71352 | L14: 114198 | M14: 25995 | N14: 11385 | O14: 42970
B15: Total 2012 | C15: 33804 | D15: 18951 | E15: 52755 | F15: 130283 | G15: 8215 | H15: 138498 | I15: 191253 | J15: 118199 | K15: 73054 | L15: 125927 | M15: 24052 | N15: 9227 | O15: 32047
B16: Total 2013 | C16: 32881 | D16: 16868 | E16: 49749 | F16: 77015 | G16: 7300 | H16: 84315 | I16: 134064 | J16: 82123 | K16: 51941 | L16: 83744 | M16: 22684 | N16: 6357 | O16: 21279
B17: Total 2014 | C17: 39418 | D17: 17578 | E17: 56996 | F17: 88526 | G17: 6051 | H17: 94577 | I17: 151573 | J17: 92874 | K17: 58699 | L17: 94154 | M17: 27039 | N17: 6541 | O17: 23839
B18: Total 2015 | C18: 31090 | D18: 18492 | E18: 49582 | F18: 88831 | G18: 2497 | H18: 91328 | I18: 140910 | J18: 86207 | K18: 54703 | L18: 84082 | M18: 29599 | N18: 5383 | O18: 21846
B19: Total 2016 | C19: 27207 | D19: 18101 | E19: 45309 | F19: 84734 | G19: 2588 | H19: 87321 | I19: 132630 | J19: 82317 | K19: 50313 | L19: 78143 | M19: 29026 | N19: 4512 | O19: 20949
B20: Enero'17 | C20: 2774 | D20: 1509 | E20: 4283 | F20: 7639 | G20: 271 | H20: 7910 | I20: 12193 | J20: 7573 | K20: 4620 | L20: 7252 | M20: 2606 | N20: 384 | O20: 1951
B21: Febrero | C21: 2017 | D21: 1346 | E21: 3363 | F21: 7226 | G21: 208 | H21: 7434 | I21: 10797 | J21: 6584 | K21: 4213 | L21: 6608 | M21: 2309 | N21: 328 | O21: 1552
B22: Marzo | C22: 2559 | D22: 1723 | E22: 4282 | F22: 8941 | G22: 224 | H22: 9165 | I22: 13447 | J22: 8246 | K22: 5201 | L22: 8053 | M22: 3052 | N22: 374 | O22: 1968
... B45: TOTAL | C45: 439850 | D45: 242451 | E45: 682302 | F45: 1286601 | G45: 75978 | H45: 1362578 | I45: 2044880 | J45: 1288326 | K45: 756554 | L45: 1306357 | M45: 297344 | N45: 57666 | O45: 383513
B46: Fuente: Elaboración propia sobre la base de información del IPS.
B47: Nota: La información estadística reportada del número de solicitudes concesionadas, en trámite, rechazadas y anuladas varía mes a mes por actualización de cifras.

Sheet Concesiones Nacional
A2: Subsecretaría de Previsión Social
A3: Dirección de Estudios Previsionales
B5: Número de beneficios concedidos mensuales en el Sistema de Pensiones Solidarias, según tipo de beneficio, sexo y origen de tramitación del beneficio | Q5: Volver Sistema de Pensiones Solidarias
B6: ='Solicitudes Nacional'!B6:O6 -> Julio de 2008 a noviembre 2018
B8: TOTAL CONCEDIDAS (no incluye ex Pasis)
B9: MES | C9: TOTAL PBS Y APS | J9: SEXO | L9: ORIGEN DE TRAMITACIÓN DEL BENEFICIO
C10: PBSV | D10: PBSI | E10: TOTAL PBS | F10: APSV | G10: APSI | H10: TOTAL APS | I10: Total PBS+APS | J10: Femenino | K10: Masculino | L10: En IPS | M10: En AFP | N10: En Cías. de Seguro | O10: En Municipio
B11: Jul a Dic 2008 | C11: 83926 | D11: 21763 | E11: =C11+D11 -> 105689 | F11: 9666 | G11: 1628 | H11: =F11+G11 -> 11294 | I11: =E11+H11 -> 116983 | J11: 89933 | K11: 27050 | L11: 79515 | M11: 1004 | N11: 0 | O11: 36464
B12: Total 2009 | C12: 57791 | D12: 20961 | E12: =C12+D12 -> 78752 | F12: 277006 | G12: 9792 | H12: =F12+G12 -> 286798 | I12: =E12+H12 -> 365550 | J12: 224962 | K12: 140588 | L12: 272721 | M12: 26657 | N12: 0 | O12: 66172
B13: Total 2010 | C13: 36098 | D13: 13242 | E13: =C13+D13 -> 49340 | F13: 137903 | G13: 9911 | H13: =F13+G13 -> 147814 | I13: =E13+H13 -> 197154 | J13: 119654 | K13: 77500 | L13: 120953 | M13: 25691 | N13: 3837 | O13: 46673
B14: Total 2011 | C14: 29811 | D14: 10346 | E14: =C14+D14 -> 40157 | F14: 90244 | G14: 8697 | H14: =F14+G14 -> 98941 | I14: =E14+H14 -> 139098 | J14: 84677 | K14: 54421 | L14: 81301 | M14: 19165 | N14: 8017 | O14: 30615
B15: Total 2012 | C15: 29013 | D15: 9891 | E15: =C15+D15 -> 38904 | F15: 113336 | G15: 7011 | H15: =F15+G15 -> 120347 | I15: =E15+H15 -> 159251 | J15: 95235 | K15: 64016 | L15: 105746 | M15: 20843 | N15: 7849 | O15: 24813
B16: Total 2013 | C16: 29558 | D16: 8904 | E16: =C16+D16 -> 38462 | F16: 65551 | G16: 6049 | H16: =F16+G16 -> 71600 | I16: =E16+H16 -> 110062 | J16: 65774 | K16: 44288 | L16: 68652 | M16: 19386 | N16: 5326 | O16: 16698
B17: Total 2014 | C17: 32593 | D17: 9996 | E17: =C17+D17 -> 42589 | F17: 70042 | G17: 5270 | H17: =F17+G17 -> 75312 | I17: =E17+H17 -> 117901 | J17: 70002 | K17: 47899 | L17: 72048 | M17: 22546 | N17: 5133 | O17: 18174
B18: Total 2015 | C18: 26414 | D18: 11689 | E18: =C18+D18 -> 38103 | F18: 71155 | G18: 2081 | H18: =F18+G18 -> 73236 | I18: =E18+H18 -> 111339 | J18: 66002 | K18: 45337 | L18: 65219 | M18: 24953 | N18: 4306 | O18: 16861
B19: Total 2016 | C19: 21821 | D19: 11783 | E19: =C19+D19 -> 33604 | F19: 65463 | G19: 2218 | H19: =F19+G19 -> 67681 | I19: =E19+H19 -> 101285 | J19: 60888 | K19: 40397 | L19: 58604 | M19: 23647 | N19: 3436 | O19: 15598
B20: Enero'17 | C20: 2359 | D20: 1001 | E20: =C20+D20 -> 3360 | F20: 6051 | G20: 225 | H20: =F20+G20 -> 6276 | I20: =E20+H20 -> 9636 | J20: 5835 | K20: 3801 | L20: 5658 | M20: 2161 | N20: 306 | O20: 1511
B21: Febrero | C21: 1593 | D21: 871 | E21: =C21+D21 -> 2464 | F21: 5680 | G21: 183 | H21: =F21+G21 -> 5863 | I21: =E21+H21 -> 8327 | J21: 4926 | K21: 3401 | L21: 5032 | M21: 1876 | N21: 256 | O21: 1163
B22: Marzo | C22: 2053 | D22: 1109 | E22: =C22+D22 -> 3162 | F22: 6997 | G22: 195 | H22: =F22+G22 -> 7192 | I22: =E22+H22 -> 10354 | J22: 6086 | K22: 4268 | L22: 6093 | M22: 2512 | N22: 284 | O22: 1465
... B31: Diciembre | C31: 1861 | D31: 911 | E31: =C31+D31 -> 2772 | F31: 6844 | G31: 255 | H31: =F31+G31 -> 7099 | I31: =E31+H31 -> 9871 | J31: 5611 | K31: 4260 | L31: 5556 | M31: 2496 | N31: 285 | O31: 1534
B32: Total 2017 | C32: =SUM(C20:C31) -> 22733 | D32: =SUM(D20:D31) -> 11892 | E32: =SUM(E20:E31) -> 34625 | F32: =SUM(F20:F31) -> 79713 | G32: =SUM(G20:G31) -> 2803 | H32: =SUM(H20:H31) -> 82516 | I32: =SUM(I20:I31) -> 117141 | J32: =SUM(J20:J31) -> 68139 | ... O32: =SUM(O20:O31) -> 17432
B33: enero'18 | C33: 2138 | D33: 923 | E33: =C33+D33 -> 3061 | F33: 10031 | G33: 361 | H33: =F33+G33 -> 10392 | I33: =E33+H33 -> 13453 | J33: 7982 | K33: 5471 | L33: 8209 | M33: 3281 | N33: 332 | O33: 1631
B34: febrero'18 | C34: 1786 | D34: 744 | E34: =C34+D34 -> 2530 | F34: 9930 | G34: 711 | H34: =F34+G34 -> 10641 | I34: =E34+H34 -> 13171 | J34: 7961 | K34: 5210 | L34: 8431 | M34: 3021 | N34: 284 | O34: 1435
B35: marzo'18 | C35: 1959 | D35: 914 | E35: =C35+D35 -> 2873 | F35: 9164 | G35: 889 | H35: =F35+G35 -> 10053 | I35: =E35+H35 -> 12926 | J35: 7526 | K35: 5400 | L35: 7448 | M35: 3439 | N35: 378 | O35: 1661
B36: abril'18 | C36: 1934 | D36: 949 | E36: 2883 | F36: 8562 | G36: 796 | H36: 9358 | I36: 12241 | J36: 6904 | K36: 5337 | L36: 6489 | M36: 3580 | N36: 439 | O36: 1733
B37: mayo'18 | C37: 1938 | D37: 906 | E37: 2844 | F37: 9897 | G37: 520 | H37: 10417 | I37: 13261 | J37: 7062 | K37: 6199 | L37: 7260 | M37: 3821 | N37: 448 | O37: 1732
B38: junio'18 | C38: 1777 | D38: 826 | E38: 2603 | F38: 8539 | G38: 489 | H38: 9028 | I38: 11631 | J38: 6492 | K38: 5139 | L38: 6373 | M38: 3320 | N38: 369 | O38: 1569
B39: julio'18 | C39: 1979 | D39: 761 | E39: 2740 | F39: 9055 | G39: 435 | H39: 9490 | I39: 12230 | J39: 6939 | K39: 5291 | L39: 6726 | M39: 3515 | N39: 386 | O39: 1603
B40: agosto'18 | C40: 2188 | D40: 590 | E40: 2778 | F40: 9628 | G40: 379 | H40: 10007 | I40: 12785 | J40: 7451 | K40: 5334 | L40: 7526 | M40: 3198 | N40: 383 | O40: 1678
B41: septiembre'18 | C41: 1919 | D41: 489 | E41: 2408 | F41: 7667 | G41: 298 | H41: 7965 | I41: 10373 | J41: 6209 | K41: 4164 | L41: 6069 | M41: 2733 | N41: 286 | O41: 1285
B42: octubre '18 | C42: 2429 | D42: 457 | E42: 2886 | F42: 10341 | G42: 362 | H42: 10703 | I42: 13589 | J42: 8012 | K42: 5577 | L42: 7642 | M42: 3842 | N42: 384 | O42: 1721
B43: noviembre '18 | C43: 2116 | D43: 109 | E43: 2225 | F43: 7070 | G43: 27 | H43: 7097 | I43: 9322 | J43: 5506 | K43: 3816 | L43: 5412 | M43: 2490 | N43: 345 | O43: 1075
B44: Total a nov-18 | C44: 22163 | D44: 7668 | E44: 29831 | F44: 99884 | G44: 5267 | H44: 105151 | I44: 134982 | J44: 78044 | K44: 56938 | L44: 77585 | M44: 36240 | N44: 4034 | O44: 17123
B45: TOTAL | C45: 391921 | D45: 138135 | E45: 530056 | F45: 1079963 | G45: 60727 | H45: 1140690 | I45: 1670746 | J45: 1023310 | K45: 647436 | L45: 1069998 | M45: 248637 | N45: 45488 | O45: 306623
B46: Fuente: Elaboración propia sobre la base de información del IPS.
B47: Nota: La información estadística reportada del número de solicitudes concesionadas, en trámite, rechazadas y anuladas varía mes a mes por actualización de cifras.
B48: El número de pensiones concesionadas no coincide con el número de pensiones pagadas por las siguientes razones: • El total acumulado de concesiones de la Reforma Previsional incluye personas fallecidas: El número de personas fallecidas durante el mes de septiembre con PBS correspondió a 1.088. El número aproximado de personas fallecidas con PBS durante el periodo jul-08 a sep-18 correspondió a 147.308. • Existen personas a quienes se les ha extinguido o suspendido el beneficio. • El mes de concedida la pensión no necesariamente coincide con el primer mes de pago.

Sheet Solicitudes Regiones
A2: Subsecretaría de Previsión Social
A3: Dirección de Estudios Previsionales
B5: Número de solicitudes del Sistema de Pensiones Solidarias según región, tipo de beneficio, sexo y origen de tramitación del beneficio | R5: Volver Sistema de Pensiones Solidarias
B6: Acumuladas de julio de 2008 a noviembre de 2018
B8: TOTAL SOLICITUDES (no incluye ex Pasis)
B9: REGIÓN | C9: TOTAL PBS Y APS | I9: TOTAL | K9: SEXO | M9: ORIGEN DE TRAMITACIÓN DEL BENEFICIO
C10: PBSV | D10: PBSI | E10: TOTAL PBS | F10: APSV | G10: APSI | H10: TOTAL APS | I10: Total PBS+APS | J10: % de Solicitudes PBS+APS | K10: Femenino | L10: Masculino | M10: En IPS | N10: En AFP | O10: En Cías. de Seguro | P10: En Municipio
B11: ARICA Y PARINACOTA | C11: 5225 | D11: 2236 | E11: =C11+D11 -> 7461 | F11: 16459 | G11: 824 | H11: =F11+G11 -> 17283 | I11: =+C11+D11+F11+G11 -> 24744 | J11: =I11/$I$27 -> 0.012100466 | K11: 15012 | L11: 9732 | M11: 15179 | N11: 4244 | O11: 687 | P11: 4634
B12: TARAPACA | C12: 5275 | D12: 3922 | E12: =C12+D12 -> 9197 | F12: 17518 | G12: 1503 | H12: =F12+G12 -> 19021 | I12: =+C12+D12+F12+G12 -> 28218 | J12: =I12/$I$27 -> 0.013799343 | K12: 17702 | L12: 10516 | M12: 16801 | N12: 3727 | O12: 998 | P12: 6692
B13: ANTOFAGASTA | C13: 10311 | D13: 4662 | E13: =C13+D13 -> 14973 | F13: 30304 | G13: 1569 | H13: =F13+G13 -> 31873 | I13: =+C13+D13+F13+G13 -> 46846 | J13: =I13/$I$27 -> 0.022908924 | K13: 31311 | L13: 15535 | M13: 33487 | N13: 6131 | O13: 631 | P13: 6597
B14: ATACAMA | C14: 6690 | D14: 3217 | E14: =C14+D14 -> 9907 | F14: 19891 | G14: 1055 | H14: =F14+G14 -> 20946 | I14: =+C14+D14+F14+G14 -> 30853 | J14: =I14/$I$27 -> 0.015087927 | K14: 19239 | L14: 11614 | M14: 19191 | N14: 4792 | O14: 903 | P14: 5967
B15: COQUIMBO | C15: 19336 | D15: 8632 | E15: =C15+D15 -> 27968 | F15: 58722 | G15: 2852 | H15: =F15+G15 -> 61574 | I15: =+C15+D15+F15+G15 -> 89542 | J15: =I15/$I$27 -> 0.043788389 | K15: 55886 | L15: 33656 | M15: 68181 | N15: 10715 | O15: 1288 | P15: 9358
B16: VALPARAISO | C16: 48571 | D16: 23417 | E16: =C16+D16 -> 71988 | F16: 161098 | G16: 9027 | H16: =F16+G16 -> 170125 | I16: =+C16+D16+F16+G16 -> 242113 | J16: =I16/$I$27 -> 0.11839961 | K16: 153965 | L16: 88148 | M16: 158442 | N16: 40145 | O16: 6033 | P16: 37493
B17: L. G. B. OHIGGINS | C17: 23169 | D17: 13727 | E17: =C17+D17 -> 36896 | F17: 75671 | G17: 5117 | H17: =F17+G17 -> 80788 | I17: =+C17+D17+F17+G17 -> 117684 | J17: =I17/$I$27 -> 0.057550565 | K17: 71396 | L17: 46288 | M17: 70812 | N17: 14809 | O17: 2871 | P17: 29192
B18: MAULE | C18: 31694 | D18: 18403 | E18: =C18+D18 -> 50097 | F18: 88010 | G18: 5768 | H18: =F18+G18 -> 93778 | I18: =+C18+D18+F18+G18 -> 143875 | J18: =I18/$I$27 -> 0.070358652 | K18: 85175 | L18: 58700 | M18: 90534 | N18: 21093 | O18: 3478 | P18: 28770
B19: ÑUBLE | C19: 16164 | D19: 20013 | E19: =C19+D19 -> 36177 | F19: 41180 | G19: 4447 | H19: =F19+G19 -> 45627 | I19: =+C19+D19+F19+G19 -> 81804 | J19: =I19/$I$27 -> 0.040004303 | K19: 50708 | L19: 31096 | M19: 48776 | N19: 10596 | O19: 1465 | P19: 20967
B20: BIO-BIO | C20: 42204 | D20: 31552 | E20: =C20+D20 -> 73756 | F20: 121298 | G20: 7506 | H20: =F20+G20 -> 128804 | I20: =+C20+D20+F20+G20 -> 202560 | J20: =I20/$I$27 -> 0.099057157 | K20: 128761 | L20: 73799 | M20: 119986 | N20: 26745 | O20: 5694 | P20: 50135
B21: LA ARAUCANIA | C21: 33851 | D21: 21970 | E21: =C21+D21 -> 55821 | F21: 69096 | G21: 4825 | H21: =F21+G21 -> 73921 | I21: =+C21+D21+F21+G21 -> 129742 | J21: =I21/$I$27 -> 0.063447244 | K21: 79355 | L21: 50387 | M21: 89308 | N21: 18263 | O21: 3198 | P21: 18973
B22: LOS RIOS | C22: 12118 | D22: 8209 | E22: =C22+D22 -> 20327 | F22: 31385 | G22: 3042 | H22: =F22+G22 -> 34427 | I22: =+C22+D22+F22+G22 -> 54754 | J22: =I22/$I$27 -> 0.026776143 | K22: 33658 | L22: 21096 | M22: 39644 | N22: 8808 | O22: 1756 | P22: 4546
... B26: METROPOLITANA | C26: 154956 | D26: 65061 | E26: =C26+D26 -> 220017 | F26: 483125 | G26: 22496 | H26: =F26+G26 -> 505621 | I26: =+C26+D26+F26+G26 -> 725638 | J26: =I26/$I$27 -> 0.35485603 | K26: 470710 | L26: 254928 | M26: 446942 | N26: 104972 | O26: 24852 | P26: 148872
B27: Totales | C27: =SUM(C11:C26) -> 439850 | D27: =SUM(D11:D26) -> 242451 | E27: =C27+D27 -> 682301 | F27: =SUM(F11:F26) -> 1286601 | G27: =SUM(G11:G26) -> 75978 | H27: =F27+G27 -> 1362579 | I27: =SUM(I11:I26) -> 2044880 | J27: =I27/$I$27 -> 1 | K27: =SUM(K11:K26) -> 1288326 | L27: =SUM(L11:L26) -> 756554 | M27: =SUM(M11:M26) -> 1306206 | N27: =SUM(N11:N26) -> 297344 | O27: =SUM(O11:O26) -> 57666 | P27: =SUM(P11:P26) -> 383664
B28: Participación sobre el total | C28: =+C27/$I$27 -> 0.2150982 | D28: =+D27/$I$27 -> 0.1185649 | F28: =+F27/$I$27 -> 0.62918166 | G28: =+G27/$I$27 -> 0.037155236 | I28: =C28+D28+F28+G28 -> 1 | K28: =+K27/$I$27 -> 0.63002523 | L28: =+L27/$I$27 -> 0.36997477 | M28: =+M27/$I$27 -> 0.63876902 | N28: =+N27/$I$27 -> 0.14540902 | O28: =+O27/$I$27 -> 0.028200188 | P28: =+P27/$I$27 -> 0.18762177
B29: Fuente: Elaboración propia sobre la base de información del IPS.
B30: Nota: La información estadística reportada del número de solicitudes concesionadas, en trámite, rechazadas y anuladas varía mes a mes por actualización de cifras.

Sheet Concesiones Regiones
A2: Subsecretaría de Previsión Social
A3: Dirección de Estudios Previsionales
B5: Número de concesiones del Sistema de Pensiones Solidarias según región, tipo de beneficio, sexo y origen de tramitación del beneficio | R5: Volver Sistema de Pensiones Solidarias
B6: ='Solicitudes Regiones'!B6:P6 -> Acumuladas de julio de 2008 a noviembre de 2018
B8: TOTAL CONCEDIDAS (no incluye ex Pasis)
B9: REGIÓN | C9: TOTAL PBS Y APS | I9: TOTAL | K9: SEXO | M9: ORIGEN DE TRAMITACIÓN DEL BENEFICIO
C10: PBSV | D10: PBSI | E10: TOTAL PBS | F10: APSV | G10: APSI | H10: TOTAL APS | I10: Total PBS+APS | J10: % de Concesiones PBS+APS | K10: Femenino | L10: Masculino | M10: En IPS | N10: En AFP | O10: En Cías. de Seguro | P10: En Municipio
B11: ARICA Y PARINACOTA | C11: 4820 | D11: 1583 | E11: =C11+D11 -> 6403 | F11: 14143 | G11: 659 | H11: =G11+F11 -> 14802 | I11: =+C11+D11+F11+G11 -> 21205 | J11: =I11/$I$27 -> 0.012691935 | K11: 12670 | L11: 8535 | M11: 13041 | N11: 3594 | O11: 555 | P11: 4015
B12: TARAPACA | C12: 4564 | D12: 2341 | E12: =C12+D12 -> 6905 | F12: 13958 | G12: 1145 | H12: =G12+F12 -> 15103 | I12: =+C12+D12+F12+G12 -> 22008 | J12: =I12/$I$27 -> 0.013172559 | K12: 13451 | L12: 8557 | M12: 13226 | N12: 3047 | O12: 749 | P12: 4986
B13: ANTOFAGASTA | C13: 8433 | D13: 2976 | E13: =C13+D13 -> 11409 | F13: 23904 | G13: 1188 | H13: =G13+F13 -> 25092 | I13: =+C13+D13+F13+G13 -> 36501 | J13: =I13/$I$27 -> 0.021847127 | K13: 23816 | L13: 12685 | M13: 26000 | N13: 4655 | O13: 485 | P13: 5361
B14: ATACAMA | C14: 5785 | D14: 2148 | E14: =C14+D14 -> 7933 | F14: 16518 | G14: 822 | H14: =G14+F14 -> 17340 | I14: =+C14+D14+F14+G14 -> 25273 | J14: =I14/$I$27 -> 0.015126776 | K14: 15395 | L14: 9878 | M14: 15532 | N14: 3955 | O14: 681 | P14: 5105
B15: COQUIMBO | C15: 16884 | D15: 5382 | E15: =C15+D15 -> 22266 | F15: 49083 | G15: 2385 | H15: =G15+F15 -> 51468 | I15: =+C15+D15+F15+G15 -> 73734 | J15: =I15/$I$27 -> 0.044132382 | K15: 44589 | L15: 29145 | M15: 56323 | N15: 8872 | O15: 940 | P15: 7597
B16: VALPARAISO | C16: 42821 | D16: 14899 | E16: =C16+D16 -> 57720 | F16: 132002 | G16: 7125 | H16: =G16+F16 -> 139127 | I16: =+C16+D16+F16+G16 -> 196847 | J16: =I16/$I$27 -> 0.11781982 | K16: 122314 | L16: 74533 | M16: 127967 | N16: 32853 | O16: 4709 | P16: 31313
B17: L. G. B. OHIGGINS | C17: 20179 | D17: 7182 | E17: =C17+D17 -> 27361 | F17: 63641 | G17: 4071 | H17: =G17+F17 -> 67712 | I17: =+C17+D17+F17+G17 -> 95073 | J17: =I17/$I$27 -> 0.05690452 | K17: 55323 | L17: 39750 | M17: 57512 | N17: 12214 | O17: 2274 | P17: 23071
B18: MAULE | C18: 28798 | D18: 9859 | E18: =C18+D18 -> 38657 | F18: 76060 | G18: 4520 | H18: =G18+F18 -> 80580 | I18: =+C18+D18+F18+G18 -> 119237 | J18: =I18/$I$27 -> 0.071367521 | K18: 68295 | L18: 50942 | M18: 75696 | N18: 18184 | O18: 2758 | P18: 22598
B19: ÑUBLE | C19: 14798 | D19: 8734 | E19: =C19+D19 -> 23532 | F19: 35979 | G19: 3774 | H19: =G19+F19 -> 39753 | I19: =+C19+D19+F19+G19 -> 63285 | J19: =I19/$I$27 -> 0.037878289 | K19: 36638 | L19: 26647 | M19: 38962 | N19: 9353 | O19: 1234 | P19: 13736
B20: BIO-BIO | C20: 37285 | D20: 15399 | E20: =C20+D20 -> 52684 | F20: 101452 | G20: 5944 | H20: =G20+F20 -> 107396 | I20: =+C20+D20+F20+G20 -> 160080 | J20: =I20/$I$27 -> 0.095813487 | K20: 96950 | L20: 63130 | M20: 96593 | N20: 21947 | O20: 4380 | P20: 37160
B21: LA ARAUCANIA | C21: 31152 | D21: 10312 | E21: =C21+D21 -> 41464 | F21: 59160 | G21: 3959 | H21: =G21+F21 -> 63119 | I21: =+C21+D21+F21+G21 -> 104583 | J21: =I21/$I$27 -> 0.062596589 | K21: 61002 | L21: 43581 | M21: 72027 | N21: 15795 | O21: 2418 | P21: 14336
B22: LOS RIOS | C22: 11186 | D22: 5636 | E22: =C22+D22 -> 16822 | F22: 26792 | G22: 2561 | H22: =G22+F22 -> 29353 | I22: =+C22+D22+F22+G22 -> 46175 | J22: =I22/$I$27 -> 0.027637355 | K22: 27623 | L22: 18552 | M22: 33363 | N22: 7595 | O22: 1392 | P22: 3823
... B26: METROPOLITANA | C26: 137371 | D26: 41620 | E26: =C26+D26 -> 178991 | F26: 405555 | G26: 17806 | H26: =G26+F26 -> 423361 | I26: =+C26+D26+F26+G26 -> 602352 | J26: =I26/$I$27 -> 0.36052877 | K26: 384702 | L26: 217650 | M26: 371008 | N26: 87517 | O26: 19866 | P26: 123960
B27: Totales | C27: =SUM(C11:C26) -> 391921 | D27: =SUM(D11:D26) -> 138135 | E27: =C27+D27 -> 530056 | F27: =SUM(F11:F26) -> 1079963 | G27: =SUM(G11:G26) -> 60727 | H27: =G27+F27 -> 1140690 | I27: =SUM(I11:I26) -> 1670746 | J27: =I27/$I$27 -> 1 | K27: =SUM(K11:K26) -> 1023310 | L27: =SUM(L11:L26) -> 647436 | M27: =SUM(M11:M26) -> 1069845 | N27: =SUM(N11:N26) -> 248637 | O27: =SUM(O11:O26) -> 45488 | P27: =SUM(P11:P26) -> 306746
B28: Participación sobre el total | C28: =+C27/$I$27 -> 0.23457845 | D28: =+D27/$I$27 -> 0.082678636 | F28: =+F27/$I$27 -> 0.64639568 | G28: =+G27/$I$27 -> 0.036347237 | I28: =C28+D28+F28+G28 -> 1 | K28: =+K27/$I$27 -> 0.61248688 | L28: =+L27/$I$27 -> 0.38751312 | M28: =+M27/$I$27 -> 0.6403397 | N28: =+N27/$I$27 -> 0.14881795 | O28: =+O27/$I$27 -> 0.027226161 | P28: =+P27/$I$27 -> 0.18359822
B29: Fuente: Elaboración propia sobre la base de información del IPS.
B30: Nota: La información estadística reportada del número de solicitudes concesionadas, en trámite, rechazadas y anuladas varía mes a mes por actualización de cifras.

Sheet XV
A2: Subsecretaría de Previsión Social
A3: Dirección de Estudios Previsionales
B5: Número de Solicitudes de Beneficios del Pilar Solidario según tipo de beneficio - XV Región de Arica y Parinacota | M5: Volver Sistema de Pensiones Solidadias
B6: ='Solicitudes Regiones'!$B$6:$P$6 -> Acumuladas de julio de 2008 a noviembre de 2018
B8: Distribución Regional Solicitudes del Pilar Solidario - no incluye ex Pasis
B9: COMUNA | C9: TOTAL PBS Y APS
C10: PBSV | D10: PBSI | E10: Total PBS | F10: % PBS | G10: APSV | H10: APSI | I10: Total APS | J10: %APS | K10: Total PBS+APS
B11: ARICA | C11: 5092 | D11: 2177 | E11: =C11+D11 -> 7269 | F11: =E11/$E$15 -> 0.97426618 | G11: 16311 | H11: 822 | I11: =G11+H11 -> 17133 | J11: =I11/$I$15 -> 0.99132095 | K11: =E11+I11 -> 24402
B12: CAMARONES | C12: 24 | D12: 9 | E12: =C12+D12 -> 33 | F12: =E12/$E$15 -> 0.0044229996 | G12: 38 | H12: 1 | I12: =G12+H12 -> 39 | J12: =I12/$I$15 -> 0.0022565527 | K12: =E12+I12 -> 72
B13: PUTRE | C13: 74 | D13: 32 | E13: =C13+D13 -> 106 | F13: =E13/$E$15 -> 0.014207211 | G13: 98 | H13: 1 | I13: =G13+H13 -> 99 | J13: =I13/$I$15 -> 0.0057281722 | K13: =E13+I13 -> 205
B14: GENERAL LAGOS | C14: 35 | D14: 18 | E14: =C14+D14 -> 53 | F14: =E14/$E$15 -> 0.0071036054 | G14: 12 | H14: 0 | I14: =G14+H14 -> 12 | J14: =I14/$I$15 -> 0.0006943239 | K14: =E14+I14 -> 65
B15: Totales | C15: =SUM(C11:C14) -> 5225 | D15: =SUM(D11:D14) -> 2236 | E15: =C15+D15 -> 7461 | F15: =E15/$E$15 -> 1 | G15: =SUM(G11:G14) -> 16459 | H15: =SUM(H11:H14) -> 824 | I15: =G15+H15 -> 17283 | J15: =I15/$I$15 -> 1 | K15: =E15+I15 -> 24744
B16: % respecto del total de solicitudes | C16: =+C15/$K$15 -> 0.2111623 | D16: =+D15/$K$15 -> 0.090365341 | E16: =+E15/$K$15 -> 0.30152764 | G16: =+G15/$K$15 -> 0.66517135 | H16: =+H15/$K$15 -> 0.033301002 | I16: =+I15/$K$15 -> 0.69847236 | K16: =E16+I16 -> 1
B19: Número de Concesiones de Beneficios del Pilar Solidario según tipo de beneficio - XV Región de Arica y Parinacota
B20: ='Solicitudes Regiones'!$B$6:$P$6 -> Acumuladas de julio de 2008 a noviembre de 2018
B22: Concesiones del Pilar Solidario a nivel comunal
B23: COMUNA | C23: TOTAL PBS Y APS
C24: PBSV | D24: PBSI | E24: Total PBS | F24: % PBS | G24: APSV | H24: APSI | I24: Total APS | J24: %APS | K24: Total PBS+APS
B25: ARICA | C25: 4699 | D25: 1559 | E25: 5994 | F25: =E25/$E$29 -> 0.93612369 | G25: 14015 | H25: 657 | I25: =G25+H25 -> 14672 | J25: =I25/$I$29 -> 0.9912174 | K25: =E25+I25 -> 20666
B26: CAMARONES | C26: 21 | D26: 3 | E26: 23 | F26: =E26/$E$29 -> 0.0035920662 | G26: 34 | H26: 1 | I26: =G26+H26 -> 35 | J26: =I26/$I$29 -> 0.0023645453 | K26: =E26+I26 -> 58
B27: PUTRE | C27: 69 | D27: 14 | E27: 82 | F27: =E27/$E$29 -> 0.012806497 | G27: 82 | H27: 1 | I27: =G27+H27 -> 83 | J27: =I27/$I$29 -> 0.0056073504 | K27: =E27+I27 -> 165
B28: GENERAL LAGOS | C28: 31 | D28: 7 | E28: 37 | F28: =E28/$E$29 -> 0.0057785413 | G28: 12 | H28: 0 | I28: =G28+H28 -> 12 | J28: =I28/$I$29 -> 0.00081070126 | K28: =E28+I28 -> 49
B29: Totales | C29: =SUM(C25:C28) -> 4820 | D29: =SUM(D25:D28) -> 1583 | E29: =C29+D29 -> 6403 | F29: =E29/$E$29 -> 1 | G29: =SUM(G25:G28) -> 14143 | H29: =SUM(H25:H28) -> 659 | I29: =G29+H29 -> 14802 | J29: =I29/$I$29 -> 1 | K29: =E29+I29 -> 21205
B30: % respecto del total de concesiones | C30: =+C29/$K$29 -> 0.22730488 | D30: =+D29/$K$29 -> 0.074652205 | E30: =+E29/$K$29 -> 0.30195709 | G30: =+G29/$K$29 -> 0.66696534 | H30: =+H29/$K$29 -> 0.031077576 | I30: =+I29/$K$29 -> 0.69804291 | K30: =E30+I30 -> 1
B31: Fuente: Elaboración propia sobre la base de información del IPS.
B32: Nota: La información estadística reportada del número de solicitudes concesionadas, en trámite, rechazadas y anuladas varía mes a mes por actualización de cifras.

Sheet I
A2: Subsecretaría de Previsión Social
A3: Dirección de Estudios Previsionales
B5: Número de Solicitudes de Beneficios del Pilar Solidario según tipo de beneficio - I Región de Tarapacá | M5: Volver Sistema de Pensiones Solidadias
B6: ='Solicitudes Regiones'!$B$6:$P$6 -> Acumuladas de julio de 2008 a noviembre de 2018
B8: Distribución Regional Solicitudes del Pilar Solidario - no incluye ex Pasis
B9: COMUNA | C9: TOTAL PBS Y APS
C10: PBSV | D10: PBSI | E10: Total PBS | F10: % PBS | G10: APSV | H10: APSI | I10: Total APS | J10: %APS | K10: Total PBS+APS
B11: IQUIQUE | C11: 3632 | D11: 2298 | E11: =C11+D11 -> 5930 | F11: =E11/$E$18 -> 0.64477547 | G11: 12628 | H11: 921 | I11: =G11+H11 -> 13549 | J11: =I11/$I$18 -> 0.71231796 | K11: =E11+I11 -> 19479
B12: ALTO HOSPICIO | C12: 1046 | D12: 1240 | E12: =C12+D12 -> 2286 | F12: =E12/$E$18 -> 0.24855931 | G12: 3488 | H12: 462 | I12: =G12+H12 -> 3950 | J12: =I12/$I$18 -> 0.20766521 | K12: =E12+I12 -> 6236
B13: POZO ALMONTE | C13: 253 | D13: 155 | E13: =C13+D13 -> 408 | F13: =E13/$E$18 -> 0.044362292 | G13: 701 | H13: 64 | I13: =G13+H13 -> 765 | J13: =I13/$I$18 -> 0.040218706 | K13: =E13+I13 -> 1173
B14: CAMIÑA | C14: 54 | D14: 40 | E14: =C14+D14 -> 94 | F14: =E14/$E$18 -> 0.010220724 | G14: 55 | H14: 9 | I14: =G14+H14 -> 64 | J14: =I14/$I$18 -> 0.0033647022 | K14: =E14+I14 -> 158
B15: COLCHANE | C15: 54 | D15: 34 | E15: =C15+D15 -> 88 | F15: =E15/$E$18 -> 0.0095683375 | G15: 33 | H15: 5 | I15: =G15+H15 -> 38 | J15: =I15/$I$18 -> 0.0019977919 | K15: =E15+I15 -> 126
B16: HUARA | C16: 90 | D16: 82 | E16: =C16+D16 -> 172 | F16: =E16/$E$18 -> 0.018701751 | G16: 207 | H16: 19 | I16: =G16+H16 -> 226 | J16: =I16/$I$18 -> 0.011881605 | K16: =E16+I16 -> 398
B17: PICA | C17: 146 | D17: 73 | E17: =C17+D17 -> 219 | F17: =E17/$E$18 -> 0.023812113 | G17: 406 | H17: 23 | I17: =G17+H17 -> 429 | J17: =I17/$I$18 -> 0.022554019 | K17: =E17+I17 -> 648
B18: Totales | C18: =SUM(C11:C17) -> 5275 | D18: =SUM(D11:D17) -> 3922 | E18: =C18+D18 -> 9197 | F18: =E18/$E$18 -> 1 | G18: =SUM(G11:G17) -> 17518 | H18: =SUM(H11:H17) -> 1503 | I18: =G18+H18 -> 19021 | J18: =I18/$I$18 -> 1 | K18: =SUM(K11:K17) -> 28218
B19: % respecto del total de solicitudes | C19: =+C18/$K$18 -> 0.18693742 | D19: =+D18/$K$18 -> 0.1389893 | E19: =C19+D19 -> 0.32592671 | G19: =+G18/$K$18 -> 0.62080941 | H19: =+H18/$K$18 -> 0.053263874 | I19: =H19+G19 -> 0.67407329 | K19: =E19+I19 -> 1
B21: Número de Concesiones de Beneficios del Pilar Solidario según tipo de beneficio - I Región de Tarapacá
B22: ='Solicitudes Regiones'!$B$6:$P$6 -> Acumuladas de julio de 2008 a noviembre de 2018
B24: Concesiones del Pilar Solidario a nivel comunal
B25: COMUNA | C25: TOTAL PBS Y APS
C26: PBSV | D26: PBSI | E26: Total PBS | F26: % PBS | G26: APSV | H26: APSI | I26: Total APS | J26: %APS | K26: Total PBS+APS
B27: IQUIQUE | C27: 3093 | D27: 1383 | E27: =C27+D27 -> 4476 | F27: =E27/$E$18 -> 0.48668044 | G27: 9914 | H27: 688 | I27: =G27+H27 -> 10602 | J27: =I27/$I$18 -> 0.55738394 | K27: =E27+I27 -> 15078
B28: ALTO HOSPICIO | C28: 951 | D28: 759 | E28: =C28+D28 -> 1710 | F28: =E28/$E$18 -> 0.18593019 | G28: 2914 | H28: 361 | I28: =G28+H28 -> 3275 | J28: =I28/$I$18 -> 0.17217812 | K28: =E28+I28 -> 4985
B29: POZO ALMONTE | C29: 210 | D29: 77 | E29: =C29+D29 -> 287 | F29: =E29/$E$18 -> 0.031205828 | G29: 554 | H29: 49 | I29: =G29+H29 -> 603 | J29: =I29/$I$18 -> 0.031701803 | K29: =E29+I29 -> 890
B30: CAMIÑA | C30: 53 | D30: 21 | E30: =C30+D30 -> 74 | F30: =E30/$E$18 -> 0.008046102 | G30: 51 | H30: 7 | I30: =G30+H30 -> 58 | J30: =I30/$I$18 -> 0.0030492613 | K30: =E30+I30 -> 132
B31: COLCHANE | C31: 50 | D31: 16 | E31: =C31+D31 -> 66 | F31: =E31/$E$18 -> 0.0071762531 | G31: 29 | H31: 5 | I31: =G31+H31 -> 34 | J31: =I31/$I$18 -> 0.001787498 | K31: =E31+I31 -> 100
B32: HUARA | C32: 82 | D32: 42 | E32: =C32+D32 -> 124 | F32: =E32/$E$18 -> 0.013482657 | G32: 168 | H32: 19 | I32: =G32+H32 -> 187 | J32: =I32/$I$18 -> 0.0098312392 | K32: =E32+I32 -> 311
B33: PICA | C33: 125 | D33: 43 | E33: =C33+D33 -> 168 | F33: =E33/$E$18 -> 0.018266826 | G33: 328 | H33: 16 | I33: =G33+H33 -> 344 | J33: =I33/$I$18 -> 0.018085274 | K33: =E33+I33 -> 512
B34: Totales | C34: =SUM(C27:C33) -> 4564 | D34: =SUM(D27:D33) -> 2341 | E34: =C34+D34 -> 6905 | F34: =E34/$E$18 -> 0.7507883 | G34: =SUM(G27:G33) -> 13958 | H34: =SUM(H27:H33) -> 1145 | I34: =G34+H34 -> 15103 | J34: =I34/$I$18 -> 0.79401714 | K34: =SUM(K27:K33) -> 22008
B35: % respecto del total de concesiones | C35: =+C34/$K$34 -> 0.20737913 | D35: =+D34/$K$34 -> 0.10637041 | E35: =C35+D35 -> 0.31374955 | G35: =+G34/$K$34 -> 0.63422392 | H35: =+H34/$K$34 -> 0.052026536 | I35: =G35+H35 -> 0.68625045 | K35: =E35+I35 -> 1
B36: Fuente: Elaboración propia sobre la base de información del IPS.
B37: Nota: La información estadística reportada del número de solicitudes concesionadas, en trámite, rechazadas y anuladas varía mes a mes por actualización de cifras.

Sheet II
A2: Subsecretaría de Previsión Social
A3: Dirección de Estudios Previsionales
B5: Número de Solicitudes de Beneficios del Pilar Solidario según tipo de beneficio - II Región de Antofagasta | M5: Volver Sistema de Pensiones Solidadias
B6: ='Solicitudes Regiones'!$B$6:$P$6 -> Acumuladas de julio de 2008 a noviembre de 2018
B8: Distribución Regional Solicitudes del Pilar Solidario - no incluye ex Pasis
B9: COMUNA | C9: TOTAL PBS Y APS
C10: PBSV | D10: PBSI | E10: Total PBS | F10: % PBS | G10: APSV | H10: APSI | I10: Total APS | J10: %APS | K10: Total PBS+APS
B11: ANTOFAGASTA | C11: 6338 | D11: 3007 | E11: =C11+D11 -> 9345 | F11: =E11/$E$20 -> 0.62412342 | G11: 19757 | H11: 1081 | I11: =G11+H11 -> 20838 | J11: =I11/$I$20 -> 0.6537822 | K11: =E11+I11 -> 30183
B12: MEJILLONES | C12: 183 | D12: 70 | E12: =C12+D12 -> 253 | F12: =E12/$E$20 -> 0.016897081 | G12: 560 | H12: 25 | I12: =G12+H12 -> 585 | J12: =I12/$I$20 -> 0.018354093 | K12: =E12+I12 -> 838
B13: SIERRA GORDA | C13: 22 | D13: 5 | E13: =C13+D13 -> 27 | F13: =E13/$E$20 -> 0.0018032458 | G13: 39 | H13: 2 | I13: =G13+H13 -> 41 | J13: =I13/$I$20 -> 0.0012863552 | K13: =E13+I13 -> 68
B14: TALTAL | C14: 287 | D14: 217 | E14: =C14+D14 -> 504 | F14: =E14/$E$20 -> 0.033660589 | G14: 962 | H14: 47 | I14: =G14+H14 -> 1009 | J14: =I14/$I$20 -> 0.031656888 | K14: =E14+I14 -> 1513
B15: CALAMA | C15: 2544 | D15: 879 | E15: =C15+D15 -> 3423 | F15: =E15/$E$20 -> 0.2286115 | G15: 6327 | H15: 290 | I15: =G15+H15 -> 6617 | J15: =I15/$I$20 -> 0.20760518 | K15: =E15+I15 -> 10040
B16: OLLAGUE | C16: 15 | D16: 1 | E16: =C16+D16 -> 16 | F16: =E16/$E$20 -> 0.0010685901 | G16: 13 | H16: 0 | I16: =G16+H16 -> 13 | J16: =I16/$I$20 -> 0.00040786873 | K16: =E16+I16 -> 29
B17: SAN PEDRO DE ATACAMA | C17: 150 | D17: 41 | E17: =C17+D17 -> 191 | F17: =E17/$E$20 -> 0.012756295 | G17: 270 | H17: 10 | I17: =G17+H17 -> 280 | J17: =I17/$I$20 -> 0.0087848649 | K17: =E17+I17 -> 471
B18: TOCOPILLA | C18: 702 | D18: 422 | E18: =C18+D18 -> 1124 | F18: =E18/$E$20 -> 0.075068457 | G18: 2195 | H18: 107 | I18: =G18+H18 -> 2302 | J18: =I18/$I$20 -> 0.07222414 | K18: =E18+I18 -> 3426
B19: MARIA ELENA | C19: 70 | D19: 20 | E19: =C19+D19 -> 90 | F19: =E19/$E$20 -> 0.0060108195 | G19: 181 | H19: 7 | I19: =G19+H19 -> 188 | J19: =I19/$I$20 -> 0.0058984093 | K19: =E19+I19 -> 278
B20: Totales | C20: =SUM(C11:C19) -> 10311 | D20: =SUM(D11:D19) -> 4662 | E20: =C20+D20 -> 14973 | F20: =E20/$E$20 -> 1 | G20: =SUM(G11:G19) -> 30304 | H20: =SUM(H11:H19) -> 1569 | I20: =G20+H20 -> 31873 | J20: =I20/$I$20 -> 1 | K20: =E20+I20 -> 46846
B21: % respecto del total de solicitudes | C21: =+C20/$K$20 -> 0.22010417 | D21: =+D20/$K$20 -> 0.099517568 | E21: =C21+D21 -> 0.31962174 | G21: =+G20/$K$20 -> 0.64688554 | H21: =+H20/$K$20 -> 0.033492721 | I21: =G21+H21 -> 0.68037826 | K21: =E21+I21 -> 1
B23: Número de Concesiones de Beneficios del Pilar Solidario según tipo de beneficio - II Región de Antofagasta
B24: ='Solicitudes Regiones'!$B$6:$P$6 -> Acumuladas de julio de 2008 a noviembre de 2018
B26: Concesiones del Pilar Solidario a nivel comunal
B27: COMUNA | C27: TOTAL PBS Y APS
C28: PBSV | D28: PBSI | E28: Total PBS | F28: % PBS | G28: APSV | H28: APSI | I28: Total APS | J28: %APS | K28: Total PBS+APS
B29: ANTOFAGASTA | C29: 5196 | D29: 1914 | E29: =D29+C29 -> 7110 | F29: =E29/$E$38 -> 0.62319222 | G29: 15520 | H29: 830 | I29: =G29+H29 -> 16350 | J29: =I29/$I$38 -> 0.6516021 | K29: =E29+I29 -> 23460
B30: MEJILLONES | C30: 139 | D30: 43 | E30: =D30+C30 -> 182 | F30: =E30/$E$38 -> 0.015952318 | G30: 427 | H30: 20 | I30: =G30+H30 -> 447 | J30: =I30/$I$38 -> 0.017814443 | K30: =E30+I30 -> 629
B31: SIERRA GORDA | C31: 19 | D31: 2 | E31: =D31+C31 -> 21 | F31: =E31/$E$38 -> 0.0018406521 | G31: 29 | H31: 1 | I31: =G31+H31 -> 30 | J31: =I31/$I$38 -> 0.0011956002 | K31: =E31+I31 -> 51
B32: TALTAL | C32: 221 | D32: 110 | E32: =D32+C32 -> 331 | F32: =E32/$E$38 -> 0.029012183 | G32: 746 | H32: 31 | I32: =G32+H32 -> 777 | J32: =I32/$I$38 -> 0.030966045 | K32: =E32+I32 -> 1108
B33: CALAMA | C33: 2072 | D33: 635 | E33: =D33+C33 -> 2707 | F33: =E33/$E$38 -> 0.23726882 | G33: 5022 | H33: 214 | I33: =G33+H33 -> 5236 | J33: =I33/$I$38 -> 0.20867209 | K33: =E33+I33 -> 7943
B34: OLLAGUE | C34: 14 | D34: 1 | E34: =D34+C34 -> 15 | F34: =E34/$E$38 -> 0.0013147515 | G34: 13 | H34: 0 | I34: =G34+H34 -> 13 | J34: =I34/$I$38 -> 0.00051809342 | K34: =E34+I34 -> 28
B35: SAN PEDRO DE ATACAMA | C35: 132 | D35: 26 | E35: =D35+C35 -> 158 | F35: =E35/$E$38 -> 0.013848716 | G35: 225 | H35: 7 | I35: =G35+H35 -> 232 | J35: =I35/$I$38 -> 0.0092459748 | K35: =E35+I35 -> 390
B36: TOCOPILLA | C36: 590 | D36: 232 | E36: =D36+C36 -> 822 | F36: =E36/$E$38 -> 0.072048383 | G36: 1786 | H36: 80 | I36: =G36+H36 -> 1866 | J36: =I36/$I$38 -> 0.074366332 | K36: =E36+I36 -> 2688
B37: MARIA ELENA | C37: 50 | D37: 13 | E37: =D37+C37 -> 63 | F37: =E37/$E$38 -> 0.0055219564 | G37: 136 | H37: 5 | I37: =G37+H37 -> 141 | J37: =I37/$I$38 -> 0.0056193209 | K37: =E37+I37 -> 204
B38: Totales | C38: =SUM(C29:C37) -> 8433 | D38: =SUM(D29:D37) -> 2976 | E38: =D38+C38 -> 11409 | F38: =E38/$E$38 -> 1 | G38: =SUM(G29:G37) -> 23904 | H38: =SUM(H29:H37) -> 1188 | I38: =G38+H38 -> 25092 | J38: =I38/$I$38 -> 1 | K38: =SUM(K29:K37) -> 36501
B39: % respecto del total de concesiones | C39: =+C38/$K$38 -> 0.23103477 | D39: =+D38/$K$38 -> 0.081532013 | E39: =C39+D39 -> 0.31256678 | G39: =+G38/$K$38 -> 0.65488617 | H39: =+H38/$K$38 -> 0.032547054 | I39: =G39+H39 -> 0.68743322 | K39: =E39+I39 -> 1
B40: Fuente: Elaboración propia sobre la base de información del IPS.
B41: Nota: La información estadística reportada del número de solicitudes concesionadas, en trámite, rechazadas y anuladas varía mes a mes por actualización de cifras.
B131: Copiar extraccion TODOS desde casilla A140, luego formatear numeros con punto sindecimales

Sheet III
A2: Subsecretaría de Previsión Social
A3: Dirección de Estudios Previsionales
B5: Número de Solicitudes de Beneficios del Pilar Solidario según tipo de beneficio - III Región de Atacama | M5: Volver Sistema de Pensiones Solidadias
B6: ='Solicitudes Regiones'!$B$6:$P$6 -> Acumuladas de julio de 2008 a noviembre de 2018
B8: Distribución Regional Solicitudes del Pilar Solidario - no incluye ex Pasis
B9: COMUNA | C9: TOTAL PBS Y APS
C10: PBSV | D10: PBSI | E10: Total PBS | F10: % PBS | G10: APSV | H10: APSI | I10: Total APS | J10: %APS | K10: Total PBS+APS
B11: COPIAPO | C11: 3148 | D11: 1475 | E11: =C11+D11 -> 4623 | F11: =E11/$E$20 -> 0.46663975 | G11: 9604 | H11: 557 | I11: =G11+H11 -> 10161 | J11: =I11/$I$20 -> 0.48510455 | K11: =E11+I11 -> 14784
B12: CALDERA | C12: 362 | D12: 181 | E12: =C12+D12 -> 543 | F12: =E12/$E$20 -> 0.05480973 | G12: 1101 | H12: 68 | I12: =G12+H12 -> 1169 | J12: =I12/$I$20 -> 0.055810179 | K12: =E12+I12 -> 1712
B13: TIERRA AMARILLA | C13: 228 | D13: 158 | E13: =C13+D13 -> 386 | F13: =E13/$E$20 -> 0.03896235 | G13: 733 | H13: 51 | I13: =G13+H13 -> 784 | J13: =I13/$I$20 -> 0.037429581 | K13: =E13+I13 -> 1170
B14: CHAÑARAL | C14: 427 | D14: 187 | E14: =C14+D14 -> 614 | F14: =E14/$E$20 -> 0.06197638 | G14: 1106 | H14: 67 | I14: =G14+H14 -> 1173 | J14: =I14/$I$20 -> 0.056001146 | K14: =E14+I14 -> 1787
B15: DIEGO DE ALMAGRO | C15: 267 | D15: 188 | E15: =C15+D15 -> 455 | F15: =E15/$E$20 -> 0.045927122 | G15: 653 | H15: 36 | I15: =G15+H15 -> 689 | J15: =I15/$I$20 -> 0.032894109 | K15: =E15+I15 -> 1144
B16: VALLENAR | C16: 1614 | D16: 746 | E16: =C16+D16 -> 2360 | F16: =E16/$E$20 -> 0.2382154 | G16: 4903 | H16: 204 | I16: =G16+H16 -> 5107 | J16: =I16/$I$20 -> 0.24381744 | K16: =E16+I16 -> 7467
B17: ALTO DEL CARMEN | C17: 172 | D17: 95 | E17: =C17+D17 -> 267 | F17: =E17/$E$20 -> 0.026950641 | G17: 474 | H17: 17 | I17: =G17+H17 -> 491 | J17: =I17/$I$20 -> 0.02344123 | K17: =E17+I17 -> 758
B18: FREIRINA | C18: 192 | D18: 88 | E18: =C18+D18 -> 280 | F18: =E18/$E$20 -> 0.028262844 | G18: 559 | H18: 25 | I18: =G18+H18 -> 584 | J18: =I18/$I$20 -> 0.027881218 | K18: =E18+I18 -> 864
B19: HUASCO | C19: 280 | D19: 99 | E19: =C19+D19 -> 379 | F19: =E19/$E$20 -> 0.038255779 | G19: 758 | H19: 30 | I19: =G19+H19 -> 788 | J19: =I19/$I$20 -> 0.037620548 | K19: =E19+I19 -> 1167
B20: Totales | C20: =SUM(C11:C19) -> 6690 | D20: =SUM(D11:D19) -> 3217 | E20: =C20+D20 -> 9907 | F20: =E20/$E$20 -> 1 | G20: =SUM(G11:G19) -> 19891 | H20: =SUM(H11:H19) -> 1055 | I20: =G20+H20 -> 20946 | J20: =I20/$I$20 -> 1 | K20: =E20+I20 -> 30853
B21: % respecto del total de solicitudes | C21: =+C20/$K$20 -> 0.21683467 | D21: =+D20/$K$20 -> 0.10426863 | E21: =C21+D21 -> 0.3211033 | G21: =+G20/$K$20 -> 0.6447023 | H21: =+H20/$K$20 -> 0.034194406 | I21: =G21+H21 -> 0.6788967 | K21: =E21+I21 -> 1
B23: Número de concesiones de Beneficios del Pilar Solidario según tipo de beneficio - III Región de Atacama
B24: ='Solicitudes Regiones'!$B$6:$P$6 -> Acumuladas de julio de 2008 a noviembre de 2018
B26: Concesiones del Pilar Solidario a nivel comunal
B27: COMUNA | C27: TOTAL PBS Y APS
C28: PBSV | D28: PBSI | E28: Total PBS | F28: % PBS | G28: APSV | H28: APSI | I28: Total APS | J28: %APS | K28: Total PBS+APS
B29: COPIAPO | C29: 2730 | D29: 1001 | E29: =C29+D29 -> 3731 | F29: =E29/$E$38 -> 0.47031388 | G29: 7858 | H29: 447 | I29: =G29+H29 -> 8305 | J29: =I29/$I$38 -> 0.4789504 | K29: =E29+I29 -> 12036
B30: CALDERA | C30: 316 | D30: 120 | E30: =C30+D30 -> 436 | F30: =E30/$E$38 -> 0.054960292 | G30: 889 | H30: 52 | I30: =G30+H30 -> 941 | J30: =I30/$I$38 -> 0.054267589 | K30: =E30+I30 -> 1377
B31: TIERRA AMARILLA | C31: 201 | D31: 100 | E31: =C31+D31 -> 301 | F31: =E31/$E$38 -> 0.037942771 | G31: 625 | H31: 38 | I31: =G31+H31 -> 663 | J31: =I31/$I$38 -> 0.038235294 | K31: =E31+I31 -> 964
B32: CHAÑARAL | C32: 364 | D32: 123 | E32: =C32+D32 -> 487 | F32: =E32/$E$38 -> 0.061389134 | G32: 910 | H32: 34 | I32: =G32+H32 -> 944 | J32: =I32/$I$38 -> 0.0544406 | K32: =E32+I32 -> 1431
B33: DIEGO DE ALMAGRO | C33: 205 | D33: 107 | E33: =C33+D33 -> 312 | F33: =E33/$E$38 -> 0.039329384 | G33: 541 | H33: 20 | I33: =G33+H33 -> 561 | J33: =I33/$I$38 -> 0.032352941 | K33: =E33+I33 -> 873
B34: VALLENAR | C34: 1411 | D34: 496 | E34: =C34+D34 -> 1907 | F34: =E34/$E$38 -> 0.24038825 | G34: 4141 | H34: 170 | I34: =G34+H34 -> 4311 | J34: =I34/$I$38 -> 0.24861592 | K34: =E34+I34 -> 6218
B35: ALTO DEL CARMEN | C35: 161 | D35: 60 | E35: =C35+D35 -> 221 | F35: =E35/$E$38 -> 0.027858313 | G35: 407 | H35: 16 | I35: =G35+H35 -> 423 | J35: =I35/$I$38 -> 0.024394464 | K35: =E35+I35 -> 644
B36: FREIRINA | C36: 164 | D36: 71 | E36: =C36+D36 -> 235 | F36: =E36/$E$38 -> 0.029623093 | G36: 486 | H36: 15 | I36: =G36+H36 -> 501 | J36: =I36/$I$38 -> 0.028892734 | K36: =E36+I36 -> 736
B37: HUASCO | C37: 233 | D37: 70 | E37: =C37+D37 -> 303 | F37: =E37/$E$38 -> 0.038194882 | G37: 661 | H37: 30 | I37: =G37+H37 -> 691 | J37: =I37/$I$38 -> 0.039850058 | K37: =E37+I37 -> 994
B38: Totales | C38: =SUM(C29:C37) -> 5785 | D38: =SUM(D29:D37) -> 2148 | E38: =C38+D38 -> 7933 | F38: =E38/$E$38 -> 1 | G38: =SUM(G29:G37) -> 16518 | H38: =SUM(H29:H37) -> 822 | I38: =G38+H38 -> 17340 | J38: =I38/$I$38 -> 1 | K38: =E38+I38 -> 25273
B39: % respecto del total de concesiones | C39: =+C38/$K$38 -> 0.22890041 | D39: =+D38/$K$38 -> 0.084991889 | E39: =C39+D39 -> 0.3138923 | G39: =+G38/$K$38 -> 0.65358288 | H39: =+H38/$K$38 -> 0.032524829 | I39: =G39+H39 -> 0.6861077 | K39: =E39+I39 -> 1
B40: Fuente: Elaboración propia sobre la base de información del IPS.
B41: Nota: La información estadística reportada del número de solicitudes concesionadas, en trámite, rechazadas y anuladas varía mes a mes por actualización de cifras.
B131: Copiar extraccion TODOS desde casilla A140, luego formatear numeros con punto sindecimales

Sheet IV
A2: Subsecretaría de Previsión Social
A3: Dirección de Estudios Previsionales
B5: Número de Solicitudes de Beneficios del Pilar Solidario según tipo de beneficio - IV Región de Coquimbo | M5: Volver Sistema de Pensiones Solidadias
B6: ='Solicitudes Regiones'!$B$6:$P$6 -> Acumuladas de julio de 2008 a noviembre de 2018
B8: Distribución Regional Solicitudes del Pilar Solidario - no incluye ex Pasis
B9: COMUNA | C9: TOTAL PBS Y APS
C10: PBSV | D10: PBSI | E10: Total PBS | F10: % PBS | G10: APSV | H10: APSI | I10: Total APS | J10: %APS | K10: Total PBS+APS
B11: LA SERENA | C11: 4490 | D11: 2075 | E11: =C11+D11 -> 6565 | F11: =E11/$E$26 -> 0.23473255 | G11: 15108 | H11: 660 | I11: =G11+H11 -> 15768 | J11: =I11/$I$26 -> 0.25608211 | K11: =E11+I11 -> 22333
B12: COQUIMBO | C12: 5074 | D12: 2157 | E12: =C12+D12 -> 7231 | F12: =E12/$E$26 -> 0.25854548 | G12: 16881 | H12: 787 | I12: =G12+H12 -> 17668 | J12: =I12/$I$26 -> 0.28693929 | K12: =E12+I12 -> 24899
B13: ANDACOLLO | C13: 323 | D13: 183 | E13: =C13+D13 -> 506 | F13: =E13/$E$26 -> 0.018092105 | G13: 1206 | H13: 43 | I13: =G13+H13 -> 1249 | J13: =I13/$I$26 -> 0.020284536 | K13: =E13+I13 -> 1755
B14: LA HIGUERA | C14: 136 | D14: 50 | E14: =C14+D14 -> 186 | F14: =E14/$E$26 -> 0.0066504577 | G14: 302 | H14: 13 | I14: =G14+H14 -> 315 | J14: =I14/$I$26 -> 0.0051157956 | K14: =E14+I14 -> 501
B15: PAIHUANO | C15: 117 | D15: 43 | E15: =C15+D15 -> 160 | F15: =E15/$E$26 -> 0.0057208238 | G15: 455 | H15: 14 | I15: =G15+H15 -> 469 | J15: =I15/$I$26 -> 0.0076168513 | K15: =E15+I15 -> 629
B16: VICUÑA | C16: 550 | D16: 279 | E16: =C16+D16 -> 829 | F16: =E16/$E$26 -> 0.029641018 | G16: 2439 | H16: 115 | I16: =G16+H16 -> 2554 | J16: =I16/$I$26 -> 0.041478546 | K16: =E16+I16 -> 3383
B17: ILLAPEL | C17: 1124 | D17: 479 | E17: =C17+D17 -> 1603 | F17: =E17/$E$26 -> 0.057315503 | G17: 3249 | H17: 159 | I17: =G17+H17 -> 3408 | J17: =I17/$I$26 -> 0.055348037 | K17: =E17+I17 -> 5011
B18: CANELA | C18: 418 | D18: 192 | E18: =C18+D18 -> 610 | F18: =E18/$E$26 -> 0.021810641 | G18: 747 | H18: 48 | I18: =G18+H18 -> 795 | J18: =I18/$I$26 -> 0.012911294 | K18: =E18+I18 -> 1405
B19: LOS VILOS | C19: 630 | D19: 288 | E19: =C19+D19 -> 918 | F19: =E19/$E$26 -> 0.032823227 | G19: 1780 | H19: 102 | I19: =G19+H19 -> 1882 | J19: =I19/$I$26 -> 0.030564849 | K19: =E19+I19 -> 2800
B20: SALAMANCA | C20: 955 | D20: 416 | E20: =C20+D20 -> 1371 | F20: =E20/$E$26 -> 0.049020309 | G20: 2660 | H20: 100 | I20: =G20+H20 -> 2760 | J20: =I20/$I$26 -> 0.044824114 | K20: =E20+I20 -> 4131
B21: OVALLE | C21: 3499 | D21: 1351 | E21: =C21+D21 -> 4850 | F21: =E21/$E$26 -> 0.17341247 | G21: 8706 | H21: 502 | I21: =G21+H21 -> 9208 | J21: =I21/$I$26 -> 0.14954364 | K21: =E21+I21 -> 14058
B22: COMBARBALA | C22: 505 | D22: 291 | E22: =C22+D22 -> 796 | F22: =E22/$E$26 -> 0.028461098 | G22: 1599 | H22: 64 | I22: =G22+H22 -> 1663 | J22: =I22/$I$26 -> 0.027008153 | K22: =E22+I22 -> 2459
... B25: RIO HURTADO | C25: 208 | D25: 63 | E25: =C25+D25 -> 271 | F25: =E25/$E$26 -> 0.0096896453 | G25: 364 | H25: 14 | I25: =G25+H25 -> 378 | J25: =I25/$I$26 -> 0.0061389548 | K25: =E25+I25 -> 649
B26: Totales | C26: =SUM(C11:C25) -> 19336 | D26: =SUM(D11:D25) -> 8632 | E26: =C26+D26 -> 27968 | F26: =E26/$E$26 -> 1 | G26: =SUM(G11:G25) -> 58722 | H26: =SUM(H11:H25) -> 2852 | I26: =G26+H26 -> 61574 | J26: =I26/$I$26 -> 1 | K26: =E26+I26 -> 89542
B27: % respecto del total de solicitudes | C27: =+C26/$K$26 -> 0.21594336 | D27: =+D26/$K$26 -> 0.096401689 | E27: =C27+D27 -> 0.31234504 | G27: =+G26/$K$26 -> 0.65580398 | H27: =+H26/$K$26 -> 0.031850975 | I27: =G27+H27 -> 0.68765496 | K27: =E27+I27 -> 1
B29: Número de Concesiones de Beneficios del Pilar Solidario según tipo de beneficio - IV Región de Coquimbo
B30: ='Solicitudes Regiones'!$B$6:$P$6 -> Acumuladas de julio de 2008 a noviembre de 2018
B32: Concesiones del Pilar Solidario a nivel comunal
B33: COMUNA | C33: TOTAL PBS Y APS
C34: PBSV | D34: PBSI | E34: Total PBS | F34: % PBS | G34: APSV | H34: APSI | I34: Total APS | J34: %APS | K34: Total PBS+APS
B35: LA SERENA | C35: 3797 | D35: 1414 | E35: =C35+D35 -> 5211 | F35: =E35/$E$50 -> 0.23403395 | G35: 11887 | H35: 550 | I35: =G35+H35 -> 12437 | J35: =I35/$I$50 -> 0.24164529 | K35: =E35+I35 -> 17648
B36: COQUIMBO | C36: 4332 | D36: 1394 | E36: =C36+D36 -> 5726 | F36: =E36/$E$50 -> 0.25716339 | G36: 13789 | H36: 686 | I36: =G36+H36 -> 14475 | J36: =I36/$I$50 -> 0.28124271 | K36: =E36+I36 -> 20201
B37: ANDACOLLO | C37: 284 | D37: 94 | E37: =C37+D37 -> 378 | F37: =E37/$E$50 -> 0.016976556 | G37: 1079 | H37: 38 | I37: =G37+H37 -> 1117 | J37: =I37/$I$50 -> 0.021702806 | K37: =E37+I37 -> 1495
B38: LA HIGUERA | C38: 127 | D38: 32 | E38: =C38+D38 -> 159 | F38: =E38/$E$50 -> 0.0071409324 | G38: 262 | H38: 12 | I38: =G38+H38 -> 274 | J38: =I38/$I$50 -> 0.0053236963 | K38: =E38+I38 -> 433
B39: PAIHUANO | C39: 104 | D39: 27 | E39: =C39+D39 -> 131 | F39: =E39/$E$50 -> 0.0058834097 | G39: 389 | H39: 11 | I39: =G39+H39 -> 400 | J39: =I39/$I$50 -> 0.0077718194 | K39: =E39+I39 -> 531
B40: VICUÑA | C40: 484 | D40: 166 | E40: =C40+D40 -> 650 | F40: =E40/$E$50 -> 0.029192491 | G40: 2122 | H40: 99 | I40: =G40+H40 -> 2221 | J40: =I40/$I$50 -> 0.043153027 | K40: =E40+I40 -> 2871
B41: ILLAPEL | C41: 985 | D41: 270 | E41: =C41+D41 -> 1255 | F41: =E41/$E$50 -> 0.056363963 | G41: 2785 | H41: 127 | I41: =G41+H41 -> 2912 | J41: =I41/$I$50 -> 0.056578845 | K41: =E41+I41 -> 4167
B42: CANELA | C42: 395 | D42: 102 | E42: =C42+D42 -> 497 | F42: =E42/$E$50 -> 0.022321028 | G42: 673 | H42: 43 | I42: =G42+H42 -> 716 | J42: =I42/$I$50 -> 0.013911557 | K42: =E42+I42 -> 1213
B43: LOS VILOS | C43: 554 | D43: 168 | E43: =C43+D43 -> 722 | F43: =E43/$E$50 -> 0.032426121 | G43: 1549 | H43: 83 | I43: =G43+H43 -> 1632 | J43: =I43/$I$50 -> 0.031709023 | K43: =E43+I43 -> 2354
B44: SALAMANCA | C44: 862 | D44: 246 | E44: =C44+D44 -> 1108 | F44: =E44/$E$50 -> 0.049761969 | G44: 2311 | H44: 79 | I44: =G44+H44 -> 2390 | J44: =I44/$I$50 -> 0.046436621 | K44: =E44+I44 -> 3498
B45: OVALLE | C45: 3139 | D45: 888 | E45: =C45+D45 -> 4027 | F45: =E45/$E$50 -> 0.18085871 | G45: 7543 | H45: 406 | I45: =G45+H45 -> 7949 | J45: =I45/$I$50 -> 0.15444548 | K45: =E45+I45 -> 11976
B46: COMBARBALA | C46: 466 | D46: 143 | E46: =C46+D46 -> 609 | F46: =E46/$E$50 -> 0.027351118 | G46: 1462 | H46: 57 | I46: =G46+H46 -> 1519 | J46: =I46/$I$50 -> 0.029513484 | K46: =E46+I46 -> 2128
... B49: RIO HURTADO | C49: 198 | D49: 40 | E49: =C49+D49 -> 238 | F49: =E49/$E$50 -> 0.010688943 | G49: 347 | H49: 14 | I49: =G49+H49 -> 361 | J49: =I49/$I$50 -> 0.007014067 | K49: =E49+I49 -> 599
...

Sheet V
A2: Subsecretaría de Previsión Social
A3: Dirección de Estudios Previsionales
B5: Número de Solicitudes de Beneficios del Pilar Solidario según tipo de beneficio - V Región de Vaparaíso | M5: Volver Sistema de Pensiones Solidadias
B6: ='Solicitudes Regiones'!$B$6:$P$6 -> Acumuladas de julio de 2008 a noviembre de 2018
B8: Distribución Regional Solicitudes del Pilar Solidario - no incluye ex Pasis
B9: COMUNA | C9: TOTAL PBS Y APS
C10: PBSV | D10: PBSI | E10: Total PBS | F10: % PBS | G10: APSV | H10: APSI | I10: Total APS | J10: %APS | K10: Total PBS+APS
B11: VALPARAISO | C11: 8511 | D11: 4650 | E11: =C11+D11 -> 13161 | F11: =E11/$E$49 -> 0.18282214 | G11: 27619 | H11: 1800 | I11: =G11+H11 -> 29419 | J11: =I11/$I$49 -> 0.17292579 | K11: =E11+I11 -> 42580
B12: CONCON | C12: 905 | D12: 398 | E12: =C12+D12 -> 1303 | F12: =E12/$E$49 -> 0.018100239 | G12: 2352 | H12: 129 | I12: =G12+H12 -> 2481 | J12: =I12/$I$49 -> 0.014583395 | K12: =E12+I12 -> 3784
B13: PUCHUNCAVI | C13: 670 | D13: 220 | E13: =C13+D13 -> 890 | F13: =E13/$E$49 -> 0.012363172 | G13: 1572 | H13: 60 | I13: =G13+H13 -> 1632 | J13: =I13/$I$49 -> 0.0095929464 | K13: =E13+I13 -> 2522
B14: VIÑA DEL MAR | C14: 7925 | D14: 3016 | E14: =C14+D14 -> 10941 | F14: =E14/$E$49 -> 0.15198366 | G14: 28200 | H14: 1275 | I14: =G14+H14 -> 29475 | J14: =I14/$I$49 -> 0.17325496 | K14: =E14+I14 -> 40416
B15: ISLA DE PASCUA | C15: 95 | D15: 59 | E15: =C15+D15 -> 154 | F15: =E15/$E$49 -> 0.0021392454 | G15: 216 | H15: 27 | I15: =G15+H15 -> 243 | J15: =I15/$I$49 -> 0.0014283615 | K15: =E15+I15 -> 397
B16: LOS ANDES | C16: 1544 | D16: 695 | E16: =C16+D16 -> 2239 | F16: =E16/$E$49 -> 0.031102406 | G16: 6125 | H16: 315 | I16: =G16+H16 -> 6440 | J16: =I16/$I$49 -> 0.037854519 | K16: =E16+I16 -> 8679
B17: RINCONADA | C17: 156 | D17: 73 | E17: =C17+D17 -> 229 | F17: =E17/$E$49 -> 0.0031810857 | G17: 772 | H17: 45 | I17: =G17+H17 -> 817 | J17: =I17/$I$49 -> 0.0048023512 | K17: =E17+I17 -> 1046
B18: SAN ESTEBAN | C18: 417 | D18: 221 | E18: =C18+D18 -> 638 | F18: =E18/$E$49 -> 0.0088625882 | G18: 1602 | H18: 77 | I18: =G18+H18 -> 1679 | J18: =I18/$I$49 -> 0.0098692138 | K18: =E18+I18 -> 2317
B19: PAPUDO | C19: 174 | D19: 93 | E19: =C19+D19 -> 267 | F19: =E19/$E$49 -> 0.0037089515 | G19: 435 | H19: 44 | I19: =G19+H19 -> 479 | J19: =I19/$I$49 -> 0.0028155768 | K19: =E19+I19 -> 746
B20: LA CALERA | C20: 1759 | D20: 855 | E20: =C20+D20 -> 2614 | F20: =E20/$E$49 -> 0.036311607 | G20: 5349 | H20: 381 | I20: =G20+H20 -> 5730 | J20: =I20/$I$49 -> 0.033681117 | K20: =E20+I20 -> 8344
B21: HIJUELAS | C21: 615 | D21: 380 | E21: =C21+D21 -> 995 | F21: =E21/$E$49 -> 0.013821748 | G21: 1586 | H21: 138 | I21: =G21+H21 -> 1724 | J21: =I21/$I$49 -> 0.010133725 | K21: =E21+I21 -> 2719
B22: LA CRUZ | C22: 363 | D22: 155 | E22: =C22+D22 -> 518 | F22: =E22/$E$49 -> 0.0071956437 | G22: 1297 | H22: 93 | I22: =G22+H22 -> 1390 | J22: =I22/$I$49 -> 0.0081704629 | K22: =E22+I22 -> 1908
... B48: VILLA ALEMANA | C48: 2634 | D48: 1500 | E48: =C48+D48 -> 4134 | F48: =E48/$E$49 -> 0.057426238 | G48: 8734 | H48: 484 | I48: =G48+H48 -> 9218 | J48: =I48/$I$49 -> 0.054183688 | K48: =E48+I48 -> 13352
B49: Totales | C49: =SUM(C11:C48) -> 48571 | D49: =SUM(D11:D48) -> 23417 | E49: =C49+D49 -> 71988 | F49: =E49/$E$49 -> 1 | G49: =SUM(G11:G48) -> 161098 | H49: =SUM(H11:H48) -> 9027 | I49: =G49+H49 -> 170125 | J49: =I49/$I$49 -> 1 | K49: =E49+I49 -> 242113
B50: % respecto del total de solicitudes | C50: =+C49/$K$49 -> 0.20061294 | D50: =+D49/$K$49 -> 0.0967193 | E50: =C50+D50 -> 0.29733224 | G50: =+G49/$K$49 -> 0.66538352 | H50: =+H49/$K$49 -> 0.037284243 | I50: =G50+H50 -> 0.70266776 | K50: =E50+I50 -> 1
B52: Número de Concesiones de Beneficios del Pilar Solidario según tipo de beneficio - V Región de Vaparaíso
B53: ='Solicitudes Regiones'!$B$6:$P$6 -> Acumuladas de julio de 2008 a noviembre de 2018
B55: Concesiones del Pilar Solidario a nivel comunal
B56: COMUNA | C56: TOTAL PBS Y APS
C57: PBSV | D57: PBSI | E57: Total PBS | F57: % PBS | G57: APSV | H57: APSI | I57: Total APS | J57: %APS | K57: Total PBS+APS
B58: VALPARAISO | C58: 7682 | D58: 3272 | E58: =C58+D58 -> 10954 | F58: =E58/$E$96 -> 0.18977824 | G58: 22601 | H58: 1493 | I58: =G58+H58 -> 24094 | J58: =I58/$I$96 -> 0.1731799 | K58: =E58+I58 -> 35048
B59: CONCON | C59: 758 | D59: 261 | E59: =C59+D59 -> 1019 | F59: =E59/$E$96 -> 0.017654193 | G59: 1910 | H59: 105 | I59: =G59+H59 -> 2015 | J59: =I59/$I$96 -> 0.01448317 | K59: =E59+I59 -> 3034
B60: PUCHUNCAVI | C60: 552 | D60: 123 | E60: =C60+D60 -> 675 | F60: =E60/$E$96 -> 0.011694387 | G60: 1256 | H60: 53 | I60: =G60+H60 -> 1309 | J60: =I60/$I$96 -> 0.0094086698 | K60: =E60+I60 -> 1984
B61: VIÑA DEL MAR | C61: 7055 | D61: 2201 | E61: =C61+D61 -> 9256 | F61: =E61/$E$96 -> 0.16036036 | G61: 22477 | H61: 1052 | I61: =G61+H61 -> 23529 | J61: =I61/$I$96 -> 0.16911886 | K61: =E61+I61 -> 32785
B62: ISLA DE PASCUA | C62: 89 | D62: 41 | E62: =C62+D62 -> 130 | F62: =E62/$E$96 -> 0.0022522523 | G62: 184 | H62: 22 | I62: =G62+H62 -> 206 | J62: =I62/$I$96 -> 0.0014806616 | K62: =E62+I62 -> 336
B63: LOS ANDES | C63: 1262 | D63: 364 | E63: =C63+D63 -> 1626 | F63: =E63/$E$96 -> 0.028170478 | G63: 4914 | H63: 257 | I63: =G63+H63 -> 5171 | J63: =I63/$I$96 -> 0.03716748 | K63: =E63+I63 -> 6797
B64: RINCONADA | C64: 143 | D64: 39 | E64: =C64+D64 -> 182 | F64: =E64/$E$96 -> 0.0031531532 | G64: 678 | H64: 40 | I64: =G64+H64 -> 718 | J64: =I64/$I$96 -> 0.0051607524 | K64: =E64+I64 -> 900
B65: SAN ESTEBAN | C65: 329 | D65: 98 | E65: =C65+D65 -> 427 | F65: =E65/$E$96 -> 0.0073977824 | G65: 1311 | H65: 61 | I65: =G65+H65 -> 1372 | J65: =I65/$I$96 -> 0.0098614935 | K65: =E65+I65 -> 1799
B66: PAPUDO | C66: 160 | D66: 59 | E66: =C66+D66 -> 219 | F66: =E66/$E$96 -> 0.0037941788 | G66: 378 | H66: 30 | I66: =G66+H66 -> 408 | J66: =I66/$I$96 -> 0.0029325724 | K66: =E66+I66 -> 627
B67: LA CALERA | C67: 1587 | D67: 538 | E67: =C67+D67 -> 2125 | F67: =E67/$E$96 -> 0.036815662 | G67: 4490 | H67: 300 | I67: =G67+H67 -> 4790 | J67: =I67/$I$96 -> 0.034428975 | K67: =E67+I67 -> 6915
B68: HIJUELAS | C68: 546 | D68: 207 | E68: =C68+D68 -> 753 | F68: =E68/$E$96 -> 0.013045738 | G68: 1328 | H68: 114 | I68: =G68+H68 -> 1442 | J68: =I68/$I$96 -> 0.010364631 | K68: =E68+I68 -> 2195
B69: LA CRUZ | C69: 326 | D69: 97 | E69: =C69+D69 -> 423 | F69: =E69/$E$96 -> 0.0073284823 | G69: 1109 | H69: 59 | I69: =G69+H69 -> 1168 | J69: =I69/$I$96 -> 0.0083952073 | K69: =E69+I69 -> 1591
... B95: VILLA ALEMANA | C95: 2344 | D95: 922 | E95: =C95+D95 -> 3266 | F95: =E95/$E$96 -> 0.056583507 | G95: 7226 | H95: 403 | I95: =G95+H95 -> 7629 | J95: =I95/$I$96 -> 0.054834791 | K95: =E95+I95 -> 10895
...

Sheet VI
A2: Subsecretaría de Previsión Social
A3: Dirección de Estudios Previsionales
B5: Número de Solicitudes de Beneficios del Pilar Solidario según tipo de beneficio - VI Región de L.G.B. O'Higgins | M5: Volver Sistema de Pensiones Solidadias
B6: ='Solicitudes Regiones'!$B$6:$P$6 -> Acumuladas de julio de 2008 a noviembre de 2018
B8: Distribución Regional Solicitudes del Pilar Solidario - no incluye ex Pasis
B9: COMUNA | C9: TOTAL PBS Y APS
C10: PBSV | D10: PBSI | E10: Total PBS | F10: % PBS | G10: APSV | H10: APSI | I10: Total APS | J10: %APS | K10: Total PBS+APS
B11: RANCAGUA | C11: 5350 | D11: 2815 | E11: =C11+D11 -> 8165 | F11: =E11/$E$44 -> 0.2212977 | G11: 17062 | H11: 1454 | I11: =G11+H11 -> 18516 | J11: =I11/$I$44 -> 0.22919245 | K11: =E11+I11 -> 26681
B12: COLTAUCO | C12: 564 | D12: 289 | E12: =C12+D12 -> 853 | F12: =E12/$E$44 -> 0.023119037 | G12: 1793 | H12: 109 | I12: =G12+H12 -> 1902 | J12: =I12/$I$44 -> 0.0235431 | K12: =E12+I12 -> 2755
B13: GRANEROS | C13: 745 | D13: 323 | E13: =C13+D13 -> 1068 | F13: =E13/$E$44 -> 0.028946227 | G13: 2324 | H13: 152 | I13: =G13+H13 -> 2476 | J13: =I13/$I$44 -> 0.030648116 | K13: =E13+I13 -> 3544
B14: PICHIDEGUA | C14: 662 | D14: 407 | E14: =C14+D14 -> 1069 | F14: =E14/$E$44 -> 0.02897333 | G14: 1914 | H14: 119 | I14: =G14+H14 -> 2033 | J14: =I14/$I$44 -> 0.025164628 | K14: =E14+I14 -> 3102
B15: REQUINOA | C15: 488 | D15: 287 | E15: =C15+D15 -> 775 | F15: =E15/$E$44 -> 0.021004987 | G15: 2007 | H15: 128 | I15: =G15+H15 -> 2135 | J15: =I15/$I$44 -> 0.026427192 | K15: =E15+I15 -> 2910
B16: LITUECHE | C16: 212 | D16: 146 | E16: =C16+D16 -> 358 | F16: =E16/$E$44 -> 0.0097029488 | G16: 492 | H16: 29 | I16: =G16+H16 -> 521 | J16: =I16/$I$44 -> 0.0064489776 | K16: =E16+I16 -> 879
B17: PAREDONES | C17: 253 | D17: 189 | E17: =C17+D17 -> 442 | F17: =E17/$E$44 -> 0.011979618 | G17: 667 | H17: 43 | I17: =G17+H17 -> 710 | J17: =I17/$I$44 -> 0.0087884339 | K17: =E17+I17 -> 1152
B18: CHEPICA | C18: 527 | D18: 388 | E18: =C18+D18 -> 915 | F18: =E18/$E$44 -> 0.024799436 | G18: 1648 | H18: 100 | I18: =G18+H18 -> 1748 | J18: =I18/$I$44 -> 0.021636877 | K18: =E18+I18 -> 2663
B19: PALMILLA | C19: 381 | D19: 213 | E19: =C19+D19 -> 594 | F19: =E19/$E$44 -> 0.016099306 | G19: 1205 | H19: 84 | I19: =G19+H19 -> 1289 | J19: =I19/$I$44 -> 0.01595534 | K19: =E19+I19 -> 1883
B20: PLACILLA | C20: 223 | D20: 191 | E20: =C20+D20 -> 414 | F20: =E20/$E$44 -> 0.011220729 | G20: 847 | H20: 64 | I20: =G20+H20 -> 911 | J20: =I20/$I$44 -> 0.011276427 | K20: =E20+I20 -> 1325
B21: SANTA CRUZ | C21: 1057 | D21: 657 | E21: =C21+D21 -> 1714 | F21: =E21/$E$44 -> 0.0464549 | G21: 3911 | H21: 259 | I21: =G21+H21 -> 4170 | J21: =I21/$I$44 -> 0.051616577 | K21: =E21+I21 -> 5884
B22: CODEGUA | C22: 252 | D22: 201 | E22: =C22+D22 -> 453 | F22: =E22/$E$44 -> 0.012277754 | G22: 951 | H22: 91 | I22: =G22+H22 -> 1042 | J22: =I22/$I$44 -> 0.012897955 | K22: =E22+I22 -> 1495
... B43: LA ESTRELLA | C43: 126 | D43: 89 | E43: =C43+D43 -> 215 | F43: =E43/$E$44 -> 0.0058271899 | G43: 361 | H43: 13 | I43: =G43+H43 -> 374 | J43: =I43/$I$44 -> 0.0046294004 | K43: =E43+I43 -> 589
B44: Totales | C44: =SUM(C11:C43) -> 23169 | D44: =SUM(D11:D43) -> 13727 | E44: =C44+D44 -> 36896 | F44: =E44/$E$44 -> 1 | G44: =SUM(G11:G43) -> 75671 | H44: =SUM(H11:H43) -> 5117 | I44: =G44+H44 -> 80788 | J44: =I44/$I$44 -> 1 | K44: =E44+I44 -> 117684
B45: % respecto del total de solicitudes | C45: =+C44/$K$44 -> 0.19687468 | D45: =+D44/$K$44 -> 0.11664287 | E45: =C45+D45 -> 0.31351756 | G45: =+G44/$K$44 -> 0.6430016 | H45: =+H44/$K$44 -> 0.043480847 | I45: =G45+H45 -> 0.68648244 | K45: =E45+I45 -> 1
B47: Número de Concesiones de Beneficios del Pilar Solidario según tipo de beneficio - VI Región de L.G.B. O'Higgins
B48: ='Solicitudes Regiones'!$B$6:$P$6 -> Acumuladas de julio de 2008 a noviembre de 2018
