Workbook

Sheet Indice General
B1: Subsecretaría de Previsión Social Dirección de Estudios Previsionales
B9: Informe trimestral del Pilar No Contributivo
B10: Trimestre JAS 2024
B12: I. Pago de Beneficios del Pilar No Contributivo
B13: 1. Total de beneficios pagados del Pilar No Contributivo a nivel nacional
B14: 2. Total de beneficios pagados del Pilar No Contributivo a nivel regional
B15: 3. Pagos Pensión Garantizada Universal (PGU)
B16: 4. Pagos Pensión Básica Solidaria (PBS)
B17: 5. Pagos Aporte Previsional Solidario (APS)
B19: II. Estado de solicitudes
B20: 1. Solicitudes del Pilar No Contributivo a nivel nacional
B21: 2. Solicitudes del Pilar No Contributivo a nivel regional y comunal
... B33: 3. Subsidio a la Cotización de Trabajadores Jóvenes

Sheet I. Beneficios pagados
B1: Subsecretaría de Previsión Social Dirección de Estudios Previsionales
B9: I. Pago de Beneficios del Pilar No Contributivo
B10: Trimestre JAS 2024
B12: 1. Total de beneficios pagados del Pilar No Contributivo a nivel nacional
B13: i. Resumen trimestral de beneficios pagados, por tipo de beneficio y sexo
B14: ii. Serie resumen de pagos de beneficios acumulados, por tipo de beneficio
B16: 2. Total de beneficios pagados del Pilar No Contributivo a nivel regional
B17: i. Resumen trimestral de beneficios pagados, por región, tipo de beneficio y sexo
B19: 3. Pagos Pensión Garantizada Universal (PGU)
B20: i. Resumen trimestral de beneficios pagados, por tipo de beneficio y sexo
B21: ii. Serie resumen de pagos de beneficios acumulado, por tipo de beneficio y sexo
B23: 4. Pagos Pensión Básica Solidaria (PBS)
... B29: ii. Serie resumen de pagos de beneficios acumulado, por tipo de beneficio y sexo

Sheet dinamica pgu
A1: PERIODO | B1: (Varios elementos)
A3: Etiquetas de fila
A4: oct
A5: Suma de PGU_NC_Mujer_n | B5: 322141
A6: Suma de PGU_NC_hombre_N | B6: 109963
A7: Suma de PGU_C_Mujer_N | B7: 686334
A8: Suma de PGU_C_hombre_N | B8: 563950
A9: nov
A10: Suma de PGU_NC_Mujer_n | B10: 327443
A11: Suma de PGU_NC_hombre_N | B11: 121585
A12: Suma de PGU_C_Mujer_N | B12: 704099
A13: Suma de PGU_C_hombre_N | B13: 584193
A14: dic
A15: Suma de PGU_NC_Mujer_n | B15: 329180
A16: Suma de PGU_NC_hombre_N | B16: 125728
A17: Suma de PGU_C_Mujer_N | B17: 717919
A18: Suma de PGU_C_hombre_N | B18: 594890
A22: PERIODO | B22: (Varios elementos)
A24: Etiquetas de fila
A25: oct
A26: Suma de PGU_NC_Mujer_Nom | B26: 62098940
A27: Suma de PGU_NC_hombre_Nom | B27: 21312758
A28: Suma de PGU_C_Mujer_Nom | B28: 1.3198656e+08
A29: Suma de PGU_C_hombre_Nom | B29: 1.0801488e+08
A30: nov
A31: Suma de PGU_NC_Mujer_Nom | B31: 63080933
A32: Suma de PGU_NC_hombre_Nom | B32: 23564397
A33: Suma de PGU_C_Mujer_Nom | B33: 1.3523624e+08
A34: Suma de PGU_C_hombre_Nom | B34: 1.115372e+08
A35: dic
A36: Suma de PGU_NC_Mujer_Nom | B36: 63417032
A37: Suma de PGU_NC_hombre_Nom | B37: 24368203
A38: Suma de PGU_C_Mujer_Nom | B38: 1.3763622e+08
A39: Suma de PGU_C_hombre_Nom | B39: 1.1328694e+08
A43: PERIODO | B43: (Varios elementos)
A45: Etiquetas de fila
A46: oct
A47: Suma de PGU_NC_Mujer_REAL | B47: 61325232
A48: Suma de PGU_NC_hombre_REAL | B48: 21047217
A49: Suma de PGU_C_Mujer_REAL | B49: 1.303421e+08
...

Sheet N PBS
A3: Etiquetas de fila | B3: Promedio de PBS VEJEZ MUJER | C3: Promedio de PBS VEJEZ HOMBRE | D3: Promedio de PBS INVALIDEZ MUJER | E3: Promedio de PBS INVALIDEZ HOMBRE | F3: Promedio de PBS TOTAL MUJER | G3: Promedio de PBS TOTAL HOMBRE
A4: 2008 | B4: 218799.83 | C4: 107682.67 | D4: 108916.5 | E4: 84536 | F4: 327716.33 | G4: 192218.67
A5: 2009 | B5: 262267.25 | C5: 117026.58 | D5: 116205.08 | E5: 86817.667 | F5: 378472.33 | G5: 203844.25
A6: 2010 | B6: 284569.67 | C6: 119969.58 | D6: 125529.75 | E6: 89731.417 | F6: 410099.42 | G6: 209701
A7: 2011 | B7: 286982.92 | C7: 118668.92 | D7: 125674.58 | E7: 89317.917 | F7: 412657.5 | G7: 207986.83
A8: 2012 | B8: 288232.25 | C8: 116683.83 | D8: 120025.92 | E8: 85446.25 | F8: 408258.17 | G8: 202130.08
A9: 2013 | B9: 288720.25 | C9: 114312 | D9: 112605.08 | E9: 79812.917 | F9: 401325.33 | G9: 194124.92
A10: 2014 | B10: 288530.42 | C10: 111136.17 | D10: 107377.17 | E10: 75527.833 | F10: 395907.58 | G10: 186664
A11: 2015 | B11: 289070.58 | C11: 110162 | D11: 105105.42 | E11: 74655.333 | F11: 394176 | G11: 184817.33
A12: 2016 | B12: 290373 | C12: 108843.42 | D12: 105459.83 | E12: 75532.583 | F12: 395832.83 | G12: 184376
A13: 2017 | B13: 291754 | C13: 107694.83 | D13: 105581.83 | E13: 76434.167 | F13: 397335.83 | G13: 184129
A14: 2018 | B14: 295171.83 | C14: 107077.42 | D14: 105559.42 | E14: 77417 | F14: 400731.25 | G14: 184494.42
A15: 2019 | B15: 299821.5 | C15: 106705.25 | D15: 104899.17 | E15: 77850.417 | F15: 404720.67 | G15: 184555.67
... A42: dic | B42: 0 | C42: 0 | D42: 103979 | E42: 81605 | F42: 103979 | G42: 81605

Sheet MONTOS PBS
I1: PERIODO | J1: (Varios elementos)
A3: Etiquetas de fila | B3: Promedio de PBSV_MUJER | C3: Promedio de PBSV_HOMBRE | D3: Promedio de PBSI_MUJER | E3: Promedio de PBSI_HOMBRE | F3: Promedio de PBS_MUJER | G3: Promedio de PBS_HOMBRE | I3: Etiquetas de fila | J3: Suma de PBSV_MUJER | K3: Suma de PBSV_HOMBRE | L3: Suma de PBSV_TOTAL | M3: Suma de PBSI_MUJER | N3: Suma de PBSI_HOMBRE | O3: Suma de PBSI_TOTAL | P3: Suma de PBS_MUJER | Q3: Suma de PBS_HOMBRE | R3: Suma de PBS_TOTAL | T3: Etiquetas de fila | U3: Suma de PBSV_MUJER | V3: Suma de PBSV_HOMBRE | W3: Suma de PBSV_TOTAL | X3: Suma de PBSI_MUJER | Y3: Suma de PBSI_HOMBRE | Z3: Suma de PBSI_TOTAL | AA3: Suma de PBS_MUJER | AB3: Suma de PBS_HOMBRE | AC3: Suma de PBS_TOTAL | AE3: Etiquetas de fila | AF3: Suma de PBSV_MUJER | AG3: Suma de PBSV_HOMBRE | AH3: Suma de PBSV_TOTAL | AI3: Suma de PBSI_MUJER | AJ3: Suma de PBSI_HOMBRE | AK3: Suma de PBSI_TOTAL | AL3: Suma de PBS_MUJER | AM3: Suma de PBS_HOMBRE | AN3: Suma de PBS_TOTAL
A4: 2008 | B4: 8.2469269e+09 | C4: 3.9732077e+09 | D4: 3.9696562e+09 | E4: 3.0646136e+09 | F4: 1.2216583e+10 | G4: 7.0378213e+09 | I4: 2022 | J4: 0 | K4: 0 | L4: 0 | M4: 6.0133313e+10 | N4: 4.7149436e+10 | O4: 1.0728275e+11 | P4: 6.0133313e+10 | Q4: 4.7149436e+10 | R4: 1.0728275e+11 | T4: oct | U4: 0 | V4: 0 | W4: 0 | X4: 1.9903687e+10 | Y4: 1.5583475e+10 | Z4: 3.5487162e+10 | AA4: 1.9903687e+10 | AB4: 1.5583475e+10 | AC4: 3.5487162e+10 | AE4: oct | AF4: =+U4/1000 -> 0 | AG4: =+V4/1000 -> 0 | AH4: =+W4/1000 -> 0 | AI4: =+X4/1000 -> 19903687 | AJ4: =+Y4/1000 -> 15583475 | AK4: =+Z4/1000 -> 35487162 | AL4: =+AA4/1000 -> 19903687 | AM4: =+AB4/1000 -> 15583475 | AN4: =+AC4/1000 -> 35487162
A5: 2009 | B5: 1.0831943e+10 | C5: 4.7784934e+09 | D5: 5.149103e+09 | E5: 3.655593e+09 | F5: 1.5981046e+10 | G5: 8.4340864e+09 | I5: oct | J5: 0 | K5: 0 | L5: 0 | M5: 1.9903687e+10 | N5: 1.5583475e+10 | O5: 3.5487162e+10 | P5: 1.9903687e+10 | Q5: 1.5583475e+10 | R5: 3.5487162e+10 | T5: nov | U5: 0 | V5: 0 | W5: 0 | X5: 2.0075789e+10 | Y5: 1.5749774e+10 | Z5: 3.5825563e+10 | AA5: 2.0075789e+10 | AB5: 1.5749774e+10 | AC5: 3.5825563e+10 | AE5: nov | AF5: =+U5/1000 -> 0 | AG5: =+V5/1000 -> 0 | AH5: =+W5/1000 -> 0 | AI5: =+X5/1000 -> 20075789 | AJ5: =+Y5/1000 -> 15749774 | AK5: =+Z5/1000 -> 35825563 | AL5: =+AA5/1000 -> 20075789 | AM5: =+AB5/1000 -> 15749774 | AN5: =+AC5/1000 -> 35825563
A6: 2010 | B6: 1.3095568e+10 | C6: 5.5029662e+09 | D6: 5.9733298e+09 | E6: 4.1819318e+09 | F6: 1.9068897e+10 | G6: 9.684898e+09 | I6: nov | J6: 0 | K6: 0 | L6: 0 | M6: 2.0075789e+10 | N6: 1.5749774e+10 | O6: 3.5825563e+10 | P6: 2.0075789e+10 | Q6: 1.5749774e+10 | R6: 3.5825563e+10 | T6: dic | U6: 0 | V6: 0 | W6: 0 | X6: 20153837159 | Y6: 15816186175 | Z6: 35970023334 | AA6: 20153837159 | AB6: 15816186175 | AC6: 35970023334 | AE6: dic | AF6: =+U6/1000 -> 0 | AG6: =+V6/1000 -> 0 | AH6: =+W6/1000 -> 0 | AI6: =+X6/1000 -> 20153837 | AJ6: =+Y6/1000 -> 15816186 | AK6: =+Z6/1000 -> 35970023 | AL6: =+AA6/1000 -> 20153837 | AM6: =+AB6/1000 -> 15816186 | AN6: =+AC6/1000 -> 35970023
A7: 2011 | B7: 1.3994994e+10 | C7: 5.7801079e+09 | D7: 6.2216009e+09 | E7: 4.3734947e+09 | F7: 2.0216595e+10 | G7: 1.0153603e+10 | I7: dic | J7: 0 | K7: 0 | L7: 0 | M7: 20153837159 | N7: 15816186175 | O7: 35970023334 | P7: 20153837159 | Q7: 15816186175 | R7: 35970023334
A8: 2012 | B8: 1.4900592e+10 | C8: 6.0276417e+09 | D8: 6.3053347e+09 | E8: 4.4481809e+09 | F8: 2.1205927e+10 | G8: 1.0475823e+10
A9: 2013 | B9: 1.5464511e+10 | C9: 6.1276381e+09 | D9: 6.1333006e+09 | E9: 4.2916174e+09 | F9: 2.1597811e+10 | G9: 1.0419256e+10
A10: 2014 | B10: 1.6719242e+10 | C10: 6.4430339e+09 | D10: 6.3328754e+09 | E10: 4.3768174e+09 | F10: 2.3052118e+10 | G10: 1.0819851e+10
A11: 2015 | B11: 1.8210703e+10 | C11: 6.9460832e+09 | D11: 6.7614414e+09 | E11: 4.7714308e+09 | F11: 2.4972144e+10 | G11: 1.1717514e+10
A12: 2016 | B12: 1.9783297e+10 | C12: 7.4256197e+09 | D12: 7.3620108e+09 | E12: 5.231601e+09 | F12: 2.7145307e+10 | G12: 1.2657221e+10 | I12: PERIODO | J12: (Varios elementos) | AE12: nominales
A13: 2017 | B13: 2.3013212e+10 | C13: 8.5012643e+09 | D13: 8.4836307e+09 | E13: 6.1043568e+09 | F13: 3.1496842e+10 | G13: 1.4605621e+10 | AF13: vejez | AI13: invalidez | AL13: total
A14: 2018 | B14: 2.4370428e+10 | C14: 8.8423454e+09 | D14: 8.863105e+09 | E14: 6.4518852e+09 | F14: 3.3233533e+10 | G14: 1.5294231e+10 | I14: Etiquetas de fila | J14: Suma de MUJER | K14: Suma de HOMBRE | L14: Suma de TOTAL | M14: Suma de MUJER2 | N14: Suma de HOMBRE2 | O14: Suma de TOTAL2 | P14: Suma de MUJER3 | Q14: Suma de HOMBRE3 | R14: Suma de TOTAL3 | T14: Etiquetas de fila | U14: Suma de MUJER | V14: Suma de HOMBRE | W14: Suma de TOTAL | X14: Suma de MUJER2 | Y14: Suma de HOMBRE2 | Z14: Suma de TOTAL2 | AA14: Suma de MUJER3 | AB14: Suma de HOMBRE3 | AC14: Suma de TOTAL3 | AE14: Etiquetas de fila | AF14: Promedio de MUJER | AG14: Promedio de HOMBRE | AH14: Promedio de TOTAL | AI14: Promedio de MUJER2 | AJ14: Promedio de HOMBRE2 | AK14: Promedio de TOTAL2 | AL14: Promedio de MUJER3 | AM14: Promedio de HOMBRE3 | AN14: Promedio de TOTAL3
A15: 2019 | B15: 2.6689511e+10 | C15: 9.492244e+09 | D15: 9.429656e+09 | E15: 6.9564548e+09 | F15: 3.6119167e+10 | G15: 1.6448699e+10 | I15: 2022 | J15: 0 | K15: 0 | L15: 0 | M15: 60441368879 | N15: 47390715970 | O15: 107832084849 | P15: 60441368879 | Q15: 47390715970 | R15: 107832084849 | T15: oct | U15: 0 | V15: 0 | W15: 0 | X15: 20154801071 | Y15: 15780083599 | Z15: 35934884670 | AA15: 20154801071 | AB15: 15780083599 | AC15: 35934884670 | AE15: oct | AF15: =+U15/1000 -> 0 | AG15: =+V15/1000 -> 0 | AH15: =+W15/1000 -> 0 | AI15: =+X15/1000 -> 20154801 | AJ15: =+Y15/1000 -> 15780084 | AK15: =+Z15/1000 -> 35934885 | AL15: =+AA15/1000 -> 20154801 | AM15: =+AB15/1000 -> 15780084 | AN15: =+AC15/1000 -> 35934885
A16: 2020 | B16: 3.659289e+10 | C16: 1.2913294e+10 | D16: 1.1894674e+10 | E16: 8.9114229e+09 | F16: 4.8487564e+10 | G16: 2.1824717e+10 | I16: oct | J16: 0 | K16: 0 | L16: 0 | M16: 20154801071 | N16: 15780083599 | O16: 35934884670 | P16: 20154801071 | Q16: 15780083599 | R16: 35934884670 | T16: nov | U16: 0 | V16: 0 | W16: 0 | X16: 20132730649 | Y16: 15794446196 | Z16: 35927176845 | AA16: 20132730649 | AB16: 15794446196 | AC16: 35927176845 | AE16: nov | AF16: =+U16/1000 -> 0 | AG16: =+V16/1000 -> 0 | AH16: =+W16/1000 -> 0 | AI16: =+X16/1000 -> 20132731 | AJ16: =+Y16/1000 -> 15794446 | AK16: =+Z16/1000 -> 35927177 | AL16: =+AA16/1000 -> 20132731 | AM16: =+AB16/1000 -> 15794446 | AN16: =+AC16/1000 -> 35927177
A17: 2021 | B17: 4.3453866e+10 | C17: 1.494933e+10 | D17: 1.4114095e+10 | E17: 1.0837333e+10 | F17: 5.7567962e+10 | G17: 2.5786663e+10 | I17: nov | J17: 0 | K17: 0 | L17: 0 | M17: 20132730649 | N17: 15794446196 | O17: 35927176845 | P17: 20132730649 | Q17: 15794446196 | R17: 35927176845 | T17: dic | U17: 0 | V17: 0 | W17: 0 | X17: 20153837159 | Y17: 15816186175 | Z17: 35970023334 | AA17: 20153837159 | AB17: 15816186175 | AC17: 35970023334 | AE17: dic | AF17: =+U17/1000 -> 0 | AG17: =+V17/1000 -> 0 | AH17: =+W17/1000 -> 0 | AI17: =+X17/1000 -> 20153837 | AJ17: =+Y17/1000 -> 15816186 | AK17: =+Z17/1000 -> 35970023 | AL17: =+AA17/1000 -> 20153837 | AM17: =+AB17/1000 -> 15816186 | AN17: =+AC17/1000 -> 35970023
A18: ene | B18: 4.1412765e+10 | C18: 1.4344175e+10 | D18: 1.357545e+10 | E18: 1.0301137e+10 | F18: 5.4988215e+10 | G18: 2.4645311e+10 | I18: dic | J18: 0 | K18: 0 | L18: 0 | M18: 20153837159 | N18: 15816186175 | O18: 35970023334 | P18: 20153837159 | Q18: 15816186175 | R18: 35970023334 | T18: Total general | U18: 0 | V18: 0 | W18: 0 | X18: 2.0147123e+10 | Y18: 1.5796905e+10 | Z18: 35944028283 | AA18: 2.0147123e+10 | AB18: 1.5796905e+10 | AC18: 35944028283
A19: feb | B19: 4.1492133e+10 | C19: 1.4338672e+10 | D19: 1.35569e+10 | E19: 1.0317361e+10 | F19: 5.5049033e+10 | G19: 2.4656033e+10
A20: mar | B20: 4.1689378e+10 | C20: 1.4389108e+10 | D20: 1.3587482e+10 | E20: 1.0363694e+10 | F20: 5.527686e+10 | G20: 2.4752801e+10
A21: abr | B21: 4.1893694e+10 | C21: 1.4448119e+10 | D21: 1.3658161e+10 | E21: 1.0436146e+10 | F21: 5.5551855e+10 | G21: 2.4884265e+10
A22: may | B22: 4.2028716e+10 | C22: 1.4474202e+10 | D22: 1.3650261e+10 | E22: 1.0455982e+10 | F22: 5.5678977e+10 | G22: 2.4930184e+10
A23: jun | B23: 4.2051494e+10 | C23: 1.4454401e+10 | D23: 1.3673345e+10 | E23: 1.0488652e+10 | F23: 5.5724839e+10 | G23: 2.4943053e+10
A24: jul | B24: 4.3968065e+10 | C24: 1.5094747e+10 | D24: 1.4296201e+10 | E24: 1.0984398e+10 | F24: 5.8264265e+10 | G24: 2.6079145e+10
A25: ago | B25: 4.4239653e+10 | C25: 1.5183281e+10 | D25: 1.4359654e+10 | E25: 1.1056169e+10 | F25: 5.8599307e+10 | G25: 2.6239451e+10
A26: sept | B26: 4.4825753e+10 | C26: 1.5361682e+10 | D26: 1.4520122e+10 | E26: 1.1196684e+10 | F26: 5.9345875e+10 | G26: 2.6558366e+10
A27: oct | B27: 4.5558469e+10 | C27: 1.5619781e+10 | D27: 1.4731002e+10 | E27: 1.1378659e+10 | F27: 6.0289471e+10 | G27: 2.6998439e+10
A28: nov | B28: 4.5907806e+10 | C28: 1.5757842e+10 | D28: 1.4819941e+10 | E28: 1.1477734e+10 | F28: 6.0727747e+10 | G28: 2.7235576e+10
A29: dic | B29: 4.6378472e+10 | C29: 1.5925944e+10 | D29: 1.4940627e+10 | E29: 1.159138e+10 | F29: 6.1319099e+10 | G29: 2.7517324e+10
A30: 2022 | B30: 4.0614957e+09 | C30: 1.3943048e+09 | D30: 1.8608107e+10 | E30: 1.4541109e+10 | F30: 2.2669603e+10 | G30: 1.5935414e+10
... A43: Total general | B43: 1.9676256e+10 | C43: 7.3869635e+09 | D43: 8.5253168e+09 | E43: 6.2527955e+09 | F43: 2.8201573e+10 | G43: 1.3639759e+10
A52: Etiquetas de fila | B52: Promedio de PBSV_MUJER | C52: Promedio de PBSV_HOMBRE | D52: Promedio de PBSI_MUJER | E52: Promedio de PBSI_HOMBRE | F52: Promedio de PBS_MUJER | G52: Promedio de PBS_HOMBRE | I52: Etiquetas de fila | J52: Promedio de PBSV_MUJER | K52: Promedio de PBSV_HOMBRE | L52: Promedio de PBSI_MUJER | M52: Promedio de PBSI_HOMBRE | N52: Promedio de PBS_MUJER | O52: Promedio de PBS_HOMBRE
A53: 2008 | B53: 8.2469269e+09 | C53: 3.9732077e+09 | D53: 3.9696562e+09 | E53: 3.0646136e+09 | F53: 1.2216583e+10 | G53: 7.0378213e+09 | I53: 2008 | J53: 8246926.9 | K53: 3973207.7 | L53: 3969656.2 | M53: 3064613.6 | N53: 12216583 | O53: 7037821.3
A54: 2009 | B54: 1.0831943e+10 | C54: 4.7784934e+09 | D54: 5.149103e+09 | E54: 3.655593e+09 | F54: 1.5981046e+10 | G54: 8.4340864e+09 | I54: 2009 | J54: 10831943 | K54: 4778493.4 | L54: 5149103 | M54: 3655593 | N54: 15981046 | O54: 8434086.4
A55: 2010 | B55: 1.3095568e+10 | C55: 5.5029662e+09 | D55: 5.9733298e+09 | E55: 4.1819318e+09 | F55: 1.9068897e+10 | G55: 9.684898e+09 | I55: 2010 | J55: 13095568 | K55: 5502966.2 | L55: 5973329.8 | M55: 4181931.8 | N55: 19068897 | O55: 9684898
A56: 2011 | B56: 1.3994994e+10 | C56: 5.7801079e+09 | D56: 6.2216009e+09 | E56: 4.3734947e+09 | F56: 2.0216595e+10 | G56: 1.0153603e+10 | I56: 2011 | J56: 13994994 | K56: 5780107.9 | L56: 6221600.9 | M56: 4373494.7 | N56: 20216595 | O56: 10153603
A57: 2012 | B57: 1.4900592e+10 | C57: 6.0276417e+09 | D57: 6.3053347e+09 | E57: 4.4481809e+09 | F57: 2.1205927e+10 | G57: 1.0475823e+10 | I57: 2012 | J57: 14900592 | K57: 6027641.7 | L57: 6305334.7 | M57: 4448180.9 | N57: 21205927 | O57: 10475823
A58: 2013 | B58: 1.5464511e+10 | C58: 6.1276381e+09 | D58: 6.1333006e+09 | E58: 4.2916174e+09 | F58: 2.1597811e+10 | G58: 1.0419256e+10 | I58: 2013 | J58: 15464511 | K58: 6127638.1 | L58: 6133300.6 | M58: 4291617.4 | N58: 21597811 | O58: 10419256
A59: 2014 | B59: 1.6719242e+10 | C59: 6.4430339e+09 | D59: 6.3328754e+09 | E59: 4.3768174e+09 | F59: 2.3052118e+10 | G59: 1.0819851e+10 | I59: 2014 | J59: 16719242 | K59: 6443033.9 | L59: 6332875.4 | M59: 4376817.4 | N59: 23052118 | O59: 10819851
A60: 2015 | B60: 1.8210703e+10 | C60: 6.9460832e+09 | D60: 6.7614414e+09 | E60: 4.7714308e+09 | F60: 2.4972144e+10 | G60: 1.1717514e+10 | I60: 2015 | J60: 18210703 | K60: 6946083.2 | L60: 6761441.4 | M60: 4771430.8 | N60: 24972144 | O60: 11717514
A61: 2016 | B61: 1.9783297e+10 | C61: 7.4256197e+09 | D61: 7.3620108e+09 | E61: 5.231601e+09 | F61: 2.7145307e+10 | G61: 1.2657221e+10 | I61: 2016 | J61: 19783297 | K61: 7425619.7 | L61: 7362010.8 | M61: 5231601 | N61: 27145307 | O61: 12657221
...

Sheet 1.1
B2: TOTAL BENEFICIOS PAGADOS DEL PILAR NO CONTRIBUTIVO A NIVEL NACIONAL
B4: Resumen trimestral de beneficios pagados, por tipo de beneficio y sexo
B5: (julio 2024 a septiembre 2024)
D7: Mujeres | G7: Hombres | J7: Total
B8: Periodo | C8: Tipo de beneficio | D8: N° beneficiarios | E8: Monto nominal (MM$)4 | F8: Monto real (MM$)5 | G8: N° beneficiarios | H8: Monto nominal (MM$)4 | I8: Monto real (MM$)5 | J8: N° beneficiarios | K8: Monto nominal (MM$)4 | L8: Monto real (MM$)5
B9: 45474 | C9: PGU no contributiva1 | D9: 348046 | E9: 74185.359 | F9: 74440.178 | G9: 133888 | H9: 28641.34 | I9: 28739.72 | J9: 481934 | K9: 102826.7 | L9: 103179.9
C10: PGU contributiva1 2 | D10: 856180 | E10: 180633.23 | F10: 181253.69 | G10: 728418 | H10: 152081.51 | I10: 152603.9 | J10: 1584598 | K10: 332714.74 | L10: 333857.58
C11: APS vejez1 | D11: 104051 | E11: 25674.329 | F11: 25762.518 | G11: 58337 | H11: 14665.675 | I11: 14716.05 | J11: 162388 | K11: 40340.004 | L11: 40478.568
C12: PBS invalidez | D12: 110743 | E12: 23718.11 | F12: 23799.579 | G12: 87013 | H12: 18637.259 | I12: 18701.276 | J12: 197756 | K12: 42355.369 | L12: 42500.856
C13: APS invalidez | D13: 47933 | E13: 8711.2758 | F13: 8741.1982 | G13: 51499 | H13: 8856.8317 | I13: 8887.2541 | J13: 99432 | K13: 17568.108 | L13: 17628.452
C14: Total beneficios3 | D14: 1466953 | E14: 312922.3 | F14: 313997.16 | G14: 1059155 | H14: 222882.62 | I14: 223648.2 | J14: 2526108 | K14: 535804.92 | L14: 537645.35
B15: 45505 | C15: PGU no contributiva1 | D15: 349176 | E15: 74407.143 | F15: 74472.45 | G15: 134137 | H15: 28694.629 | I15: 28719.814 | J15: 483313 | K15: 103101.77 | L15: 103192.26
C16: PGU contributiva1 2 | D16: 859346 | E16: 181274.18 | F16: 181433.28 | G16: 731265 | H16: 152658.6 | I16: 152792.59 | J16: 1590611 | K16: 333932.78 | L16: 334225.87
C17: APS vejez1 | D17: 103719 | E17: 25611.173 | F17: 25633.651 | G17: 57968 | H17: 14591.401 | I17: 14604.208 | J17: 161687 | K17: 40202.574 | L17: 40237.859
C18: PBS invalidez | D18: 111054 | E18: 23784.904 | F18: 23805.78 | G18: 87337 | H18: 18706.699 | I18: 18723.118 | J18: 198391 | K18: 42491.603 | L18: 42528.898
C19: APS invalidez | D19: 48030 | E19: 8722.7025 | F19: 8730.3583 | G19: 51610 | H19: 8871.6556 | I19: 8879.4421 | J19: 99640 | K19: 17594.358 | L19: 17609.8
C20: Total beneficios3 | D20: 1471325 | E20: 313800.1 | F20: 314075.52 | G20: 1062317 | H20: 223522.99 | I20: 223719.17 | J20: 2533642 | K20: 537323.09 | L20: 537794.69
B21: 45536 | C21: PGU no contributiva1 | D21: 420895 | E21: 89641.814 | F21: 89641.814 | G21: 167174 | H21: 35771.66 | I21: 35771.66 | J21: 588069 | K21: 125413.47 | L21: 125413.47
C22: PGU contributiva1 2 | D22: 792093 | E22: 166908.85 | F22: 166908.85 | G22: 702144 | H22: 146387.69 | I22: 146387.69 | J22: 1494237 | K22: 313296.54 | L22: 313296.54
C23: APS vejez1 | D23: 103429 | E23: 25543.78 | F23: 25543.78 | G23: 57557 | H23: 14498.056 | I23: 14498.056 | J23: 160986 | K23: 40041.836 | L23: 40041.836
C24: PBS invalidez | D24: 111277 | E24: 23832.989 | F24: 23832.989 | G24: 87585 | H24: 18759.924 | I24: 18759.924 | J24: 198862 | K24: 42592.913 | L24: 42592.913
C25: APS invalidez | D25: 48029 | E25: 8709.9113 | F25: 8709.9113 | G25: 51658 | H25: 8871.5786 | I25: 8871.5786 | J25: 99687 | K25: 17581.49 | L25: 17581.49
C26: Total beneficios3 | D26: 1475723 | E26: 314637.34 | F26: 314637.34 | G26: 1066118 | H26: 224288.91 | I26: 224288.91 | J26: 2541841 | K26: 538926.25 | L26: 538926.25
B27: Fuente: Elaboración propia con datos de la Superintendencia de Pensiones
B28: 1 La Pensión Garantizada Universal (PGU) es un nuevo beneficio generado a partir de la ley 21.419 del 29-01-2022. El concepto de PGU No Contributiva o Contributiva está relacionado con la calidad de la persona que está recibiendo el beneficio, si es No Contributiva quiere decir que no estaba afiliado a un sistema previsional (D.L. 3.500 o antiguo Sistema de Reparto) ni recibe pensión de sobrevivencia, si es Contributiva quiere decir que sí estaba afiliado a un sistema previsional o que recibe una pensión de sobrevivencia. De manera automática, en febrero 2022, los PBS de Vejez pasaron a ser PGU No Contributiva y los APS Vejez Subsidio Definido, los Beneficio artículo 9° bis y los APS Vejez con una Pensión Final Garantizada inferior o igual al monto de la PGU pasaron a ser PGU Contributiva. En los casos en que el APS Vejez con una Pensión Final Garantizada tuviera un monto superior a la PGU, se mantuvo el pago del beneficio.
B29: 2 El beneficio Complemento por trabajo pesado se informa dentro de la categoría de beneficios pagados por PGU contributiva.
B30: 3 A la fecha de publicación de este informe no se cuenta con información de las pensiones asistenciales (ex PASIS) que continúan vigentes, pagadas a septiembre 2024. 4 Montos nominales de cada periodo de pago. 5 Montos deflactados a septiembre 2024.
B32: Serie resumen de pagos de beneficios acumulados, por tipo de beneficio
B33: (julio 2008 a septiembre 2024)
C35: PGU1 | H35: PBS vejez1 | M35: APS vejez1 | R35: PBS invalidez | W35: APS invalidez | AB35: Nbis1 | AG35: Total beneficios3
C36: N° Beneficios | E36: Monto real (MM$)4 | G36: Monto nominal (MM$)5 | H36: N° Beneficios | J36: Monto real (MM$)4 | L36: Monto nominal (MM$)5 | M36: N° Beneficios | O36: Monto real (MM$)4 | Q36: Monto nominal (MM$)5 | R36: N° Beneficios | T36: Monto real (MM$)4 | V36: Monto nominal (MM$)5 | W36: N° Beneficios | Y36: Monto real (MM$)4 | AA36: Monto nominal (MM$)5 | AB36: N° Beneficios | AD36: Monto real (MM$)4 | AF36: Monto nominal (MM$)5 | AG36: N° Beneficios | AI36: Monto real (MM$)4 | AK36: Monto nominal (MM$)5
B37: Periodo | C37: N° | D37: %6 | E37: N° | F37: %6 | G37: N° | H37: N° | I37: %6 | J37: N° | K37: %6 | L37: N° | M37: N° | N37: %6 | O37: N° | P37: %6 | Q37: N° | R37: N° | S37: %6 | T37: N° | U37: %6 | V37: N° | W37: N° | X37: %6 | Y37: N° | Z37: %6 | AA37: N° | AB37: N° | AC37: %6 | AD37: N° | AE37: %6 | AF37: N° | AG37: N° | AH37: %6 | AI37: N° | AJ37: %6 | AK37: N°
B38: 39630 | H38: 290570 | I38: 0.60124441 | J38: 31113.122 | K38: 0.60124441 | L38: 17434.2 | R38: 192711 | S38: 0.39875559 | T38: 20634.755 | U38: 0.39875559 | V38: 11562.66 | AG38: 483281 | AH38: 1 | AI38: 51747.878 | AJ38: 1 | AK38: 28996.86
B39: 39661 | H39: 292137 | I39: 0.60055999 | J39: 30991.966 | K39: 0.60055999 | L39: 17528.22 | R39: 194304 | S39: 0.39944001 | T39: 20613.147 | U39: 0.39944001 | V39: 11658.24 | AG39: 486441 | AH39: 1 | AI39: 51605.113 | AJ39: 1 | AK39: 29186.46
B40: 39692 | H40: 329546 | I40: 0.63002998 | J40: 34585.411 | K40: 0.62997894 | L40: 19768.431 | R40: 193518 | S40: 0.36997002 | T40: 20313.902 | U40: 0.37002106 | V40: 11611.08 | AG40: 523064 | AH40: 1 | AI40: 54899.314 | AJ40: 1 | AK40: 31379.511
B41: 39722 | H41: 340883 | I41: 0.63388369 | J41: 38399.534 | K41: 0.64317182 | L41: 22142.51 | M41: 3399 | N41: 0.0063205577 | O41: 1001.0654 | P41: 0.016767314 | Q41: 577.24922 | R41: 193041 | S41: 0.3589664 | T41: 20179.221 | U41: 0.33799124 | V41: 11636.042 | W41: 446 | X41: 0.00082935238 | Y41: 123.5639 | Z41: 0.0020696299 | AA41: 71.251256 | AG41: 537769 | AH41: 1 | AI41: 59703.384 | AJ41: 1 | AK41: 34427.053
B42: 39753 | H42: 347314 | I42: 0.63749096 | J42: 38275.903 | K42: 0.64785948 | L42: 22044.175 | M42: 4226 | N42: 0.0077567757 | O42: 483.77908 | P42: 0.0081884642 | Q42: 278.62206 | R42: 192690 | S42: 0.35368034 | T42: 20251.155 | U42: 0.34277187 | V42: 11663.213 | W42: 584 | X42: 0.0010719255 | Y42: 69.725805 | Z42: 0.0011801818 | AA42: 40.157064 | AG42: 544814 | AH42: 1 | AI42: 59080.563 | AJ42: 1 | AK42: 34026.168
B43: 39783 | H43: 358445 | I43: 0.64228132 | J43: 41232.988 | K43: 0.64842422 | L43: 23467.261 | M43: 4485 | N43: 0.0080364678 | O43: 538.10101 | P43: 0.0084621016 | Q43: 306.25375 | R43: 194451 | S43: 0.34842792 | T43: 21745.753 | U43: 0.34197068 | V43: 12376.335 | W43: 700 | X43: 0.0012542982 | Y43: 72.683009 | Z43: 0.0011430029 | AA43: 41.366664 | AG43: 558081 | AH43: 1 | AI43: 63589.524 | AJ43: 1 | AK43: 36191.216
B44: 39814 | H44: 364131 | I44: 0.64167332 | J44: 40243.81 | K44: 0.63183868 | L44: 22729.604 | M44: 6199 | N44: 0.010923906 | O44: 1029.4652 | P44: 0.016162881 | Q44: 581.43938 | R44: 196192 | S44: 0.34573044 | T44: 22275.196 | U44: 0.34972659 | V44: 12580.975 | W44: 949 | X44: 0.0016723322 | Y44: 144.70068 | Z44: 0.0022718397 | AA44: 81.726581 | AG44: 567471 | AH44: 1 | AI44: 63693.172 | AJ44: 1 | AK44: 35973.745
B45: 39845 | H45: 366991 | I45: 0.64091253 | J45: 40661.709 | K45: 0.63378798 | L45: 22667.397 | M45: 7180 | N45: 0.012539141 | O45: 814.58801 | P45: 0.012696861 | Q45: 454.10265 | R45: 197256 | S45: 0.34448758 | T45: 22517.278 | U45: 0.35097345 | V45: 12552.549 | W45: 1180 | X45: 0.0020607502 | Y45: 163.06713 | Z45: 0.0025417029 | AA45: 90.903886 | AG45: 572607 | AH45: 1 | AI45: 64156.643 | AJ45: 1 | AK45: 35764.953
...

Sheet 1.2
B2: TOTAL DE BENEFICIOS PAGADOS DEL PILAR NO CONTRIBUTIVO A NIVEL REGIONAL
B4: Resumen trimestral de beneficios pagados, por región, tipo de beneficio y sexo
B5: (julio 2024 a septiembre 2024)
B7: Región | C7: Tipo de beneficio | D7: 45474 | M7: 45505 | V7: 45536 | AE7: Total tercer trimestre 2024
D8: Mujeres | G8: Hombres | J8: Total | M8: Mujeres | P8: Hombres | S8: Total | V8: Mujeres | Y8: Hombres | AB8: Total | AE8: Mujeres | AH8: Hombres | AK8: Total
D9: N° beneficiarios | E9: Monto total (M$)4 | F9: Monto promedio por beneficiario ($)5 | G9: N° beneficiarios | H9: Monto total (M$)4 | I9: Monto promedio por beneficiario ($)5 | J9: N° beneficiarios | K9: Monto total (M$)4 | L9: Monto promedio por beneficiario ($)5 | M9: N° beneficiarios | N9: Monto total (M$)4 | O9: Monto promedio por beneficiario ($)5 | P9: N° beneficiarios | Q9: Monto total (M$)4 | R9: Monto promedio por beneficiario ($)5 | S9: N° beneficiarios | T9: Monto total (M$)4 | U9: Monto promedio por beneficiario ($)5 | V9: N° beneficiarios | W9: Monto total (M$)4 | X9: Monto promedio por beneficiario ($)5 | Y9: N° beneficiarios | Z9: Monto total (M$)4 | AA9: Monto promedio por beneficiario ($)5 | AB9: N° beneficiarios | AC9: Monto total (M$)4 | AD9: Monto promedio por beneficiario ($)5 | AE9: N° promedio beneficiarios6 | AF9: Monto total (M$)7 | AG9: Monto promedio por beneficiario ($)8 | AH9: N° promedio beneficiarios6 | AI9: Monto total (M$)7 | AJ9: Monto promedio por beneficiario ($)8 | AK9: N° promedio beneficiarios6 | AL9: Monto total (M$)7 | AM9: Monto promedio por beneficiario ($)8
B10: Región de Arica y Parinacota | C10: PGU no contributiva1 | D10: 3409 | E10: 728.7047 | F10: 213759.08 | G10: 1406 | H10: 301.92399 | I10: 214739.68 | J10: 4815 | K10: 1030.6287 | L10: 214045.42 | M10: 3422 | N10: 729.2411 | O10: 213103.77 | P10: 1404 | Q10: 300.77976 | R10: 214230.6 | S10: 4826 | T10: 1030.0209 | U10: 213431.59 | V10: 4084 | W10: 869.34283 | X10: 212865.53 | Y10: 1714 | Z10: 366.94777 | AA10: 214088.54 | AB10: 5798 | AC10: 1236.2906 | AD10: 213227.08 | AE10: 3638.3333 | AF10: 2327.2886 | AG10: 213242.79 | AH10: 1508 | AI10: 969.65152 | AJ10: 214352.94 | AK10: 5146.3333 | AL10: 3296.9402 | AM10: 213568.03
C11: PGU contributiva1 2 | D11: 10602 | E11: 2247.359 | F11: 211975.01 | G11: 8956 | H11: 1879.9949 | I11: 209914.58 | J11: 19558 | K11: 4127.354 | L11: 211031.49 | M11: 10645 | N11: 2250.2084 | O11: 211386.42 | P11: 8966 | Q11: 1877.3373 | R11: 209384.04 | S11: 19611 | T11: 4127.5457 | U11: 210470.95 | V11: 10036 | W11: 2119.0549 | X11: 211145.37 | Y11: 8706 | Z11: 1820.3558 | AA11: 209092.1 | AB11: 18742 | AC11: 3939.4107 | AD11: 210191.59 | AE11: 10427.667 | AF11: 6616.6223 | AG11: 211502.26 | AH11: 8876 | AI11: 5577.6881 | AJ11: 209463.57 | AK11: 19303.667 | AL11: 12194.31 | AM11: 210564.68
C12: APS vejez1 | D12: 1298 | E12: 321.45977 | F12: 247657.76 | G12: 711 | H12: 178.51447 | I12: 251075.21 | J12: 2009 | K12: 499.97424 | L12: 248867.22 | M12: 1289 | N12: 318.97507 | O12: 247459.33 | P12: 710 | Q12: 177.84317 | R12: 250483.34 | S12: 1999 | T12: 496.81825 | U12: 248533.39 | V12: 1284 | W12: 317.41898 | X12: 247211.05 | Y12: 703 | Z12: 175.89847 | AA12: 250211.19 | AB12: 1987 | AC12: 493.31745 | AD12: 248272.5 | AE12: 1290.3333 | AF12: 957.85383 | AG12: 247442.71 | AH12: 708 | AI12: 532.25612 | AJ12: 250589.92 | AK12: 1998.3333 | AL12: 1490.1099 | AM12: 248557.7
C13: PBS invalidez | D13: 1181 | E13: 253.84969 | F13: 214944.7 | G13: 1232 | H13: 264.622 | I13: 214790.58 | J13: 2413 | K13: 518.47169 | L13: 214866.01 | M13: 1197 | N13: 256.63451 | O13: 214398.09 | P13: 1232 | Q13: 263.94762 | R13: 214243.2 | S13: 2429 | T13: 520.58213 | U13: 214319.53 | V13: 1211 | W13: 259.40961 | X13: 214211.07 | Y13: 1263 | Z13: 270.35934 | AA13: 214061.23 | AB13: 2474 | AC13: 529.76894 | AD13: 214134.58 | AE13: 1196.3333 | AF13: 769.89381 | AG13: 214517.95 | AH13: 1242.3333 | AI13: 798.92896 | AJ13: 214365 | AK13: 2438.6667 | AL13: 1568.8228 | AM13: 214440.04
C14: APS invalidez | D14: 463 | E14: 81.199823 | F14: 175377.59 | G14: 597 | H14: 99.221098 | I14: 166199.49 | J14: 1060 | K14: 180.42092 | L14: 170208.42 | M14: 465 | N14: 81.027387 | O14: 174252.45 | P14: 595 | Q14: 98.52617 | R14: 165590.2 | S14: 1060 | T14: 179.55356 | U14: 169390.15 | V14: 466 | W14: 80.848986 | X14: 173495.68 | Y14: 593 | Z14: 97.771546 | AA14: 164876.13 | AB14: 1059 | AC14: 178.62053 | AD14: 168669.06 | AE14: 464.66667 | AF14: 243.0762 | AG14: 174375.24 | AH14: 595 | AI14: 295.51881 | AJ14: 165555.28 | AK14: 1059.6667 | AL14: 538.59501 | AM14: 169422.54
C15: Total beneficios3 | D15: 16953 | E15: 3632.573 | F15: 214273.17 | G15: 12902 | H15: 2724.2765 | I15: 211151.49 | J15: 29855 | K15: 6356.8495 | L15: 212924.12 | M15: 17018 | N15: 3636.0865 | O15: 213661.21 | P15: 12907 | Q15: 2718.434 | R15: 210617.03 | S15: 29925 | T15: 6354.5205 | U15: 212348.22 | V15: 17081 | W15: 3646.0753 | X15: 213457.95 | Y15: 12979 | Z15: 2731.333 | AA15: 210442.48 | AB15: 30060 | AC15: 6377.4083 | AD15: 212155.96 | AE15: 17017.333 | AF15: 10914.735 | AG15: 213797.44 | AH15: 12929.333 | AI15: 8174.0435 | AJ15: 210737 | AK15: 29946.667 | AL15: 19088.778 | AM15: 212476.1
B16: Región de Tarapacá | C16: PGU no contributiva1 | D16: 3801 | E16: 815.954 | F16: 214668.24 | G16: 1561 | H16: 335.21346 | I16: 214742.77 | J16: 5362 | K16: 1151.1675 | L16: 214689.94 | M16: 3824 | N16: 818.38042 | O16: 214011.62 | P16: 1569 | Q16: 336.0383 | R16: 214173.55 | S16: 5393 | T16: 1154.4187 | U16: 214058.73 | V16: 4543 | W16: 970.27501 | X16: 213575.83 | Y16: 1925 | Z16: 411.90042 | AA16: 213974.25 | AB16: 6468 | AC16: 1382.1754 | AD16: 213694.41 | AE16: 4056 | AF16: 2604.6094 | AG16: 214085.23 | AH16: 1685 | AI16: 1083.1522 | AJ16: 214296.85 | AK16: 5741 | AL16: 3687.7616 | AM16: 214147.69
B17: Región de Tarapacá | C17: PGU contributiva1 2 | D17: 11489 | E17: 2433.9672 | F17: 211851.97 | G17: 10670 | H17: 2224.2506 | I17: 208458.35 | J17: 22159 | K17: 4658.2179 | L17: 210217.87 | M17: 11534 | N17: 2437.051 | O17: 211292.78 | P17: 10693 | Q17: 2222.9134 | R17: 207884.92 | S17: 22227 | T17: 4659.9644 | U17: 209653.32 | V17: 10889 | W17: 2296.3384 | X17: 210886.07 | Y17: 10380 | Z17: 2153.9375 | AA17: 207508.43 | AB17: 21269 | AC17: 4450.2759 | AD17: 209237.67 | AE17: 11304 | AF17: 7167.3566 | AG17: 211343.6 | AH17: 10581 | AI17: 6601.1016 | AJ17: 207950.57 | AK17: 21885 | AL17: 13768.458 | AM17: 209702.95
B18: Región de Tarapacá | C18: APS vejez1 | D18: 1601 | E18: 398.29738 | F18: 248780.38 | G18: 846 | H18: 213.78211 | I18: 252697.53 | J18: 2447 | K18: 612.0795 | L18: 250134.65 | M18: 1597 | N18: 396.58979 | O18: 248334.24 | P18: 840 | Q18: 212.19828 | R18: 252617.01 | S18: 2437 | T18: 608.78807 | U18: 249810.45 | V18: 1584 | W18: 393.14336 | X18: 248196.57 | Y18: 838 | Z18: 211.65304 | AA18: 252569.26 | AB18: 2422 | AC18: 604.7964 | AD18: 249709.5 | AE18: 1594 | AF18: 1188.0305 | AG18: 248437.06 | AH18: 841.33333 | AI18: 637.63344 | AJ18: 252627.93 | AK18: 2435.3333 | AL18: 1825.664 | AM18: 249884.87
B19: Región de Tarapacá | C19: PBS invalidez | D19: 1414 | E19: 304.05537 | F19: 215032.09 | G19: 1188 | H19: 255.30935 | I19: 214906.86 | J19: 2602 | K19: 559.36472 | L19: 214974.91 | M19: 1422 | N19: 304.99637 | O19: 214484.08 | P19: 1196 | Q19: 256.37458 | R19: 214360.02 | S19: 2618 | T19: 561.37095 | U19: 214427.41 | V19: 1431 | W19: 306.65758 | X19: 214296 | Y19: 1212 | Z19: 259.5785 | AA19: 214173.68 | AB19: 2643 | AC19: 566.23607 | AD19: 214239.91 | AE19: 1422.3333 | AF19: 915.70931 | AG19: 214604.06 | AH19: 1198.6667 | AI19: 771.26243 | AJ19: 214480.19 | AK19: 2621 | AL19: 1686.9717 | AM19: 214547.41
B20: Región de Tarapacá | C20: APS invalidez | D20: 657 | E20: 117.76128 | F20: 179240.92 | G20: 768 | H20: 129.72177 | I20: 168908.55 | J20: 1425 | K20: 247.48305 | L20: 173672.32 | M20: 657 | N20: 117.25743 | O20: 178474.02 | P20: 773 | Q20: 130.05133 | R20: 168242.34 | S20: 1430 | T20: 247.30876 | U20: 172943.19 | V20: 654 | W20: 116.2291 | X20: 177720.34 | Y20: 770 | Z20: 129.4496 | AA20: 168116.37 | AB20: 1424 | AC20: 245.67871 | AD20: 172527.18 | AE20: 656 | AF20: 351.24781 | AG20: 178478.42 | AH20: 770.33333 | AI20: 389.22271 | AJ20: 168422.42 | AK20: 1426.3333 | AL20: 740.47052 | AM20: 173047.56
B21: Región de Tarapacá | C21: Total beneficios3 | D21: 18962 | E21: 4070.0353 | F21: 214641.67 | G21: 15033 | H21: 3158.2773 | I21: 210089.62 | J21: 33995 | K21: 7228.3126 | L21: 212628.7 | M21: 19034 | N21: 4074.275 | O21: 214052.48 | P21: 15071 | Q21: 3157.5759 | R21: 209513.36 | S21: 34105 | T21: 7231.8509 | U21: 212046.65 | V21: 19101 | W21: 4082.6434 | X21: 213739.77 | Y21: 15125 | Z21: 3166.5191 | AA21: 209356.63 | AB21: 34226 | AC21: 7249.1625 | AD21: 211802.8 | AE21: 19032.333 | AF21: 12226.954 | AG21: 214144.64 | AH21: 15076.333 | AI21: 9482.3723 | AJ21: 209653.21 | AK21: 34108.667 | AL21: 21709.326 | AM21: 212159.38
B22: Región de Antofagasta | C22: PGU no contributiva1 | D22: 7235 | E22: 1551.4788 | F22: 214440.75 | G22: 2069 | H22: 442.66476 | I22: 213951.07 | J22: 9304 | K22: 1994.1436 | L22: 214331.86 | M22: 7276 | N22: 1555.8936 | O22: 213839.14 | P22: 2078 | Q22: 443.5775 | R22: 213463.67 | S22: 9354 | T22: 1999.4711 | U22: 213755.73 | V22: 8898 | W22: 1900.8196 | X22: 213623.24 | Y22: 2527 | Z22: 539.51336 | AA22: 213499.55 | AB22: 11425 | AC22: 2440.333 | AD22: 213595.88 | AE22: 7803 | AF22: 5008.192 | AG22: 213967.71 | AH22: 2224.6667 | AI22: 1425.7556 | AJ22: 213638.1 | AK22: 10027.667 | AL22: 6433.9477 | AM22: 213894.49
B23: Región de Antofagasta | C23: PGU contributiva1 2 | D23: 21210 | E23: 4477.1497 | F23: 211086.74 | G23: 18049 | H23: 3647.0933 | I23: 202066.23 | J23: 39259 | K23: 8124.243 | L23: 206939.63 | M23: 21283 | N23: 4479.9732 | O23: 210495.38 | P23: 18139 | Q23: 3651.4882 | R23: 201305.93 | S23: 39422 | T23: 8131.4615 | U23: 206267.1 | V23: 19772 | W23: 4151.3867 | X23: 209962.91 | Y23: 17803 | Z23: 3572.8043 | AA23: 200685.52 | AB23: 37575 | AC23: 7724.191 | AD23: 205567.29 | AE23: 20755 | AF23: 13108.51 | AG23: 210515.01 | AH23: 17997 | AI23: 10871.386 | AJ23: 201352.56 | AK23: 38752 | AL23: 23979.895 | AM23: 206258.01
B24: Región de Antofagasta | C24: APS vejez1 | D24: 2472 | E24: 610.13704 | F24: 246819.19 | G24: 1043 | H24: 266.60668 | I24: 255615.22 | J24: 3515 | K24: 876.74372 | L24: 249429.22 | M24: 2466 | N24: 607.53905 | O24: 246366.2 | P24: 1038 | Q24: 265.29609 | R24: 255583.9 | S24: 3504 | T24: 872.83513 | U24: 249096.78 | V24: 2459 | W24: 605.27975 | X24: 246148.74 | Y24: 1023 | Z24: 261.68164 | AA24: 255798.28 | AB24: 3482 | AC24: 866.96139 | AD24: 248983.74 | AE24: 2465.6667 | AF24: 1822.9558 | AG24: 246444.71 | AH24: 1034.6667 | AI24: 793.58441 | AJ24: 255665.8 | AK24: 3500.3333 | AL24: 2616.5402 | AM24: 249169.92
B25: Región de Antofagasta | C25: PBS invalidez | D25: 2226 | E25: 478.33915 | F25: 214887.31 | G25: 1633 | H25: 350.91394 | I25: 214889.12 | J25: 3859 | K25: 829.25309 | L25: 214888.08 | M25: 2228 | N25: 477.54909 | O25: 214339.81 | P25: 1649 | Q25: 353.45139 | R25: 214342.87 | S25: 3877 | T25: 831.00048 | U25: 214341.11 | V25: 2243 | W25: 480.34476 | X25: 214152.81 | Y25: 1655 | Z25: 354.42722 | AA25: 214155.42 | AB25: 3898 | AC25: 834.77198 | AD25: 214153.92 | AE25: 2232.3333 | AF25: 1436.233 | AG25: 214459.98 | AH25: 1645.6667 | AI25: 1058.7925 | AJ25: 214462.47 | AK25: 3878 | AL25: 2495.0255 | AM25: 214461.03
B26: Región de Antofagasta | C26: APS invalidez | D26: 855 | E26: 150.46042 | F26: 175977.1 | G26: 900 | H26: 151.26097 | I26: 168067.75 | J26: 1755 | K26: 301.7214 | L26: 171921.02 | M26: 857 | N26: 150.73663 | O26: 175888.72 | P26: 905 | Q26: 151.39722 | R26: 167289.75 | S26: 1762 | T26: 302.13386 | U26: 171472.11 | V26: 861 | W26: 150.93032 | X26: 175296.54 | Y26: 904 | Z26: 150.98436 | AA26: 167018.1 | AB26: 1765 | AC26: 301.91468 | AD26: 171056.48 | AE26: 857.66667 | AF26: 452.12738 | AG26: 175720.79 | AH26: 903 | AI26: 453.64256 | AJ26: 167458.53 | AK26: 1760.6667 | AL26: 905.76993 | AM26: 171483.2
B27: Región de Antofagasta | C27: Total beneficios3 | D27: 33998 | E27: 7267.5651 | F27: 213764.49 | G27: 23694 | H27: 4858.5397 | I27: 205053.59 | J27: 57692 | K27: 12126.105 | L27: 210186.94 | M27: 34110 | N27: 7271.6916 | O27: 213183.57 | P27: 23809 | Q27: 4865.2104 | R27: 204343.33 | S27: 57919 | T27: 12136.902 | U27: 209549.58 | V27: 34233 | W27: 7288.7611 | X27: 212916.23 | Y27: 23912 | Z27: 4879.4109 | AA27: 204056.99 | AB27: 58145 | AC27: 12168.172 | AD27: 209272.89 | AE27: 34113.667 | AF27: 21828.018 | AG27: 213288.1 | AH27: 23805 | AI27: 14603.161 | AJ27: 204484.64 | AK27: 57918.667 | AL27: 36431.179 | AM27: 209669.8
... B105: Región de Magallanes y la Antártica Chilena | C105: Total beneficios3 | D105: 12768 | E105: 2719.3069 | F105: 212978.3 | G105: 9139 | H105: 1929.2496 | I105: 211100.73 | J105: 21907 | K105: 4648.5565 | L105: 212195.03 | M105: 12836 | N105: 2726.147 | O105: 212382.9 | P105: 9183 | Q105: 1933.0287 | R105: 210500.78 | S105: 22019 | T105: 4659.1757 | U105: 211597.97 | V105: 12887 | W105: 2732.69 | X105: 212050.13 | Y105: 9182 | Z105: 1930.5028 | AA105: 210248.62 | AB105: 22069 | AC105: 4663.1929 | AD105: 211300.6 | AE105: 12830.333 | AF105: 8178.1439 | AG105: 212470.44 | AH105: 9168 | AI105: 5792.7811 | AJ105: 210616.71 | AK105: 21998.333 | AL105: 13970.925 | AM105: 211697.86
B106: Sin información | C106: PGU no contributiva1 | D106: 0 | E106: 0 | G106: 0 | H106: 0 | J106: 0 | K106: 0 | M106: 0 | N106: 0 | P106: 0 | Q106: 0 | S106: 0 | T106: 0 | V106: 0 | W106: 0 | Y106: 0 | Z106: 0 | AB106: 0 | AC106: 0 | AE106: 0 | AF106: 0 | AH106: 0 | AI106: 0 | AK106: 0 | AL106: 0
C107: PGU contributiva1 2 | D107: 0 | E107: 0 | G107: 0 | H107: 0 | J107: 0 | K107: 0 | M107: 0 | N107: 0 | P107: 0 | Q107: 0 | S107: 0 | T107: 0 | V107: 0 | W107: 0 | Y107: 0 | Z107: 0 | AB107: 0 | AC107: 0 | AE107: 0 | AF107: 0 | AH107: 0 | AI107: 0 | AK107: 0 | AL107: 0
C108: APS vejez1 | D108: 0 | E108: 0 | G108: 0 | H108: 0 | J108: 0 | K108: 0 | M108: 0 | N108: 0 | P108: 0 | Q108: 0 | S108: 0 | T108: 0 | V108: 0 | W108: 0 | Y108: 0 | Z108: 0 | AB108: 0 | AC108: 0 | AE108: 0 | AF108: 0 | AH108: 0 | AI108: 0 | AK108: 0 | AL108: 0
C109: PBS invalidez | D109: 0 | E109: 0 | G109: 0 | H109: 0 | J109: 0 | K109: 0 | M109: 0 | N109: 0 | P109: 0 | Q109: 0 | S109: 0 | T109: 0 | V109: 0 | W109: 0 | Y109: 0 | Z109: 0 | AB109: 0 | AC109: 0 | AE109: 0 | AF109: 0 | AH109: 0 | AI109: 0 | AK109: 0 | AL109: 0
C110: APS invalidez | D110: 0 | E110: 0 | G110: 0 | H110: 0 | J110: 0 | K110: 0 | M110: 0 | N110: 0 | P110: 0 | Q110: 0 | S110: 0 | T110: 0 | V110: 0 | W110: 0 | Y110: 0 | Z110: 0 | AB110: 0 | AC110: 0 | AE110: 0 | AF110: 0 | AH110: 0 | AI110: 0 | AK110: 0 | AL110: 0
C111: Total beneficios3 | D111: 0 | E111: 0 | G111: 0 | H111: 0 | J111: 0 | K111: 0 | M111: 0 | N111: 0 | P111: 0 | Q111: 0 | S111: 0 | T111: 0 | V111: 0 | W111: 0 | Y111: 0 | Z111: 0 | AB111: 0 | AC111: 0 | AE111: 0 | AF111: 0 | AH111: 0 | AI111: 0 | AK111: 0 | AL111: 0
B112: Total nacional | C112: PGU no contributiva1 | D112: 348046 | E112: 74440.178 | F112: 213880.29 | G112: 133888 | H112: 28739.72 | I112: 214654.93 | J112: 481934 | K112: 103179.9 | L112: 214095.49 | M112: 349176 | N112: 74472.45 | O112: 213280.55 | P112: 134137 | Q112: 28719.814 | R112: 214108.07 | S112: 483313 | T112: 103192.26 | U112: 213510.22 | V112: 420895 | W112: 89641.814 | X112: 212979.04 | Y112: 167174 | Z112: 35771.66 | AA112: 213978.61 | AB112: 588069 | AC112: 125413.47 | AD112: 213263.19 | AE112: 372705.67 | AF112: 238554.44 | AG112: 213379.96 | AH112: 145066.33 | AI112: 93231.193 | AJ112: 214247.2 | AK112: 517772 | AL112: 331785.63 | AM112: 213622.97
B113: Total Nacional | C113: PGU contributiva1 2 | D113: 856180 | E113: 181253.69 | F113: 211700.44 | G113: 728418 | H113: 152603.9 | I113: 209500.45 | J113: 1584598 | K113: 333857.58 | L113: 210689.13 | M113: 859346 | N113: 181433.28 | O113: 211129.48 | P113: 731265 | Q113: 152792.59 | R113: 208942.85 | S113: 1590611 | T113: 334225.87 | U113: 210124.2 | V113: 792093 | W113: 166908.85 | X113: 210718.75 | Y113: 702144 | Z113: 146387.69 | AA113: 208486.71 | AB113: 1494237 | AC113: 313296.54 | AD113: 209669.91 | AE113: 835873 | AF113: 529595.81 | AG113: 211182.89 | AH113: 720609 | AI113: 451784.18 | AJ113: 208976.67 | AK113: 1556482 | AL113: 981379.99 | AM113: 210161.08
B114: Total Nacional | C114: APS vejez1 | D114: 104051 | E114: 25762.518 | F114: 247595.1 | G114: 58337 | H114: 14716.05 | I114: 252259.28 | J114: 162388 | K114: 40478.568 | L114: 249270.68 | M114: 103719 | N114: 25633.651 | O114: 247145.18 | P114: 57968 | Q114: 14604.208 | R114: 251935.69 | S114: 161687 | T114: 40237.859 | U114: 248862.67 | V114: 103429 | W114: 25543.78 | X114: 246969.23 | Y114: 57557 | Z114: 14498.056 | AA114: 251890.4 | AB114: 160986 | AC114: 40041.836 | AD114: 248728.68 | AE114: 103733 | AF114: 76939.949 | AG114: 247236.5 | AH114: 57954 | AI114: 43818.313 | AJ114: 252028.46 | AK114: 161687 | AL114: 120758.26 | AM114: 248954.01
B115: Total Nacional | C115: PBS invalidez | D115: 110743 | E115: 23799.579 | F115: 214908.21 | G115: 87013 | H115: 18701.276 | I115: 214925.08 | J115: 197756 | K115: 42500.856 | L115: 214915.63 | M115: 111054 | N115: 23805.78 | O115: 214362.2 | P115: 87337 | Q115: 18723.118 | R115: 214377.84 | S115: 198391 | T115: 42528.898 | U115: 214369.09 | V115: 111277 | W115: 23832.989 | X115: 214177.13 | Y115: 87585 | Z115: 18759.924 | AA115: 214191.06 | AB115: 198862 | AC115: 42592.913 | AD115: 214183.27 | AE115: 111024.67 | AF115: 71438.348 | AG115: 214482.51 | AH115: 87311.667 | AI115: 56184.318 | AJ115: 214498 | AK115: 198336.33 | AL115: 127622.67 | AM115: 214489.33
B116: Total Nacional | C116: APS invalidez | D116: 47933 | E116: 8741.1982 | F116: 182362.84 | G116: 51499 | H116: 8887.2541 | I116: 172571.39 | J116: 99432 | K116: 17628.452 | L116: 177291.54 | M116: 48030 | N116: 8730.3583 | O116: 181768.86 | P116: 51610 | Q116: 8879.4421 | R116: 172048.87 | S116: 99640 | T116: 17609.8 | U116: 176734.25 | V116: 48029 | W116: 8709.9113 | X116: 181346.92 | Y116: 51658 | Z116: 8871.5786 | AA116: 171736.78 | AB116: 99687 | AC116: 17581.49 | AD116: 176366.93 | AE116: 47997.333 | AF116: 26181.468 | AG116: 181826.21 | AH116: 51589 | AI116: 26638.275 | AJ116: 172119.01 | AK116: 99586.333 | AL116: 52819.743 | AM116: 176797.57
B117: Total Nacional | C117: Total beneficios3 | D117: 1466953 | E117: 313997.16 | F117: 214047.18 | G117: 1059155 | H117: 223648.2 | I117: 211157.19 | J117: 2526108 | K117: 537645.35 | L117: 212835.46 | M117: 1471325 | N117: 314075.52 | O117: 213464.41 | P117: 1062317 | Q117: 223719.17 | R117: 210595.49 | S117: 2533642 | T117: 537794.69 | U117: 212261.51 | V117: 1475723 | W117: 314637.34 | X117: 213208.94 | Y117: 1066118 | Z117: 224288.91 | AA117: 210379.07 | AB117: 2541841 | AC117: 538926.25 | AD117: 212022.02 | AE117: 1471333.7 | AF117: 942710.02 | AG117: 213573.51 | AH117: 1062530 | AI117: 671656.28 | AJ117: 210710.58 | AK117: 2533863.7 | AL117: 1614366.3 | AM117: 212373
B118: Fuente: Elaboración propia con datos de la Superintendencia de Pensiones
B119: 1 La Pensión Garantizada Universal (PGU) es un nuevo beneficio generado a partir de la ley 21.419 del 29-01-2022. El concepto de PGU No Contributiva o Contributiva está relacionado con la calidad de la persona que está recibiendo el beneficio, si es No Contributiva quiere decir que no estaba afiliado a un sistema previsional (D.L. 3.500 o antiguo Sistema de Reparto) ni recibe pensión de sobrevivencia, si es Contributiva quiere decir que sí estaba afiliado a un sistema previsional o que recibe una pensión de sobrevivencia. De manera automática, en febrero 2022, los PBS de Vejez pasaron a ser PGU No Contributiva y los APS Vejez Subsidio Definido, los Beneficio artículo 9° bis y los APS Vejez con una Pensión Final Garantizada inferior o igual al monto de la PGU pasaron a ser PGU Contributiva. En los casos en que el APS Vejez con una Pensión Final Garantizada tuviera un monto superior a la PGU, se mantuvo el pago del beneficio.
B120: 2 El beneficio Complemento por trabajo pesado se informa dentro de la categoría de beneficios pagados por PGU contributiva.
...

Sheet 1.3
B2: PAGOS PENSIÓN GARANTIZADA UNIVERSAL (PGU)
B4: Resumen trimestral de beneficios pagados, por tipo de beneficio y sexo
B5: (julio 2024 a septiembre 2024)
D7: PGU No Contributiva1 | G7: PGU Contributiva1 2 | J7: PGU Total1
B8: Periodo | C8: Sexo Beneficiarios | D8: N° beneficiarios | E8: Monto nominal (MM$)3 | F8: Monto real (MM$)4 | G8: N° beneficiarios | H8: Monto nominal (MM$)3 | I8: Monto real (MM$)4 | J8: N° beneficiarios | K8: Monto nominal (MM$)3 | L8: Monto real (MM$)4
B9: 45474 | C9: Mujeres | D9: 348046 | E9: 74185.359 | F9: 74440.178 | G9: 856180 | H9: 180633.23 | I9: 181253.69 | J9: 1204226 | K9: 254818.59 | L9: 255693.86
C10: Hombres | D10: 133888 | E10: 28641.34 | F10: 28739.72 | G10: 728418 | H10: 152081.51 | I10: 152603.9 | J10: 862306 | K10: 180722.85 | L10: 181343.62
C11: Total | D11: 481934 | E11: 102826.7 | F11: 103179.9 | G11: 1584598 | H11: 332714.74 | I11: 333857.58 | J11: 2066532 | K11: 435541.44 | L11: 437037.48
B12: 45505 | C12: Mujeres | D12: 349176 | E12: 74407.143 | F12: 74472.45 | G12: 859346 | H12: 181274.18 | I12: 181433.28 | J12: 1208522 | K12: 255681.32 | L12: 255905.73
C13: Hombres | D13: 134137 | E13: 28694.629 | F13: 28719.814 | G13: 731265 | H13: 152658.6 | I13: 152792.59 | J13: 865402 | K13: 181353.23 | L13: 181512.4
C14: Total | D14: 483313 | E14: 103101.77 | F14: 103192.26 | G14: 1590611 | H14: 333932.78 | I14: 334225.87 | J14: 2073924 | K14: 437034.55 | L14: 437418.13
B15: 45536 | C15: Mujeres | D15: 420895 | E15: 89641.814 | F15: 89641.814 | G15: 792093 | H15: 166908.85 | I15: 166908.85 | J15: 1212988 | K15: 256550.66 | L15: 256550.66
C16: Hombres | D16: 167174 | E16: 35771.66 | F16: 35771.66 | G16: 702144 | H16: 146387.69 | I16: 146387.69 | J16: 869318 | K16: 182159.35 | L16: 182159.35
C17: Total | D17: 588069 | E17: 125413.47 | F17: 125413.47 | G17: 1494237 | H17: 313296.54 | I17: 313296.54 | J17: 2082306 | K17: 438710.01 | L17: 438710.01
B18: Fuente: Elaboración propia con datos de la Superintendencia de Pensiones
B19: 1 La Pensión Garantizada Universal (PGU) es un nuevo beneficio generado a partir de la ley 21.419 del 29-01-2022. El concepto de PGU No Contributiva o Contributiva está relacionado con la calidad de la persona que está recibiendo el beneficio, si es No Contributiva quiere decir que no estaba afiliado a un sistema previsional (D.L. 3.500 o antiguo Sistema de Reparto) ni recibe pensión de sobrevivencia, si es Contributiva quiere decir que sí estaba afiliado a un sistema previsional o que recibe una pensión de sobrevivencia. De manera automática, en febrero 2022, los PBS de Vejez pasaron a ser PGU No Contributiva y los APS Vejez Subsidio Definido, los Beneficio artículo 9° bis y los APS Vejez con una Pensión Final Garantizada inferior o igual al monto de la PGU pasaron a ser PGU Contributiva. En los casos en que el APS Vejez con una Pensión Final Garantizada tuviera un monto superior a la PGU, se mantuvo el pago del beneficio.
B20: 2 El beneficio Complemento por trabajo pesado se informa dentro de la categoría de beneficios pagados por PGU contributiva.
B21: 3 Montos nominales de cada periodo de pago. 4 Montos deflactados a septiembre 2024.
B23: Serie resumen de pagos de beneficios acumulado, por tipo de beneficio y sexo
B24: (febrero 2022 a septiembre 2024)
C26: PGU No Contributiva1 | L26: PGU Contributiva1 2 | U26: PGU Total1
C27: Mujeres | F27: Hombres | I27: Total | L27: Mujeres | O27: Hombres | R27: Total | U27: Mujeres | X27: Hombres | AA27: Total
B28: Periodo | C28: N° Beneficiarios | D28: Monto real (MM$)3 | E28: Monto nominal (MM$)4 | F28: N° Beneficiarios | G28: Monto real (MM$)3 | H28: Monto nominal (MM$)4 | I28: N° Beneficiarios | J28: Monto real (MM$)3 | K28: Monto nominal (MM$)4 | L28: N° Beneficiarios | M28: Monto real (MM$)3 | N28: Monto nominal (MM$)4 | O28: N° Beneficiarios | P28: Monto real (MM$)3 | Q28: Monto nominal (MM$)4 | R28: N° Beneficiarios | S28: Monto real (MM$)3 | T28: Monto nominal (MM$)4 | U28: N° Beneficiarios | V28: Monto real (MM$)3 | W28: Monto nominal (MM$)4 | X28: N° Beneficiarios | Y28: Monto real (MM$)3 | Z28: Monto nominal (MM$)4 | AA28: N° Beneficiarios | AB28: Monto real (MM$)3 | AC28: Monto nominal (MM$)4
B29: 44593 | C29: 309683 | D29: 67989.492 | E29: 57205.361 | F29: 106066 | G29: 23315.509 | H29: 19617.327 | I29: 415749 | J29: 91305.001 | K29: 76822.687 | L29: 517361 | M29: 101116.83 | N29: 85078.214 | O29: 340110 | P29: 69295.395 | Q29: 58304.128 | R29: 857471 | S29: 170412.22 | T29: 143382.34 | U29: 827044 | V29: 169106.32 | W29: 142283.57 | X29: 446176 | Y29: 92610.903 | Z29: 77921.454 | AA29: 1273220 | AB29: 261717.22 | AC29: 220205.03
B30: 44621 | C30: 312946 | D30: 67345.032 | E30: 57713.942 | F30: 107255 | G30: 23147.128 | H30: 19836.831 | I30: 420201 | J30: 90492.16 | K30: 77550.774 | L30: 536699 | M30: 115610.33 | N30: 99076.767 | O30: 361057 | P30: 77854.963 | Q30: 66720.837 | R30: 897756 | S30: 193465.29 | T30: 165797.6 | U30: 849645 | V30: 182955.36 | W30: 156790.71 | X30: 468312 | Y30: 101002.09 | Z30: 86557.668 | AA30: 1317957 | AB30: 283957.45 | AC30: 243348.38
B31: 44652 | C31: 314601 | D31: 66696.211 | E31: 57957.137 | F31: 107763 | G31: 22935.035 | H31: 19929.902 | I31: 422364 | J31: 89631.246 | K31: 77887.039 | L31: 552501 | M31: 117294.16 | N31: 101925.33 | O31: 374925 | P31: 79756.355 | Q31: 69306.036 | R31: 927426 | S31: 197050.51 | T31: 171231.37 | U31: 867102 | V31: 183990.37 | W31: 159882.47 | X31: 482688 | Y31: 102691.39 | Z31: 89235.939 | AA31: 1349790 | AB31: 286681.76 | AC31: 249118.41
B32: 44682 | C32: 316872 | D32: 66325.152 | E32: 58325.654 | F32: 108938 | G32: 22908.346 | H32: 20145.363 | I32: 425810 | J32: 89233.498 | K32: 78471.017 | L32: 605836 | M32: 127041.45 | N32: 111718.94 | O32: 477591 | P32: 100406.01 | Q32: 88296.01 | R32: 1083427 | S32: 227447.47 | T32: 200014.95 | U32: 922708 | V32: 193366.61 | W32: 170044.6 | X32: 586529 | Y32: 123314.36 | Z32: 108441.37 | AA32: 1509237 | AB32: 316680.96 | AC32: 278485.97
B33: 44713 | C33: 317138 | D33: 65744.78 | E33: 58354.483 | F33: 109221 | G33: 22754.87 | H33: 20197.021 | I33: 426359 | J33: 88499.65 | K33: 78551.504 | L33: 615086 | M33: 127736.92 | N33: 113378.15 | O33: 487043 | P33: 101447.1 | Q33: 90043.543 | R33: 1102129 | S33: 229184.01 | T33: 203421.7 | U33: 932224 | V33: 193481.7 | W33: 171732.64 | X33: 596264 | Y33: 124201.97 | Z33: 110240.56 | AA33: 1528488 | AB33: 317683.66 | AC33: 281973.2
B34: 44743 | C34: 317824 | D34: 68125.523 | E34: 61298.892 | F34: 109691 | G34: 23629.36 | H34: 21261.541 | I34: 427515 | J34: 91754.883 | K34: 82560.433 | L34: 621791 | M34: 133530.79 | N34: 120150.12 | O34: 498271 | P34: 107320.34 | Q34: 96566.129 | R34: 1120062 | S34: 240851.14 | T34: 216716.25 | U34: 939615 | V34: 201656.32 | W34: 181449.01 | X34: 607962 | Y34: 130949.7 | Z34: 117827.67 | AA34: 1547577 | AB34: 332606.02 | AC34: 299276.68
B35: 44774 | C35: 322017 | D35: 68183.798 | E35: 62094.245 | F35: 110018 | G35: 23415.344 | H35: 21324.1 | I35: 432035 | J35: 91599.142 | K35: 83418.345 | L35: 660104 | M35: 139634.6 | N35: 127163.71 | O35: 538150 | P35: 113743.81 | Q35: 103585.25 | R35: 1198254 | S35: 253378.41 | T35: 230748.97 | U35: 982121 | V35: 207818.4 | W35: 189257.96 | X35: 648168 | Y35: 137159.15 | Z35: 124909.35 | AA35: 1630289 | AB35: 344977.55 | AC35: 314167.31
B36: 44805 | C36: 321661 | D36: 67511.542 | E36: 62013.553 | F36: 109838 | G36: 23175.713 | H36: 21288.335 | I36: 431499 | J36: 90687.255 | K36: 83301.888 | L36: 679141 | M36: 142280.06 | N36: 130693.09 | O36: 553055 | P36: 115521.98 | Q36: 106114.12 | R36: 1232196 | S36: 257802.04 | T36: 236807.22 | U36: 1000802 | V36: 209791.6 | W36: 192706.64 | X36: 662893 | Y36: 138697.69 | Z36: 127402.46 | AA36: 1663695 | AB36: 348489.29 | AC36: 320109.1
B37: 44835 | C37: 322141 | D37: 67256.74 | E37: 62098.94 | F37: 109963 | G37: 23082.949 | H37: 21312.758 | I37: 432104 | J37: 90339.688 | K37: 83411.698 | L37: 686334 | M37: 142949.07 | N37: 131986.56 | O37: 563950 | P37: 116986.36 | Q37: 108014.88 | R37: 1250284 | S37: 259935.43 | T37: 240001.44 | U37: 1008475 | V37: 210205.81 | W37: 194085.5 | X37: 673913 | Y37: 140069.31 | Z37: 129327.64 | AA37: 1682388 | AB37: 350275.12 | AC37: 323413.14
B38: 44866 | C38: 327443 | D38: 67660.44 | E38: 63080.933 | F38: 121585 | G38: 25275.109 | H38: 23564.397 | I38: 449028 | J38: 92935.549 | K38: 86645.33 | L38: 704099 | M38: 145054.03 | N38: 135236.24 | O38: 584193 | P38: 119634.5 | Q38: 111537.2 | R38: 1288292 | S38: 264688.53 | T38: 246773.44 | U38: 1031542 | V38: 212714.47 | W38: 198317.17 | X38: 705778 | Y38: 144909.61 | Z38: 135101.6 | AA38: 1737320 | AB38: 357624.08 | AC38: 333418.77
B39: 44896 | C39: 329180 | D39: 67828.554 | E39: 63417.032 | F39: 125728 | G39: 26063.344 | H39: 24368.203 | I39: 454908 | J39: 93891.898 | K39: 87785.234 | L39: 717919 | M39: 147210.7 | N39: 137636.22 | O39: 594890 | P39: 121167.59 | Q39: 113286.94 | R39: 1312809 | S39: 268378.29 | T39: 250923.16 | U39: 1047099 | V39: 215039.25 | W39: 201053.25 | X39: 720618 | Y39: 147230.94 | Z39: 137655.14 | AA39: 1767717 | AB39: 362270.19 | AC39: 338708.39
B40: 44927 | C40: 331003 | D40: 67834.311 | E40: 63933.034 | F40: 126303 | G40: 25942.248 | H40: 24450.261 | I40: 457306 | J40: 93776.558 | K40: 88383.295 | L40: 729835 | M40: 148398.24 | N40: 139863.58 | O40: 605454 | P40: 122137.1 | Q40: 115112.77 | R40: 1335289 | S40: 270535.34 | T40: 254976.35 | U40: 1060838 | V40: 216232.55 | W40: 203796.61 | X40: 731757 | Y40: 148079.35 | Z40: 139563.03 | AA40: 1792595 | AB40: 364311.9 | AC40: 343359.65
... B60: 45536 | C60: 420895 | D60: 89641.814 | E60: 89641.814 | F60: 167174 | G60: 35771.66 | H60: 35771.66 | I60: 588069 | J60: 125413.47 | K60: 125413.47 | L60: 792093 | M60: 166908.85 | N60: 166908.85 | O60: 702144 | P60: 146387.69 | Q60: 146387.69 | R60: 1494237 | S60: 313296.54 | T60: 313296.54 | U60: 1212988 | V60: 256550.66 | W60: 256550.66 | X60: 869318 | Y60: 182159.35 | Z60: 182159.35 | AA60: 2082306 | AB60: 438710.01 | AC60: 438710.01
B61: Fuente: Elaboración propia con datos de la Superintendencia de Pensiones
B62: 1 La Pensión Garantizada Universal (PGU) es un nuevo beneficio generado a partir de la ley 21.419 del 29-01-2022. El concepto de PGU No Contributiva o Contributiva está relacionado con la calidad de la persona que está recibiendo el beneficio, si es No Contributiva quiere decir que no estaba afiliado a un sistema previsional (D.L. 3.500 o antiguo Sistema de Reparto) ni recibe pensión de sobrevivencia, si es Contributiva quiere decir que sí estaba afiliado a un sistema previsional o que recibe una pensión de sobrevivencia. De manera automática, en febrero 2022, los PBS de Vejez pasaron a ser PGU No Contributiva y los APS Vejez Subsidio Definido, los Beneficio artículo 9° bis y los APS Vejez con una Pensión Final Garantizada inferior o igual al monto de la PGU pasaron a ser PGU Contributiva. En los casos en que el APS Vejez con una Pensión Final Garantizada tuviera un monto superior a la PGU, se mantuvo el pago del beneficio.
B63: 2 El beneficio Complemento por trabajo pesado se informa dentro de la categoría de beneficios pagados por PGU contributiva.
B64: 3 Montos deflactados a septiembre 2024. 4 Montos nominales de cada periodo de pago.

Sheet 1.4
B2: PAGOS PENSIÓN BÁSICA SOLIDARIA (PBS)
B4: Resumen trimestral de beneficios pagados, por tipo de beneficio y sexo
B5: (julio 2024 a septiembre 2024)
D7: PBS Invalidez1
B8: Periodo | C8: Sexo Beneficiarios | D8: N° beneficiarios | E8: Monto nominal (MM$)2 | F8: Monto real (MM$)3
B9: 45474 | C9: Mujeres | D9: 110743 | E9: 23718.11 | F9: 23799.579
C10: Hombres | D10: 87013 | E10: 18637.259 | F10: 18701.276
C11: Total | D11: 197756 | E11: 42355.369 | F11: 42500.856
B12: 45505 | C12: Mujeres | D12: 111054 | E12: 23784.904 | F12: 23805.78
C13: Hombres | D13: 87337 | E13: 18706.699 | F13: 18723.118
C14: Total | D14: 198391 | E14: 42491.603 | F14: 42528.898
B15: 45536 | C15: Mujeres | D15: 111277 | E15: 23832.989 | F15: 23832.989
C16: Hombres | D16: 87585 | E16: 18759.924 | F16: 18759.924
C17: Total | D17: 198862 | E17: 42592.913 | F17: 42592.913
B18: Fuente: Elaboración propia con datos de la Superintendencia de Pensiones
B19: 1 De manera automática, en febrero 2022, los PBS de Vejez pasaron a ser PGU No Contributiva y los APS Vejez Subsidio Definido, los Beneficio artículo 9° bis y los APS Vejez con una Pensión Final Garantizada inferior o igual al monto de la PGU pasaron a ser PGU Contributiva. En los casos en que el APS Vejez con una Pensión Final Garantizada tuviera un monto superior a la PGU, se mantuvo el pago del beneficio.
B20: 2 Montos nominales de cada periodo de pago. 3 Montos deflactados a septiembre 2024.
B22: Serie resumen de pagos de beneficios acumulado, por tipo de beneficio y sexo
B23: (julio 2008 a septiembre 2024)
C25: PBS Vejez1 | L25: PBS Invalidez | U25: PBS Total
C26: Mujeres | F26: Hombres | I26: Total | L26: Mujeres | O26: Hombres | R26: Total | U26: Mujeres | X26: Hombres | AA26: Total
B27: Periodo | C27: N° Beneficiarios | D27: Monto real (MM$)2 | E27: Monto nominal (MM$)3 | F27: N° Beneficiarios | G27: Monto real (MM$)2 | H27: Monto nominal (MM$)3 | I27: N° Beneficiarios | J27: Monto real (MM$)2 | K27: Monto nominal (MM$)3 | L27: N° Beneficiarios | M27: Monto real (MM$)2 | N27: Monto nominal (MM$)3 | O27: N° Beneficiarios | P27: Monto real (MM$)2 | Q27: Monto nominal (MM$)3 | R27: N° Beneficiarios | S27: Monto real (MM$)2 | T27: Monto nominal (MM$)3 | U27: N° Beneficiarios | V27: Monto real (MM$)2 | W27: Monto nominal (MM$)3 | X27: N° Beneficiarios | Y27: Monto real (MM$)2 | Z27: Monto nominal (MM$)3 | AA27: N° Beneficiarios | AB27: Monto real (MM$)2 | AC27: Monto nominal (MM$)3
